Workbook

Sheet Theo_Doi_Tan_Suat_Be_Tong
A1: STT | B1: HẠNG MỤC CÔNG VIỆC | C1: N/T/N | D1: KL/T.tế (m3) | E1: Tuổi Bt | G1: 30Mpa-18±2 (Cọc nhồi) | J1: 30Mpa-14±2 (Bệ, thân, mố, trụ, dầm) | M1: Khối lượng vật tư lũy kế | P1: Tần suất lấy mẫu thí nghiệm | S1: Số lô | T1: KL (Tấn)
E2: R7 | F2: R28 | G2: Xi măng 0,445 | H2: Cát 0,525 | I2: Đá 0,696 | J2: Xi măng 0,425 | K2: Cát 0,555 | L2: Đá 0,700 | M2: Xi măng (Tấn) | N2: Cát (m3) | O2: Đá (m3) | P2: Xi măng 50 tấn Lần | Q2: Cát 200m3 Lần | R2: Đá 350m3 Lần
A3: I. HẠNG MỤC CỌC KHOAN NHỒI D1.2M (C30 ĐỘ SỤT 18±2CM) - 26 CỌC (L=872M)
A4: 1 | B4: Bê tông cọc khoan nhồi - C1 mố M1 (L=20m) | D4: 24.71 | E4: =IF(C4="","",C4+7) | F4: =IF(C4="","",C4+28) | G4: 0.445 | H4: 0.525 | I4: 0.696 | M4: =IF(D4="","",ROUND(IF(G4>0,D4*G4,D4*J4),2)) | N4: =IF(D4="","",ROUND(IF(H4>0,D4*H4,D4*K4),2)) | O4: =IF(D4="","",ROUND(IF(I4>0,D4*I4,D4*L4),2)) | P4: =IF(M4="","",IF(INT(M4/50)>0,"Lần " & INT(M4/50),"")) | Q4: =IF(N4="","",IF(INT(N4/200)>0,"Lần " & INT(N4/200),"")) | R4: =IF(O4="","",IF(INT(O4/350)>0,"Lần " & INT(O4/350),""))
A5: 2 | B5: Bê tông cọc khoan nhồi - C2 mố M1 (L=20m) | D5: 24.71 | E5: =IF(C5="","",C5+7) | F5: =IF(C5="","",C5+28) | G5: 0.445 | H5: 0.525 | I5: 0.696 | M5: =IF(D5="","",ROUND(M4+IF(G5>0,D5*G5,D5*J5),2)) | N5: =IF(D5="","",ROUND(N4+IF(H5>0,D5*H5,D5*K5),2)) | O5: =IF(D5="","",ROUND(O4+IF(I5>0,D5*I5,D5*L5),2)) | P5: =IF(M5="","",IF(INT(M5/50)>INT(M4/50),"Lần " & INT(M5/50),"")) | Q5: =IF(N5="","",IF(INT(N5/200)>INT(N4/200),"Lần " & INT(N5/200),"")) | R5: =IF(O5="","",IF(INT(O5/350)>INT(O4/350),"Lần " & INT(O5/350),""))
A6: 3 | B6: Bê tông cọc khoan nhồi - C3 mố M1 (L=20m) | D6: 24.71 | E6: =IF(C6="","",C6+7) | F6: =IF(C6="","",C6+28) | G6: 0.445 | H6: 0.525 | I6: 0.696 | M6: =IF(D6="","",ROUND(M5+IF(G6>0,D6*G6,D6*J6),2)) | N6: =IF(D6="","",ROUND(N5+IF(H6>0,D6*H6,D6*K6),2)) | O6: =IF(D6="","",ROUND(O5+IF(I6>0,D6*I6,D6*L6),2)) | P6: =IF(M6="","",IF(INT(M6/50)>INT(M5/50),"Lần " & INT(M6/50),"")) | Q6: =IF(N6="","",IF(INT(N6/200)>INT(N5/200),"Lần " & INT(N6/200),"")) | R6: =IF(O6="","",IF(INT(O6/350)>INT(O5/350),"Lần " & INT(O6/350),""))
A7: 4 | B7: Bê tông cọc khoan nhồi - C1 trụ T1 (L=40m) | D7: 47.01 | E7: =IF(C7="","",C7+7) | F7: =IF(C7="","",C7+28) | G7: 0.445 | H7: 0.525 | I7: 0.696 | M7: =IF(D7="","",ROUND(M6+IF(G7>0,D7*G7,D7*J7),2)) | N7: =IF(D7="","",ROUND(N6+IF(H7>0,D7*H7,D7*K7),2)) | O7: =IF(D7="","",ROUND(O6+IF(I7>0,D7*I7,D7*L7),2)) | P7: =IF(M7="","",IF(INT(M7/50)>INT(M6/50),"Lần " & INT(M7/50),"")) | Q7: =IF(N7="","",IF(INT(N7/200)>INT(N6/200),"Lần " & INT(N7/200),"")) | R7: =IF(O7="","",IF(INT(O7/350)>INT(O6/350),"Lần " & INT(O7/350),""))
A8: 5 | B8: Bê tông cọc khoan nhồi - C2 trụ T1 (L=40m) | D8: 47.01 | E8: =IF(C8="","",C8+7) | F8: =IF(C8="","",C8+28) | G8: 0.445 | H8: 0.525 | I8: 0.696 | M8: =IF(D8="","",ROUND(M7+IF(G8>0,D8*G8,D8*J8),2)) | N8: =IF(D8="","",ROUND(N7+IF(H8>0,D8*H8,D8*K8),2)) | O8: =IF(D8="","",ROUND(O7+IF(I8>0,D8*I8,D8*L8),2)) | P8: =IF(M8="","",IF(INT(M8/50)>INT(M7/50),"Lần " & INT(M8/50),"")) | Q8: =IF(N8="","",IF(INT(N8/200)>INT(N7/200),"Lần " & INT(N8/200),"")) | R8: =IF(O8="","",IF(INT(O8/350)>INT(O7/350),"Lần " & INT(O8/350),""))
A9: 6 | B9: Bê tông cọc khoan nhồi - C3 trụ T1 (L=40m) | D9: 47.01 | E9: =IF(C9="","",C9+7) | F9: =IF(C9="","",C9+28) | G9: 0.445 | H9: 0.525 | I9: 0.696 | M9: =IF(D9="","",ROUND(M8+IF(G9>0,D9*G9,D9*J9),2)) | N9: =IF(D9="","",ROUND(N8+IF(H9>0,D9*H9,D9*K9),2)) | O9: =IF(D9="","",ROUND(O8+IF(I9>0,D9*I9,D9*L9),2)) | P9: =IF(M9="","",IF(INT(M9/50)>INT(M8/50),"Lần " & INT(M9/50),"")) | Q9: =IF(N9="","",IF(INT(N9/200)>INT(N8/200),"Lần " & INT(N9/200),"")) | R9: =IF(O9="","",IF(INT(O9/350)>INT(O8/350),"Lần " & INT(O9/350),""))
A10: 7 | B10: Bê tông cọc khoan nhồi - C4 trụ T1 (L=40m) | D10: 47.01 | E10: =IF(C10="","",C10+7) | F10: =IF(C10="","",C10+28) | G10: 0.445 | H10: 0.525 | I10: 0.696 | M10: =IF(D10="","",ROUND(M9+IF(G10>0,D10*G10,D10*J10),2)) | N10: =IF(D10="","",ROUND(N9+IF(H10>0,D10*H10,D10*K10),2)) | O10: =IF(D10="","",ROUND(O9+IF(I10>0,D10*I10,D10*L10),2)) | P10: =IF(M10="","",IF(INT(M10/50)>INT(M9/50),"Lần " & INT(M10/50),"")) | Q10: =IF(N10="","",IF(INT(N10/200)>INT(N9/200),"Lần " & INT(N10/200),"")) | R10: =IF(O10="","",IF(INT(O10/350)>INT(O9/350),"Lần " & INT(O10/350),""))
A11: 8 | B11: Bê tông cọc khoan nhồi - C5 trụ T1 (L=40m) | D11: 47.01 | E11: =IF(C11="","",C11+7) | F11: =IF(C11="","",C11+28) | G11: 0.445 | H11: 0.525 | I11: 0.696 | M11: =IF(D11="","",ROUND(M10+IF(G11>0,D11*G11,D11*J11),2)) | N11: =IF(D11="","",ROUND(N10+IF(H11>0,D11*H11,D11*K11),2)) | O11: =IF(D11="","",ROUND(O10+IF(I11>0,D11*I11,D11*L11),2)) | P11: =IF(M11="","",IF(INT(M11/50)>INT(M10/50),"Lần " & INT(M11/50),"")) | Q11: =IF(N11="","",IF(INT(N11/200)>INT(N10/200),"Lần " & INT(N11/200),"")) | R11: =IF(O11="","",IF(INT(O11/350)>INT(O10/350),"Lần " & INT(O11/350),""))
A12: 9 | B12: Bê tông cọc khoan nhồi - C6 trụ T1 (L=40m) | D12: 47.01 | E12: =IF(C12="","",C12+7) | F12: =IF(C12="","",C12+28) | G12: 0.445 | H12: 0.525 | I12: 0.696 | M12: =IF(D12="","",ROUND(M11+IF(G12>0,D12*G12,D12*J12),2)) | N12: =IF(D12="","",ROUND(N11+IF(H12>0,D12*H12,D12*K12),2)) | O12: =IF(D12="","",ROUND(O11+IF(I12>0,D12*I12,D12*L12),2)) | P12: =IF(M12="","",IF(INT(M12/50)>INT(M11/50),"Lần " & INT(M12/50),"")) | Q12: =IF(N12="","",IF(INT(N12/200)>INT(N11/200),"Lần " & INT(N12/200),"")) | R12: =IF(O12="","",IF(INT(O12/350)>INT(O11/350),"Lần " & INT(O12/350),""))
A13: 10 | B13: Bê tông cọc khoan nhồi - C7 trụ T1 (L=40m) | D13: 47.01 | E13: =IF(C13="","",C13+7) | F13: =IF(C13="","",C13+28) | G13: 0.445 | H13: 0.525 | I13: 0.696 | M13: =IF(D13="","",ROUND(M12+IF(G13>0,D13*G13,D13*J13),2)) | N13: =IF(D13="","",ROUND(N12+IF(H13>0,D13*H13,D13*K13),2)) | O13: =IF(D13="","",ROUND(O12+IF(I13>0,D13*I13,D13*L13),2)) | P13: =IF(M13="","",IF(INT(M13/50)>INT(M12/50),"Lần " & INT(M13/50),"")) | Q13: =IF(N13="","",IF(INT(N13/200)>INT(N12/200),"Lần " & INT(N13/200),"")) | R13: =IF(O13="","",IF(INT(O13/350)>INT(O12/350),"Lần " & INT(O13/350),""))
A14: 11 | B14: Bê tông cọc khoan nhồi - C8 trụ T1 (L=40m) | D14: 47.01 | E14: =IF(C14="","",C14+7) | F14: =IF(C14="","",C14+28) | G14: 0.445 | H14: 0.525 | I14: 0.696 | M14: =IF(D14="","",ROUND(M13+IF(G14>0,D14*G14,D14*J14),2)) | N14: =IF(D14="","",ROUND(N13+IF(H14>0,D14*H14,D14*K14),2)) | O14: =IF(D14="","",ROUND(O13+IF(I14>0,D14*I14,D14*L14),2)) | P14: =IF(M14="","",IF(INT(M14/50)>INT(M13/50),"Lần " & INT(M14/50),"")) | Q14: =IF(N14="","",IF(INT(N14/200)>INT(N13/200),"Lần " & INT(N14/200),"")) | R14: =IF(O14="","",IF(INT(O14/350)>INT(O13/350),"Lần " & INT(O14/350),""))
A15: 12 | B15: Bê tông cọc khoan nhồi - C1 trụ T2 (L=30m) | D15: 35.86 | E15: =IF(C15="","",C15+7) | F15: =IF(C15="","",C15+28) | G15: 0.445 | H15: 0.525 | I15: 0.696 | M15: =IF(D15="","",ROUND(M14+IF(G15>0,D15*G15,D15*J15),2)) | N15: =IF(D15="","",ROUND(N14+IF(H15>0,D15*H15,D15*K15),2)) | O15: =IF(D15="","",ROUND(O14+IF(I15>0,D15*I15,D15*L15),2)) | P15: =IF(M15="","",IF(INT(M15/50)>INT(M14/50),"Lần " & INT(M15/50),"")) | Q15: =IF(N15="","",IF(INT(N15/200)>INT(N14/200),"Lần " & INT(N15/200),"")) | R15: =IF(O15="","",IF(INT(O15/350)>INT(O14/350),"Lần " & INT(O15/350),""))
A16: 13 | B16: Bê tông cọc khoan nhồi - C2 trụ T2 (L=30m) | D16: 35.86 | E16: =IF(C16="","",C16+7) | F16: =IF(C16="","",C16+28) | G16: 0.445 | H16: 0.525 | I16: 0.696 | M16: =IF(D16="","",ROUND(M15+IF(G16>0,D16*G16,D16*J16),2)) | N16: =IF(D16="","",ROUND(N15+IF(H16>0,D16*H16,D16*K16),2)) | O16: =IF(D16="","",ROUND(O15+IF(I16>0,D16*I16,D16*L16),2)) | P16: =IF(M16="","",IF(INT(M16/50)>INT(M15/50),"Lần " & INT(M16/50),"")) | Q16: =IF(N16="","",IF(INT(N16/200)>INT(N15/200),"Lần " & INT(N16/200),"")) | R16: =IF(O16="","",IF(INT(O16/350)>INT(O15/350),"Lần " & INT(O16/350),""))
... A29: 26 | B29: Bê tông cọc khoan nhồi - C7 mố M2 (L=36m) | D29: 42.83 | E29: =IF(C29="","",C29+7) | F29: =IF(C29="","",C29+28) | G29: 0.445 | H29: 0.525 | I29: 0.696 | M29: =IF(D29="","",ROUND(M28+IF(G29>0,D29*G29,D29*J29),2)) | N29: =IF(D29="","",ROUND(N28+IF(H29>0,D29*H29,D29*K29),2)) | O29: =IF(D29="","",ROUND(O28+IF(I29>0,D29*I29,D29*L29),2)) | P29: =IF(M29="","",IF(INT(M29/50)>INT(M28/50),"Lần " & INT(M29/50),"")) | Q29: =IF(N29="","",IF(INT(N29/200)>INT(N28/200),"Lần " & INT(N29/200),"")) | R29: =IF(O29="","",IF(INT(O29/350)>INT(O28/350),"Lần " & INT(O29/350),""))
A30: II. HẠNG MỤC BÊ TÔNG BỆ MỐ & BỆ TRỤ (C30 ĐỘ SỤT 14±2CM)
A31: 27 | B31: Bê tông lót móng bệ mố M1 (M100 đá 4x6) | D31: 9.55 | E31: =IF(C31="","",C31+7) | F31: =IF(C31="","",C31+28) | J31: 0.425 | K31: 0.555 | L31: 0.7 | M31: =IF(D31="","",ROUND(M29+IF(G31>0,D31*G31,D31*J31),2)) | N31: =IF(D31="","",ROUND(N29+IF(H31>0,D31*H31,D31*K31),2)) | O31: =IF(D31="","",ROUND(O29+IF(I31>0,D31*I31,D31*L31),2)) | P31: =IF(M31="","",IF(INT(M31/50)>INT(M29/50),"Lần " & INT(M31/50),"")) | Q31: =IF(N31="","",IF(INT(N31/200)>INT(N29/200),"Lần " & INT(N31/200),"")) | R31: =IF(O31="","",IF(INT(O31/350)>INT(O29/350),"Lần " & INT(O31/350),""))
A32: 28 | B32: Bê tông bệ mố M1 (C30 đá 1x2) | D32: 74.5 | E32: =IF(C32="","",C32+7) | F32: =IF(C32="","",C32+28) | J32: 0.425 | K32: 0.555 | L32: 0.7 | M32: =IF(D32="","",ROUND(M31+IF(G32>0,D32*G32,D32*J32),2)) | N32: =IF(D32="","",ROUND(N31+IF(H32>0,D32*H32,D32*K32),2)) | O32: =IF(D32="","",ROUND(O31+IF(I32>0,D32*I32,D32*L32),2)) | P32: =IF(M32="","",IF(INT(M32/50)>INT(M31/50),"Lần " & INT(M32/50),"")) | Q32: =IF(N32="","",IF(INT(N32/200)>INT(N31/200),"Lần " & INT(N32/200),"")) | R32: =IF(O32="","",IF(INT(O32/350)>INT(O31/350),"Lần " & INT(O32/350),""))
A33: 29 | B33: Bê tông lót móng bệ trụ T1 (M100 đá 4x6) | D33: 12.5 | E33: =IF(C33="","",C33+7) | F33: =IF(C33="","",C33+28) | J33: 0.425 | K33: 0.555 | L33: 0.7 | M33: =IF(D33="","",ROUND(M32+IF(G33>0,D33*G33,D33*J33),2)) | N33: =IF(D33="","",ROUND(N32+IF(H33>0,D33*H33,D33*K33),2)) | O33: =IF(D33="","",ROUND(O32+IF(I33>0,D33*I33,D33*L33),2)) | P33: =IF(M33="","",IF(INT(M33/50)>INT(M32/50),"Lần " & INT(M33/50),"")) | Q33: =IF(N33="","",IF(INT(N33/200)>INT(N32/200),"Lần " & INT(N33/200),"")) | R33: =IF(O33="","",IF(INT(O33/350)>INT(O32/350),"Lần " & INT(O33/350),""))
A34: 30 | B34: Bê tông bệ trụ T1 - Đợt 1 (C30 đá 1x2) | D34: 82.5 | E34: =IF(C34="","",C34+7) | F34: =IF(C34="","",C34+28) | J34: 0.425 | K34: 0.555 | L34: 0.7 | M34: =IF(D34="","",ROUND(M33+IF(G34>0,D34*G34,D34*J34),2)) | N34: =IF(D34="","",ROUND(N33+IF(H34>0,D34*H34,D34*K34),2)) | O34: =IF(D34="","",ROUND(O33+IF(I34>0,D34*I34,D34*L34),2)) | P34: =IF(M34="","",IF(INT(M34/50)>INT(M33/50),"Lần " & INT(M34/50),"")) | Q34: =IF(N34="","",IF(INT(N34/200)>INT(N33/200),"Lần " & INT(N34/200),"")) | R34: =IF(O34="","",IF(INT(O34/350)>INT(O33/350),"Lần " & INT(O34/350),""))
A35: 31 | B35: Bê tông bệ trụ T1 - Đợt 2 (C30 đá 1x2) | D35: 82.5 | E35: =IF(C35="","",C35+7) | F35: =IF(C35="","",C35+28) | J35: 0.425 | K35: 0.555 | L35: 0.7 | M35: =IF(D35="","",ROUND(M34+IF(G35>0,D35*G35,D35*J35),2)) | N35: =IF(D35="","",ROUND(N34+IF(H35>0,D35*H35,D35*K35),2)) | O35: =IF(D35="","",ROUND(O34+IF(I35>0,D35*I35,D35*L35),2)) | P35: =IF(M35="","",IF(INT(M35/50)>INT(M34/50),"Lần " & INT(M35/50),"")) | Q35: =IF(N35="","",IF(INT(N35/200)>INT(N34/200),"Lần " & INT(N35/200),"")) | R35: =IF(O35="","",IF(INT(O35/350)>INT(O34/350),"Lần " & INT(O35/350),""))
A36: 32 | B36: Bê tông lót móng bệ trụ T2 (M100 đá 4x6) | D36: 12.5 | E36: =IF(C36="","",C36+7) | F36: =IF(C36="","",C36+28) | J36: 0.425 | K36: 0.555 | L36: 0.7 | M36: =IF(D36="","",ROUND(M35+IF(G36>0,D36*G36,D36*J36),2)) | N36: =IF(D36="","",ROUND(N35+IF(H36>0,D36*H36,D36*K36),2)) | O36: =IF(D36="","",ROUND(O35+IF(I36>0,D36*I36,D36*L36),2)) | P36: =IF(M36="","",IF(INT(M36/50)>INT(M35/50),"Lần " & INT(M36/50),"")) | Q36: =IF(N36="","",IF(INT(N36/200)>INT(N35/200),"Lần " & INT(N36/200),"")) | R36: =IF(O36="","",IF(INT(O36/350)>INT(O35/350),"Lần " & INT(O36/350),""))
A37: 33 | B37: Bê tông bệ trụ T2 - Đợt 1 (C30 đá 1x2) | D37: 82.5 | E37: =IF(C37="","",C37+7) | F37: =IF(C37="","",C37+28) | J37: 0.425 | K37: 0.555 | L37: 0.7 | M37: =IF(D37="","",ROUND(M36+IF(G37>0,D37*G37,D37*J37),2)) | N37: =IF(D37="","",ROUND(N36+IF(H37>0,D37*H37,D37*K37),2)) | O37: =IF(D37="","",ROUND(O36+IF(I37>0,D37*I37,D37*L37),2)) | P37: =IF(M37="","",IF(INT(M37/50)>INT(M36/50),"Lần " & INT(M37/50),"")) | Q37: =IF(N37="","",IF(INT(N37/200)>INT(N36/200),"Lần " & INT(N37/200),"")) | R37: =IF(O37="","",IF(INT(O37/350)>INT(O36/350),"Lần " & INT(O37/350),""))
A38: 34 | B38: Bê tông bệ trụ T2 - Đợt 2 (C30 đá 1x2) | D38: 82.5 | E38: =IF(C38="","",C38+7) | F38: =IF(C38="","",C38+28) | J38: 0.425 | K38: 0.555 | L38: 0.7 | M38: =IF(D38="","",ROUND(M37+IF(G38>0,D38*G38,D38*J38),2)) | N38: =IF(D38="","",ROUND(N37+IF(H38>0,D38*H38,D38*K38),2)) | O38: =IF(D38="","",ROUND(O37+IF(I38>0,D38*I38,D38*L38),2)) | P38: =IF(M38="","",IF(INT(M38/50)>INT(M37/50),"Lần " & INT(M38/50),"")) | Q38: =IF(N38="","",IF(INT(N38/200)>INT(N37/200),"Lần " & INT(N38/200),"")) | R38: =IF(O38="","",IF(INT(O38/350)>INT(O37/350),"Lần " & INT(O38/350),""))
A39: 35 | B39: Bê tông lót móng bệ mố M2 (M100 đá 4x6) | D39: 9.55 | E39: =IF(C39="","",C39+7) | F39: =IF(C39="","",C39+28) | J39: 0.425 | K39: 0.555 | L39: 0.7 | M39: =IF(D39="","",ROUND(M38+IF(G39>0,D39*G39,D39*J39),2)) | N39: =IF(D39="","",ROUND(N38+IF(H39>0,D39*H39,D39*K39),2)) | O39: =IF(D39="","",ROUND(O38+IF(I39>0,D39*I39,D39*L39),2)) | P39: =IF(M39="","",IF(INT(M39/50)>INT(M38/50),"Lần " & INT(M39/50),"")) | Q39: =IF(N39="","",IF(INT(N39/200)>INT(N38/200),"Lần " & INT(N39/200),"")) | R39: =IF(O39="","",IF(INT(O39/350)>INT(O38/350),"Lần " & INT(O39/350),""))
A40: 36 | B40: Bê tông bệ mố M2 (C30 đá 1x2) | D40: 74.5 | E40: =IF(C40="","",C40+7) | F40: =IF(C40="","",C40+28) | J40: 0.425 | K40: 0.555 | L40: 0.7 | M40: =IF(D40="","",ROUND(M39+IF(G40>0,D40*G40,D40*J40),2)) | N40: =IF(D40="","",ROUND(N39+IF(H40>0,D40*H40,D40*K40),2)) | O40: =IF(D40="","",ROUND(O39+IF(I40>0,D40*I40,D40*L40),2)) | P40: =IF(M40="","",IF(INT(M40/50)>INT(M39/50),"Lần " & INT(M40/50),"")) | Q40: =IF(N40="","",IF(INT(N40/200)>INT(N39/200),"Lần " & INT(N40/200),"")) | R40: =IF(O40="","",IF(INT(O40/350)>INT(O39/350),"Lần " & INT(O40/350),""))
A41: III. HẠNG MỤC THÂN TRỤ, THÂN MỐ & XÀ MŨ (CÁC ĐỐT LÊN HOÀN THIỆN)
A42: 37 | B42: Bê tông thân trụ T1 - Đốt 1 (C30 đá 1x2) | D42: 42 | E42: =IF(C42="","",C42+7) | F42: =IF(C42="","",C42+28) | J42: 0.425 | K42: 0.555 | L42: 0.7 | M42: =IF(D42="","",ROUND(M40+IF(G42>0,D42*G42,D42*J42),2)) | N42: =IF(D42="","",ROUND(N40+IF(H42>0,D42*H42,D42*K42),2)) | O42: =IF(D42="","",ROUND(O40+IF(I42>0,D42*I42,D42*L42),2)) | P42: =IF(M42="","",IF(INT(M42/50)>INT(M40/50),"Lần " & INT(M42/50),"")) | Q42: =IF(N42="","",IF(INT(N42/200)>INT(N40/200),"Lần " & INT(N42/200),"")) | R42: =IF(O42="","",IF(INT(O42/350)>INT(O40/350),"Lần " & INT(O42/350),""))
A43: 38 | B43: Bê tông thân trụ T1 - Đốt 2 (C30 đá 1x2) | D43: 42 | E43: =IF(C43="","",C43+7) | F43: =IF(C43="","",C43+28) | J43: 0.425 | K43: 0.555 | L43: 0.7 | M43: =IF(D43="","",ROUND(M42+IF(G43>0,D43*G43,D43*J43),2)) | N43: =IF(D43="","",ROUND(N42+IF(H43>0,D43*H43,D43*K43),2)) | O43: =IF(D43="","",ROUND(O42+IF(I43>0,D43*I43,D43*L43),2)) | P43: =IF(M43="","",IF(INT(M43/50)>INT(M42/50),"Lần " & INT(M43/50),"")) | Q43: =IF(N43="","",IF(INT(N43/200)>INT(N42/200),"Lần " & INT(N43/200),"")) | R43: =IF(O43="","",IF(INT(O43/350)>INT(O42/350),"Lần " & INT(O43/350),""))
A44: 39 | B44: Bê tông thân trụ T1 - Đốt 3 (C30 đá 1x2) | D44: 38 | E44: =IF(C44="","",C44+7) | F44: =IF(C44="","",C44+28) | J44: 0.425 | K44: 0.555 | L44: 0.7 | M44: =IF(D44="","",ROUND(M43+IF(G44>0,D44*G44,D44*J44),2)) | N44: =IF(D44="","",ROUND(N43+IF(H44>0,D44*H44,D44*K44),2)) | O44: =IF(D44="","",ROUND(O43+IF(I44>0,D44*I44,D44*L44),2)) | P44: =IF(M44="","",IF(INT(M44/50)>INT(M43/50),"Lần " & INT(M44/50),"")) | Q44: =IF(N44="","",IF(INT(N44/200)>INT(N43/200),"Lần " & INT(N44/200),"")) | R44: =IF(O44="","",IF(INT(O44/350)>INT(O43/350),"Lần " & INT(O44/350),""))
A45: 40 | B45: Bê tông xà mũ trụ T1 & đá kê gối (C35/C30 đá 1x2) | D45: 45 | E45: =IF(C45="","",C45+7) | F45: =IF(C45="","",C45+28) | J45: 0.425 | K45: 0.555 | L45: 0.7 | M45: =IF(D45="","",ROUND(M44+IF(G45>0,D45*G45,D45*J45),2)) | N45: =IF(D45="","",ROUND(N44+IF(H45>0,D45*H45,D45*K45),2)) | O45: =IF(D45="","",ROUND(O44+IF(I45>0,D45*I45,D45*L45),2)) | P45: =IF(M45="","",IF(INT(M45/50)>INT(M44/50),"Lần " & INT(M45/50),"")) | Q45: =IF(N45="","",IF(INT(N45/200)>INT(N44/200),"Lần " & INT(N45/200),"")) | R45: =IF(O45="","",IF(INT(O45/350)>INT(O44/350),"Lần " & INT(O45/350),""))
A46: 41 | B46: Bê tông thân trụ T2 - Đốt 1 (C30 đá 1x2) | D46: 45 | E46: =IF(C46="","",C46+7) | F46: =IF(C46="","",C46+28) | J46: 0.425 | K46: 0.555 | L46: 0.7 | M46: =IF(D46="","",ROUND(M45+IF(G46>0,D46*G46,D46*J46),2)) | N46: =IF(D46="","",ROUND(N45+IF(H46>0,D46*H46,D46*K46),2)) | O46: =IF(D46="","",ROUND(O45+IF(I46>0,D46*I46,D46*L46),2)) | P46: =IF(M46="","",IF(INT(M46/50)>INT(M45/50),"Lần " & INT(M46/50),"")) | Q46: =IF(N46="","",IF(INT(N46/200)>INT(N45/200),"Lần " & INT(N46/200),"")) | R46: =IF(O46="","",IF(INT(O46/350)>INT(O45/350),"Lần " & INT(O46/350),""))
A47: 42 | B47: Bê tông thân trụ T2 - Đốt 2 (C30 đá 1x2) | D47: 45 | E47: =IF(C47="","",C47+7) | F47: =IF(C47="","",C47+28) | J47: 0.425 | K47: 0.555 | L47: 0.7 | M47: =IF(D47="","",ROUND(M46+IF(G47>0,D47*G47,D47*J47),2)) | N47: =IF(D47="","",ROUND(N46+IF(H47>0,D47*H47,D47*K47),2)) | O47: =IF(D47="","",ROUND(O46+IF(I47>0,D47*I47,D47*L47),2)) | P47: =IF(M47="","",IF(INT(M47/50)>INT(M46/50),"Lần " & INT(M47/50),"")) | Q47: =IF(N47="","",IF(INT(N47/200)>INT(N46/200),"Lần " & INT(N47/200),"")) | R47: =IF(O47="","",IF(INT(O47/350)>INT(O46/350),"Lần " & INT(O47/350),""))
A48: 43 | B48: Bê tông thân trụ T2 - Đốt 3 (C30 đá 1x2) | D48: 42 | E48: =IF(C48="","",C48+7) | F48: =IF(C48="","",C48+28) | J48: 0.425 | K48: 0.555 | L48: 0.7 | M48: =IF(D48="","",ROUND(M47+IF(G48>0,D48*G48,D48*J48),2)) | N48: =IF(D48="","",ROUND(N47+IF(H48>0,D48*H48,D48*K48),2)) | O48: =IF(D48="","",ROUND(O47+IF(I48>0,D48*I48,D48*L48),2)) | P48: =IF(M48="","",IF(INT(M48/50)>INT(M47/50),"Lần " & INT(M48/50),"")) | Q48: =IF(N48="","",IF(INT(N48/200)>INT(N47/200),"Lần " & INT(N48/200),"")) | R48: =IF(O48="","",IF(INT(O48/350)>INT(O47/350),"Lần " & INT(O48/350),""))
A49: 44 | B49: Bê tông xà mũ trụ T2 & đá kê gối (C35/C30 đá 1x2) | D49: 45 | E49: =IF(C49="","",C49+7) | F49: =IF(C49="","",C49+28) | J49: 0.425 | K49: 0.555 | L49: 0.7 | M49: =IF(D49="","",ROUND(M48+IF(G49>0,D49*G49,D49*J49),2)) | N49: =IF(D49="","",ROUND(N48+IF(H49>0,D49*H49,D49*K49),2)) | O49: =IF(D49="","",ROUND(O48+IF(I49>0,D49*I49,D49*L49),2)) | P49: =IF(M49="","",IF(INT(M49/50)>INT(M48/50),"Lần " & INT(M49/50),"")) | Q49: =IF(N49="","",IF(INT(N49/200)>INT(N48/200),"Lần " & INT(N49/200),"")) | R49: =IF(O49="","",IF(INT(O49/350)>INT(O48/350),"Lần " & INT(O49/350),""))
A50: 45 | B50: Bê tông tường thân mố M1 - Đợt 1 (C30 đá 1x2) | D50: 45 | E50: =IF(C50="","",C50+7) | F50: =IF(C50="","",C50+28) | J50: 0.425 | K50: 0.555 | L50: 0.7 | M50: =IF(D50="","",ROUND(M49+IF(G50>0,D50*G50,D50*J50),2)) | N50: =IF(D50="","",ROUND(N49+IF(H50>0,D50*H50,D50*K50),2)) | O50: =IF(D50="","",ROUND(O49+IF(I50>0,D50*I50,D50*L50),2)) | P50: =IF(M50="","",IF(INT(M50/50)>INT(M49/50),"Lần " & INT(M50/50),"")) | Q50: =IF(N50="","",IF(INT(N50/200)>INT(N49/200),"Lần " & INT(N50/200),"")) | R50: =IF(O50="","",IF(INT(O50/350)>INT(O49/350),"Lần " & INT(O50/350),""))
A51: 46 | B51: Bê tông tường thân mố M1 - Đợt 2 (C30 đá 1x2) | D51: 39.44 | E51: =IF(C51="","",C51+7) | F51: =IF(C51="","",C51+28) | J51: 0.425 | K51: 0.555 | L51: 0.7 | M51: =IF(D51="","",ROUND(M50+IF(G51>0,D51*G51,D51*J51),2)) | N51: =IF(D51="","",ROUND(N50+IF(H51>0,D51*H51,D51*K51),2)) | O51: =IF(D51="","",ROUND(O50+IF(I51>0,D51*I51,D51*L51),2)) | P51: =IF(M51="","",IF(INT(M51/50)>INT(M50/50),"Lần " & INT(M51/50),"")) | Q51: =IF(N51="","",IF(INT(N51/200)>INT(N50/200),"Lần " & INT(N51/200),"")) | R51: =IF(O51="","",IF(INT(O51/350)>INT(O50/350),"Lần " & INT(O51/350),""))
A52: 47 | B52: Bê tông tường đỉnh mố M1 & đá kê gối (C30) | D52: 14.33 | E52: =IF(C52="","",C52+7) | F52: =IF(C52="","",C52+28) | J52: 0.425 | K52: 0.555 | L52: 0.7 | M52: =IF(D52="","",ROUND(M51+IF(G52>0,D52*G52,D52*J52),2)) | N52: =IF(D52="","",ROUND(N51+IF(H52>0,D52*H52,D52*K52),2)) | O52: =IF(D52="","",ROUND(O51+IF(I52>0,D52*I52,D52*L52),2)) | P52: =IF(M52="","",IF(INT(M52/50)>INT(M51/50),"Lần " & INT(M52/50),"")) | Q52: =IF(N52="","",IF(INT(N52/200)>INT(N51/200),"Lần " & INT(N52/200),"")) | R52: =IF(O52="","",IF(INT(O52/350)>INT(O51/350),"Lần " & INT(O52/350),""))
...

Sheet Theo_Doi_Tan_Suat_Cot_Thep
A1: STT | B1: HẠNG MỤC CẤU KIỆN | C1: BỘ PHẬN / VỊ TRÍ CHI TIẾT | D1: KÝ HIỆU THANH | E1: ĐƯỜNG KÍNH Ø (mm) | F1: MÁC THÉP / TIÊU CHUẨN | G1: HÌNH DẠNG / QUY CÁCH | H1: CHIỀU DÀI 1 THANH (m) | I1: SỐ LƯỢNG (Thanh) | J1: TRỌNG LƯỢNG 1M (kg/m) | K1: TỔNG KL (kg) | L1: KHỐI LƯỢNG (Tấn) | M1: N/T/N LẮP DỰNG | N1: SỐ LÔ / HEAT NO CO-CQ RIÊNG TỪNG Ø | O1: CẢNH BÁO LẤY MẪU TN KÉO/UỐN (20T/LẦN) | P1: KHỐI LƯỢNG LŨY KẾ THEO TỪNG LOẠI ĐƯỜNG KÍNH Ø (TẤN) | AA1: TẦN SUẤT THÍ NGHIỆM CƠ LÝ KÉO / UỐN RIÊNG TỪNG Ø (20 TẤN / LẦN - TCVN 1651:2018) | AL1: ĐÁNH GIÁ & KẾT LUẬN
P2: Ø10 (kèm Ø8) (CB240-T) | Q2: Ø12 (CB400-V) | R2: Ø14 (CB400-V) | S2: Ø16 (CB400-V) | T2: Ø18 (CB400-V) | U2: Ø20 (CB400-V) | V2: Ø22 (CB400-V) | W2: Ø25 (CB400-V) | X2: Ø28 (CB400-V) | Y2: Ø32 (CB400-V) | Z2: Cáp DƯL 15.2 (ASTM A416) | AA2: TN Ø10 20T / Lần | AB2: TN Ø12 20T / Lần | AC2: TN Ø14 20T / Lần | AD2: TN Ø16 20T / Lần | AE2: TN Ø18 20T / Lần | AF2: TN Ø20 20T / Lần | AG2: TN Ø22 20T / Lần | AH2: TN Ø25 20T / Lần | AI2: TN Ø28 20T / Lần | AJ2: TN Ø32 20T / Lần | AK2: TN Cáp 15.2 20T / Lần
A3: PHẦN I: KẾT CẤU CỌC KHOAN NHỒI D1.2M (26 CỌC TOÀN CẦU: M1=3, T1=8, T2=8, M2=7)
A4: --- CỌC KHOAN NHỒI C1 MỐ M1 (D1.2M, L=20.0M) ---
A5: 1 | B5: Cọc khoan nhồi C1 Mố M1 (D1.2m, L=20.0m) | C5: Thép đai xoắn lồng cọc | D5: P1 | E5: 10 | F5: CB240-T | G5: Đai xoắn tròn | H5: 96.604 | I5: 1 | J5: 0.617 | K5: =ROUND(H5*I5*J5, 2) | L5: =ROUND(K5/1000, 3) | P5: =IF(AND(E5<=10, F5<>"ASTM A416"), L5, 0) | Q5: =IF(AND(E5=12, F5<>"ASTM A416"), L5, 0) | R5: =IF(AND(E5=14, F5<>"ASTM A416"), L5, 0) | S5: =IF(AND(E5=16, F5<>"ASTM A416"), L5, 0) | T5: =IF(AND(E5=18, F5<>"ASTM A416"), L5, 0) | U5: =IF(AND(E5=20, F5<>"ASTM A416"), L5, 0) | V5: =IF(AND(E5=22, F5<>"ASTM A416"), L5, 0) | W5: =IF(AND(E5=25, F5<>"ASTM A416"), L5, 0) | X5: =IF(AND(E5=28, F5<>"ASTM A416"), L5, 0) | Y5: =IF(AND(E5=32, F5<>"ASTM A416"), L5, 0) | Z5: =IF(F5="ASTM A416", L5, 0) | AA5: =IF(P5=0, "", IF(INT(P5/20)>0, "Lần " & INT(P5/20), "")) | AB5: =IF(Q5=0, "", IF(INT(Q5/20)>0, "Lần " & INT(Q5/20), "")) | AC5: =IF(R5=0, "", IF(INT(R5/20)>0, "Lần " & INT(R5/20), "")) | AD5: =IF(S5=0, "", IF(INT(S5/20)>0, "Lần " & INT(S5/20), "")) | AE5: =IF(T5=0, "", IF(INT(T5/20)>0, "Lần " & INT(T5/20), "")) | AF5: =IF(U5=0, "", IF(INT(U5/20)>0, "Lần " & INT(U5/20), "")) | AG5: =IF(V5=0, "", IF(INT(V5/20)>0, "Lần " & INT(V5/20), "")) | AH5: =IF(W5=0, "", IF(INT(W5/20)>0, "Lần " & INT(W5/20), "")) | ... AK5: =IF(Z5=0, "", IF(INT(Z5/20)>0, "Lần " & INT(Z5/20), "")) | AL5: ĐẠT TCVN 1651:2018
A6: 2 | B6: Cọc khoan nhồi C1 Mố M1 (D1.2m, L=20.0m) | C6: Thép đai xoắn lồng cọc | D6: P1A | E6: 10 | F6: CB240-T | G6: Đai xoắn tròn | H6: 373.535 | I6: 1 | J6: 0.617 | K6: =ROUND(H6*I6*J6, 2) | L6: =ROUND(K6/1000, 3) | O6: =IF(AND(E6<=10, F6<>"ASTM A416", INT(P6/20)>INT(P5/20)), "TN Ø10 (Lần " & INT(P6/20) & ")", IF(AND(E6=12, INT(Q6/20)>INT(Q5/20)), "TN Ø12 (Lần " & INT(Q6/20) & ")", IF(AND(E6=14, INT(R6/20)>INT(R5/20)), "TN Ø14 (Lần " & INT(R6/20) & ")", IF(AND(E6=16, INT(S6/20)>INT(S5/20)), "TN Ø16 (Lần " & INT(S6/20) & ")", IF(AND(E6=18, INT(T6/20)>INT(T5/20)), "TN Ø18 (Lần " & INT(T6/20) & ")", IF(AND(E6=20, INT(U6/20)>INT(U5/20)), "TN Ø20 (Lần " & INT(U6/20) & ")", IF(AND(E6=22, INT(V6/20)>INT(V5/20)), "TN Ø22 (Lần " & INT(V6/20) & ")", IF(AND(E6=25, INT(W6/20)>INT(W5/20)), "TN Ø25 (Lần " & INT(W6/20) & ")", IF(AND(E6=28, INT(X6/20)>INT(X5/20)), "TN Ø28 (Lần " & INT(X6/20) & ")", IF(AND(E6=32, INT(Y6/20)>INT(Y5/20)), "TN Ø32 (Lần " & INT(Y6/20) & ")", IF(AND(F6="ASTM A416", INT(Z6/20)>INT(Z5/20)), "TN Cáp 15.2 (Lần " & INT(Z6/20) & ")", ""))))))))))) | P6: =ROUND(P5 + IF(AND(E6<=10, F6<>"ASTM A416"), L6, 0), 3) | Q6: =ROUND(Q5 + IF(AND(E6=12, F6<>"ASTM A416"), L6, 0), 3) | R6: =ROUND(R5 + IF(AND(E6=14, F6<>"ASTM A416"), L6, 0), 3) | S6: =ROUND(S5 + IF(AND(E6=16, F6<>"ASTM A416"), L6, 0), 3) | T6: =ROUND(T5 + IF(AND(E6=18, F6<>"ASTM A416"), L6, 0), 3) | U6: =ROUND(U5 + IF(AND(E6=20, F6<>"ASTM A416"), L6, 0), 3) | V6: =ROUND(V5 + IF(AND(E6=22, F6<>"ASTM A416"), L6, 0), 3) | W6: =ROUND(W5 + IF(AND(E6=25, F6<>"ASTM A416"), L6, 0), 3) | X6: =ROUND(X5 + IF(AND(E6=28, F6<>"ASTM A416"), L6, 0), 3) | Y6: =ROUND(Y5 + IF(AND(E6=32, F6<>"ASTM A416"), L6, 0), 3) | Z6: =ROUND(Z5 + IF(F6="ASTM A416", L6, 0), 3) | AA6: =IF(INT(P6/20)>INT(P5/20), "Lần " & INT(P6/20), "") | AB6: =IF(INT(Q6/20)>INT(Q5/20), "Lần " & INT(Q6/20), "") | AC6: =IF(INT(R6/20)>INT(R5/20), "Lần " & INT(R6/20), "") | AD6: =IF(INT(S6/20)>INT(S5/20), "Lần " & INT(S6/20), "") | AE6: =IF(INT(T6/20)>INT(T5/20), "Lần " & INT(T6/20), "") | AF6: =IF(INT(U6/20)>INT(U5/20), "Lần " & INT(U6/20), "") | AG6: =IF(INT(V6/20)>INT(V5/20), "Lần " & INT(V6/20), "") | AH6: =IF(INT(W6/20)>INT(W5/20), "Lần " & INT(W6/20), "") | ... AK6: =IF(INT(Z6/20)>INT(Z5/20), "Lần " & INT(Z6/20), "") | AL6: ĐẠT TCVN 1651:2018
A7: 3 | B7: Cọc khoan nhồi C1 Mố M1 (D1.2m, L=20.0m) | C7: Thép đai xoắn lồng cọc | D7: P1C | E7: 10 | F7: CB240-T | G7: Đai xoắn tròn | H7: 3.592 | I7: 2 | J7: 0.617 | K7: =ROUND(H7*I7*J7, 2) | L7: =ROUND(K7/1000, 3) | O7: =IF(AND(E7<=10, F7<>"ASTM A416", INT(P7/20)>INT(P6/20)), "TN Ø10 (Lần " & INT(P7/20) & ")", IF(AND(E7=12, INT(Q7/20)>INT(Q6/20)), "TN Ø12 (Lần " & INT(Q7/20) & ")", IF(AND(E7=14, INT(R7/20)>INT(R6/20)), "TN Ø14 (Lần " & INT(R7/20) & ")", IF(AND(E7=16, INT(S7/20)>INT(S6/20)), "TN Ø16 (Lần " & INT(S7/20) & ")", IF(AND(E7=18, INT(T7/20)>INT(T6/20)), "TN Ø18 (Lần " & INT(T7/20) & ")", IF(AND(E7=20, INT(U7/20)>INT(U6/20)), "TN Ø20 (Lần " & INT(U7/20) & ")", IF(AND(E7=22, INT(V7/20)>INT(V6/20)), "TN Ø22 (Lần " & INT(V7/20) & ")", IF(AND(E7=25, INT(W7/20)>INT(W6/20)), "TN Ø25 (Lần " & INT(W7/20) & ")", IF(AND(E7=28, INT(X7/20)>INT(X6/20)), "TN Ø28 (Lần " & INT(X7/20) & ")", IF(AND(E7=32, INT(Y7/20)>INT(Y6/20)), "TN Ø32 (Lần " & INT(Y7/20) & ")", IF(AND(F7="ASTM A416", INT(Z7/20)>INT(Z6/20)), "TN Cáp 15.2 (Lần " & INT(Z7/20) & ")", ""))))))))))) | P7: =ROUND(P6 + IF(AND(E7<=10, F7<>"ASTM A416"), L7, 0), 3) | Q7: =ROUND(Q6 + IF(AND(E7=12, F7<>"ASTM A416"), L7, 0), 3) | R7: =ROUND(R6 + IF(AND(E7=14, F7<>"ASTM A416"), L7, 0), 3) | S7: =ROUND(S6 + IF(AND(E7=16, F7<>"ASTM A416"), L7, 0), 3) | T7: =ROUND(T6 + IF(AND(E7=18, F7<>"ASTM A416"), L7, 0), 3) | U7: =ROUND(U6 + IF(AND(E7=20, F7<>"ASTM A416"), L7, 0), 3) | V7: =ROUND(V6 + IF(AND(E7=22, F7<>"ASTM A416"), L7, 0), 3) | W7: =ROUND(W6 + IF(AND(E7=25, F7<>"ASTM A416"), L7, 0), 3) | X7: =ROUND(X6 + IF(AND(E7=28, F7<>"ASTM A416"), L7, 0), 3) | Y7: =ROUND(Y6 + IF(AND(E7=32, F7<>"ASTM A416"), L7, 0), 3) | Z7: =ROUND(Z6 + IF(F7="ASTM A416", L7, 0), 3) | AA7: =IF(INT(P7/20)>INT(P6/20), "Lần " & INT(P7/20), "") | AB7: =IF(INT(Q7/20)>INT(Q6/20), "Lần " & INT(Q7/20), "") | AC7: =IF(INT(R7/20)>INT(R6/20), "Lần " & INT(R7/20), "") | AD7: =IF(INT(S7/20)>INT(S6/20), "Lần " & INT(S7/20), "") | AE7: =IF(INT(T7/20)>INT(T6/20), "Lần " & INT(T7/20), "") | AF7: =IF(INT(U7/20)>INT(U6/20), "Lần " & INT(U7/20), "") | AG7: =IF(INT(V7/20)>INT(V6/20), "Lần " & INT(V7/20), "") | AH7: =IF(INT(W7/20)>INT(W6/20), "Lần " & INT(W7/20), "") | ... AK7: =IF(INT(Z7/20)>INT(Z6/20), "Lần " & INT(Z7/20), "") | AL7: ĐẠT TCVN 1651:2018
A8: 4 | B8: Cọc khoan nhồi C1 Mố M1 (D1.2m, L=20.0m) | C8: Thép đai xoắn lồng cọc | D8: P1D | E8: 10 | F8: CB240-T | G8: Đai xoắn tròn | H8: 19.721 | I8: 1 | J8: 0.617 | K8: =ROUND(H8*I8*J8, 2) | L8: =ROUND(K8/1000, 3) | O8: =IF(AND(E8<=10, F8<>"ASTM A416", INT(P8/20)>INT(P7/20)), "TN Ø10 (Lần " & INT(P8/20) & ")", IF(AND(E8=12, INT(Q8/20)>INT(Q7/20)), "TN Ø12 (Lần " & INT(Q8/20) & ")", IF(AND(E8=14, INT(R8/20)>INT(R7/20)), "TN Ø14 (Lần " & INT(R8/20) & ")", IF(AND(E8=16, INT(S8/20)>INT(S7/20)), "TN Ø16 (Lần " & INT(S8/20) & ")", IF(AND(E8=18, INT(T8/20)>INT(T7/20)), "TN Ø18 (Lần " & INT(T8/20) & ")", IF(AND(E8=20, INT(U8/20)>INT(U7/20)), "TN Ø20 (Lần " & INT(U8/20) & ")", IF(AND(E8=22, INT(V8/20)>INT(V7/20)), "TN Ø22 (Lần " & INT(V8/20) & ")", IF(AND(E8=25, INT(W8/20)>INT(W7/20)), "TN Ø25 (Lần " & INT(W8/20) & ")", IF(AND(E8=28, INT(X8/20)>INT(X7/20)), "TN Ø28 (Lần " & INT(X8/20) & ")", IF(AND(E8=32, INT(Y8/20)>INT(Y7/20)), "TN Ø32 (Lần " & INT(Y8/20) & ")", IF(AND(F8="ASTM A416", INT(Z8/20)>INT(Z7/20)), "TN Cáp 15.2 (Lần " & INT(Z8/20) & ")", ""))))))))))) | P8: =ROUND(P7 + IF(AND(E8<=10, F8<>"ASTM A416"), L8, 0), 3) | Q8: =ROUND(Q7 + IF(AND(E8=12, F8<>"ASTM A416"), L8, 0), 3) | R8: =ROUND(R7 + IF(AND(E8=14, F8<>"ASTM A416"), L8, 0), 3) | S8: =ROUND(S7 + IF(AND(E8=16, F8<>"ASTM A416"), L8, 0), 3) | T8: =ROUND(T7 + IF(AND(E8=18, F8<>"ASTM A416"), L8, 0), 3) | U8: =ROUND(U7 + IF(AND(E8=20, F8<>"ASTM A416"), L8, 0), 3) | V8: =ROUND(V7 + IF(AND(E8=22, F8<>"ASTM A416"), L8, 0), 3) | W8: =ROUND(W7 + IF(AND(E8=25, F8<>"ASTM A416"), L8, 0), 3) | X8: =ROUND(X7 + IF(AND(E8=28, F8<>"ASTM A416"), L8, 0), 3) | Y8: =ROUND(Y7 + IF(AND(E8=32, F8<>"ASTM A416"), L8, 0), 3) | Z8: =ROUND(Z7 + IF(F8="ASTM A416", L8, 0), 3) | AA8: =IF(INT(P8/20)>INT(P7/20), "Lần " & INT(P8/20), "") | AB8: =IF(INT(Q8/20)>INT(Q7/20), "Lần " & INT(Q8/20), "") | AC8: =IF(INT(R8/20)>INT(R7/20), "Lần " & INT(R8/20), "") | AD8: =IF(INT(S8/20)>INT(S7/20), "Lần " & INT(S8/20), "") | AE8: =IF(INT(T8/20)>INT(T7/20), "Lần " & INT(T8/20), "") | AF8: =IF(INT(U8/20)>INT(U7/20), "Lần " & INT(U8/20), "") | AG8: =IF(INT(V8/20)>INT(V7/20), "Lần " & INT(V8/20), "") | AH8: =IF(INT(W8/20)>INT(W7/20), "Lần " & INT(W8/20), "") | ... AK8: =IF(INT(Z8/20)>INT(Z7/20), "Lần " & INT(Z8/20), "") | AL8: ĐẠT TCVN 1651:2018
A9: 5 | B9: Cọc khoan nhồi C1 Mố M1 (D1.2m, L=20.0m) | C9: Cốt thép chủ chịu lực cọc | D9: P2B | E9: 25 | F9: CB400-V | G9: Thanh thẳng nối ren/hàn | H9: 2.985 | I9: 8 | J9: 3.85 | K9: =ROUND(H9*I9*J9, 2) | L9: =ROUND(K9/1000, 3) | O9: =IF(AND(E9<=10, F9<>"ASTM A416", INT(P9/20)>INT(P8/20)), "TN Ø10 (Lần " & INT(P9/20) & ")", IF(AND(E9=12, INT(Q9/20)>INT(Q8/20)), "TN Ø12 (Lần " & INT(Q9/20) & ")", IF(AND(E9=14, INT(R9/20)>INT(R8/20)), "TN Ø14 (Lần " & INT(R9/20) & ")", IF(AND(E9=16, INT(S9/20)>INT(S8/20)), "TN Ø16 (Lần " & INT(S9/20) & ")", IF(AND(E9=18, INT(T9/20)>INT(T8/20)), "TN Ø18 (Lần " & INT(T9/20) & ")", IF(AND(E9=20, INT(U9/20)>INT(U8/20)), "TN Ø20 (Lần " & INT(U9/20) & ")", IF(AND(E9=22, INT(V9/20)>INT(V8/20)), "TN Ø22 (Lần " & INT(V9/20) & ")", IF(AND(E9=25, INT(W9/20)>INT(W8/20)), "TN Ø25 (Lần " & INT(W9/20) & ")", IF(AND(E9=28, INT(X9/20)>INT(X8/20)), "TN Ø28 (Lần " & INT(X9/20) & ")", IF(AND(E9=32, INT(Y9/20)>INT(Y8/20)), "TN Ø32 (Lần " & INT(Y9/20) & ")", IF(AND(F9="ASTM A416", INT(Z9/20)>INT(Z8/20)), "TN Cáp 15.2 (Lần " & INT(Z9/20) & ")", ""))))))))))) | P9: =ROUND(P8 + IF(AND(E9<=10, F9<>"ASTM A416"), L9, 0), 3) | Q9: =ROUND(Q8 + IF(AND(E9=12, F9<>"ASTM A416"), L9, 0), 3) | R9: =ROUND(R8 + IF(AND(E9=14, F9<>"ASTM A416"), L9, 0), 3) | S9: =ROUND(S8 + IF(AND(E9=16, F9<>"ASTM A416"), L9, 0), 3) | T9: =ROUND(T8 + IF(AND(E9=18, F9<>"ASTM A416"), L9, 0), 3) | U9: =ROUND(U8 + IF(AND(E9=20, F9<>"ASTM A416"), L9, 0), 3) | V9: =ROUND(V8 + IF(AND(E9=22, F9<>"ASTM A416"), L9, 0), 3) | W9: =ROUND(W8 + IF(AND(E9=25, F9<>"ASTM A416"), L9, 0), 3) | X9: =ROUND(X8 + IF(AND(E9=28, F9<>"ASTM A416"), L9, 0), 3) | Y9: =ROUND(Y8 + IF(AND(E9=32, F9<>"ASTM A416"), L9, 0), 3) | Z9: =ROUND(Z8 + IF(F9="ASTM A416", L9, 0), 3) | AA9: =IF(INT(P9/20)>INT(P8/20), "Lần " & INT(P9/20), "") | AB9: =IF(INT(Q9/20)>INT(Q8/20), "Lần " & INT(Q9/20), "") | AC9: =IF(INT(R9/20)>INT(R8/20), "Lần " & INT(R9/20), "") | AD9: =IF(INT(S9/20)>INT(S8/20), "Lần " & INT(S9/20), "") | AE9: =IF(INT(T9/20)>INT(T8/20), "Lần " & INT(T9/20), "") | AF9: =IF(INT(U9/20)>INT(U8/20), "Lần " & INT(U9/20), "") | AG9: =IF(INT(V9/20)>INT(V8/20), "Lần " & INT(V9/20), "") | AH9: =IF(INT(W9/20)>INT(W8/20), "Lần " & INT(W9/20), "") | ... AK9: =IF(INT(Z9/20)>INT(Z8/20), "Lần " & INT(Z9/20), "") | AL9: ĐẠT TCVN 1651:2018
A10: 6 | B10: Cọc khoan nhồi C1 Mố M1 (D1.2m, L=20.0m) | C10: Cốt thép chủ chịu lực cọc | D10: P3 | E10: 25 | F10: CB400-V | G10: Thanh thẳng nối ren/hàn | H10: 10.7 | I10: 12 | J10: 3.85 | K10: =ROUND(H10*I10*J10, 2) | L10: =ROUND(K10/1000, 3) | O10: =IF(AND(E10<=10, F10<>"ASTM A416", INT(P10/20)>INT(P9/20)), "TN Ø10 (Lần " & INT(P10/20) & ")", IF(AND(E10=12, INT(Q10/20)>INT(Q9/20)), "TN Ø12 (Lần " & INT(Q10/20) & ")", IF(AND(E10=14, INT(R10/20)>INT(R9/20)), "TN Ø14 (Lần " & INT(R10/20) & ")", IF(AND(E10=16, INT(S10/20)>INT(S9/20)), "TN Ø16 (Lần " & INT(S10/20) & ")", IF(AND(E10=18, INT(T10/20)>INT(T9/20)), "TN Ø18 (Lần " & INT(T10/20) & ")", IF(AND(E10=20, INT(U10/20)>INT(U9/20)), "TN Ø20 (Lần " & INT(U10/20) & ")", IF(AND(E10=22, INT(V10/20)>INT(V9/20)), "TN Ø22 (Lần " & INT(V10/20) & ")", IF(AND(E10=25, INT(W10/20)>INT(W9/20)), "TN Ø25 (Lần " & INT(W10/20) & ")", IF(AND(E10=28, INT(X10/20)>INT(X9/20)), "TN Ø28 (Lần " & INT(X10/20) & ")", IF(AND(E10=32, INT(Y10/20)>INT(Y9/20)), "TN Ø32 (Lần " & INT(Y10/20) & ")", IF(AND(F10="ASTM A416", INT(Z10/20)>INT(Z9/20)), "TN Cáp 15.2 (Lần " & INT(Z10/20) & ")", ""))))))))))) | P10: =ROUND(P9 + IF(AND(E10<=10, F10<>"ASTM A416"), L10, 0), 3) | Q10: =ROUND(Q9 + IF(AND(E10=12, F10<>"ASTM A416"), L10, 0), 3) | R10: =ROUND(R9 + IF(AND(E10=14, F10<>"ASTM A416"), L10, 0), 3) | S10: =ROUND(S9 + IF(AND(E10=16, F10<>"ASTM A416"), L10, 0), 3) | T10: =ROUND(T9 + IF(AND(E10=18, F10<>"ASTM A416"), L10, 0), 3) | U10: =ROUND(U9 + IF(AND(E10=20, F10<>"ASTM A416"), L10, 0), 3) | V10: =ROUND(V9 + IF(AND(E10=22, F10<>"ASTM A416"), L10, 0), 3) | W10: =ROUND(W9 + IF(AND(E10=25, F10<>"ASTM A416"), L10, 0), 3) | X10: =ROUND(X9 + IF(AND(E10=28, F10<>"ASTM A416"), L10, 0), 3) | Y10: =ROUND(Y9 + IF(AND(E10=32, F10<>"ASTM A416"), L10, 0), 3) | Z10: =ROUND(Z9 + IF(F10="ASTM A416", L10, 0), 3) | AA10: =IF(INT(P10/20)>INT(P9/20), "Lần " & INT(P10/20), "") | AB10: =IF(INT(Q10/20)>INT(Q9/20), "Lần " & INT(Q10/20), "") | AC10: =IF(INT(R10/20)>INT(R9/20), "Lần " & INT(R10/20), "") | AD10: =IF(INT(S10/20)>INT(S9/20), "Lần " & INT(S10/20), "") | AE10: =IF(INT(T10/20)>INT(T9/20), "Lần " & INT(T10/20), "") | AF10: =IF(INT(U10/20)>INT(U9/20), "Lần " & INT(U10/20), "") | AG10: =IF(INT(V10/20)>INT(V9/20), "Lần " & INT(V10/20), "") | AH10: =IF(INT(W10/20)>INT(W9/20), "Lần " & INT(W10/20), "") | ... AK10: =IF(INT(Z10/20)>INT(Z9/20), "Lần " & INT(Z10/20), "") | AL10: ĐẠT TCVN 1651:2018
A11: 7 | B11: Cọc khoan nhồi C1 Mố M1 (D1.2m, L=20.0m) | C11: Cốt thép chủ chịu lực cọc | D11: P4 | E11: 25 | F11: CB400-V | G11: Thanh thẳng nối ren/hàn | H11: 11.7 | I11: 12 | J11: 3.85 | K11: =ROUND(H11*I11*J11, 2) | L11: =ROUND(K11/1000, 3) | O11: =IF(AND(E11<=10, F11<>"ASTM A416", INT(P11/20)>INT(P10/20)), "TN Ø10 (Lần " & INT(P11/20) & ")", IF(AND(E11=12, INT(Q11/20)>INT(Q10/20)), "TN Ø12 (Lần " & INT(Q11/20) & ")", IF(AND(E11=14, INT(R11/20)>INT(R10/20)), "TN Ø14 (Lần " & INT(R11/20) & ")", IF(AND(E11=16, INT(S11/20)>INT(S10/20)), "TN Ø16 (Lần " & INT(S11/20) & ")", IF(AND(E11=18, INT(T11/20)>INT(T10/20)), "TN Ø18 (Lần " & INT(T11/20) & ")", IF(AND(E11=20, INT(U11/20)>INT(U10/20)), "TN Ø20 (Lần " & INT(U11/20) & ")", IF(AND(E11=22, INT(V11/20)>INT(V10/20)), "TN Ø22 (Lần " & INT(V11/20) & ")", IF(AND(E11=25, INT(W11/20)>INT(W10/20)), "TN Ø25 (Lần " & INT(W11/20) & ")", IF(AND(E11=28, INT(X11/20)>INT(X10/20)), "TN Ø28 (Lần " & INT(X11/20) & ")", IF(AND(E11=32, INT(Y11/20)>INT(Y10/20)), "TN Ø32 (Lần " & INT(Y11/20) & ")", IF(AND(F11="ASTM A416", INT(Z11/20)>INT(Z10/20)), "TN Cáp 15.2 (Lần " & INT(Z11/20) & ")", ""))))))))))) | P11: =ROUND(P10 + IF(AND(E11<=10, F11<>"ASTM A416"), L11, 0), 3) | Q11: =ROUND(Q10 + IF(AND(E11=12, F11<>"ASTM A416"), L11, 0), 3) | R11: =ROUND(R10 + IF(AND(E11=14, F11<>"ASTM A416"), L11, 0), 3) | S11: =ROUND(S10 + IF(AND(E11=16, F11<>"ASTM A416"), L11, 0), 3) | T11: =ROUND(T10 + IF(AND(E11=18, F11<>"ASTM A416"), L11, 0), 3) | U11: =ROUND(U10 + IF(AND(E11=20, F11<>"ASTM A416"), L11, 0), 3) | V11: =ROUND(V10 + IF(AND(E11=22, F11<>"ASTM A416"), L11, 0), 3) | W11: =ROUND(W10 + IF(AND(E11=25, F11<>"ASTM A416"), L11, 0), 3) | X11: =ROUND(X10 + IF(AND(E11=28, F11<>"ASTM A416"), L11, 0), 3) | Y11: =ROUND(Y10 + IF(AND(E11=32, F11<>"ASTM A416"), L11, 0), 3) | Z11: =ROUND(Z10 + IF(F11="ASTM A416", L11, 0), 3) | AA11: =IF(INT(P11/20)>INT(P10/20), "Lần " & INT(P11/20), "") | AB11: =IF(INT(Q11/20)>INT(Q10/20), "Lần " & INT(Q11/20), "") | AC11: =IF(INT(R11/20)>INT(R10/20), "Lần " & INT(R11/20), "") | AD11: =IF(INT(S11/20)>INT(S10/20), "Lần " & INT(S11/20), "") | AE11: =IF(INT(T11/20)>INT(T10/20), "Lần " & INT(T11/20), "") | AF11: =IF(INT(U11/20)>INT(U10/20), "Lần " & INT(U11/20), "") | AG11: =IF(INT(V11/20)>INT(V10/20), "Lần " & INT(V11/20), "") | AH11: =IF(INT(W11/20)>INT(W10/20), "Lần " & INT(W11/20), "") | ... AK11: =IF(INT(Z11/20)>INT(Z10/20), "Lần " & INT(Z11/20), "") | AL11: ĐẠT TCVN 1651:2018
A12: 8 | B12: Cọc khoan nhồi C1 Mố M1 (D1.2m, L=20.0m) | C12: Cốt thép chủ chịu lực cọc | D12: P6 | E12: 25 | F12: CB400-V | G12: Thanh thẳng nối ren/hàn | H12: 10.433 | I12: 12 | J12: 3.85 | K12: =ROUND(H12*I12*J12, 2) | L12: =ROUND(K12/1000, 3) | O12: =IF(AND(E12<=10, F12<>"ASTM A416", INT(P12/20)>INT(P11/20)), "TN Ø10 (Lần " & INT(P12/20) & ")", IF(AND(E12=12, INT(Q12/20)>INT(Q11/20)), "TN Ø12 (Lần " & INT(Q12/20) & ")", IF(AND(E12=14, INT(R12/20)>INT(R11/20)), "TN Ø14 (Lần " & INT(R12/20) & ")", IF(AND(E12=16, INT(S12/20)>INT(S11/20)), "TN Ø16 (Lần " & INT(S12/20) & ")", IF(AND(E12=18, INT(T12/20)>INT(T11/20)), "TN Ø18 (Lần " & INT(T12/20) & ")", IF(AND(E12=20, INT(U12/20)>INT(U11/20)), "TN Ø20 (Lần " & INT(U12/20) & ")", IF(AND(E12=22, INT(V12/20)>INT(V11/20)), "TN Ø22 (Lần " & INT(V12/20) & ")", IF(AND(E12=25, INT(W12/20)>INT(W11/20)), "TN Ø25 (Lần " & INT(W12/20) & ")", IF(AND(E12=28, INT(X12/20)>INT(X11/20)), "TN Ø28 (Lần " & INT(X12/20) & ")", IF(AND(E12=32, INT(Y12/20)>INT(Y11/20)), "TN Ø32 (Lần " & INT(Y12/20) & ")", IF(AND(F12="ASTM A416", INT(Z12/20)>INT(Z11/20)), "TN Cáp 15.2 (Lần " & INT(Z12/20) & ")", ""))))))))))) | P12: =ROUND(P11 + IF(AND(E12<=10, F12<>"ASTM A416"), L12, 0), 3) | Q12: =ROUND(Q11 + IF(AND(E12=12, F12<>"ASTM A416"), L12, 0), 3) | R12: =ROUND(R11 + IF(AND(E12=14, F12<>"ASTM A416"), L12, 0), 3) | S12: =ROUND(S11 + IF(AND(E12=16, F12<>"ASTM A416"), L12, 0), 3) | T12: =ROUND(T11 + IF(AND(E12=18, F12<>"ASTM A416"), L12, 0), 3) | U12: =ROUND(U11 + IF(AND(E12=20, F12<>"ASTM A416"), L12, 0), 3) | V12: =ROUND(V11 + IF(AND(E12=22, F12<>"ASTM A416"), L12, 0), 3) | W12: =ROUND(W11 + IF(AND(E12=25, F12<>"ASTM A416"), L12, 0), 3) | X12: =ROUND(X11 + IF(AND(E12=28, F12<>"ASTM A416"), L12, 0), 3) | Y12: =ROUND(Y11 + IF(AND(E12=32, F12<>"ASTM A416"), L12, 0), 3) | Z12: =ROUND(Z11 + IF(F12="ASTM A416", L12, 0), 3) | AA12: =IF(INT(P12/20)>INT(P11/20), "Lần " & INT(P12/20), "") | AB12: =IF(INT(Q12/20)>INT(Q11/20), "Lần " & INT(Q12/20), "") | AC12: =IF(INT(R12/20)>INT(R11/20), "Lần " & INT(R12/20), "") | AD12: =IF(INT(S12/20)>INT(S11/20), "Lần " & INT(S12/20), "") | AE12: =IF(INT(T12/20)>INT(T11/20), "Lần " & INT(T12/20), "") | AF12: =IF(INT(U12/20)>INT(U11/20), "Lần " & INT(U12/20), "") | AG12: =IF(INT(V12/20)>INT(V11/20), "Lần " & INT(V12/20), "") | AH12: =IF(INT(W12/20)>INT(W11/20), "Lần " & INT(W12/20), "") | ... AK12: =IF(INT(Z12/20)>INT(Z11/20), "Lần " & INT(Z12/20), "") | AL12: ĐẠT TCVN 1651:2018
A13: 9 | B13: Cọc khoan nhồi C1 Mố M1 (D1.2m, L=20.0m) | C13: Cốt thép chủ chịu lực cọc | D13: P7 | E13: 25 | F13: CB400-V | G13: Thanh thẳng nối ren/hàn | H13: 11.433 | I13: 12 | J13: 3.85 | K13: =ROUND(H13*I13*J13, 2) | L13: =ROUND(K13/1000, 3) | O13: =IF(AND(E13<=10, F13<>"ASTM A416", INT(P13/20)>INT(P12/20)), "TN Ø10 (Lần " & INT(P13/20) & ")", IF(AND(E13=12, INT(Q13/20)>INT(Q12/20)), "TN Ø12 (Lần " & INT(Q13/20) & ")", IF(AND(E13=14, INT(R13/20)>INT(R12/20)), "TN Ø14 (Lần " & INT(R13/20) & ")", IF(AND(E13=16, INT(S13/20)>INT(S12/20)), "TN Ø16 (Lần " & INT(S13/20) & ")", IF(AND(E13=18, INT(T13/20)>INT(T12/20)), "TN Ø18 (Lần " & INT(T13/20) & ")", IF(AND(E13=20, INT(U13/20)>INT(U12/20)), "TN Ø20 (Lần " & INT(U13/20) & ")", IF(AND(E13=22, INT(V13/20)>INT(V12/20)), "TN Ø22 (Lần " & INT(V13/20) & ")", IF(AND(E13=25, INT(W13/20)>INT(W12/20)), "TN Ø25 (Lần " & INT(W13/20) & ")", IF(AND(E13=28, INT(X13/20)>INT(X12/20)), "TN Ø28 (Lần " & INT(X13/20) & ")", IF(AND(E13=32, INT(Y13/20)>INT(Y12/20)), "TN Ø32 (Lần " & INT(Y13/20) & ")", IF(AND(F13="ASTM A416", INT(Z13/20)>INT(Z12/20)), "TN Cáp 15.2 (Lần " & INT(Z13/20) & ")", ""))))))))))) | P13: =ROUND(P12 + IF(AND(E13<=10, F13<>"ASTM A416"), L13, 0), 3) | Q13: =ROUND(Q12 + IF(AND(E13=12, F13<>"ASTM A416"), L13, 0), 3) | R13: =ROUND(R12 + IF(AND(E13=14, F13<>"ASTM A416"), L13, 0), 3) | S13: =ROUND(S12 + IF(AND(E13=16, F13<>"ASTM A416"), L13, 0), 3) | T13: =ROUND(T12 + IF(AND(E13=18, F13<>"ASTM A416"), L13, 0), 3) | U13: =ROUND(U12 + IF(AND(E13=20, F13<>"ASTM A416"), L13, 0), 3) | V13: =ROUND(V12 + IF(AND(E13=22, F13<>"ASTM A416"), L13, 0), 3) | W13: =ROUND(W12 + IF(AND(E13=25, F13<>"ASTM A416"), L13, 0), 3) | X13: =ROUND(X12 + IF(AND(E13=28, F13<>"ASTM A416"), L13, 0), 3) | Y13: =ROUND(Y12 + IF(AND(E13=32, F13<>"ASTM A416"), L13, 0), 3) | Z13: =ROUND(Z12 + IF(F13="ASTM A416", L13, 0), 3) | AA13: =IF(INT(P13/20)>INT(P12/20), "Lần " & INT(P13/20), "") | AB13: =IF(INT(Q13/20)>INT(Q12/20), "Lần " & INT(Q13/20), "") | AC13: =IF(INT(R13/20)>INT(R12/20), "Lần " & INT(R13/20), "") | AD13: =IF(INT(S13/20)>INT(S12/20), "Lần " & INT(S13/20), "") | AE13: =IF(INT(T13/20)>INT(T12/20), "Lần " & INT(T13/20), "") | AF13: =IF(INT(U13/20)>INT(U12/20), "Lần " & INT(U13/20), "") | AG13: =IF(INT(V13/20)>INT(V12/20), "Lần " & INT(V13/20), "") | AH13: =IF(INT(W13/20)>INT(W12/20), "Lần " & INT(W13/20), "") | ... AK13: =IF(INT(Z13/20)>INT(Z12/20), "Lần " & INT(Z13/20), "") | AL13: ĐẠT TCVN 1651:2018
A14: 10 | B14: Cọc khoan nhồi C1 Mố M1 (D1.2m, L=20.0m) | C14: Đai tăng cường / Con kê bảo vệ | D14: P8 | E14: 12 | F14: CB400-V | G14: Móc neo / Vòng đai | H14: 0.647 | I14: 8 | J14: 0.888 | K14: =ROUND(H14*I14*J14, 2) | L14: =ROUND(K14/1000, 3) | O14: =IF(AND(E14<=10, F14<>"ASTM A416", INT(P14/20)>INT(P13/20)), "TN Ø10 (Lần " & INT(P14/20) & ")", IF(AND(E14=12, INT(Q14/20)>INT(Q13/20)), "TN Ø12 (Lần " & INT(Q14/20) & ")", IF(AND(E14=14, INT(R14/20)>INT(R13/20)), "TN Ø14 (Lần " & INT(R14/20) & ")", IF(AND(E14=16, INT(S14/20)>INT(S13/20)), "TN Ø16 (Lần " & INT(S14/20) & ")", IF(AND(E14=18, INT(T14/20)>INT(T13/20)), "TN Ø18 (Lần " & INT(T14/20) & ")", IF(AND(E14=20, INT(U14/20)>INT(U13/20)), "TN Ø20 (Lần " & INT(U14/20) & ")", IF(AND(E14=22, INT(V14/20)>INT(V13/20)), "TN Ø22 (Lần " & INT(V14/20) & ")", IF(AND(E14=25, INT(W14/20)>INT(W13/20)), "TN Ø25 (Lần " & INT(W14/20) & ")", IF(AND(E14=28, INT(X14/20)>INT(X13/20)), "TN Ø28 (Lần " & INT(X14/20) & ")", IF(AND(E14=32, INT(Y14/20)>INT(Y13/20)), "TN Ø32 (Lần " & INT(Y14/20) & ")", IF(AND(F14="ASTM A416", INT(Z14/20)>INT(Z13/20)), "TN Cáp 15.2 (Lần " & INT(Z14/20) & ")", ""))))))))))) | P14: =ROUND(P13 + IF(AND(E14<=10, F14<>"ASTM A416"), L14, 0), 3) | Q14: =ROUND(Q13 + IF(AND(E14=12, F14<>"ASTM A416"), L14, 0), 3) | R14: =ROUND(R13 + IF(AND(E14=14, F14<>"ASTM A416"), L14, 0), 3) | S14: =ROUND(S13 + IF(AND(E14=16, F14<>"ASTM A416"), L14, 0), 3) | T14: =ROUND(T13 + IF(AND(E14=18, F14<>"ASTM A416"), L14, 0), 3) | U14: =ROUND(U13 + IF(AND(E14=20, F14<>"ASTM A416"), L14, 0), 3) | V14: =ROUND(V13 + IF(AND(E14=22, F14<>"ASTM A416"), L14, 0), 3) | W14: =ROUND(W13 + IF(AND(E14=25, F14<>"ASTM A416"), L14, 0), 3) | X14: =ROUND(X13 + IF(AND(E14=28, F14<>"ASTM A416"), L14, 0), 3) | Y14: =ROUND(Y13 + IF(AND(E14=32, F14<>"ASTM A416"), L14, 0), 3) | Z14: =ROUND(Z13 + IF(F14="ASTM A416", L14, 0), 3) | AA14: =IF(INT(P14/20)>INT(P13/20), "Lần " & INT(P14/20), "") | AB14: =IF(INT(Q14/20)>INT(Q13/20), "Lần " & INT(Q14/20), "") | AC14: =IF(INT(R14/20)>INT(R13/20), "Lần " & INT(R14/20), "") | AD14: =IF(INT(S14/20)>INT(S13/20), "Lần " & INT(S14/20), "") | AE14: =IF(INT(T14/20)>INT(T13/20), "Lần " & INT(T14/20), "") | AF14: =IF(INT(U14/20)>INT(U13/20), "Lần " & INT(U14/20), "") | AG14: =IF(INT(V14/20)>INT(V13/20), "Lần " & INT(V14/20), "") | AH14: =IF(INT(W14/20)>INT(W13/20), "Lần " & INT(W14/20), "") | ... AK14: =IF(INT(Z14/20)>INT(Z13/20), "Lần " & INT(Z14/20), "") | AL14: ĐẠT TCVN 1651:2018
A15: 11 | B15: Cọc khoan nhồi C1 Mố M1 (D1.2m, L=20.0m) | C15: Đai tăng cường / Con kê bảo vệ | D15: P9 | E15: 12 | F15: CB400-V | G15: Móc neo / Vòng đai | H15: 0.379 | I15: 24 | J15: 0.888 | K15: =ROUND(H15*I15*J15, 2) | L15: =ROUND(K15/1000, 3) | O15: =IF(AND(E15<=10, F15<>"ASTM A416", INT(P15/20)>INT(P14/20)), "TN Ø10 (Lần " & INT(P15/20) & ")", IF(AND(E15=12, INT(Q15/20)>INT(Q14/20)), "TN Ø12 (Lần " & INT(Q15/20) & ")", IF(AND(E15=14, INT(R15/20)>INT(R14/20)), "TN Ø14 (Lần " & INT(R15/20) & ")", IF(AND(E15=16, INT(S15/20)>INT(S14/20)), "TN Ø16 (Lần " & INT(S15/20) & ")", IF(AND(E15=18, INT(T15/20)>INT(T14/20)), "TN Ø18 (Lần " & INT(T15/20) & ")", IF(AND(E15=20, INT(U15/20)>INT(U14/20)), "TN Ø20 (Lần " & INT(U15/20) & ")", IF(AND(E15=22, INT(V15/20)>INT(V14/20)), "TN Ø22 (Lần " & INT(V15/20) & ")", IF(AND(E15=25, INT(W15/20)>INT(W14/20)), "TN Ø25 (Lần " & INT(W15/20) & ")", IF(AND(E15=28, INT(X15/20)>INT(X14/20)), "TN Ø28 (Lần " & INT(X15/20) & ")", IF(AND(E15=32, INT(Y15/20)>INT(Y14/20)), "TN Ø32 (Lần " & INT(Y15/20) & ")", IF(AND(F15="ASTM A416", INT(Z15/20)>INT(Z14/20)), "TN Cáp 15.2 (Lần " & INT(Z15/20) & ")", ""))))))))))) | P15: =ROUND(P14 + IF(AND(E15<=10, F15<>"ASTM A416"), L15, 0), 3) | Q15: =ROUND(Q14 + IF(AND(E15=12, F15<>"ASTM A416"), L15, 0), 3) | R15: =ROUND(R14 + IF(AND(E15=14, F15<>"ASTM A416"), L15, 0), 3) | S15: =ROUND(S14 + IF(AND(E15=16, F15<>"ASTM A416"), L15, 0), 3) | T15: =ROUND(T14 + IF(AND(E15=18, F15<>"ASTM A416"), L15, 0), 3) | U15: =ROUND(U14 + IF(AND(E15=20, F15<>"ASTM A416"), L15, 0), 3) | V15: =ROUND(V14 + IF(AND(E15=22, F15<>"ASTM A416"), L15, 0), 3) | W15: =ROUND(W14 + IF(AND(E15=25, F15<>"ASTM A416"), L15, 0), 3) | X15: =ROUND(X14 + IF(AND(E15=28, F15<>"ASTM A416"), L15, 0), 3) | Y15: =ROUND(Y14 + IF(AND(E15=32, F15<>"ASTM A416"), L15, 0), 3) | Z15: =ROUND(Z14 + IF(F15="ASTM A416", L15, 0), 3) | AA15: =IF(INT(P15/20)>INT(P14/20), "Lần " & INT(P15/20), "") | AB15: =IF(INT(Q15/20)>INT(Q14/20), "Lần " & INT(Q15/20), "") | AC15: =IF(INT(R15/20)>INT(R14/20), "Lần " & INT(R15/20), "") | AD15: =IF(INT(S15/20)>INT(S14/20), "Lần " & INT(S15/20), "") | AE15: =IF(INT(T15/20)>INT(T14/20), "Lần " & INT(T15/20), "") | AF15: =IF(INT(U15/20)>INT(U14/20), "Lần " & INT(U15/20), "") | AG15: =IF(INT(V15/20)>INT(V14/20), "Lần " & INT(V15/20), "") | AH15: =IF(INT(W15/20)>INT(W14/20), "Lần " & INT(W15/20), "") | ... AK15: =IF(INT(Z15/20)>INT(Z14/20), "Lần " & INT(Z15/20), "") | AL15: ĐẠT TCVN 1651:2018
A16: 12 | B16: Cọc khoan nhồi C1 Mố M1 (D1.2m, L=20.0m) | C16: Thép đai xoắn lồng cọc | D16: P10 | E16: 20 | F16: CB400-V | G16: Đai xoắn tròn | H16: 2.057 | I16: 1 | J16: 2.47 | K16: =ROUND(H16*I16*J16, 2) | L16: =ROUND(K16/1000, 3) | O16: =IF(AND(E16<=10, F16<>"ASTM A416", INT(P16/20)>INT(P15/20)), "TN Ø10 (Lần " & INT(P16/20) & ")", IF(AND(E16=12, INT(Q16/20)>INT(Q15/20)), "TN Ø12 (Lần " & INT(Q16/20) & ")", IF(AND(E16=14, INT(R16/20)>INT(R15/20)), "TN Ø14 (Lần " & INT(R16/20) & ")", IF(AND(E16=16, INT(S16/20)>INT(S15/20)), "TN Ø16 (Lần " & INT(S16/20) & ")", IF(AND(E16=18, INT(T16/20)>INT(T15/20)), "TN Ø18 (Lần " & INT(T16/20) & ")", IF(AND(E16=20, INT(U16/20)>INT(U15/20)), "TN Ø20 (Lần " & INT(U16/20) & ")", IF(AND(E16=22, INT(V16/20)>INT(V15/20)), "TN Ø22 (Lần " & INT(V16/20) & ")", IF(AND(E16=25, INT(W16/20)>INT(W15/20)), "TN Ø25 (Lần " & INT(W16/20) & ")", IF(AND(E16=28, INT(X16/20)>INT(X15/20)), "TN Ø28 (Lần " & INT(X16/20) & ")", IF(AND(E16=32, INT(Y16/20)>INT(Y15/20)), "TN Ø32 (Lần " & INT(Y16/20) & ")", IF(AND(F16="ASTM A416", INT(Z16/20)>INT(Z15/20)), "TN Cáp 15.2 (Lần " & INT(Z16/20) & ")", ""))))))))))) | P16: =ROUND(P15 + IF(AND(E16<=10, F16<>"ASTM A416"), L16, 0), 3) | Q16: =ROUND(Q15 + IF(AND(E16=12, F16<>"ASTM A416"), L16, 0), 3) | R16: =ROUND(R15 + IF(AND(E16=14, F16<>"ASTM A416"), L16, 0), 3) | S16: =ROUND(S15 + IF(AND(E16=16, F16<>"ASTM A416"), L16, 0), 3) | T16: =ROUND(T15 + IF(AND(E16=18, F16<>"ASTM A416"), L16, 0), 3) | U16: =ROUND(U15 + IF(AND(E16=20, F16<>"ASTM A416"), L16, 0), 3) | V16: =ROUND(V15 + IF(AND(E16=22, F16<>"ASTM A416"), L16, 0), 3) | W16: =ROUND(W15 + IF(AND(E16=25, F16<>"ASTM A416"), L16, 0), 3) | X16: =ROUND(X15 + IF(AND(E16=28, F16<>"ASTM A416"), L16, 0), 3) | Y16: =ROUND(Y15 + IF(AND(E16=32, F16<>"ASTM A416"), L16, 0), 3) | Z16: =ROUND(Z15 + IF(F16="ASTM A416", L16, 0), 3) | AA16: =IF(INT(P16/20)>INT(P15/20), "Lần " & INT(P16/20), "") | AB16: =IF(INT(Q16/20)>INT(Q15/20), "Lần " & INT(Q16/20), "") | AC16: =IF(INT(R16/20)>INT(R15/20), "Lần " & INT(R16/20), "") | AD16: =IF(INT(S16/20)>INT(S15/20), "Lần " & INT(S16/20), "") | AE16: =IF(INT(T16/20)>INT(T15/20), "Lần " & INT(T16/20), "") | AF16: =IF(INT(U16/20)>INT(U15/20), "Lần " & INT(U16/20), "") | AG16: =IF(INT(V16/20)>INT(V15/20), "Lần " & INT(V16/20), "") | AH16: =IF(INT(W16/20)>INT(W15/20), "Lần " & INT(W16/20), "") | ... AK16: =IF(INT(Z16/20)>INT(Z15/20), "Lần " & INT(Z16/20), "") | AL16: ĐẠT TCVN 1651:2018
A17: 13 | B17: Cọc khoan nhồi C1 Mố M1 (D1.2m, L=20.0m) | C17: Thanh thép treo lồng cọc | D17: P11 | E17: 16 | F17: CB400-V | G17: Thanh treo lồng (bảng phụ tr.64) | H17: 2.604 | I17: 4 | J17: 1.58 | K17: =ROUND(H17*I17*J17, 2) | L17: =ROUND(K17/1000, 3) | O17: =IF(AND(E17<=10, F17<>"ASTM A416", INT(P17/20)>INT(P16/20)), "TN Ø10 (Lần " & INT(P17/20) & ")", IF(AND(E17=12, INT(Q17/20)>INT(Q16/20)), "TN Ø12 (Lần " & INT(Q17/20) & ")", IF(AND(E17=14, INT(R17/20)>INT(R16/20)), "TN Ø14 (Lần " & INT(R17/20) & ")", IF(AND(E17=16, INT(S17/20)>INT(S16/20)), "TN Ø16 (Lần " & INT(S17/20) & ")", IF(AND(E17=18, INT(T17/20)>INT(T16/20)), "TN Ø18 (Lần " & INT(T17/20) & ")", IF(AND(E17=20, INT(U17/20)>INT(U16/20)), "TN Ø20 (Lần " & INT(U17/20) & ")", IF(AND(E17=22, INT(V17/20)>INT(V16/20)), "TN Ø22 (Lần " & INT(V17/20) & ")", IF(AND(E17=25, INT(W17/20)>INT(W16/20)), "TN Ø25 (Lần " & INT(W17/20) & ")", IF(AND(E17=28, INT(X17/20)>INT(X16/20)), "TN Ø28 (Lần " & INT(X17/20) & ")", IF(AND(E17=32, INT(Y17/20)>INT(Y16/20)), "TN Ø32 (Lần " & INT(Y17/20) & ")", IF(AND(F17="ASTM A416", INT(Z17/20)>INT(Z16/20)), "TN Cáp 15.2 (Lần " & INT(Z17/20) & ")", ""))))))))))) | P17: =ROUND(P16 + IF(AND(E17<=10, F17<>"ASTM A416"), L17, 0), 3) | Q17: =ROUND(Q16 + IF(AND(E17=12, F17<>"ASTM A416"), L17, 0), 3) | R17: =ROUND(R16 + IF(AND(E17=14, F17<>"ASTM A416"), L17, 0), 3) | S17: =ROUND(S16 + IF(AND(E17=16, F17<>"ASTM A416"), L17, 0), 3) | T17: =ROUND(T16 + IF(AND(E17=18, F17<>"ASTM A416"), L17, 0), 3) | U17: =ROUND(U16 + IF(AND(E17=20, F17<>"ASTM A416"), L17, 0), 3) | V17: =ROUND(V16 + IF(AND(E17=22, F17<>"ASTM A416"), L17, 0), 3) | W17: =ROUND(W16 + IF(AND(E17=25, F17<>"ASTM A416"), L17, 0), 3) | X17: =ROUND(X16 + IF(AND(E17=28, F17<>"ASTM A416"), L17, 0), 3) | Y17: =ROUND(Y16 + IF(AND(E17=32, F17<>"ASTM A416"), L17, 0), 3) | Z17: =ROUND(Z16 + IF(F17="ASTM A416", L17, 0), 3) | AA17: =IF(INT(P17/20)>INT(P16/20), "Lần " & INT(P17/20), "") | AB17: =IF(INT(Q17/20)>INT(Q16/20), "Lần " & INT(Q17/20), "") | AC17: =IF(INT(R17/20)>INT(R16/20), "Lần " & INT(R17/20), "") | AD17: =IF(INT(S17/20)>INT(S16/20), "Lần " & INT(S17/20), "") | AE17: =IF(INT(T17/20)>INT(T16/20), "Lần " & INT(T17/20), "") | AF17: =IF(INT(U17/20)>INT(U16/20), "Lần " & INT(U17/20), "") | AG17: =IF(INT(V17/20)>INT(V16/20), "Lần " & INT(V17/20), "") | AH17: =IF(INT(W17/20)>INT(W16/20), "Lần " & INT(W17/20), "") | ... AK17: =IF(INT(Z17/20)>INT(Z16/20), "Lần " & INT(Z17/20), "") | AL17: ĐẠT TCVN 1651:2018
A18: 14 | B18: Cọc khoan nhồi C1 Mố M1 (D1.2m, L=20.0m) | C18: Thép đai xoắn lồng cọc | D18: P12 | E18: 20 | F18: CB400-V | G18: Đai xoắn tròn | H18: 0.583 | I18: 32 | J18: 2.47 | K18: =ROUND(H18*I18*J18, 2) | L18: =ROUND(K18/1000, 3) | O18: =IF(AND(E18<=10, F18<>"ASTM A416", INT(P18/20)>INT(P17/20)), "TN Ø10 (Lần " & INT(P18/20) & ")", IF(AND(E18=12, INT(Q18/20)>INT(Q17/20)), "TN Ø12 (Lần " & INT(Q18/20) & ")", IF(AND(E18=14, INT(R18/20)>INT(R17/20)), "TN Ø14 (Lần " & INT(R18/20) & ")", IF(AND(E18=16, INT(S18/20)>INT(S17/20)), "TN Ø16 (Lần " & INT(S18/20) & ")", IF(AND(E18=18, INT(T18/20)>INT(T17/20)), "TN Ø18 (Lần " & INT(T18/20) & ")", IF(AND(E18=20, INT(U18/20)>INT(U17/20)), "TN Ø20 (Lần " & INT(U18/20) & ")", IF(AND(E18=22, INT(V18/20)>INT(V17/20)), "TN Ø22 (Lần " & INT(V18/20) & ")", IF(AND(E18=25, INT(W18/20)>INT(W17/20)), "TN Ø25 (Lần " & INT(W18/20) & ")", IF(AND(E18=28, INT(X18/20)>INT(X17/20)), "TN Ø28 (Lần " & INT(X18/20) & ")", IF(AND(E18=32, INT(Y18/20)>INT(Y17/20)), "TN Ø32 (Lần " & INT(Y18/20) & ")", IF(AND(F18="ASTM A416", INT(Z18/20)>INT(Z17/20)), "TN Cáp 15.2 (Lần " & INT(Z18/20) & ")", ""))))))))))) | P18: =ROUND(P17 + IF(AND(E18<=10, F18<>"ASTM A416"), L18, 0), 3) | Q18: =ROUND(Q17 + IF(AND(E18=12, F18<>"ASTM A416"), L18, 0), 3) | R18: =ROUND(R17 + IF(AND(E18=14, F18<>"ASTM A416"), L18, 0), 3) | S18: =ROUND(S17 + IF(AND(E18=16, F18<>"ASTM A416"), L18, 0), 3) | T18: =ROUND(T17 + IF(AND(E18=18, F18<>"ASTM A416"), L18, 0), 3) | U18: =ROUND(U17 + IF(AND(E18=20, F18<>"ASTM A416"), L18, 0), 3) | V18: =ROUND(V17 + IF(AND(E18=22, F18<>"ASTM A416"), L18, 0), 3) | W18: =ROUND(W17 + IF(AND(E18=25, F18<>"ASTM A416"), L18, 0), 3) | X18: =ROUND(X17 + IF(AND(E18=28, F18<>"ASTM A416"), L18, 0), 3) | Y18: =ROUND(Y17 + IF(AND(E18=32, F18<>"ASTM A416"), L18, 0), 3) | Z18: =ROUND(Z17 + IF(F18="ASTM A416", L18, 0), 3) | AA18: =IF(INT(P18/20)>INT(P17/20), "Lần " & INT(P18/20), "") | AB18: =IF(INT(Q18/20)>INT(Q17/20), "Lần " & INT(Q18/20), "") | AC18: =IF(INT(R18/20)>INT(R17/20), "Lần " & INT(R18/20), "") | AD18: =IF(INT(S18/20)>INT(S17/20), "Lần " & INT(S18/20), "") | AE18: =IF(INT(T18/20)>INT(T17/20), "Lần " & INT(T18/20), "") | AF18: =IF(INT(U18/20)>INT(U17/20), "Lần " & INT(U18/20), "") | AG18: =IF(INT(V18/20)>INT(V17/20), "Lần " & INT(V18/20), "") | AH18: =IF(INT(W18/20)>INT(W17/20), "Lần " & INT(W18/20), "") | ... AK18: =IF(INT(Z18/20)>INT(Z17/20), "Lần " & INT(Z18/20), "") | AL18: ĐẠT TCVN 1651:2018
A19: --- CỌC KHOAN NHỒI C2 MỐ M1 (D1.2M, L=20.0M) ---
A20: 15 | B20: Cọc khoan nhồi C2 Mố M1 (D1.2m, L=20.0m) | C20: Thép đai xoắn lồng cọc | D20: P1 | E20: 10 | F20: CB240-T | G20: Đai xoắn tròn | H20: 96.604 | I20: 1 | J20: 0.617 | K20: =ROUND(H20*I20*J20, 2) | L20: =ROUND(K20/1000, 3) | O20: =IF(AND(E20<=10, F20<>"ASTM A416", INT(P20/20)>INT(P18/20)), "TN Ø10 (Lần " & INT(P20/20) & ")", IF(AND(E20=12, INT(Q20/20)>INT(Q18/20)), "TN Ø12 (Lần " & INT(Q20/20) & ")", IF(AND(E20=14, INT(R20/20)>INT(R18/20)), "TN Ø14 (Lần " & INT(R20/20) & ")", IF(AND(E20=16, INT(S20/20)>INT(S18/20)), "TN Ø16 (Lần " & INT(S20/20) & ")", IF(AND(E20=18, INT(T20/20)>INT(T18/20)), "TN Ø18 (Lần " & INT(T20/20) & ")", IF(AND(E20=20, INT(U20/20)>INT(U18/20)), "TN Ø20 (Lần " & INT(U20/20) & ")", IF(AND(E20=22, INT(V20/20)>INT(V18/20)), "TN Ø22 (Lần " & INT(V20/20) & ")", IF(AND(E20=25, INT(W20/20)>INT(W18/20)), "TN Ø25 (Lần " & INT(W20/20) & ")", IF(AND(E20=28, INT(X20/20)>INT(X18/20)), "TN Ø28 (Lần " & INT(X20/20) & ")", IF(AND(E20=32, INT(Y20/20)>INT(Y18/20)), "TN Ø32 (Lần " & INT(Y20/20) & ")", IF(AND(F20="ASTM A416", INT(Z20/20)>INT(Z18/20)), "TN Cáp 15.2 (Lần " & INT(Z20/20) & ")", ""))))))))))) | P20: =ROUND(P18 + IF(AND(E20<=10, F20<>"ASTM A416"), L20, 0), 3) | Q20: =ROUND(Q18 + IF(AND(E20=12, F20<>"ASTM A416"), L20, 0), 3) | R20: =ROUND(R18 + IF(AND(E20=14, F20<>"ASTM A416"), L20, 0), 3) | S20: =ROUND(S18 + IF(AND(E20=16, F20<>"ASTM A416"), L20, 0), 3) | T20: =ROUND(T18 + IF(AND(E20=18, F20<>"ASTM A416"), L20, 0), 3) | U20: =ROUND(U18 + IF(AND(E20=20, F20<>"ASTM A416"), L20, 0), 3) | V20: =ROUND(V18 + IF(AND(E20=22, F20<>"ASTM A416"), L20, 0), 3) | W20: =ROUND(W18 + IF(AND(E20=25, F20<>"ASTM A416"), L20, 0), 3) | X20: =ROUND(X18 + IF(AND(E20=28, F20<>"ASTM A416"), L20, 0), 3) | Y20: =ROUND(Y18 + IF(AND(E20=32, F20<>"ASTM A416"), L20, 0), 3) | Z20: =ROUND(Z18 + IF(F20="ASTM A416", L20, 0), 3) | AA20: =IF(INT(P20/20)>INT(P18/20), "Lần " & INT(P20/20), "") | AB20: =IF(INT(Q20/20)>INT(Q18/20), "Lần " & INT(Q20/20), "") | AC20: =IF(INT(R20/20)>INT(R18/20), "Lần " & INT(R20/20), "") | AD20: =IF(INT(S20/20)>INT(S18/20), "Lần " & INT(S20/20), "") | AE20: =IF(INT(T20/20)>INT(T18/20), "Lần " & INT(T20/20), "") | AF20: =IF(INT(U20/20)>INT(U18/20), "Lần " & INT(U20/20), "") | AG20: =IF(INT(V20/20)>INT(V18/20), "Lần " & INT(V20/20), "") | AH20: =IF(INT(W20/20)>INT(W18/20), "Lần " & INT(W20/20), "") | ... AK20: =IF(INT(Z20/20)>INT(Z18/20), "Lần " & INT(Z20/20), "") | AL20: ĐẠT TCVN 1651:2018
A21: 16 | B21: Cọc khoan nhồi C2 Mố M1 (D1.2m, L=20.0m) | C21: Thép đai xoắn lồng cọc | D21: P1A | E21: 10 | F21: CB240-T | G21: Đai xoắn tròn | H21: 373.535 | I21: 1 | J21: 0.617 | K21: =ROUND(H21*I21*J21, 2) | L21: =ROUND(K21/1000, 3) | O21: =IF(AND(E21<=10, F21<>"ASTM A416", INT(P21/20)>INT(P20/20)), "TN Ø10 (Lần " & INT(P21/20) & ")", IF(AND(E21=12, INT(Q21/20)>INT(Q20/20)), "TN Ø12 (Lần " & INT(Q21/20) & ")", IF(AND(E21=14, INT(R21/20)>INT(R20/20)), "TN Ø14 (Lần " & INT(R21/20) & ")", IF(AND(E21=16, INT(S21/20)>INT(S20/20)), "TN Ø16 (Lần " & INT(S21/20) & ")", IF(AND(E21=18, INT(T21/20)>INT(T20/20)), "TN Ø18 (Lần " & INT(T21/20) & ")", IF(AND(E21=20, INT(U21/20)>INT(U20/20)), "TN Ø20 (Lần " & INT(U21/20) & ")", IF(AND(E21=22, INT(V21/20)>INT(V20/20)), "TN Ø22 (Lần " & INT(V21/20) & ")", IF(AND(E21=25, INT(W21/20)>INT(W20/20)), "TN Ø25 (Lần " & INT(W21/20) & ")", IF(AND(E21=28, INT(X21/20)>INT(X20/20)), "TN Ø28 (Lần " & INT(X21/20) & ")", IF(AND(E21=32, INT(Y21/20)>INT(Y20/20)), "TN Ø32 (Lần " & INT(Y21/20) & ")", IF(AND(F21="ASTM A416", INT(Z21/20)>INT(Z20/20)), "TN Cáp 15.2 (Lần " & INT(Z21/20) & ")", ""))))))))))) | P21: =ROUND(P20 + IF(AND(E21<=10, F21<>"ASTM A416"), L21, 0), 3) | Q21: =ROUND(Q20 + IF(AND(E21=12, F21<>"ASTM A416"), L21, 0), 3) | R21: =ROUND(R20 + IF(AND(E21=14, F21<>"ASTM A416"), L21, 0), 3) | S21: =ROUND(S20 + IF(AND(E21=16, F21<>"ASTM A416"), L21, 0), 3) | T21: =ROUND(T20 + IF(AND(E21=18, F21<>"ASTM A416"), L21, 0), 3) | U21: =ROUND(U20 + IF(AND(E21=20, F21<>"ASTM A416"), L21, 0), 3) | V21: =ROUND(V20 + IF(AND(E21=22, F21<>"ASTM A416"), L21, 0), 3) | W21: =ROUND(W20 + IF(AND(E21=25, F21<>"ASTM A416"), L21, 0), 3) | X21: =ROUND(X20 + IF(AND(E21=28, F21<>"ASTM A416"), L21, 0), 3) | Y21: =ROUND(Y20 + IF(AND(E21=32, F21<>"ASTM A416"), L21, 0), 3) | Z21: =ROUND(Z20 + IF(F21="ASTM A416", L21, 0), 3) | AA21: =IF(INT(P21/20)>INT(P20/20), "Lần " & INT(P21/20), "") | AB21: =IF(INT(Q21/20)>INT(Q20/20), "Lần " & INT(Q21/20), "") | AC21: =IF(INT(R21/20)>INT(R20/20), "Lần " & INT(R21/20), "") | AD21: =IF(INT(S21/20)>INT(S20/20), "Lần " & INT(S21/20), "") | AE21: =IF(INT(T21/20)>INT(T20/20), "Lần " & INT(T21/20), "") | AF21: =IF(INT(U21/20)>INT(U20/20), "Lần " & INT(U21/20), "") | AG21: =IF(INT(V21/20)>INT(V20/20), "Lần " & INT(V21/20), "") | AH21: =IF(INT(W21/20)>INT(W20/20), "Lần " & INT(W21/20), "") | ... AK21: =IF(INT(Z21/20)>INT(Z20/20), "Lần " & INT(Z21/20), "") | AL21: ĐẠT TCVN 1651:2018
