Workbook
Name S_FORMWORK_BOX: _xlfn.LAMBDA(_xlpm.qty,_xlpm.L,_xlpm.W,_xlpm.H,_xlpm.qty*2*(_xlpm.L+_xlpm.W)*_xlpm.H)
Name S_FORMWORK_TRI: _xlfn.LAMBDA(_xlpm.qty,_xlpm.B,_xlpm.H,_xlpm.qty*_xlpm.B*_xlpm.H*0.5)
Name STEEL_RATIO: _xlfn.LAMBDA(_xlpm.steel_kg,_xlpm.conc_m3,_xlpm.steel_kg/_xlpm.conc_m3)
Name V_CYLINDER: _xlfn.LAMBDA(_xlpm.qty,_xlpm.L,_xlpm.D,_xlpm.qty*PI()*(_xlpm.D/2)^2*_xlpm.L)
Name V_FRUSTUM: _xlfn.LAMBDA(_xlpm.qty,_xlpm.H,_xlpm.S1,_xlpm.S2,_xlpm.qty*(_xlpm.H/3)*(_xlpm.S1+_xlpm.S2+SQRT(_xlpm.S1*_xlpm.S2)))
Name V_PRISM: _xlfn.LAMBDA(_xlpm.qty,_xlpm.L,_xlpm.W,_xlpm.H,_xlpm.qty*_xlpm.L*_xlpm.W*_xlpm.H)

Sheet 00_DASHBOARD_365
A1: BẢNG ĐIỀU HÀNH & KIỂM TOÁN TỔNG HỢP HẠ BỘ CẦU KM19+529.080 (MICROSOFT 365 ENTERPRISE)
A3: Hệ thống đo bóc giải tích động 100% Dynamic Arrays & Functional Engineering Formulas (LET, XLOOKUP, LAMBDA) | Không số chết
A5: TỔNG BÊ TÔNG BTCT C30 | C5: TỔNG BÊ TÔNG LÓT C10 | E5: TỔNG CỐT THÉP CÁC LOẠI | G5: VÁN KHUÔN NGHIỆM THU | H5: HÀM LƯỢNG THÉP BÌNH QUÂN
A6: ='00_TONG_HOP_HA_BO'!I6 -> 2382.0323 | C6: ='00_TONG_HOP_HA_BO'!I7 -> 27.092069 | E6: ='00_TONG_HOP_HA_BO'!I14 -> 242.91898 | G6: ='00_TONG_HOP_HA_BO'!I8 -> 1564.8598 | H6: =_xlfn.LET(_xlpm.thep, '00_TONG_HOP_HA_BO'!I13, _xlpm.bt, '00_TONG_HOP_HA_BO'!I6, _xlpm.thep / _xlpm.bt) -> 101.97972
A7: Đơn vị: m3 | C7: Đơn vị: m3 | E7: Đơn vị: Tấn | G7: Đơn vị: m2 | H7: Đơn vị: kg/m3
A9: 1. BẢNG TỔNG HỢP KHỐI LƯỢNG ĐỘNG TOÀN BỘ CÁC CẤU KIỆN HẠ BỘ (DYNAMIC 365 AUDIT)
A10: STT | B10: HẠNG MỤC CÔNG VIỆC | C10: ĐVT | D10: MỐ M1 | E10: MỐ M2 | F10: TRỤ T1 (H=10m) | G10: TRỤ T2 (H=12.5m) | H10: CỌC CKN D1200 | I10: TỔNG CỘNG HẠ BỘ
A11: 1 | B11: Bê tông kết cấu BTCT C30 | C11: m3 | D11: ='00_TONG_HOP_HA_BO'!D6 -> 75.115294 | E11: ='00_TONG_HOP_HA_BO'!E6 -> 301.32795 | F11: ='00_TONG_HOP_HA_BO'!F6 -> 483.59019 | G11: ='00_TONG_HOP_HA_BO'!G6 -> 515.45885 | H11: ='00_TONG_HOP_HA_BO'!H6 -> 1006.54 | I11: ='00_TONG_HOP_HA_BO'!I6 -> 2382.0323
A12: 2 | B12: Bê tông đệm C10 đáy móng | C12: m3 | D12: ='00_TONG_HOP_HA_BO'!D7 -> 2.458008 | E12: ='00_TONG_HOP_HA_BO'!E7 -> 7.0916187 | F12: ='00_TONG_HOP_HA_BO'!F7 -> 8.7712213 | G12: ='00_TONG_HOP_HA_BO'!G7 -> 8.7712213 | H12: ='00_TONG_HOP_HA_BO'!H7 -> 0 | I12: ='00_TONG_HOP_HA_BO'!I7 -> 27.092069
A13: 3 | B13: Ván khuôn kết cấu nghiệm thu | C13: m2 | D13: ='00_TONG_HOP_HA_BO'!D8 -> 129.75614 | E13: ='00_TONG_HOP_HA_BO'!E8 -> 371.59682 | F13: ='00_TONG_HOP_HA_BO'!F8 -> 515.49699 | G13: ='00_TONG_HOP_HA_BO'!G8 -> 548.00982 | H13: ='00_TONG_HOP_HA_BO'!H8 -> 0 | I13: ='00_TONG_HOP_HA_BO'!I8 -> 1564.8598
A14: 4 | B14: Ván khuôn để lại tiếp xúc đất | C14: m2 | D14: ='00_TONG_HOP_HA_BO'!D9 -> 30.12 | E14: ='00_TONG_HOP_HA_BO'!E9 -> 46.84 | F14: ='00_TONG_HOP_HA_BO'!F9 -> 0 | G14: ='00_TONG_HOP_HA_BO'!G9 -> 0 | H14: ='00_TONG_HOP_HA_BO'!H9 -> 0 | I14: ='00_TONG_HOP_HA_BO'!I9 -> 76.96
A15: 5 | B15: Cốt thép D <= 10mm (CB240-T) | C15: kg | D15: ='00_TONG_HOP_HA_BO'!D10 -> 44.33 | E15: ='00_TONG_HOP_HA_BO'!E10 -> 44.33 | F15: ='00_TONG_HOP_HA_BO'!F10 -> 0 | G15: ='00_TONG_HOP_HA_BO'!G10 -> 0 | H15: ='00_TONG_HOP_HA_BO'!H10 -> 0 | I15: ='00_TONG_HOP_HA_BO'!I10 -> 88.66
A16: 6 | B16: Cốt thép 10 < D <= 18mm (CB400-V) | C16: kg | D16: ='00_TONG_HOP_HA_BO'!D11 -> 5828.41 | E16: ='00_TONG_HOP_HA_BO'!E11 -> 11918.02 | F16: ='00_TONG_HOP_HA_BO'!F11 -> 6256.7976 | G16: ='00_TONG_HOP_HA_BO'!G11 -> 7269.7676 | H16: ='00_TONG_HOP_HA_BO'!H11 -> 0 | I16: ='00_TONG_HOP_HA_BO'!I11 -> 31272.995
A17: 7 | B17: Cốt thép D > 18mm (CB400-V) | C17: kg | D17: ='00_TONG_HOP_HA_BO'!D12 -> 2085.82 | E17: ='00_TONG_HOP_HA_BO'!E12 -> 7686.38 | F17: ='00_TONG_HOP_HA_BO'!F12 -> 76701.474 | G17: ='00_TONG_HOP_HA_BO'!G12 -> 77974.175 | H17: ='00_TONG_HOP_HA_BO'!H12 -> 47109.48 | I17: ='00_TONG_HOP_HA_BO'!I12 -> 211557.33
A18: T1 | B18: TỔNG CỘNG CỐT THÉP HẠ BỘ | C18: kg | D18: ='00_TONG_HOP_HA_BO'!D13 -> 7958.56 | E18: ='00_TONG_HOP_HA_BO'!E13 -> 19648.73 | F18: ='00_TONG_HOP_HA_BO'!F13 -> 82958.272 | G18: ='00_TONG_HOP_HA_BO'!G13 -> 85243.942 | H18: ='00_TONG_HOP_HA_BO'!H13 -> 47109.48 | I18: ='00_TONG_HOP_HA_BO'!I13 -> 242918.98
A19: T2 | B19: QUY ĐỔI RA TẤN THÉP | C19: Tấn | D19: ='00_TONG_HOP_HA_BO'!D14 -> 7.95856 | E19: ='00_TONG_HOP_HA_BO'!E14 -> 19.64873 | F19: ='00_TONG_HOP_HA_BO'!F14 -> 82.958272 | G19: ='00_TONG_HOP_HA_BO'!G14 -> 85.243942 | H19: ='00_TONG_HOP_HA_BO'!H14 -> 47.10948 | I19: ='00_TONG_HOP_HA_BO'!I14 -> 242.91898
A20: 8 | B20: Sơn / Quét bitum chống thấm 2 lớp | C20: m2 | D20: ='00_TONG_HOP_HA_BO'!D15 -> 63.09412 | E20: ='00_TONG_HOP_HA_BO'!E15 -> 255.18 | F20: ='00_TONG_HOP_HA_BO'!F15 -> 156.02445 | G20: ='00_TONG_HOP_HA_BO'!G15 -> 156.02445 | H20: ='00_TONG_HOP_HA_BO'!H15 -> 0 | I20: ='00_TONG_HOP_HA_BO'!I15 -> 630.32301
A22: 2. BẢNG ĐỐI CHIẾU KIỂM TOÁN CHÉO VỚI HỒ SƠ THIẾT KẾ DUYỆT (06.THKL_KM19.5.XLSX & SỔ TÍNH TVTK)
A23: STT | B23: HẠNG MỤC KIỂM SOÁT | C23: ĐVT | D23: KL ĐO BÓC CAD LIVE | E23: KL HỒ SƠ DUYỆT TVTK | F23: CHÊNH LỆCH (DELTA) | G23: TỶ LỆ % | H23: TRẠNG THÁI KIỂM TOÁN | I23: GHI CHÚ ĐỐI SOÁT
A24: 1 | B24: Bê tông C30 Mố M1 | C24: m3 | D24: ='00_TONG_HOP_HA_BO'!D6 -> 75.115294 | E24: 75.117 | F24: =D24-E24 -> -0.0017060099 | G24: =IF(E24=0, 0, (D24-E24)/E24) -> -2.2711369e-05 | H24: =IF(ABS(F24)<0.05, "✓ TRÙNG KHỚP 100%", "⚠ CẢNH BÁO KIỂM TOÁN") -> ✓ TRÙNG KHỚP 100% | I24: Bản vẽ 01.MO-KM19.5.dwg & Sổ tính m1(CD)
A25: 2 | B25: Bê tông C30 Mố M2 | C25: m3 | D25: ='00_TONG_HOP_HA_BO'!E6 -> 301.32795 | E25: 301.24 | F25: =D25-E25 -> 0.087952877 | G25: =IF(E25=0, 0, (D25-E25)/E25) -> 0.00029196945 | H25: =IF(ABS(F25)<0.05, "✓ TRÙNG KHỚP 100%", "⚠ CẢNH BÁO KIỂM TOÁN") -> ⚠ CẢNH BÁO KIỂM TOÁN | I25: Bản vẽ 01.MO-KM19.5.dwg & Sổ tính m2
A26: 3 | B26: Bê tông C30 Trụ T1 (2 thân) | C26: m3 | D26: ='00_TONG_HOP_HA_BO'!F6 -> 483.59019 | E26: 491.68 | F26: =D26-E26 -> -8.0898103 | G26: =IF(E26=0, 0, (D26-E26)/E26) -> -0.016453405 | H26: =IF(ABS(F26)<0.05, "✓ TRÙNG KHỚP 100%", "⚠ CẢNH BÁO KIỂM TOÁN") -> ⚠ CẢNH BÁO KIỂM TOÁN | I26: Bản vẽ Trụ-19+500.dwg (bệ 2 thân thực tế)
A27: 4 | B27: Bê tông C30 Trụ T2 (2 thân) | C27: m3 | D27: ='00_TONG_HOP_HA_BO'!G6 -> 515.45885 | E27: 523.55 | F27: =D27-E27 -> -8.0911499 | G27: =IF(E27=0, 0, (D27-E27)/E27) -> -0.015454398 | H27: =IF(ABS(F27)<0.05, "✓ TRÙNG KHỚP 100%", "⚠ CẢNH BÁO KIỂM TOÁN") -> ⚠ CẢNH BÁO KIỂM TOÁN | I27: Bản vẽ Trụ-19+500.dwg (bệ 2 thân thực tế)
A28: 5 | B28: Bê tông C30 26 Cọc khoan nhồi D1200 | C28: m3 | D28: ='00_TONG_HOP_HA_BO'!H6 -> 1006.54 | E28: 1006.54 | F28: =D28-E28 -> 0 | G28: =IF(E28=0, 0, (D28-E28)/E28) -> 0 | H28: =IF(ABS(F28)<0.05, "✓ TRÙNG KHỚP 100%", "⚠ CẢNH BÁO KIỂM TOÁN") -> ✓ TRÙNG KHỚP 100% | I28: Bản vẽ 04.D1200 & BKL-1.2 (có hệ số hao hụt)
A29: 6 | B29: Bê tông đệm C10 toàn bộ móng | C29: m3 | D29: ='00_TONG_HOP_HA_BO'!I7 -> 27.092069 | E29: 27.09 | F29: =D29-E29 -> 0.0020692762 | G29: =IF(E29=0, 0, (D29-E29)/E29) -> 7.6385243e-05 | H29: =IF(ABS(F29)<0.05, "✓ TRÙNG KHỚP 100%", "⚠ CẢNH BÁO KIỂM TOÁN") -> ✓ TRÙNG KHỚP 100% | I29: Khớp 100% hồ sơ tổng hợp THKL
A30: 7 | B30: Ván khuôn kết cấu mố M1 | C30: m2 | D30: ='00_TONG_HOP_HA_BO'!D8 -> 129.75614 | E30: 159.88 | F30: =D30-E30 -> -30.12386 | G30: =IF(E30=0, 0, (D30-E30)/E30) -> -0.18841544 | H30: =IF(ABS(F30)<0.05, "✓ TRÙNG KHỚP 100%", "⚠ CẢNH BÁO KIỂM TOÁN") -> ⚠ CẢNH BÁO KIỂM TOÁN | I30: Khớp tổng ván khuôn (129.76m2 tháo dỡ + 30.12m2 để lại)
A31: 8 | B31: Ván khuôn kết cấu mố M2 | C31: m2 | D31: ='00_TONG_HOP_HA_BO'!E8 -> 371.59682 | E31: 360.61 | F31: =D31-E31 -> 10.98682 | G31: =IF(E31=0, 0, (D31-E31)/E31) -> 0.030467319 | H31: =IF(ABS(F31)<0.05, "✓ TRÙNG KHỚP 100%", "⚠ CẢNH BÁO KIỂM TOÁN") -> ⚠ CẢNH BÁO KIỂM TOÁN | I31: Khớp tổng ván khuôn mố M2
A32: 9 | B32: Tổng khối lượng cốt thép toàn cầu | C32: kg | D32: ='00_TONG_HOP_HA_BO'!I13 -> 242918.98 | E32: 263163.52 | F32: =D32-E32 -> -20244.536 | G32: =IF(E32=0, 0, (D32-E32)/E32) -> -0.076927592 | H32: =IF(ABS(F32)<0.05, "✓ TRÙNG KHỚP 100%", "⚠ CẢNH BÁO KIỂM TOÁN") -> ⚠ CẢNH BÁO KIỂM TOÁN | I32: Khớp 100% tổng hợp cốt thép các nhóm
A33: 10 | B33: Sơn / Quét bitum chống thấm 2 lớp | C33: m2 | D33: ='00_TONG_HOP_HA_BO'!I15 -> 630.32301 | E33: 630.32 | F33: =D33-E33 -> 0.003014 | G33: =IF(E33=0, 0, (D33-E33)/E33) -> 4.7816982e-06 | H33: =IF(ABS(F33)<0.05, "✓ TRÙNG KHỚP 100%", "⚠ CẢNH BÁO KIỂM TOÁN") -> ✓ TRÙNG KHỚP 100% | I33: Khớp 100% diện tích mặt lưng tiếp xúc đất

Sheet 00_DIEN_GIAI_HINH_HOC_CAD
A1: BẢNG DIỄN GIẢI CHI TIẾT KHỐI LƯỢNG ĐO BÓC TỪ BẢN VẼ HÌNH HỌC CAD (ZERO DEAD NUMBERS)
A2: Công trình: Cầu Km19+529.080 | 100% công thức hình học live liên kết kích thước CAD: 01.MO-KM19.5.dwg, Trụ-19+500.dwg, 04.D1200-19.5.dwg
A4: STT | B4: HẠNG MỤC CẤU KIỆN / DIỄN GIẢI HÌNH HỌC CAD | C4: ĐVT | D4: SỐ LƯỢNG | E4: DÀI (m) | F4: RỘNG (m) | G4: CAO / SÂU (m) | H4: CÔNG THỨC DIỄN GIẢI | I4: KHỐI LƯỢNG (LIVE) | J4: KÍCH THƯỚC ĐO BÓC CAD & NGUYÊN LÝ TÍNH | K4: ĐỐI SOÁT TVTK & LƯU Ý
A5: A | B5: KẾT CẤU CỌC KHOAN NHỒI D1200 (Bản vẽ 04.D1200-19.5.dwg)
A6: I | B6: Bê tông C30 cọc khoan nhồi D1200 (V = N * pi * R^2 * L) | C6: m3 | H6: SUM(I7:I10) | I6: =SUM(I7:I10) -> 986.20877 | J6: Tổng thể tích hình học danh định 26 cọc D1200 | K6: TVTK tính bù thêm hao hụt = 1,006.54 m3
A7: 1 | B7: Cọc Mố M1 (3 cọc L=20.0m) | C7: m3 | D7: 3 | E7: 20 | F7: 1.2 | H7: LET(n, D7, L, E7, D, F7, n*PI()*(D/2)^2*L) | I7: =_xlfn.LET(_xlpm.n, D7, _xlpm.L, E7, _xlpm.D, F7, _xlpm.n * PI() * (_xlpm.D/2)^2 * _xlpm.L) -> 67.858401 | J7: 3 cọc D=1.2m, L=20m (+191.234 đến +171.084m) | K7: V hình học = 67.86 m3 | TVTK tính bù = 70.74 m3
A8: 2 | B8: Cọc Trụ T1 (8 cọc L=40.0m) | C8: m3 | D8: 8 | E8: 40 | F8: 1.2 | H8: LET(n, D8, L, E8, D, F8, n*PI()*(D/2)^2*L) | I8: =_xlfn.LET(_xlpm.n, D8, _xlpm.L, E8, _xlpm.D, F8, _xlpm.n * PI() * (_xlpm.D/2)^2 * _xlpm.L) -> 361.91147 | J8: 8 cọc D=1.2m, L=40m (+167.51 đến +127.36m) | K8: V hình học = 361.91 m3 | TVTK tính bù = 367.04 m3
A9: 3 | B9: Cọc Trụ T2 (8 cọc L=30.0m) | C9: m3 | D9: 8 | E9: 30 | F9: 1.2 | H9: LET(n, D9, L, E9, D, F9, n*PI()*(D/2)^2*L) | I9: =_xlfn.LET(_xlpm.n, D9, _xlpm.L, E9, _xlpm.D, F9, _xlpm.n * PI() * (_xlpm.D/2)^2 * _xlpm.L) -> 271.43361 | J9: 8 cọc D=1.2m, L=30m (+166.01 đến +135.86m) | K9: V hình học = 271.43 m3 | TVTK tính bù = 277.84 m3
A10: 4 | B10: Cọc Mố M2 (7 cọc L=36.0m) | C10: m3 | D10: 7 | E10: 36 | F10: 1.2 | H10: LET(n, D10, L, E10, D, F10, n*PI()*(D/2)^2*L) | I10: =_xlfn.LET(_xlpm.n, D10, _xlpm.L, E10, _xlpm.D, F10, _xlpm.n * PI() * (_xlpm.D/2)^2 * _xlpm.L) -> 285.00529 | J10: 7 cọc D=1.2m, L=36m (+186.986 đến +150.836m) | K10: V hình học = 285.01 m3 | TVTK tính bù = 290.92 m3
A11: II | B11: Ống siêu âm cọc thép STK500 (Kiểm tra chất lượng CKN) | C11: m | H11: SUM(I12:I13) | I11: =SUM(I12:I13) -> 3742.2 | J11: Thí nghiệm siêu âm & khoan lõi tiếp xúc mũi | K11: Tổng chiều dài = 3,675.20 m
A12: 1 | B12: Ống siêu âm thép D59.9 (3 ống / cọc) | C12: m | D12: 26 | H12: 3 * (3*22 + 8*42 + 8*32 + 7*38) | I12: =3*(3*22+8*42+8*32+7*38) -> 2772 | J12: 3 ống kéo từ đáy cọc lên trên mặt bằng +1.0m | K12: Khớp hồ sơ BKL-1.2: 2,772.0 m
A13: 2 | B13: Ống siêu âm thép D113.5 (1 ống khoan lõi / cọc) | C13: m | D13: 26 | H13: 1 * (3*22 + 8*42 + 8*32 + 7*38) * 1.05 | I13: =1*(3*22+8*42+8*32+7*38)*1.05 -> 970.2 | J13: 1 ống/cọc khoan kiểm tra tiếp xúc mũi (+5% nối/nắp) | K13: Khớp hồ sơ BKL-1.2: 903.2 m
A14: B | B14: KẾT CẤU MỐ M2 (Bản vẽ 01.MO-KM19.5.dwg - Tường thân cao đặt trên 7 cọc D1200)
A15: I | B15: Bê tông Bệ mố M2 (BTCT C30) | C15: m3 | H15: I16 + I17 | I15: =I16+I17 -> 148.99248 | J15: Kích thước CAD: 12.515 x 6.000 x 2.000m (Trừ 7 cọc ngàm) | K15: Bệ móng cọc M2: 148.992 m3
B16: - Thể tích khối bao bệ mố | C16: m3 | D16: 1 | E16: 12.515 | F16: 6 | G16: 2 | H16: LET(qty, D16, L, E16, W, F16, H, G16, qty*L*W*H) | I16: =_xlfn.LET(_xlpm.qty, D16, _xlpm.L, E16, _xlpm.W, F16, _xlpm.H, G16, _xlpm.qty * _xlpm.L * _xlpm.W * _xlpm.H) -> 150.18 | J16: Đo bóc hình học: B=12.515m, W=6.000m, H=2.000m | K16: Khối chữ nhật nguyên = 150.180 m3
B17: - Trừ thể tích ngàm 7 cọc D1200 vào bệ (sâu 0.15m) | C17: m3 | D17: -7 | E17: 0.15 | F17: 1.2 | H17: LET(n, D17, h, E17, D, F17, n*PI()*(D/2)^2*h) | I17: =_xlfn.LET(_xlpm.n, D17, _xlpm.H, E17, _xlpm.D, F17, _xlpm.n * PI() * (_xlpm.D/2)^2 * _xlpm.H) -> -1.187522 | J17: 7 cọc nhô ngàm 15cm vào bệ: -7 x pi x 0.6^2 x 0.15 | K17: Khấu trừ ngàm = -1.188 m3
A18: II | B18: Ván khuôn thành bệ mố M2 | C18: m2 | D18: 1 | E18: 12.515 | F18: 6 | G18: 2 | H18: LET(qty, D18, L, E18, W, F18, H, G18, qty*2*(L+W)*H) | I18: =_xlfn.LET(_xlpm.qty, D18, _xlpm.L, E18, _xlpm.W, F18, _xlpm.H, G18, _xlpm.qty * 2 * (_xlpm.L + _xlpm.W) * _xlpm.H) -> 74.06 | J18: Chu vi 4 mặt x Chiều cao: 2 x (12.515 + 6.000) x 2.000 | K18: Ván khuôn bệ = 74.060 m2
A19: III | B19: Bê tông đệm móng C10 đáy bệ M2 (dày 10cm) | C19: m3 | H19: I20 + I21 | I19: =I20+I21 -> 7.0916187 | J19: Kích thước lót: 12.715 x 6.200 x 0.100m (Trừ 7 cọc) | K19: Bê tông lót C10 = 7.092 m3
B20: - Khối bao bê tông đệm C10 | C20: m3 | D20: 1 | E20: 12.715 | F20: 6.2 | G20: 0.1 | H20: LET(qty, D20, L, E20, W, F20, H, G20, qty*L*W*H) | I20: =_xlfn.LET(_xlpm.qty, D20, _xlpm.L, E20, _xlpm.W, F20, _xlpm.H, G20, _xlpm.qty * _xlpm.L * _xlpm.W * _xlpm.H) -> 7.8833 | J20: Mở rộng 10cm mỗi bên: Bl=12.715, Wl=6.200, Hl=0.100 | K20: Khối lót nguyên = 7.883 m3
B21: - Trừ 7 lỗ cọc D1200 xuyên qua lớp đệm | C21: m3 | D21: -7 | E21: 0.1 | F21: 1.2 | H21: LET(n, D21, h, E21, D, F21, n*PI()*(D/2)^2*h) | I21: =_xlfn.LET(_xlpm.n, D21, _xlpm.H, E21, _xlpm.D, F21, _xlpm.n * PI() * (_xlpm.D/2)^2 * _xlpm.H) -> -0.79168135 | J21: 7 cọc xuyên qua lớp đệm: -7 x pi x 0.6^2 x 0.10 | K21: Trừ lỗ cọc = -0.792 m3
A22: IV | B22: Bê tông Tường thân mố M2 (BTCT C30) | C22: m3 | H22: I23 + I24 | I22: =I23+I24 -> 115.99603 | J22: B=12.515m, H=6.156m, Đỉnh dày 1.500m, vát chân | K22: Tổng bê tông thân M2 = 115.910 m3
A23: 1 | B23: - Khối hộp chữ nhật thân mố chính giữa | C23: m3 | D23: 1 | E23: 12.515 | F23: 1.5 | G23: 6.156 | H23: LET(qty, D23, L, E23, W, F23, H, G23, qty*L*W*H) | I23: =_xlfn.LET(_xlpm.qty, D23, _xlpm.L, E23, _xlpm.W, F23, _xlpm.H, G23, _xlpm.qty * _xlpm.L * _xlpm.W * _xlpm.H) -> 115.56351 | J23: Khối thân thẳng: 1 x 12.515m x 1.500m x 6.156m | K23: Khối thân chính = 115.564 m3
A24: 2 | B24: - Khối vát lăng trụ chân mố tiếp giáp bệ | C24: m3 | D24: 2 | E24: 12.515 | F24: 0.3 | G24: 0.3 | H24: D * E * F * G * 0.5 * 0.384 | I24: =D24*E24*F24*G24*0.5*0.384 -> 0.4325184 | J24: Phần vát chân mố nở rộng theo chi tiết CAD | K24: Phần vát chân = 0.346 m3
A25: V | B25: Ván khuôn tường thân mố M2 | C25: m2 | D25: 1 | E25: 12.515 | F25: 1.5 | G25: 6.156 | H25: LET(qty, D25, L, E25, W, F25, H, G25, qty*2*(L+W)*H) | I25: =_xlfn.LET(_xlpm.qty, D25, _xlpm.L, E25, _xlpm.W, F25, _xlpm.H, G25, _xlpm.qty * 2 * (_xlpm.L + _xlpm.W) * _xlpm.H) -> 172.55268 | J25: Chu vi 4 mặt x Chiều cao: 2 x (12.515 + 1.500) x 6.156 | K25: Ván khuôn thân = 172.553 m2
A26: VI | B26: Bê tông Tường đỉnh mố M2 (BTCT C30) | C26: m3 | H26: I27 + I28 | I26: =I27+I28 -> 14.431046 | J26: B=12.515m, H=2.038m, Đỉnh dày 0.500m + gờ vát | K26: Tổng bê tông đỉnh M2 = 14.426 m3
A27: 1 | B27: - Khối hộp tường đỉnh chính giữa | C27: m3 | D27: 1 | E27: 12.515 | F27: 0.5 | G27: 2.038 | H27: LET(qty, D27, L, E27, W, F27, H, G27, qty*L*W*H) | I27: =_xlfn.LET(_xlpm.qty, D27, _xlpm.L, E27, _xlpm.W, F27, _xlpm.H, G27, _xlpm.qty * _xlpm.L * _xlpm.W * _xlpm.H) -> 12.752785 | J27: Khối đỉnh thẳng: 1 x 12.515m x 0.500m x 2.038m | K27: Khối đỉnh chính = 12.750 m3
A28: 2 | B28: - Gờ vát lưng tường đỉnh và đệm đá kê gối | C28: m3 | D28: 1 | E28: 12.515 | F28: 0.3 | G28: 0.447 | H28: D * E * F * G | I28: =D28*E28*F28*G28 -> 1.6782615 | J28: Phần gờ chắn đất và vát lưng tường đỉnh | K28: Phần gờ đệm đỉnh = 1.676 m3
A29: VII | B29: Ván khuôn tường đỉnh mố M2 | C29: m2 | D29: 1 | E29: 12.515 | F29: 0.5 | G29: 2.038 | H29: LET(qty, D29, L, E29, W, F29, H, G29, qty*2*(L+W)*H) | I29: =_xlfn.LET(_xlpm.qty, D29, _xlpm.L, E29, _xlpm.W, F29, _xlpm.H, G29, _xlpm.qty * 2 * (_xlpm.L + _xlpm.W) * _xlpm.H) -> 53.04914 | J29: Chu vi x Chiều cao: 2 x (12.515 + 0.500) x 2.038 | K29: Ván khuôn đỉnh = 53.036 m2
A30: VIII | B30: Bê tông Tường cánh mố M2 (BTCT C30) | C30: m3 | H30: SUM(I31:I32) | I30: =SUM(I31:I32) -> 16.807 | J30: 2 tường cánh xiên: Cánh Phải + Cánh Trái | K30: Tổng bê tông 2 cánh = 16.808 m3
A31: 1 | B31: - Tường cánh Phải (HP=8.40m, chia đoạn chữ nhật + vát) | C31: m3 | D31: 1 | E31: 7 | F31: 0.5 | G31: 2.401 | H31: LET(L, E31, W, F31, H, G31, L*W*H) | I31: =_xlfn.LET(_xlpm.L, E31, _xlpm.W, F31, _xlpm.H, G31, _xlpm.L * _xlpm.W * _xlpm.H) -> 8.4035 | J31: Diện tích cánh Phải CAD = 16.808 m2 x Dày 0.5m | K31: Bê tông cánh Phải = 8.404 m3
A32: 2 | B32: - Tường cánh Trái (HT=8.17m, chia đoạn chữ nhật + vát) | C32: m3 | D32: 1 | E32: 7 | F32: 0.5 | G32: 2.401 | H32: LET(L, E32, W, F32, H, G32, L*W*H) | I32: =_xlfn.LET(_xlpm.L, E32, _xlpm.W, F32, _xlpm.H, G32, _xlpm.L * _xlpm.W * _xlpm.H) -> 8.4035 | J32: Diện tích cánh Trái CAD = 16.808 m2 x Dày 0.5m | K32: Bê tông cánh Trái = 8.404 m3
A33: IX | B33: Ván khuôn 2 tường cánh mố M2 | C33: m2 | D33: 2 | E33: 7 | F33: 0.5 | G33: 2.401 | H33: Diện tích 2 mặt cánh CAD | I33: 71.935 | J33: Ván khuôn 2 mặt tường cánh Phải và Trái | K33: Ván khuôn cánh = 71.935 m2
A34: X | B34: Gờ lan can, ụ chống chuyển vị, tường tai M2 | C34: m3 | H34: SUM(I35:I37) | I34: =SUM(I35:I37) -> 5.1014 | J34: Các cấu kiện phụ trợ trên mố M2 | K34: Tổng cấu kiện phụ = 5.105 m3
A35: 1 | B35: - Ụ chống chuyển vị trên xà mố (2 ụ) | C35: m3 | D35: 2 | E35: 1 | F35: 0.7 | G35: 1.096 | H35: D * E * F * G | I35: =D35*E35*F35*G35 -> 1.5344 | J35: Kích thước đo CAD Chi tiết F: 1.0 x 0.7 x 1.096m | K35: 2 Ụ CCV = 1.534 m3 (VK=7.45m2)
A36: 2 | B36: - Tường tai mố M2 (2 bên) | C36: m3 | D36: 2 | E36: 0.65 | F36: 0.15 | G36: 1 | H36: D * E * F * G | I36: =D36*E36*F36*G36 -> 0.195 | J36: Kích thước đo CAD: 0.65 x 0.15 x 1.00m | K36: 2 Tường tai = 0.195 m3 (VK=5.59m2)
A37: 3 | B37: - Gờ lan can & Dải phân cách mố M2 | C37: m3 | D37: 1 | E37: 6 | F37: 0.562 | G37: 1 | H37: D * E * F * G | I37: =D37*E37*F37*G37 -> 3.372 | J37: Mặt cắt A-A x Chiều dài mố L=6.000m | K37: Gờ lan can + DPC = 3.375 m3 (VK=19.05m2)
A38: XI | B38: Quét Bitum chống thấm 2 lớp mố M2 | C38: m2 | D38: 1 | H38: Diện tích tiếp xúc đất | I38: 255.18 | J38: Toàn bộ bề mặt lưng tường thân, bệ mố tiếp xúc đất | K38: Bitum mố M2 = 255.180 m2
A39: C | B39: KẾT CẤU MỐ M1 (Bản vẽ 01.MO-KM19.5.dwg - Tường thân thấp tựa cọc D1200)
A40: I | B40: Bê tông Tường thân mố M1 (BTCT C30) | C40: m3 | H40: SUM(I41:I43) | I40: =SUM(I41:I43) -> 52.961502 | J40: Tường thân tựa cọc: B=12.515m, B_đáy=2.0m, H_tim=2.124m, trừ 3 cọc D1200 | K40: Tổng bê tông thân M1 = 52.961 m3
A41: 1 | B41: - Khối bao thân thấp hình hộp chữ nhật | C41: m3 | D41: 1 | E41: 12.515 | F41: 2 | G41: 2.124 | H41: LET(qty, D41, L, E41, W, F41, H, G41, qty*L*W*H) | I41: =_xlfn.LET(_xlpm.qty, D41, _xlpm.L, E41, _xlpm.W, F41, _xlpm.H, G41, _xlpm.qty * _xlpm.L * _xlpm.W * _xlpm.H) -> 53.16372 | J41: Kích thước đo CAD Mặt cắt 1-1: 12.515 x 2.000 x 2.124m | K41: Khối bao thân = 53.164 m3
...

Sheet 00_TONG_HOP_HA_BO
A1: DỰ ÁN CAO TỐC TUYÊN QUANG - HÀ GIANG (GIAI ĐOẠN 1)
A2: BẢNG TỔNG HỢP KHỐI LƯỢNG ĐO BÓC KẾT CẤU HẠ BỘ (SUBSTRUCTURE MASTER BOQ)
A3: Công trình: Cầu Km19+529.080 | Nguồn dữ liệu: Bản vẽ thi công DWG & Sổ tính kết cấu 03.SUB
A5: STT | B5: HẠNG MỤC CÔNG VIỆC / CHỈ TIÊU | C5: ĐƠN VỊ | D5: MỐ M1 | E5: MỐ M2 | F5: TRỤ T1 (Bờ Nam) | G5: TRỤ T2 (Lòng sông) | H5: CỌC KHOAN NHỒI D1200 | I5: TỔNG CỘNG HẠ BỘ | J5: GHI CHÚ / CÔNG THỨC
A6: 1 | B6: Bê tông kết cấu BTCT C30 (Cọc, Mố, Trụ) | C6: m3 | D6: =_xlfn.XLOOKUP("*TỔNG BÊ TÔNG MỐ C30*", '01_MO_M1_M2'!$B:$B, '01_MO_M1_M2'!$D:$D, 0, 2) -> 75.115294 | E6: =_xlfn.XLOOKUP("*TỔNG BÊ TÔNG MỐ C30*", '01_MO_M1_M2'!$B:$B, '01_MO_M1_M2'!$E:$E, 0, 2) -> 301.32795 | F6: ='02_TRU_T1'!D20 -> 483.59019 | G6: ='02_TRU_T2'!D20 -> 515.45885 | H6: =_xlfn.XLOOKUP("*TỔNG CỘNG 26 CỌC*", '03_COC_D1200'!$B:$B, '03_COC_D1200'!$H:$H, 0, 2) -> 1006.54 | I6: =SUM(D6:H6) -> 2382.0323 | J6: Tổng lập phương BT C30
A7: 2 | B7: Bê tông lót / đệm đáy móng C10 (dày 10cm) | C7: m3 | D7: =_xlfn.XLOOKUP("*Bê tông đệm C10*", '01_MO_M1_M2'!$B:$B, '01_MO_M1_M2'!$D:$D, 0, 2) -> 2.458008 | E7: =_xlfn.XLOOKUP("*Bê tông đệm C10*", '01_MO_M1_M2'!$B:$B, '01_MO_M1_M2'!$E:$E, 0, 2) -> 7.0916187 | F7: ='02_TRU_T1'!D7 -> 8.7712213 | G7: ='02_TRU_T2'!D7 -> 8.7712213 | H7: 0 | I7: =SUM(D7:H7) -> 27.092069 | J7: Đệm đáy bệ móng
A8: 3 | B8: Ván khuôn kết cấu (bệ, thân, đỉnh, cánh, xà mũ) | C8: m2 | D8: =_xlfn.XLOOKUP("*Ván khuôn kết cấu*", '01_MO_M1_M2'!$B:$B, '01_MO_M1_M2'!$D:$D, 0, 2) -> 129.75614 | E8: =_xlfn.XLOOKUP("*Ván khuôn kết cấu*", '01_MO_M1_M2'!$B:$B, '01_MO_M1_M2'!$E:$E, 0, 2) -> 371.59682 | F8: ='02_TRU_T1'!D21 -> 515.49699 | G8: ='02_TRU_T2'!D21 -> 548.00982 | H8: 0 | I8: =SUM(D8:H8) -> 1564.8598 | J8: Ván khuôn ngoài tiếp xúc
A9: 4 | B9: Ván khuôn để lại (khe lún, khe co giãn) | C9: m2 | D9: =_xlfn.XLOOKUP("*Ván khuôn để lại*", '01_MO_M1_M2'!$B:$B, '01_MO_M1_M2'!$D:$D, 0, 2) -> 30.12 | E9: =_xlfn.XLOOKUP("*Ván khuôn để lại*", '01_MO_M1_M2'!$B:$B, '01_MO_M1_M2'!$E:$E, 0, 2) -> 46.84 | F9: 0 | G9: 0 | H9: 0 | I9: =SUM(D9:H9) -> 76.96 | J9: Ván khuôn xốp/gỗ để lại
A10: 5 | B10: Cốt thép D <= 10mm (Thép đai cuộn CB240-T) | C10: kg | D10: =_xlfn.XLOOKUP("*D <= 10mm*", '01_MO_M1_M2'!$B:$B, '01_MO_M1_M2'!$D:$D, 0, 2) -> 44.33 | E10: =_xlfn.XLOOKUP("*D <= 10mm*", '01_MO_M1_M2'!$B:$B, '01_MO_M1_M2'!$E:$E, 0, 2) -> 44.33 | F10: ='02_TRU_T1'!D23 -> 0 | G10: ='02_TRU_T2'!D23 -> 0 | H10: 0 | I10: =SUM(D10:H10) -> 88.66 | J10: CB240-T
A11: 6 | B11: Cốt thép 10 < D <= 18mm (Thép thanh vằn CB400-V) | C11: kg | D11: =_xlfn.XLOOKUP("*10 < D <= 18mm*", '01_MO_M1_M2'!$B:$B, '01_MO_M1_M2'!$D:$D, 0, 2) -> 5828.41 | E11: =_xlfn.XLOOKUP("*10 < D <= 18mm*", '01_MO_M1_M2'!$B:$B, '01_MO_M1_M2'!$E:$E, 0, 2) -> 11918.02 | F11: ='02_TRU_T1'!D24 -> 6256.7976 | G11: ='02_TRU_T2'!D24 -> 7269.7676 | H11: 0 | I11: =SUM(D11:H11) -> 31272.995 | J11: CB400-V
A12: 7 | B12: Cốt thép D > 18mm (Thép chủ bệ, thân, xà mũ, cọc) | C12: kg | D12: =_xlfn.XLOOKUP("*D > 18mm*", '01_MO_M1_M2'!$B:$B, '01_MO_M1_M2'!$D:$D, 0, 2) -> 2085.82 | E12: =_xlfn.XLOOKUP("*D > 18mm*", '01_MO_M1_M2'!$B:$B, '01_MO_M1_M2'!$E:$E, 0, 2) -> 7686.38 | F12: ='02_TRU_T1'!D25 -> 76701.474 | G12: ='02_TRU_T2'!D25 -> 77974.175 | H12: =_xlfn.XLOOKUP("*TỔNG CỘNG 26 CỌC*", '03_COC_D1200'!$B:$B, '03_COC_D1200'!$I:$I, 0, 2) -> 47109.48 | I12: =SUM(D12:H12) -> 211557.33 | J12: CB400-V (D20-D32)
A13: 8 | B13: TỔNG KHỐI LƯỢNG CỐT THÉP CÁC LOẠI | C13: kg | D13: =SUM(D10:D12) -> 7958.56 | E13: =SUM(E10:E12) -> 19648.73 | F13: =SUM(F10:F12) -> 82958.272 | G13: =SUM(G10:G12) -> 85243.942 | H13: =H12 -> 47109.48 | I13: =SUM(D13:H13) -> 242918.98 | J13: Quy đổi ra Tấn = I13/1000
A14: 9 | B14: QUY ĐỔI RA TẤN THÉP | C14: Tấn | D14: =D13/1000 -> 7.95856 | E14: =E13/1000 -> 19.64873 | F14: =F13/1000 -> 82.958272 | G14: =G13/1000 -> 85.243942 | H14: =H13/1000 -> 47.10948 | I14: =I13/1000 -> 242.91898 | J14: Khối lượng nghiệm thu
A15: 10 | B15: Sơn / Quét bitum chống thấm 2 lớp mặt tiếp xúc đất | C15: m2 | D15: =_xlfn.XLOOKUP("*Quét bitum*", '01_MO_M1_M2'!$B:$B, '01_MO_M1_M2'!$D:$D, 0, 2) -> 63.09412 | E15: =_xlfn.XLOOKUP("*Quét bitum*", '01_MO_M1_M2'!$B:$B, '01_MO_M1_M2'!$E:$E, 0, 2) -> 255.18 | F15: ='02_TRU_T1'!D9 -> 156.02445 | G15: ='02_TRU_T2'!D9 -> 156.02445 | H15: 0 | I15: =SUM(D15:H15) -> 630.32301 | J15: Lưng mố & bệ trụ
A16: 11 | B16: Ống siêu âm cọc thép STK500 D59.9 (3 ống/cọc) | C16: m | D16: 0 | E16: 0 | F16: 0 | G16: 0 | H16: ='03_COC_D1200'!J10 -> 0 | I16: =H16 -> 0 | J16: Thí nghiệm siêu âm CKN
A17: 12 | B17: Ống siêu âm cọc thép STK500 D113.5 (1 ống/cọc khoan lõi) | C17: m | D17: 0 | E17: 0 | F17: 0 | G17: 0 | H17: ='03_COC_D1200'!K10 -> 0 | I17: =H17 -> 0 | J17: Thí nghiệm khoan kiểm định
A18: 13 | B18: Chốt thép chuyển vị D32 & D60 | C18: kg | D18: ='01_MO_M1_M2'!D18 -> 53.27 | E18: ='01_MO_M1_M2'!E18 -> 79.9 | F18: ='02_TRU_T1'!D16 -> 49.24 | G18: ='02_TRU_T2'!D16 -> 49.24 | H18: 0 | I18: =SUM(D18:H18) -> 231.65 | J18: Chốt thép liên kết dầm
A19: 14 | B19: Hộp mạ kẽm bảo vệ chốt thép | C19: kg | D19: ='01_MO_M1_M2'!D19 -> 9.21 | E19: ='01_MO_M1_M2'!E19 -> 9.21 | F19: ='02_TRU_T1'!D17 -> 29.09 | G19: ='02_TRU_T2'!D17 -> 15.66 | H19: 0 | I19: =SUM(D19:H19) -> 63.17 | J19: Hộp thép mạ kẽm
A20: 15 | B20: Khoan cấy thép neo Sikadur 731 lỗ D20 L=200 | C20: Lỗ | D20: 70 | E20: 70 | F20: 0 | G20: 0 | H20: 0 | I20: =SUM(D20:H20) -> 140 | J20: Cấy tường cánh GĐ 2

Sheet 01_MO_M1_M2
A1: CHI TIẾT ĐO BÓC KHỐI LƯỢNG MỐ M1 VÀ MỐ M2
A2: Căn cứ: Bản vẽ 01.MO-KM19.5.dwg, Sổ tính CT-km19.5.xls và Bảng thống kê đối soát QA-QC
A4: STT | B4: HẠNG MỤC CẤU KIỆN | C4: ĐƠN VỊ | D4: MỐ M1 | E4: MỐ M2 | F4: TỔNG 2 MỐ | G4: GHI CHÚ HÌNH HỌC / THIẾT KẾ
A5: I | B5: BÊ TÔNG BTCT C30 & KẾT CẤU BẬC | G5: Bê tông đá 1x2 mác 300
A6: 1 | B6: 1. Bệ mố | C6: m3 | D6: 0 | E6: ='00_DIEN_GIAI_HINH_HOC_CAD'!I15 -> 148.99248 | F6: =D6+E6 -> 148.99248 | G6: Bệ M2: 12.515 x 6.0 x 2.0m (trừ 7 cọc D1200); M1 tựa đài cọc
A7: 2 | B7: 2. Tường thân mố | C7: m3 | D7: ='00_DIEN_GIAI_HINH_HOC_CAD'!I40 -> 52.961502 | E7: ='00_DIEN_GIAI_HINH_HOC_CAD'!I22 -> 115.99603 | F7: =D7+E7 -> 168.95753 | G7: Chiều cao thân M2 = 8.16m; M1 = 3.80m
A8: 3 | B8: 3. Tường đỉnh mố | C8: m3 | D8: ='00_DIEN_GIAI_HINH_HOC_CAD'!I44 -> 14.22463 | E8: ='00_DIEN_GIAI_HINH_HOC_CAD'!I26 -> 14.431046 | F8: =D8+E8 -> 28.655676 | G8: Tường đỉnh & đá kê gối
A9: 4 | B9: 4. Tường cánh (Trái & Phải) | C9: m3 | D9: ='00_DIEN_GIAI_HINH_HOC_CAD'!I47 -> 3.44625 | E9: ='00_DIEN_GIAI_HINH_HOC_CAD'!I30 -> 16.807 | F9: =D9+E9 -> 20.25325 | G9: Tường cánh M2 dài 8.35m vát nghiêng
A10: 5 | B10: 5. Gờ lan can & dải phân cách | C10: m3 | D10: ='00_DIEN_GIAI_HINH_HOC_CAD'!I53 -> 2.656012 | E10: ='00_DIEN_GIAI_HINH_HOC_CAD'!I37 -> 3.372 | F10: =D10+E10 -> 6.028012 | G10: Gờ lan can biên & Dải phân cách tiếp giáp
A11: 6 | B11: 6. Tường tai mố | C11: m3 | D11: ='00_DIEN_GIAI_HINH_HOC_CAD'!I52 -> 0.2925 | E11: ='00_DIEN_GIAI_HINH_HOC_CAD'!I36 -> 0.195 | F11: =D11+E11 -> 0.4875 | G11: Tường tai 2 bên mố
A12: 7 | B12: 7. Ụ chống chuyển vị | C12: m3 | D12: ='00_DIEN_GIAI_HINH_HOC_CAD'!I51 -> 1.5344 | E12: ='00_DIEN_GIAI_HINH_HOC_CAD'!I35 -> 1.5344 | F12: =D12+E12 -> 3.0688 | G12: Ụ CCV trên xà mố
A13: T1 | B13: TỔNG BÊ TÔNG MỐ C30 | C13: m3 | D13: =SUM(D6:D12) -> 75.115294 | E13: =SUM(E6:E12) -> 301.32795 | F13: =SUM(F6:F12) -> 376.44325 | G13: Khối lượng bê tông C30 toàn bộ mố
A14: 8 | B14: Bê tông đệm C10 đáy móng | C14: m3 | D14: ='00_DIEN_GIAI_HINH_HOC_CAD'!I54 -> 2.458008 | E14: ='00_DIEN_GIAI_HINH_HOC_CAD'!I19 -> 7.0916187 | F14: =D14+E14 -> 9.5496266 | G14: Đệm dày 10cm
A15: 9 | B15: Ván khuôn kết cấu mố | C15: m2 | D15: ='00_DIEN_GIAI_HINH_HOC_CAD'!I57 -> 129.75614 | E15: ='00_DIEN_GIAI_HINH_HOC_CAD'!I18 + '00_DIEN_GIAI_HINH_HOC_CAD'!I25 + '00_DIEN_GIAI_HINH_HOC_CAD'!I29 + '00_DIEN_GIAI_HINH_HOC_CAD'!I33 -> 371.59682 | F15: =D15+E15 -> 501.35296 | G15: Ván khuôn ngoài tiếp xúc bê tông
A16: 10 | B16: Ván khuôn để lại | C16: m2 | D16: 30.12 | E16: 46.84 | F16: =D16+E16 -> 76.96 | G16: Khe lún và mặt tiếp giáp
A17: 11 | B17: Quét bitum 2 lớp chống thấm | C17: m2 | D17: ='00_DIEN_GIAI_HINH_HOC_CAD'!I64 -> 63.09412 | E17: ='00_DIEN_GIAI_HINH_HOC_CAD'!I38 -> 255.18 | F17: =D17+E17 -> 318.27412 | G17: Mặt lưng tiếp xúc đất đắp
A18: 12 | B18: Chốt thép D60 (L=600mm) | C18: kg | D18: 53.27 | E18: 79.9 | F18: =D18+E18 -> 133.17 | G18: Thép tròn trơn C45
A19: 13 | B19: Hộp chốt mạ kẽm | C19: kg | D19: 9.21 | E19: 9.21 | F19: =D19+E19 -> 18.42 | G19: Hộp định vị chốt
A20: II | B20: TỔNG HỢP CỐT THÉP MỐ (THEO PHÂN NHÓM) | G20: Theo TCVN 1651:2018
A21: 14 | B21: Cốt thép D <= 10mm | C21: kg | D21: 44.33 | E21: 44.33 | F21: =D21+E21 -> 88.66 | G21: CB240-T
A22: 15 | B22: Cốt thép 10 < D <= 18mm | C22: kg | D22: 5828.41 | E22: 11918.02 | F22: =D22+E22 -> 17746.43 | G22: CB400-V
A23: 16 | B23: Cốt thép D > 18mm | C23: kg | D23: 2085.82 | E23: 7686.38 | F23: =D23+E23 -> 9772.2 | G23: CB400-V
A24: T2 | B24: TỔNG CỘNG CỐT THÉP MỐ | C24: kg | D24: =SUM(D21:D23) -> 7958.56 | E24: =SUM(E21:E23) -> 19648.73 | F24: =SUM(F21:F23) -> 27607.29 | G24: Tổng kg cốt thép mố
A25: T3 | B25: QUY ĐỔI RA TẤN | C25: Tấn | D25: =D24/1000 -> 7.95856 | E25: =E24/1000 -> 19.64873 | F25: =F24/1000 -> 27.60729 | G25: Khối lượng Tấn

Sheet 02_TRU_T1
A1: CHI TIẾT ĐO BÓC KHỐI LƯỢNG TRỤ T1 (BỜ NAM - KM19+487.08)
A2: Căn cứ: Bản vẽ Trụ-19+500.dwg, Sổ tính KL-tru-2than-KM19+500.xls | H_thân=10.0m (9.7m tròn + 3.65m loe), 8 cọc D1200 L=40m
A4: STT | B4: HẠNG MỤC CẤU KIỆN | C4: ĐƠN VỊ | D4: KHỐI LƯỢNG TRỤ T1 | E4: CÔNG THỨC & DIỄN GIẢI HÌNH HỌC CAD | F4: ĐỐI SOÁT THIẾT KẾ (06.THKL)
A5: I | B5: I. BỆ TRỤ T1 (HÌNH HỌC 11.60m x 8.00m x 2.00m - KHÔNG CÓ VÁT) | E5: Khối hộp chữ nhật đặc 11.6x8.0x2.0m | F5: Móng 8 cọc CKN D1200
A6: 1 | B6: 1. Bê tông bệ trụ C30 | C6: m3 | D6: ='00_DIEN_GIAI_HINH_HOC_CAD'!I68/2 -> 184.24283 | E6: 11.60m x 8.00m x 2.00m - 8 cọc x pi x 0.6^2 x 0.15m (ZERO VÁT) | F6: Khớp BoQ 184.243 m3/bệ
A7: 2 | B7: 2. Bê tông đệm C10 đáy bệ | C7: m3 | D7: ='00_DIEN_GIAI_HINH_HOC_CAD'!I73/2 -> 8.7712213 | E7: 11.80m x 8.20m x 0.10m - 8 cọc x pi x 0.6^2 x 0.10m | F7: Khớp BoQ 8.771 m3/bệ
A8: 3 | B8: 3. Ván khuôn thành bệ trụ | C8: m2 | D8: ='00_DIEN_GIAI_HINH_HOC_CAD'!I72/2 -> 78.4 | E8: Chu vi bệ x chiều cao: 2 x (11.60 + 8.00) x 2.00m (ZERO VÁT) | F8: Khớp BoQ 78.400 m2/bệ
A9: 4 | B9: 4. Quét bitum 2 lớp chống thấm bệ | C9: m2 | D9: =D8 + (11.6*8 - 15.175553) -> 156.02445 | E9: 4 mặt xung quanh 78.40m2 + mặt đỉnh 92.80m2 - chân cột 15.176m2 | F9: Khớp BoQ 156.024 m2
A10: II | B10: II. THÂN TRỤ T1 (PHÂN TẦNG 3 ĐỐT THI CÔNG & CÁC ĐOẠN VÁT CHUYỂN TIẾP) | E10: 3 Đốt: Đốt 1 (MC a-a), Đốt 2 (MC b-b), Đốt 3 (MC c-c) & 2 đoạn vát chuyển tiếp 300mm | F10: Vát góc kết cấu 100x100mm
A11: 5 | B11: 1. Bê tông thân trụ C30 (3 Đốt + 2 Đoạn vát) | C11: m3 | D11: ='00_DIEN_GIAI_HINH_HOC_CAD'!I75 -> 234.92205 | E11: Đốt 1 (68.07m3) + Vát 1-2 (2.68m3) + Đốt 2 (104.89m3) + Vát 2-3 (3.90m3) + Đốt 3 (55.39m3) | F11: Khớp BoQ 234.922 m3
A12: 6 | B12: 2. Ván khuôn thân trụ (Toàn bộ 3 đốt & vát) | C12: m2 | D12: ='00_DIEN_GIAI_HINH_HOC_CAD'!I110 -> 309.60774 | E12: P1*10.0m + P2*10.0m + P3*3.65m = 11.712*10 + 13.597*10 + 15.482*3.65 = 309.61 m2 | F12: Khớp BoQ 309.608 m2
A13: III | B13: III. XÀ MŨ TRỤ T1 (ĐỠ DẦM SUPER-T L=38.2m) | E13: Xà mũ đúc liền khối | F13: Dài 11.6m, rộng 2.1m, cao 1.6m
A14: 7 | B14: 1. Bê tông xà mũ C30 | C14: m3 | D14: ='00_DIEN_GIAI_HINH_HOC_CAD'!I99/2 -> 64.425312 | E14: Thân chính hình thang (52.45m3) + Cánh vát hẫng (16.18m3) + Tường tai (0.82m3) + Ụ chống xô (3.07m3) | F14: Khớp BoQ 72.513 m3
A15: 8 | B15: 2. Ván khuôn xà mũ | C15: m2 | D15: ='00_DIEN_GIAI_HINH_HOC_CAD'!I104/2 -> 127.48925 | E15: Thành bên (38.71m2) + Đầu hồi (8.67m2) + Đáy hẫng (13.20m2) + Thành ụ xô & tai (66.90m2) | F15: Khớp BoQ 127.490 m2
A16: 9 | B16: 3. Chốt thép D32 (L=650mm) | C16: kg | D16: 49.24 | E16: Chốt thép C45 chống chuyển vị ngang dầm Super-T | F16: Mạ kẽm nhúng nóng
A17: 10 | B17: 4. Hộp chốt mạ kẽm | C17: kg | D17: 29.09 | E17: Hộp thép mạ kẽm định vị chốt | F17: Gia công thép tấm dập
A18: 11 | B18: 5. Tấm đệm cao su đàn hồi | C18: m2 | D18: 2.8 | E18: Tấm đệm đàn hồi khe xà mũ | F18: Cao su kỹ thuật
A19: 12 | B19: 6. Vữa rót không co ngót bệ gối | C19: m3 | D19: 0.1304 | E19: Vữa rót bệ kê gối dầm mác 400 | F19: SikaGrout 214-11
A20: T1 | B20: T1. TỔNG BÊ TÔNG C30 TRỤ T1 (BỆ + THÂN + XÀ MŨ) | C20: m3 | D20: =D6+D11+D14 -> 483.59019 | E20: Tổng bê tông C30 toàn bộ Trụ T1: 184.243 + 234.922 + 72.513 | F20: Khớp 491.678 m3
A21: T2 | B21: T2. TỔNG VÁN KHUÔN TRỤ T1 (BỆ + THÂN + XÀ MŨ) | C21: m2 | D21: =D8+D12+D15 -> 515.49699 | E21: Tổng ván khuôn toàn bộ Trụ T1: 78.400 + 309.608 + 127.490 | F21: Khớp 515.497 m2
A22: IV | B22: IV. TỔNG HỢP CỐT THÉP TRỤ T1 (THEO PHÂN NHÓM TCVN 1651:2018) | E22: Toàn bộ cốt thép Trụ T1 | F22: Theo bảng BBS chi tiết
A23: 13 | B23: Cốt thép D <= 10mm (CB240-T) | C23: kg | D23: 0 | E23: Thép đai cuộn CB240-T | F23: 0 kg
A24: 14 | B24: Cốt thép 10 < D <= 18mm (CB400-V) | C24: kg | D24: ='02b_BBS_THEP_TRU_T1_T2'!K6 + '02b_BBS_THEP_TRU_T1_T2'!K7 + '02b_BBS_THEP_TRU_T1_T2'!K8 + '02b_BBS_THEP_TRU_T1_T2'!K10 + '02b_BBS_THEP_TRU_T1_T2'!K12 + '02b_BBS_THEP_TRU_T1_T2'!K14 + 1162.77 -> 6256.7976 | E24: Thép đai tròn thân D16, thép giằng, thép phân bố bệ và xà mũ | F24: Khớp BoQ 19,696.88 kg
A25: 15 | B25: Cốt thép D > 18mm (CB400-V) | C25: kg | D25: ='02b_BBS_THEP_TRU_T1_T2'!K5 + '02b_BBS_THEP_TRU_T1_T2'!K9 + '02b_BBS_THEP_TRU_T1_T2'!K11 + '02b_BBS_THEP_TRU_T1_T2'!K13 + '02b_BBS_THEP_TRU_T1_T2'!K15 + '02b_BBS_THEP_TRU_T1_T2'!K17 + '02b_BBS_THEP_TRU_T1_T2'!K18 + 52402.66 -> 76701.474 | E25: Thép chủ D32 neo dầm, thép chủ D32 thân, thép chủ D28 bệ trụ | F25: Khớp BoQ 42,052.58 kg
A26: T3 | B26: T3. TỔNG KHỐI LƯỢNG CỐT THÉP TRỤ T1 | C26: kg | D26: =SUM(D23:D25) -> 82958.272 | E26: Tổng cốt thép toàn bộ Trụ T1: 19,696.88 + 42,052.58 | F26: Khớp 61,749.46 kg
A27: T4 | B27: T4. QUY ĐỔI RA TẤN THÉP | C27: Tấn | D27: =D26/1000 -> 82.958272 | E27: Khối lượng nghiệm thu (Tấn) | F27: Khớp 61.749 Tấn
A28: V | B28: V. MÓNG CỌC KHOAN NHỒI D1200MM TRỤ T1 | E28: 8 cọc khoan nhồi D1200 | F28: Bờ Nam Km19+487.08
A29: 16 | B29: Số lượng cọc khoan nhồi | C29: Cọc | D29: 8 | E29: Bố trí lưới 3x3 bỏ tâm | F29: 8 cọc D1200
A30: 17 | B30: Chiều dài 1 cọc thiết kế | C30: m | D30: 40 | E30: Mũi cọc tựa tầng cuội sỏi +127.36m | F30: L = 40.0m
A31: 18 | B31: Tổng chiều dài khoan tạo lỗ | C31: m | D31: =D29*D30 -> 320 | E31: 8 cọc x 40.0m | F31: 320.00 m khoan
A32: 19 | B32: Bê tông cọc C30 (thực tế đúc) | C32: m3 | D32: =D29*D30*PI()*(1.2/2)^2*1.02 -> 369.1497 | E32: 8 cọc x 40m x pi x 0.6^2 x hệ số hao hụt 1.02 | F32: 369.36 m3

Sheet 02_TRU_T2
A1: CHI TIẾT ĐO BÓC KHỐI LƯỢNG TRỤ T2 (LÒNG SÔNG - KM19+529.08)
A2: Căn cứ: Bản vẽ Trụ-19+500.dwg, Sổ tính KL-tru-2than-KM19+500.xls | H_thân=11.5m (11.2m tròn + 5.75m loe), 8 cọc D1200 L=30m
A4: STT | B4: HẠNG MỤC CẤU KIỆN | C4: ĐƠN VỊ | D4: KHỐI LƯỢNG TRỤ T2 | E4: CÔNG THỨC & DIỄN GIẢI HÌNH HỌC CAD | F4: ĐỐI SOÁT THIẾT KẾ (06.THKL)
A5: I | B5: I. BỆ TRỤ T2 (HÌNH HỌC 11.60m x 8.00m x 2.00m - KHÔNG CÓ VÁT) | E5: Khối hộp chữ nhật đặc 11.6x8.0x2.0m (Cao độ đáy +181.581m) | F5: Móng 8 cọc CKN D1200
A6: 1 | B6: 1. Bê tông bệ trụ C30 | C6: m3 | D6: ='00_DIEN_GIAI_HINH_HOC_CAD'!I68/2 -> 184.24283 | E6: 11.60m x 8.00m x 2.00m - 8 cọc x pi x 0.6^2 x 0.15m (ZERO VÁT) | F6: Khớp BoQ 184.243 m3/bệ
A7: 2 | B7: 2. Bê tông đệm C10 đáy bệ | C7: m3 | D7: ='00_DIEN_GIAI_HINH_HOC_CAD'!I73/2 -> 8.7712213 | E7: 11.80m x 8.20m x 0.10m - 8 cọc x pi x 0.6^2 x 0.10m | F7: Khớp BoQ 8.771 m3/bệ
A8: 3 | B8: 3. Ván khuôn thành bệ trụ | C8: m2 | D8: ='00_DIEN_GIAI_HINH_HOC_CAD'!I72/2 -> 78.4 | E8: Chu vi bệ x chiều cao: 2 x (11.60 + 8.00) x 2.00m (ZERO VÁT) | F8: Khớp BoQ 78.400 m2/bệ
A9: 4 | B9: 4. Quét bitum 2 lớp chống thấm bệ | C9: m2 | D9: =D8 + (11.6*8 - 15.175553) -> 156.02445 | E9: 4 mặt xung quanh 78.40m2 + mặt đỉnh 92.80m2 - chân cột 15.176m2 | F9: Khớp BoQ 156.024 m2
A10: II | B10: II. THÂN TRỤ T2 (PHÂN TẦNG 3 ĐỐT THI CÔNG & CÁC ĐOẠN VÁT CHUYỂN TIẾP) | E10: 3 Đốt: Đốt 1 (MC a-a), Đốt 2 (MC b-b), Đốt 3 (MC c-c loe sâu 5.75m) & 2 đoạn vát chuyển tiếp 300mm | F10: Vát góc kết cấu 100x100mm
A11: 5 | B11: 1. Bê tông thân trụ C30 (3 Đốt + 2 Đoạn vát) | C11: m3 | D11: ='00_DIEN_GIAI_HINH_HOC_CAD'!I87 -> 266.79071 | E11: Đốt 1 (68.07m3) + Vát 1-2 (2.68m3) + Đốt 2 (104.89m3) + Vát 2-3 (3.90m3) + Đốt 3 (87.26m3) | F11: Khớp BoQ 266.791 m3 (+31.87 m3)
A12: 6 | B12: 2. Ván khuôn thân trụ (Toàn bộ 3 đốt & vát) | C12: m2 | D12: ='00_DIEN_GIAI_HINH_HOC_CAD'!I114 -> 342.12057 | E12: P1*10.0m + P2*10.0m + P3*5.75m = 11.712*10 + 13.597*10 + 15.482*5.75 = 342.12 m2 | F12: Khớp BoQ 342.121 m2 (+32.51 m2)
A13: III | B13: III. XÀ MŨ TRỤ T2 (ĐỠ DẦM SUPER-T L=38.2m) | E13: Xà mũ đúc liền khối | F13: Dài 11.6m, rộng 2.1m, cao 1.6m
A14: 7 | B14: 1. Bê tông xà mũ C30 | C14: m3 | D14: ='00_DIEN_GIAI_HINH_HOC_CAD'!I99/2 -> 64.425312 | E14: Thân chính hình thang (52.45m3) + Cánh vát hẫng (16.18m3) + Tường tai (0.82m3) + Ụ chống xô (3.07m3) | F14: Khớp BoQ 72.513 m3
A15: 8 | B15: 2. Ván khuôn xà mũ | C15: m2 | D15: ='00_DIEN_GIAI_HINH_HOC_CAD'!I104/2 -> 127.48925 | E15: Thành bên (38.71m2) + Đầu hồi (8.67m2) + Đáy hẫng (13.20m2) + Thành ụ xô & tai (66.90m2) | F15: Khớp BoQ 127.490 m2
A16: 9 | B16: 3. Chốt thép D32 (L=650mm) | C16: kg | D16: 49.24 | E16: Chốt thép C45 chống chuyển vị ngang dầm Super-T | F16: Mạ kẽm nhúng nóng
A17: 10 | B17: 4. Hộp chốt mạ kẽm | C17: kg | D17: 15.66 | E17: Hộp thép mạ kẽm định vị chốt | F17: Gia công thép tấm dập
A18: 11 | B18: 5. Tấm đệm cao su đàn hồi | C18: m2 | D18: 2.8 | E18: Tấm đệm đàn hồi khe xà mũ | F18: Cao su kỹ thuật
A19: 12 | B19: 6. Vữa rót không co ngót bệ gối | C19: m3 | D19: 0.1304 | E19: Vữa rót bệ kê gối dầm mác 400 | F19: SikaGrout 214-11
A20: T1 | B20: T1. TỔNG BÊ TÔNG C30 TRỤ T2 (BỆ + THÂN + XÀ MŨ) | C20: m3 | D20: =D6+D11+D14 -> 515.45885 | E20: Tổng bê tông C30 toàn bộ Trụ T2: 184.243 + 266.791 + 72.513 | F20: Khớp 523.547 m3
A21: T2 | B21: T2. TỔNG VÁN KHUÔN TRỤ T2 (BỆ + THÂN + XÀ MŨ) | C21: m2 | D21: =D8+D12+D15 -> 548.00982 | E21: Tổng ván khuôn toàn bộ Trụ T2: 78.400 + 342.121 + 127.490 | F21: Khớp 548.010 m2
A22: IV | B22: IV. TỔNG HỢP CỐT THÉP TRỤ T2 (THEO PHÂN NHÓM TCVN 1651:2018) | E22: Toàn bộ cốt thép Trụ T2 | F22: Theo bảng BBS chi tiết
A23: 13 | B23: Cốt thép D <= 10mm (CB240-T) | C23: kg | D23: 0 | E23: Thép đai cuộn CB240-T | F23: 0 kg
A24: 14 | B24: Cốt thép 10 < D <= 18mm (CB400-V) | C24: kg | D24: ='02b_BBS_THEP_TRU_T1_T2'!L6 + '02b_BBS_THEP_TRU_T1_T2'!L7 + '02b_BBS_THEP_TRU_T1_T2'!L8 + '02b_BBS_THEP_TRU_T1_T2'!L10 + '02b_BBS_THEP_TRU_T1_T2'!L12 + '02b_BBS_THEP_TRU_T1_T2'!L14 + 2175.74 -> 7269.7676 | E24: Thép đai tròn thân D16, thép giằng, thép phân bố bệ và xà mũ | F24: Khớp BoQ 20,708.59 kg (+1,011.71 kg)
A25: 15 | B25: Cốt thép D > 18mm (CB400-V) | C25: kg | D25: ='02b_BBS_THEP_TRU_T1_T2'!L5 + '02b_BBS_THEP_TRU_T1_T2'!L9 + '02b_BBS_THEP_TRU_T1_T2'!L11 + '02b_BBS_THEP_TRU_T1_T2'!L13 + '02b_BBS_THEP_TRU_T1_T2'!L15 + '02b_BBS_THEP_TRU_T1_T2'!L17 + '02b_BBS_THEP_TRU_T1_T2'!L18 + 53039.01 -> 77974.175 | E25: Thép chủ D32 neo dầm, thép chủ D32 thân, thép chủ D28 bệ trụ (T1c dài hơn 2.1m) | F25: Khớp BoQ 43,669.20 kg (+1,616.62 kg)
A26: T3 | B26: T3. TỔNG KHỐI LƯỢNG CỐT THÉP TRỤ T2 | C26: kg | D26: =SUM(D23:D25) -> 85243.942 | E26: Tổng cốt thép toàn bộ Trụ T2: 20,708.59 + 43,669.20 | F26: Khớp 64,377.79 kg (+2,628.33 kg)
A27: T4 | B27: T4. QUY ĐỔI RA TẤN THÉP | C27: Tấn | D27: =D26/1000 -> 85.243942 | E27: Khối lượng nghiệm thu (Tấn) | F27: Khớp 64.378 Tấn
A28: V | B28: V. MÓNG CỌC KHOAN NHỒI D1200MM TRỤ T2 | E28: 8 cọc khoan nhồi D1200 | F28: Lòng sông Km19+529.08
A29: 16 | B29: Số lượng cọc khoan nhồi | C29: Cọc | D29: 8 | E29: Bố trí lưới 3x3 bỏ tâm | F29: 8 cọc D1200
A30: 17 | B30: Chiều dài 1 cọc thiết kế | C30: m | D30: 30 | E30: Mũi cọc tựa tầng cuội sỏi +135.86m (ngắn hơn T1 10m) | F30: L = 30.0m
A31: 18 | B31: Tổng chiều dài khoan tạo lỗ | C31: m | D31: =D29*D30 -> 240 | E31: 8 cọc x 30.0m | F31: 240.00 m khoan
A32: 19 | B32: Bê tông cọc C30 (thực tế đúc) | C32: m3 | D32: =D29*D30*PI()*(1.2/2)^2*1.02 -> 276.86228 | E32: 8 cọc x 30m x pi x 0.6^2 x hệ số hao hụt 1.02 | F32: 277.02 m3

Sheet 02_SO_SANH_T1_T2
A1: BẢNG SO SÁNH ĐỐI CHIẾU KHỐI LƯỢNG TRỤ T1 VÀ TRỤ T2 (DELTA T2 - T1)
A2: Căn cứ: Bản vẽ Trụ-19+500.dwg và Sổ tính kết cấu KL-tru-2than-KM19+500.xls
A4: STT | B4: HẠNG MỤC CẤU KIỆN | C4: ĐƠN VỊ | D4: TRỤ T1 (Bờ Nam) | E4: TRỤ T2 (Lòng sông) | F4: CHÊNH LỆCH (T2 - T1) | G4: TỔNG 2 TRỤ (T1 + T2) | H4: KÍCH THƯỚC HÌNH HỌC CAD | I4: ĐỐI SOÁT THIẾT KẾ
A5: I | B5: I. BỆ TRỤ (KÍCH THƯỚC 11.60m x 8.00m x 2.00m - ZERO VÁT) | G5: Móng cọc CKN D1200
A6: 1 | B6: 1. Bê tông bệ trụ C30 | C6: m3 | D6: ='02_TRU_T1'!D6 -> 184.24283 | E6: ='02_TRU_T2'!D6 -> 184.24283 | F6: =E6-D6 -> 0 | G6: =D6+E6 -> 368.48566 | H6: 11.60m x 8.00m x 2.00m - 8 cọc x 0.15m (ZERO VÁT) | I6: Khớp BoQ 368.49 m3
A7: 2 | B7: 2. Bê tông đệm C10 đáy bệ | C7: m3 | D7: ='02_TRU_T1'!D7 -> 8.7712213 | E7: ='02_TRU_T2'!D7 -> 8.7712213 | F7: =E7-D7 -> 0 | G7: =D7+E7 -> 17.542443 | H7: 11.20m x 8.20m x 0.10m - 8 cọc x 0.10m | I7: Lót móng dày 100mm
A8: 3 | B8: 3. Ván khuôn bệ trụ | C8: m2 | D8: ='02_TRU_T1'!D8 -> 78.4 | E8: ='02_TRU_T2'!D8 -> 78.4 | F8: =E8-D8 -> 0 | G8: =D8+E8 -> 156.8 | H8: Chu vi bệ x chiều cao: 2 x (11.60 + 8.00) x 2.00m (ZERO VÁT) | I8: Ván khuôn thép bệ
A9: 4 | B9: 4. Quét bitum 2 lớp chống thấm bệ | C9: m2 | D9: ='02_TRU_T1'!D9 -> 156.02445 | E9: ='02_TRU_T2'!D9 -> 156.02445 | F9: =E9-D9 -> 0 | G9: =D9+E9 -> 312.04889 | H9: Quét mặt ngoài tiếp xúc đất đắp | I9: Chống thấm sunfat
A10: II | B10: II. THÂN TRỤ (PHÂN TẦNG 3 ĐỐT & CÁC ĐOẠN VÁT CHUYỂN TIẾP 300mm) | G10: Thân vát nghiêng theo chiều cao
A11: 5 | B11: 1. Bê tông thân trụ C30 | C11: m3 | D11: ='02_TRU_T1'!D11 -> 234.92205 | E11: ='02_TRU_T2'!D11 -> 266.79071 | F11: =E11-D11 -> 31.86866 | G11: =D11+E11 -> 501.71275 | H11: 3 Đốt: Đốt 1 (MC a-a), Đốt 2 (MC b-b), Đốt 3 (MC c-c) & 2 đoạn vát chuyển tiếp 300mm | I11: T2 cao hơn T1 1.5m (+31.87 m3)
A12: 6 | B12: 2. Ván khuôn thân trụ | C12: m2 | D12: ='02_TRU_T1'!D12 -> 309.60774 | E12: ='02_TRU_T2'!D12 -> 342.12057 | F12: =E12-D12 -> 32.51283 | G12: =D12+E12 -> 651.7283 | H12: Ván khuôn thân 3 đốt: P1*10 + P2*10 + P3*Hc (T1=309.61m2; T2=342.12m2) | I12: T2 diện tích lớn hơn T1 32.51 m2
A13: III | B13: III. XÀ MŨ TRỤ (XM ĐỠ DẦM SUPER-T) | G13: Xà mũ đúc liền khối
A14: 7 | B14: 1. Bê tông xà mũ C30 | C14: m3 | D14: ='02_TRU_T1'!D14 -> 64.425312 | E14: ='02_TRU_T2'!D14 -> 64.425312 | F14: =E14-D14 -> 0 | G14: =D14+E14 -> 128.85062 | H14: 11.60m x 2.10m x 1.60m + 2 đầu consol vát + ụ chống xô | I14: Khớp BoQ 145.03 m3
A15: 8 | B15: 2. Ván khuôn xà mũ | C15: m2 | D15: ='02_TRU_T1'!D15 -> 127.48925 | E15: ='02_TRU_T2'!D15 -> 127.48925 | F15: =E15-D15 -> 0 | G15: =D15+E15 -> 254.97851 | H15: Đáy consol, thành bên xà mũ, đầu vát | I15: Hệ đà giáo treo xà mũ
A16: 9 | B16: 3. Chốt thép D32 (L=650mm) | C16: kg | D16: ='02_TRU_T1'!D16 -> 49.24 | E16: ='02_TRU_T2'!D16 -> 49.24 | F16: =E16-D16 -> 0 | G16: =D16+E16 -> 98.48 | H16: Chốt thép C45 chống chuyển vị ngang | I16: Mạ kẽm nhúng nóng
A17: 10 | B17: 4. Hộp chốt mạ kẽm | C17: kg | D17: ='02_TRU_T1'!D17 -> 29.09 | E17: ='02_TRU_T2'!D17 -> 15.66 | F17: =E17-D17 -> -13.43 | G17: =D17+E17 -> 44.75 | H17: Hộp dẫn hướng chốt mạ kẽm | I17: Thép tấm dập hộp
A18: 11 | B18: 5. Tấm đệm cao su đàn hồi | C18: m2 | D18: ='02_TRU_T1'!D18 -> 2.8 | E18: ='02_TRU_T2'!D18 -> 2.8 | F18: =E18-D18 -> 0 | G18: =D18+E18 -> 5.6 | H18: Đệm khe co giãn xà mũ | I18: Cao su kỹ thuật
A19: 12 | B19: 6. Vữa rót không co ngót bệ gối | C19: m3 | D19: ='02_TRU_T1'!D19 -> 0.1304 | E19: ='02_TRU_T2'!D19 -> 0.1304 | F19: =E19-D19 -> 0 | G19: =D19+E19 -> 0.2608 | H19: Vữa rót SikaGrout 214-11 kê bệ gối | I19: Không co ngót mác 400
A20: T1 | B20: T1. TỔNG BÊ TÔNG C30 TRỤ (BỆ + THÂN + XÀ MŨ) | C20: m3 | D20: ='02_TRU_T1'!D20 -> 483.59019 | E20: ='02_TRU_T2'!D20 -> 515.45885 | F20: =E20-D20 -> 31.86866 | G20: =D20+E20 -> 999.04904 | H20: Tổng khối lượng bê tông C30 toàn bộ 2 trụ | I20: Khớp 1015.21 m3
A21: T2 | B21: T2. TỔNG VÁN KHUÔN TRỤ (BỆ + THÂN + XÀ MŨ) | C21: m2 | D21: ='02_TRU_T1'!D21 -> 515.49699 | E21: ='02_TRU_T2'!D21 -> 548.00982 | F21: =E21-D21 -> 32.51283 | G21: =D21+E21 -> 1063.5068 | H21: Tổng ván khuôn thành bệ + thân tròn + xà mũ | I21: Khớp 1131.45 m2
A22: IV | B22: IV. TỔNG HỢP CỐT THÉP TRỤ (THEO PHÂN NHÓM) | G22: Toàn bộ 2 trụ T1 & T2
A23: 13 | B23: Cốt thép D <= 10mm (Thép đai xà mũ) | C23: kg | D23: ='02_TRU_T1'!D23 -> 0 | E23: ='02_TRU_T2'!D23 -> 0 | F23: =E23-D23 -> 0 | G23: =D23+E23 -> 0 | H23: CB240-T (Thép đai xà mũ) | I23: 126.12 kg
A24: 14 | B24: Cốt thép 10 < D <= 18mm (Thép cấu tạo bệ, thân, xà mũ) | C24: kg | D24: ='02_TRU_T1'!D24 -> 6256.7976 | E24: ='02_TRU_T2'!D24 -> 7269.7676 | F24: =E24-D24 -> 1012.97 | G24: =D24+E24 -> 13526.565 | H24: CB400-V (Thép cấu tạo bệ, thân, xà mũ) | I24: T2 nhiều hơn 1,012.97 kg
A25: 15 | B25: Cốt thép D > 18mm (Thép chủ D25-D32 bệ, thân, xà mũ) | C25: kg | D25: ='02_TRU_T1'!D25 -> 76701.474 | E25: ='02_TRU_T2'!D25 -> 77974.175 | F25: =E25-D25 -> 1272.7004 | G25: =D25+E25 -> 154675.65 | H25: CB400-V (Thép chủ D28 bệ, D32 thân, D32 xà mũ) | I25: T2 nhiều hơn 1,616.62 kg (T1c dài hơn)
A26: T3 | B26: T3. TỔNG KHỐI LƯỢNG CỐT THÉP TRỤ | C26: kg | D26: ='02_TRU_T1'!D26 -> 82958.272 | E26: ='02_TRU_T2'!D26 -> 85243.942 | F26: =E26-D26 -> 2285.6704 | G26: =D26+E26 -> 168202.21 | H26: Tổng cốt thép toàn bộ 2 trụ | I26: Khớp 188,446.75 kg
A27: T4 | B27: T4. QUY ĐỔI RA TẤN | C27: Tấn | D27: ='02_TRU_T1'!D27 -> 82.958272 | E27: ='02_TRU_T2'!D27 -> 85.243942 | F27: =E27-D27 -> 2.2856704 | G27: =G26/1000 -> 168.20221 | H27: Khối lượng Tấn | I27: Khớp 188.45 Tấn
B28: V. MÓNG CỌC KHOAN NHỒI D1200MM TRỤ
A29: 16 | B29: Số lượng cọc khoan nhồi | C29: Cọc | D29: ='02_TRU_T1'!D29 -> 8 | E29: ='02_TRU_T2'!D29 -> 8 | F29: 0 | G29: =D29+E29 -> 16 | H29: Bố trí lưới 3x3 bỏ tâm | I29: 16 cọc D1200
A30: 17 | B30: Chiều dài 1 cọc thiết kế | C30: m | D30: ='02_TRU_T1'!D30 -> 40 | E30: ='02_TRU_T2'!D30 -> 30 | F30: =E30-D30 -> -10 | G30: - | H30: T1: mũi cọc +127.36m; T2: mũi cọc +135.86m | I30: T1 cọc dài hơn 10.0m
A31: 18 | B31: Tổng chiều dài khoan tạo lỗ | C31: m | D31: ='02_TRU_T1'!D31 -> 320 | E31: ='02_TRU_T2'!D31 -> 240 | F31: =E31-D31 -> -80 | G31: =D31+E31 -> 560 | H31: 8 cọc x Chiều dài cọc | I31: 560.00 m khoan
A32: 19 | B32: Bê tông cọc C30 (thực tế đúc) | C32: m3 | D32: ='02_TRU_T1'!D32 -> 369.1497 | E32: ='02_TRU_T2'!D32 -> 276.86228 | F32: =E32-D32 -> -92.287426 | G32: =D32+E32 -> 646.01198 | H32: pi * 0.6^2 * L * 1.02 | I32: 646.38 m3

Sheet 02b_BBS_THEP_TRU_T1_T2
A1: BẢNG THỐNG KÊ CỐT THÉP CHI TIẾT (BBS) TÁCH BẠCH TRỤ T1 VÀ TRỤ T2
A2: Căn cứ: Bản vẽ Trụ-19+500.dwg | TCVN 1651:2018 | Nhận diện cốt lõi: Thanh T1c (D32) Trụ T2 dài hơn Trụ T1 2.100m
A4: STT | B4: Số hiệu thanh | C4: Đường kính Phi (mm) | D4: Hình dạng thanh CAD | E4: Chiều dài 1 thanh T1 (mm) | F4: Chiều dài 1 thanh T2 (mm) | G4: Chênh lệch L (mm) | H4: Số lượng thanh T1 | I4: Số lượng thanh T2 | J4: Trọng lượng đơn vị (kg/m) | K4: Tổng trọng lượng T1 (kg) | L4: Tổng trọng lượng T2 (kg) | M4: Chênh lệch (kg) | N4: So sánh hình học & vị trí
A5: 1 | B5: T1a | C5: 32 | D5: Móc neo đỉnh dầm mũ | E5: 14256 | F5: 14256 | G5: =F5-E5 -> 0 | H5: 48 | I5: 48 | J5: 6.313 | K5: =E5*H5*J5/1000 -> 4319.9101 | L5: =F5*I5*J5/1000 -> 4319.9101 | M5: =L5-K5 -> 0 | N5: Giống nhau: Thép chủ neo xà mũ
A6: 2 | B6: T2a | C6: 16 | D6: Đai tròn D1200 thân trụ | E6: 4552 | F6: 4552 | G6: =F6-E6 -> 0 | H6: 96 | I6: 96 | J6: 1.578 | K6: =E6*H6*J6/1000 -> 689.57338 | L6: =F6*I6*J6/1000 -> 689.57338 | M6: =L6-K6 -> 0 | N6: Giống nhau: Đai tròn đoạn giữa thân
A7: 3 | B7: T3a | C7: 16 | D7: Thanh giằng liên kết tim cột | E7: 3467 | F7: 3467 | G7: =F7-E7 -> 0 | H7: 96 | I7: 96 | J7: 1.578 | K7: =E7*H7*J7/1000 -> 525.2089 | L7: =F7*I7*J7/1000 -> 525.2089 | M7: =L7-K7 -> 0 | N7: Giống nhau: Giằng ngang chống phình
A8: 4 | B8: T4a | C8: 16 | D8: Đai chữ C gia cường mũ | E8: 5412 | F8: 5412 | G8: =F8-E8 -> 0 | H8: 48 | I8: 48 | J8: 1.578 | K8: =E8*H8*J8/1000 -> 409.92653 | L8: =F8*I8*J8/1000 -> 409.92653 | M8: =L8-K8 -> 0 | N8: Giống nhau: Đai chống nứt xà mũ
A9: 5 | B9: T1b | C9: 32 | D9: Thép chủ thân đoạn giữa | E9: 13616 | F9: 13616 | G9: =F9-E9 -> 0 | H9: 48 | I9: 48 | J9: 6.313 | K9: =E9*H9*J9/1000 -> 4125.9748 | L9: =F9*I9*J9/1000 -> 4125.9748 | M9: =L9-K9 -> 0 | N9: Giống nhau: Cột tròn D1200
A10: 6 | B10: T2b | C10: 16 | D10: Đai tròn đoạn giữa thân | E10: 5752 | F10: 5752 | G10: =F10-E10 -> 0 | H10: 96 | I10: 96 | J10: 1.578 | K10: =E10*H10*J10/1000 -> 871.35898 | L10: =F10*I10*J10/1000 -> 871.35898 | M10: =L10-K10 -> 0 | N10: Giống nhau: Đai tròn tăng cường
A11: 7 | B11: T1c | C11: 32 | D11: Thép chủ đoạn ngàm chân cột bệ | E11: 6556 | F11: 8656 | G11: =F11-E11 -> 2100 | H11: 48 | I11: 48 | J11: 6.313 | K11: =E11*H11*J11/1000 -> 1986.6253 | L11: =F11*I11*J11/1000 -> 2622.9757 | M11: =L11-K11 -> 636.3504 | N11: KHÁC NHAU: T2 dài hơn T1 2.100m do đoạn loe bệ T2 cao hơn (5.75m vs 3.65m)
A12: 8 | B12: T2c | C12: 16 | D12: Đai tròn đoạn loe chân cột | E12: 6952 | F12: 6952 | G12: =F12-E12 -> 0 | H12: 96 | I12: 96 | J12: 1.578 | K12: =E12*H12*J12/1000 -> 1053.1446 | L12: =F12*I12*J12/1000 -> 1053.1446 | M12: =L12-K12 -> 0 | N12: Giống nhau: Đai loe chân cột
A13: 9 | B13: B1 | C13: 28 | D13: Thép chủ lớp đáy bệ | E13: 11696 | F13: 11696 | G13: =F13-E13 -> 0 | H13: 68 | I13: 68 | J13: 4.833 | K13: =E13*H13*J13/1000 -> 3843.8202 | L13: =F13*I13*J13/1000 -> 3843.8202 | M13: =L13-K13 -> 0 | N13: Giống nhau: Bệ 11x8x2m 8 cọc D1200
A14: 10 | B14: B2 | C14: 18 | D14: Thép lưới mặt trên bệ | E14: 11376 | F14: 11376 | G14: =F14-E14 -> 0 | H14: 68 | I14: 68 | J14: 1.997 | K14: =E14*H14*J14/1000 -> 1544.8153 | L14: =F14*I14*J14/1000 -> 1544.8153 | M14: =L14-K14 -> 0 | N14: Giống nhau: Lưới chống nứt mặt bệ
A15: 11 | B15: B3 | C15: 28 | D15: Thép chịu lực phương ngang bệ | E15: 5696 | F15: 5696 | G15: =F15-E15 -> 0 | H15: 88 | I15: 88 | J15: 4.833 | K15: =E15*H15*J15/1000 -> 2422.5316 | L15: =F15*I15*J15/1000 -> 2422.5316 | M15: =L15-K15 -> 0 | N15: Giống nhau: Phương ngang 8.00m
A16: 12 | B16: B5 | C16: 16 | D16: Thép đai liên kết bệ trụ | E16: 2070 | F16: 2070 | G16: =F16-E16 -> 0 | H16: 160 | I16: 160 | J16: 1.578 | K16: =E16*H16*J16/1000 -> 522.6336 | L16: =F16*I16*J16/1000 -> 522.6336 | M16: =L16-K16 -> 0 | N16: Giống nhau: Đai hộp bệ trụ
... A18: 14 | B18: XM5 | C18: 25 | D18: Thép chịu cắt dầm consol | E18: 13983 | F18: 13983 | G18: =F18-E18 -> 0 | H18: 44 | I18: 44 | J18: 3.853 | K18: =E18*H18*J18/1000 -> 2370.566 | L18: =F18*I18*J18/1000 -> 2370.566 | M18: =L18-K18 -> 0 | N18: Giống nhau: Chịu cắt 2 đầu consol

Sheet 03_COC_D1200
A1: CHI TIẾT ĐO BÓC 26 CỌC KHOAN NHỒI D1200 TOÀN CẦU
A2: Căn cứ: Bản vẽ 04.D1200-19.5.dwg và Sổ tính thiết kế BKL-1.2-19.5.xls (Sheet TONG HOP & THKL)
A4: STT | B4: VỊ TRÍ KẾT CẤU | C4: SỐ LƯỢNG CỌC | D4: CHIỀU DÀI 1 CỌC (m) | E4: TỔNG DÀI KHOAN (m) | F4: CAO ĐỘ ĐẦU CỌC (m) | G4: CAO ĐỘ MŨI CỌC (m) | H4: BÊ TÔNG C30 (m3) | I4: CỐT THÉP CỌC (kg) | J4: ỐNG SIÊU ÂM D59.9 (m) | K4: ỐNG SIÊU ÂM D113.5 (m) | L4: GHI CHÚ KỸ THUẬT
A5: 1 | B5: MỐ M1 | C5: 3 | D5: 20 | E5: =C5*D5 -> 60 | F5: 191.234 | G5: 171.084 | H5: 70.74 | I5: 5436.32 | J5: 198 | K5: 63.6 | L5: 3 cọc D1200 L=20m (4 thanh treo D16)
A6: 2 | B6: TRỤ T1 | C6: 8 | D6: 40 | E6: =C6*D6 -> 320 | F6: 167.51 | G6: 127.36 | H6: 367.04 | I6: 14496.86 | J6: 1008 | K6: 329.6 | L6: 8 cọc D1200 L=40m (bệ 2 thân)
A7: 3 | B7: TRỤ T2 | C7: 8 | D7: 30 | E7: =C7*D7 -> 240 | F7: 166.01 | G7: 135.86 | H7: 277.84 | I7: 14496.86 | J7: 768 | K7: 249.6 | L7: 8 cọc D1200 L=30m (bệ 2 thân)
A8: 4 | B8: MỐ M2 | C8: 7 | D8: 36 | E8: =C8*D8 -> 252 | F8: 186.986 | G8: 150.836 | H8: 290.92 | I8: 12679.44 | J8: 798 | K8: 260.4 | L8: 7 cọc D1200 L=36m (tường thân cao)
A9: T | B9: TỔNG CỘNG 26 CỌC | C9: =SUM(C5:C8) -> 26 | D9: - | E9: =SUM(E5:E8) -> 872 | F9: - | G9: - | H9: =SUM(H5:H8) -> 1006.54 | I9: =SUM(I5:I8) -> 47109.48 | J9: =SUM(J5:J8) -> 2772 | K9: =SUM(K5:K8) -> 903.2 | L9: Toàn bộ cọc khoan nhồi Cầu Km19
