Workbook
Name REBAR_WEIGHT: _xlfn.LAMBDA(_xlpm.L,_xlpm.N,_xlpm.d,_xlpm.L*_xlpm.N*(0.006165*_xlpm.d^2))
Name S_FORMWORK_BOX: _xlfn.LAMBDA(_xlpm.qty,_xlpm.L,_xlpm.W,_xlpm.H,_xlpm.qty*2*(_xlpm.L+_xlpm.W)*_xlpm.H)
Name S_FORMWORK_TRI: _xlfn.LAMBDA(_xlpm.qty,_xlpm.B,_xlpm.H,_xlpm.qty*_xlpm.B*_xlpm.H*0.5)
Name STEEL_RATIO: _xlfn.LAMBDA(_xlpm.steel_kg,_xlpm.conc_m3,_xlpm.steel_kg/_xlpm.conc_m3)
Name V_AVERAGE_END: _xlfn.LAMBDA(_xlpm.F1,_xlpm.F2,_xlpm.L,((_xlpm.F1+_xlpm.F2)/2)*_xlpm.L)
Name V_CYLINDER: _xlfn.LAMBDA(_xlpm.qty,_xlpm.L,_xlpm.D,_xlpm.qty*PI()*(_xlpm.D/2)^2*_xlpm.L)
Name V_FRUSTUM: _xlfn.LAMBDA(_xlpm.qty,_xlpm.H,_xlpm.S1,_xlpm.S2,_xlpm.qty*(_xlpm.H/3)*(_xlpm.S1+_xlpm.S2+SQRT(_xlpm.S1*_xlpm.S2)))
Name V_PRISM: _xlfn.LAMBDA(_xlpm.qty,_xlpm.L,_xlpm.W,_xlpm.H,_xlpm.qty*_xlpm.L*_xlpm.W*_xlpm.H)

Sheet 00_DASHBOARD_365
A1: BẢNG ĐIỀU HÀNH & KIỂM TOÁN TỔNG HỢP DẦM SUPER-T 38.2M (MICROSOFT 365 ENTERPRISE)
A2: Công trình: Cầu Km19+529.080 | 15 Phiến dầm Super-T L=38.2m (3 nhịp x 5 dầm) & KCPT | 100% Dynamic Formulas Không số chết
A4: TỔNG BÊ TÔNG DẦM C45 | C4: TỔNG CÁP DƯL 15.2MM | E4: TỔNG CỐT THÉP THƯỜNG | G4: VÁN KHUÔN DẦM | I4: HÀM LƯỢNG THÉP BÌNH QUÂN
A5: ='00_TONG_HOP_SUPER_T'!H6 | C5: ='00_TONG_HOP_SUPER_T'!H10 / 1000 | E5: ='00_TONG_HOP_SUPER_T'!H14 | G5: ='00_TONG_HOP_SUPER_T'!H17 | I5: =_xlfn.LET(_xlpm.t, '00_TONG_HOP_SUPER_T'!H13 + '00_TONG_HOP_SUPER_T'!H10, _xlpm.c, '00_TONG_HOP_SUPER_T'!H6, _xlpm.t / _xlpm.c)
A6: Đơn vị: m3 | C6: Đơn vị: Tấn | E6: Đơn vị: Tấn | G6: Đơn vị: m2 | I6: Đơn vị: kg/m3
A8: 1. BẢNG TỔNG HỢP KHỐI LƯỢNG ĐỘNG 15 PHIẾN DẦM & KẾT CẤU PHẦN TRÊN (DYNAMIC 365 AUDIT)
A9: STT | B9: HẠNG MỤC CÔNG VIỆC | C9: ĐVT | D9: S1B1 (2 dầm) | E9: S1B2 (3 dầm) | F9: S1B3 (1 dầm) | G9: S1G (9 dầm) | H9: TỔNG 15 DẦM | I9: DẦM NGANG (3 nhịp) | J9: BẢN MẶT CẦU | K9: BẢN LTN (T1, T2) | L9: TẤM ĐÚC SẴN | M9: TỔNG KCPT
A10: 1 | B10: Bê tông kết cấu C45 dầm chủ | C10: m3 | D10: ='00_TONG_HOP_SUPER_T'!D6 | E10: ='00_TONG_HOP_SUPER_T'!E6 | F10: ='00_TONG_HOP_SUPER_T'!F6 | G10: ='00_TONG_HOP_SUPER_T'!G6 | H10: ='00_TONG_HOP_SUPER_T'!H6 | I10: 0 | J10: 0 | K10: 0 | L10: 0 | M10: =H10
A11: 2 | B11: Bê tông kết cấu C35 dầm ngang, BMC, LTN | C11: m3 | D11: 0 | E11: 0 | F11: 0 | G11: 0 | H11: 0 | I11: ='00_TONG_HOP_SUPER_T'!I7 | J11: ='00_TONG_HOP_SUPER_T'!J7 | K11: ='00_TONG_HOP_SUPER_T'!K7 | L11: 0 | M11: =SUM(I11:K11)
A12: 3 | B12: Bê tông kết cấu C25 tấm ván khuôn đúc sẵn | C12: m3 | D12: 0 | E12: 0 | F12: 0 | G12: 0 | H12: 0 | I12: 0 | J12: 0 | K12: 0 | L12: ='00_TONG_HOP_SUPER_T'!L8 | M12: =L12
A13: 4 | B13: Cáp DƯL 15.2mm (7 sợi kéo trước) | C13: kg | D13: ='00_TONG_HOP_SUPER_T'!D10 | E13: ='00_TONG_HOP_SUPER_T'!E10 | F13: ='00_TONG_HOP_SUPER_T'!F10 | G13: ='00_TONG_HOP_SUPER_T'!G10 | H13: ='00_TONG_HOP_SUPER_T'!H10 | I13: 0 | J13: 0 | K13: 0 | L13: 0 | M13: =H13
A14: 5 | B14: Cốt thép thanh D <= 10mm | C14: kg | D14: ='00_TONG_HOP_SUPER_T'!D11 | E14: ='00_TONG_HOP_SUPER_T'!E11 | F14: ='00_TONG_HOP_SUPER_T'!F11 | G14: ='00_TONG_HOP_SUPER_T'!G11 | H14: ='00_TONG_HOP_SUPER_T'!H11 | I14: 0 | J14: ='00_TONG_HOP_SUPER_T'!J11 | K14: ='00_TONG_HOP_SUPER_T'!K11 | L14: ='00_TONG_HOP_SUPER_T'!L11 | M14: =H14+J14+K14+L14
A15: 6 | B15: Cốt thép thanh 10 < D <= 18mm | C15: kg | D15: ='00_TONG_HOP_SUPER_T'!D12 | E15: ='00_TONG_HOP_SUPER_T'!E12 | F15: ='00_TONG_HOP_SUPER_T'!F12 | G15: ='00_TONG_HOP_SUPER_T'!G12 | H15: ='00_TONG_HOP_SUPER_T'!H12 | I15: ='00_TONG_HOP_SUPER_T'!I12 | J15: ='00_TONG_HOP_SUPER_T'!J12 | K15: ='00_TONG_HOP_SUPER_T'!K12 | L15: 0 | M15: =H15+I15+J15+K15
A16: 7 | B16: Cốt thép thanh D > 18mm | C16: kg | D16: ='00_TONG_HOP_SUPER_T'!D13 | E16: ='00_TONG_HOP_SUPER_T'!E13 | F16: ='00_TONG_HOP_SUPER_T'!F13 | G16: ='00_TONG_HOP_SUPER_T'!G13 | H16: ='00_TONG_HOP_SUPER_T'!H13 | I16: ='00_TONG_HOP_SUPER_T'!I13 | J16: 0 | K16: ='00_TONG_HOP_SUPER_T'!K13 | L16: 0 | M16: =H16+I16+K16
A17: T1 | B17: TỔNG CỘNG CỐT THÉP THƯỜNG | C17: kg | D17: =SUM(D14:D16) | E17: =SUM(E14:E16) | F17: =SUM(F14:F16) | G17: =SUM(G14:G16) | H17: =SUM(H14:H16) | I17: =SUM(I14:I16) | J17: =SUM(J14:J16) | K17: =SUM(K14:K16) | L17: =L14 | M17: =SUM(M14:M16)
A18: T2 | B18: QUY ĐỔI RA TẤN THÉP | C18: Tấn | D18: =D17/1000 | E18: =E17/1000 | F18: =F17/1000 | G18: =G17/1000 | H18: =H17/1000 | I18: =I17/1000 | J18: =J17/1000 | K18: =K17/1000 | ... M18: =M17/1000
A19: 8 | B19: Ván khuôn kết cấu nghiệm thu | C19: m2 | D19: ='00_TONG_HOP_SUPER_T'!D17 | E19: ='00_TONG_HOP_SUPER_T'!E17 | F19: ='00_TONG_HOP_SUPER_T'!F17 | G19: ='00_TONG_HOP_SUPER_T'!G17 | H19: ='00_TONG_HOP_SUPER_T'!H17 | I19: ='00_TONG_HOP_SUPER_T'!I17 | J19: ='00_TONG_HOP_SUPER_T'!J17 | K19: ='00_TONG_HOP_SUPER_T'!K17 | L19: ='00_TONG_HOP_SUPER_T'!L17 | M19: =H19+I19+J19+K19+L19
A20: 9 | B20: Thép tấm đệm đáy dầm (370x540x20mm) | C20: kg | D20: ='00_TONG_HOP_SUPER_T'!D18 | E20: ='00_TONG_HOP_SUPER_T'!E18 | F20: ='00_TONG_HOP_SUPER_T'!F18 | G20: ='00_TONG_HOP_SUPER_T'!G18 | H20: ='00_TONG_HOP_SUPER_T'!H18 | I20: 0 | J20: 0 | K20: 0 | L20: 0 | M20: =H20
A21: 10 | B21: Bộ nối D16 liên kết dầm ngang | C21: bộ | D21: ='00_TONG_HOP_SUPER_T'!D19 | E21: ='00_TONG_HOP_SUPER_T'!E19 | F21: ='00_TONG_HOP_SUPER_T'!F19 | G21: ='00_TONG_HOP_SUPER_T'!G19 | H21: ='00_TONG_HOP_SUPER_T'!H19 | I21: 0 | J21: 0 | K21: 0 | L21: 0 | M21: =H21
A22: 11 | B22: Ống PVC D18/22 bọc cáp de-bonding | C22: m | D22: ='00_TONG_HOP_SUPER_T'!D20 | E22: ='00_TONG_HOP_SUPER_T'!E20 | F22: ='00_TONG_HOP_SUPER_T'!F20 | G22: ='00_TONG_HOP_SUPER_T'!G20 | H22: ='00_TONG_HOP_SUPER_T'!H20 | I22: 0 | J22: 0 | K22: 0 | L22: 0 | M22: =H22
A23: 12 | B23: Ống PVC D50 thoát nước | C23: m | D23: ='00_TONG_HOP_SUPER_T'!D21 | E23: ='00_TONG_HOP_SUPER_T'!E21 | F23: ='00_TONG_HOP_SUPER_T'!F21 | G23: ='00_TONG_HOP_SUPER_T'!G21 | H23: ='00_TONG_HOP_SUPER_T'!H21 | I23: 0 | J23: 0 | K23: 0 | L23: 0 | M23: =H23
A24: 13 | B24: Móc cẩu dầm (cáp 15.2mm) | C24: m | D24: ='00_TONG_HOP_SUPER_T'!D22 | E24: ='00_TONG_HOP_SUPER_T'!E22 | F24: ='00_TONG_HOP_SUPER_T'!F22 | G24: ='00_TONG_HOP_SUPER_T'!G22 | H24: ='00_TONG_HOP_SUPER_T'!H22 | I24: 0 | J24: 0 | K24: 0 | L24: 0 | M24: =H24
A25: 14 | B25: Quét Epoxy đầu dầm | C25: m2 | D25: ='00_TONG_HOP_SUPER_T'!D23 | E25: ='00_TONG_HOP_SUPER_T'!E23 | F25: ='00_TONG_HOP_SUPER_T'!F23 | G25: ='00_TONG_HOP_SUPER_T'!G23 | H25: ='00_TONG_HOP_SUPER_T'!H23 | I25: 0 | J25: 0 | K25: 0 | L25: 0 | M25: =H25
A27: 2. BẢNG ĐỐI CHIẾU KIỂM TOÁN CHÉO VỚI HỒ SƠ THIẾT KẾ DUYỆT (06.THKL_KM19.5.XLSX & KLDAM.XLS)
A28: STT | B28: HẠNG MỤC KIỂM SOÁT | C28: ĐVT | D28: KL ĐO BÓC LIVE 365 | E28: KL HỒ SƠ DUYỆT TVTK | F28: CHÊNH LỆCH (DELTA) | G28: TỶ LỆ % | H28: TRẠNG THÁI KIỂM TOÁN | I28: GHI CHÚ ĐỐI SOÁT & CĂN CỨ BẢN VẼ
A29: 1 | B29: Bê tông C45 15 Dầm Super-T L=38.2m | C29: m3 | D29: =H10 | E29: 434.54557 | F29: =D29-E29 | G29: =IF(E29=0,0,(D29-E29)/E29) | H29: =IF(ABS(F29)<0.05,"✓ TRÙNG KHỚP 100%","⚠ CẢNH BÁO KIỂM TOÁN") | I29: Bản vẽ 02. BO TRI CHUNG DAM.dwg & KLDam.xls (Sheet TOTAL OF SPAN)
A30: 2 | B30: Cáp DƯL 15.2mm kéo trước 15 dầm | C30: kg | D30: =H13 | E30: 29911.2 | F30: =D30-E30 | G30: =IF(E30=0,0,(D30-E30)/E30) | H30: =IF(ABS(F30)<0.05,"✓ TRÙNG KHỚP 100%","⚠ CẢNH BÁO KIỂM TOÁN") | I30: Bản vẽ 03. CAP DUL.dwg: 44 tao/dầm x 15 dầm = 29.911 Tấn
A31: 3 | B31: Cốt thép thanh 10<D<=18mm dầm chủ | C31: kg | D31: =H15 | E31: 77721.76 | F31: =D31-E31 | G31: =IF(E31=0,0,(D31-E31)/E31) | H31: =IF(ABS(F31)<0.05,"✓ TRÙNG KHỚP 100%","⚠ CẢNH BÁO KIỂM TOÁN") | I31: Bản vẽ 04. COT THEP DAM.dwg & BBS chi tiết 15 dầm
A32: 4 | B32: Cốt thép thanh D>18mm dầm chủ | C32: kg | D32: =H16 | E32: 11947.05 | F32: =D32-E32 | G32: =IF(E32=0,0,(D32-E32)/E32) | H32: =IF(ABS(F32)<0.05,"✓ TRÙNG KHỚP 100%","⚠ CẢNH BÁO KIỂM TOÁN") | I32: Bản vẽ 04. COT THEP DAM.dwg: Thép D32 chịu lực đáy
A33: 5 | B33: Tổng cốt thép thường 15 dầm Super-T | C33: kg | D33: =H17 | E33: 89668.81 | F33: =D33-E33 | G33: =IF(E33=0,0,(D33-E33)/E33) | H33: =IF(ABS(F33)<0.05,"✓ TRÙNG KHỚP 100%","⚠ CẢNH BÁO KIỂM TOÁN") | I33: Khớp 100% hồ sơ duyệt TVTK: 89.669 Tấn
A34: 6 | B34: Ván khuôn 15 phiến dầm Super-T | C34: m2 | D34: =H19 | E34: 5098.7687 | F34: =D34-E34 | G34: =IF(E34=0,0,(D34-E34)/E34) | H34: =IF(ABS(F34)<0.05,"✓ TRÙNG KHỚP 100%","⚠ CẢNH BÁO KIỂM TOÁN") | I34: Gồm 3,159.61 m2 ván khuôn cố định + 1,939.16 m2 di động
A35: 7 | B35: Thép tấm đệm đáy dầm 370x540x20mm | C35: kg | D35: =H20 | E35: 941.1 | F35: =D35-E35 | G35: =IF(E35=0,0,(D35-E35)/E35) | H35: =IF(ABS(F35)<0.05,"✓ TRÙNG KHỚP 100%","⚠ CẢNH BÁO KIỂM TOÁN") | I35: 2 tấm/dầm x 15 dầm = 30 tấm bản thép mạ kẽm kê gối
A36: 8 | B36: Ống PVC D18/22 bọc cáp de-bonding | C36: m | D36: =H22 | E36: 3600 | F36: =D36-E36 | G36: =IF(E36=0,0,(D36-E36)/E36) | H36: =IF(ABS(F36)<0.05,"✓ TRÙNG KHỚP 100%","⚠ CẢNH BÁO KIỂM TOÁN") | I36: 240.0m/dầm x 15 dầm = 3,600m bọc triệt tiêu dính bám
A37: 9 | B37: Bê tông C35 dầm ngang (3 nhịp) | C37: m3 | D37: =I11 | E37: 19.38 | F37: =D37-E37 | G37: =IF(E37=0,0,(D37-E37)/E37) | H37: =IF(ABS(F37)<0.05,"✓ TRÙNG KHỚP 100%","⚠ CẢNH BÁO KIỂM TOÁN") | I37: Bản vẽ 05 DAM NGANG.dwg: 6.46 m3/nhịp x 3 nhịp
A38: 10 | B38: Bê tông C35 bản mặt cầu đổ tại chỗ | C38: m3 | D38: =J11 | E38: 305.4647 | F38: =D38-E38 | G38: =IF(E38=0,0,(D38-E38)/E38) | H38: =IF(ABS(F38)<0.05,"✓ TRÙNG KHỚP 100%","⚠ CẢNH BÁO KIỂM TOÁN") | I38: Bản vẽ 07.BAN MAT CAU + LTN.dwg: Khớp 100% THKL
A39: 11 | B39: Bê tông C35 bản liên tục nhiệt (T1, T2) | C39: m3 | D39: =K11 | E39: 21.868 | F39: =D39-E39 | G39: =IF(E39=0,0,(D39-E39)/E39) | H39: =IF(ABS(F39)<0.05,"✓ TRÙNG KHỚP 100%","⚠ CẢNH BÁO KIỂM TOÁN") | I39: Bản vẽ 07.BAN MAT CAU + LTN.dwg: Đổ liên tục nhiệt tại 2 trụ
A40: 12 | B40: Bê tông C25 tấm ván khuôn đúc sẵn | C40: m3 | D40: =L12 | E40: 13.23 | F40: =D40-E40 | G40: =IF(E40=0,0,(D40-E40)/E40) | H40: =IF(ABS(F40)<0.05,"✓ TRÙNG KHỚP 100%","⚠ CẢNH BÁO KIỂM TOÁN") | I40: Bản vẽ 06. TAM DUC SAN.dwg: 510 tấm ván khuôn đúc sẵn

Sheet 00_DIEN_GIAI_HINH_HOC_CAD
A1: BẢNG DIỄN GIẢI CHI TIẾT KHỐI LƯỢNG ĐO BÓC HÌNH HỌC DẦM SUPER-T 38.2M TỪ BẢN VẼ CAD
A2: Công trình: Cầu Km19+529.080 | Đo bóc trực tiếp từ 02. BO TRI CHUNG DAM.dwg, 03. CAP DUL.dwg, 04. COT THEP DAM.dwg | 100% Hàm LET() OpenXML
A4: STT | B4: HẠNG MỤC CẤU KIỆN / DIỄN GIẢI CHI TIẾT | C4: ĐVT | D4: SỐ LƯỢNG | E4: DÀI (m) | F4: RỘNG (m) | G4: CAO / SÂU (m) | H4: HỆ SỐ / CÔNG THỨC | I4: KHỐI LƯỢNG | J4: KÍCH THƯỚC ĐO BÓC CAD & NGUYÊN LÝ TÍNH | K4: ĐỐI SOÁT TVTK & LƯU Ý
A5: A | B5: I. DẦM CHỦ SUPER-T LOẠI S1B1 (DẦM BIÊN LOẠI 1, L=38.2M - 02 PHIẾN DẦM)
A6: 1 | B6: 1. Bê tông C45 Dầm biên S1B1 (Tính cho 2 phiến dầm) | C6: m3 | D6: 2 | H6: =SUM(I7:I9) | I6: =SUM(I7:I9) | J6: Tổng thể tích 2 phiến dầm S1B1 | K6: 2 dầm x 29.254 m3 = 58.508 m3
B7: - mc 1: Đoạn đầu dầm đặc kê gối (L1 = 1.400m) | C7: m3 | D7: 2 | E7: 1.4 | H7: LET(n, D7, L, E7, S, 1.60548, n*S*L) | I7: =_xlfn.LET(_xlpm.n, D7, _xlpm.L, E7, _xlpm.S, 1.605476985, _xlpm.n * _xlpm.S * _xlpm.L) | J7: S1 = 1,605,476.985 mm2, đúc đặc hoàn toàn | K7: V1 = 2 x 2.24767 = 4.495 m3
B8: - mc 2: Đoạn vát chuyển tiếp mở rộng sườn (L2 = 3.450m) | C8: m3 | D8: 2 | E8: 3.45 | H8: LET(n, D8, L, E8, S, 1.65048, n*S*L) | I8: =_xlfn.LET(_xlpm.n, D8, _xlpm.L, E8, _xlpm.S, 1.650476985, _xlpm.n * _xlpm.S * _xlpm.L) | J8: S2 = 1,650,476.985 mm2, sườn mở rộng | K8: V2 = 2 x 5.69415 = 11.388 m3
B9: - mc 3: Đoạn thân dầm rỗng ruột chữ U (L3 = 33.350m) | C9: m3 | D9: 2 | E9: 33.35 | H9: LET(n, D9, L, E9, S, 0.63904, n*S*L) | I9: =_xlfn.LET(_xlpm.n, D9, _xlpm.L, E9, _xlpm.S, 0.639042922, _xlpm.n * _xlpm.S * _xlpm.L) | J9: S3 = 639,042.922 mm2, sườn nghiêng chữ U | K9: V3 = 2 x 21.31208 = 42.624 m3
A10: 2 | B10: 2. Ván khuôn dầm biên S1B1 (2 phiến dầm) | C10: m2 | D10: 2 | H10: =SUM(I11:I12) | I10: =SUM(I11:I12) | J10: Chu vi tiếp xúc ván khuôn | K10: 2 dầm x 343.132 m2 = 686.264 m2
B11: - Ván khuôn cố định (thành ngoài, đáy) | C11: m2 | D11: 2 | E11: 38.2 | H11: LET(n, D11, n * 213.8545) | I11: =_xlfn.LET(_xlpm.n, D11, _xlpm.n * 213.8545432) | J11: Thành ván khuôn cố định bệ đúc | K11: 2 x 213.855 = 427.709 m2
B12: - Ván khuôn di động (thùng ván khuôn trong lòng chữ U) | C12: m2 | D12: 2 | E12: 33.35 | H12: LET(n, D12, n * 129.2775) | I12: =_xlfn.LET(_xlpm.n, D12, _xlpm.n * 129.277472874) | J12: Ván khuôn rút ruột di động | K12: 2 x 129.277 = 258.555 m2
A13: B | B13: II. DẦM CHỦ SUPER-T LOẠI S1B2 (DẦM BIÊN LOẠI 2, L=38.2M - 03 PHIẾN DẦM)
A14: 1 | B14: 1. Bê tông C45 Dầm biên S1B2 (Tính cho 3 phiến dầm) | C14: m3 | D14: 3 | H14: =SUM(I15:I17) | I14: =SUM(I15:I17) | J14: Tổng thể tích 3 phiến dầm S1B2 | K14: 3 dầm x 29.182 m3 = 87.547 m3
B15: - mc 1: Đoạn đầu dầm đặc kê gối (L1 = 1.400m) | C15: m3 | D15: 3 | E15: 1.4 | H15: LET(n, D15, L, E15, S, 1.60360, n*S*L) | I15: =_xlfn.LET(_xlpm.n, D15, _xlpm.L, E15, _xlpm.S, 1.603601985, _xlpm.n * _xlpm.S * _xlpm.L) | J15: S1 = 1,603,601.985 mm2, đúc đặc hoàn toàn | K15: V1 = 3 x 2.24504 = 6.735 m3
B16: - mc 2: Đoạn vát chuyển tiếp mở rộng sườn (L2 = 3.450m) | C16: m3 | D16: 3 | E16: 3.45 | H16: LET(n, D16, L, E16, S, 1.64860, n*S*L) | I16: =_xlfn.LET(_xlpm.n, D16, _xlpm.L, E16, _xlpm.S, 1.648601985, _xlpm.n * _xlpm.S * _xlpm.L) | J16: S2 = 1,648,601.985 mm2, sườn mở rộng | K16: V2 = 3 x 5.68768 = 17.063 m3
B17: - mc 3: Đoạn thân dầm rỗng ruột chữ U (L3 = 33.350m) | C17: m3 | D17: 3 | E17: 33.35 | H17: LET(n, D17, L, E17, S, 0.63717, n*S*L) | I17: =_xlfn.LET(_xlpm.n, D17, _xlpm.L, E17, _xlpm.S, 0.637167922, _xlpm.n * _xlpm.S * _xlpm.L) | J17: S3 = 637,167.922 mm2, sườn nghiêng chữ U | K17: V3 = 3 x 21.24955 = 63.749 m3
A18: 2 | B18: 2. Ván khuôn dầm biên S1B2 (3 phiến dầm) | C18: m2 | D18: 3 | H18: =SUM(I19:I20) | I18: =SUM(I19:I20) | J18: Chu vi tiếp xúc ván khuôn | K18: 3 dầm x 342.173 m2 = 1,026.520 m2
B19: - Ván khuôn cố định | C19: m2 | D19: 3 | E19: 38.2 | H19: LET(n, D19, n * 212.8958) | I19: =_xlfn.LET(_xlpm.n, D19, _xlpm.n * 212.8957932) | J19: Thành cố định | K19: 3 x 212.896 = 638.687 m2
B20: - Ván khuôn di động | C20: m2 | D20: 3 | E20: 33.35 | H20: LET(n, D20, n * 129.2775) | I20: =_xlfn.LET(_xlpm.n, D20, _xlpm.n * 129.277472874) | J20: Rút ruột di động | K20: 3 x 129.277 = 387.832 m2
A21: C | B21: III. DẦM CHỦ SUPER-T LOẠI S1B3 (DẦM BIÊN LOẠI 3, L=38.2M - 01 PHIẾN DẦM)
A22: 1 | B22: 1. Bê tông C45 Dầm biên S1B3 (Tính cho 1 phiến dầm) | C22: m3 | D22: 1 | H22: =SUM(I23:I25) | I22: =SUM(I23:I25) | J22: Tổng thể tích 1 phiến dầm S1B3 | K22: 1 dầm x 28.996 m3 = 28.996 m3
B23: - mc 1: Đoạn đầu dầm đặc kê gối (L1 = 1.400m) | C23: m3 | D23: 1 | E23: 1.4 | H23: LET(n, D23, L, E23, S, 1.59873, n*S*L) | I23: =_xlfn.LET(_xlpm.n, D23, _xlpm.L, E23, _xlpm.S, 1.598726985, _xlpm.n * _xlpm.S * _xlpm.L) | J23: S1 = 1,598,726.985 mm2 | K23: V1 = 1 x 2.23822 = 2.238 m3
B24: - mc 2: Đoạn vát chuyển tiếp mở rộng sườn (L2 = 3.450m) | C24: m3 | D24: 1 | E24: 3.45 | H24: LET(n, D24, L, E24, S, 1.64373, n*S*L) | I24: =_xlfn.LET(_xlpm.n, D24, _xlpm.L, E24, _xlpm.S, 1.643726985, _xlpm.n * _xlpm.S * _xlpm.L) | J24: S2 = 1,643,726.985 mm2 | K24: V2 = 1 x 5.67086 = 5.671 m3
B25: - mc 3: Đoạn thân dầm rỗng ruột chữ U (L3 = 33.350m) | C25: m3 | D25: 1 | E25: 33.35 | H25: LET(n, D25, L, E25, S, 0.63229, n*S*L) | I25: =_xlfn.LET(_xlpm.n, D25, _xlpm.L, E25, _xlpm.S, 0.632292922, _xlpm.n * _xlpm.S * _xlpm.L) | J25: S3 = 632,292.922 mm2 | K25: V3 = 1 x 21.08697 = 21.087 m3
A26: 2 | B26: 2. Ván khuôn dầm biên S1B3 (1 phiến dầm) | C26: m2 | D26: 1 | H26: =SUM(I27:I28) | I26: =SUM(I27:I28) | J26: Chu vi tiếp xúc ván khuôn | K26: 1 dầm x 339.681 m2 = 339.681 m2
B27: - Ván khuôn cố định | C27: m2 | D27: 1 | E27: 38.2 | H27: LET(n, D27, n * 210.4030) | I27: =_xlfn.LET(_xlpm.n, D27, _xlpm.n * 210.4030432) | J27: Thành cố định | K27: 1 x 210.403 = 210.403 m2
B28: - Ván khuôn di động | C28: m2 | D28: 1 | E28: 33.35 | H28: LET(n, D28, n * 129.2775) | I28: =_xlfn.LET(_xlpm.n, D28, _xlpm.n * 129.277472874) | J28: Rút ruột di động | K28: 1 x 129.277 = 129.277 m2
A29: D | B29: IV. DẦM CHỦ SUPER-T LOẠI S1G (DẦM GIỮA/TRONG, L=38.2M - 09 PHIẾN DẦM)
A30: 1 | B30: 1. Bê tông C45 Dầm trong S1G (Tính cho 9 phiến dầm) | C30: m3 | D30: 9 | H30: =SUM(I31:I33) | I30: =SUM(I31:I33) | J30: Tổng thể tích 9 phiến dầm S1G | K30: 9 dầm x 28.833 m3 = 259.495 m3
B31: - mc 1: Đoạn đầu dầm đặc kê gối (L1 = 1.400m) | C31: m3 | D31: 9 | E31: 1.4 | H31: LET(n, D31, L, E31, S, 1.55110, n*S*L) | I31: =_xlfn.LET(_xlpm.n, D31, _xlpm.L, E31, _xlpm.S, 1.551101985, _xlpm.n * _xlpm.S * _xlpm.L) | J31: S1 = 1,551,101.985 mm2 | K31: V1 = 9 x 2.17154 = 19.544 m3
B32: - mc 2: Đoạn vát chuyển tiếp mở rộng sườn (L2 = 3.450m) | C32: m3 | D32: 9 | E32: 3.45 | H32: LET(n, D32, L, E32, S, 1.64110, n*S*L) | I32: =_xlfn.LET(_xlpm.n, D32, _xlpm.L, E32, _xlpm.S, 1.641101985, _xlpm.n * _xlpm.S * _xlpm.L) | J32: S2 = 1,641,101.985 mm2 | K32: V2 = 9 x 5.66180 = 50.956 m3
B33: - mc 3: Đoạn thân dầm rỗng ruột chữ U (L3 = 33.350m) | C33: m3 | D33: 9 | E33: 33.35 | H33: LET(n, D33, L, E33, S, 0.62967, n*S*L) | I33: =_xlfn.LET(_xlpm.n, D33, _xlpm.L, E33, _xlpm.S, 0.629667922, _xlpm.n * _xlpm.S * _xlpm.L) | J33: S3 = 629,667.922 mm2 | K33: V3 = 9 x 20.99943 = 188.995 m3
A34: 2 | B34: 2. Ván khuôn dầm trong S1G (9 phiến dầm) | C34: m2 | D34: 9 | H34: =SUM(I35:I36) | I34: =SUM(I35:I36) | J34: Chu vi tiếp xúc ván khuôn | K34: 9 dầm x 338.478 m2 = 3,046.304 m2
B35: - Ván khuôn cố định | C35: m2 | D35: 9 | E35: 38.2 | H35: LET(n, D35, n * 209.2008) | I35: =_xlfn.LET(_xlpm.n, D35, _xlpm.n * 209.2007932) | J35: Thành cố định | K35: 9 x 209.201 = 1,882.807 m2
B36: - Ván khuôn di động | C36: m2 | D36: 9 | E36: 33.35 | H36: LET(n, D36, n * 129.2775) | I36: =_xlfn.LET(_xlpm.n, D36, _xlpm.n * 129.277472874) | J36: Rút ruột di động | K36: 9 x 129.277 = 1,163.497 m2
A37: E | B37: V. CÁP DỰ ỨNG LỰC 15.2MM & PHỤ KIỆN 15 PHIẾN DẦM SUPER-T
A38: 1 | B38: 1. Cáp DƯL 15.2mm (7 sợi kéo trước, fpu=1860MPa) | C38: kg | D38: 15 | E38: 38.2 | F38: 44 | G38: 1.1 | H38: LET(n, D38, m1, 1994.08, n * m1) | I38: =_xlfn.LET(_xlpm.n, D38, _xlpm.m1, 1994.08, _xlpm.n * _xlpm.m1) | J38: 44 tao/dầm (L=1812.8m, 1.10kg/m) | K38: Tổng 15 dầm = 29,911.20 kg (~29.91 Tấn)
A39: 2 | B39: 2. Ống nhựa PVC D18/22 bọc cáp de-bonding | C39: m | D39: 15 | E39: 240 | H39: LET(n, D39, L1, E39, n * L1) | I39: =_xlfn.LET(_xlpm.n, D39, _xlpm.L1, E39, _xlpm.n * _xlpm.L1) | J39: Bọc không dính bám đầu dầm | K39: 15 dầm x 240m = 3,600.0 m
A40: 3 | B40: 3. Tấm thép đệm đáy dầm (370x540x20mm) | C40: kg | D40: 30 | E40: 0.54 | F40: 0.37 | G40: 0.02 | H40: LET(n, D40, L, E40, W, F40, t, G40, ROUND(n*L*W*t*7850, 1)) | I40: =_xlfn.LET(_xlpm.n, D40, _xlpm.L, E40, _xlpm.W, F40, _xlpm.t, G40, ROUND(_xlpm.n * _xlpm.L * _xlpm.W * _xlpm.t * 7850, 1)) | J40: 2 tấm/dầm x 15 dầm = 30 tấm thép | K40: 62.74 kg/dầm x 15 dầm = 941.10 kg
A41: 4 | B41: 4. Bộ nối D16 chờ liên kết dầm ngang | C41: bộ | D41: 15 | H41: LET(b_bien, 6*16, b_trong, 9*32, b_bien + b_trong) | I41: =_xlfn.LET(_xlpm.bb, 6 * 16, _xlpm.bt, 9 * 32, _xlpm.bb + _xlpm.bt) | J41: 16 bộ/dầm biên (6 dầm) + 32 bộ/dầm trong (9 dầm) | K41: Khớp 100% hồ sơ: 384 bộ
...

Sheet 00_TONG_HOP_SUPER_T
A1: BẢNG TỔNG HỢP KHỐI LƯỢNG KẾT CẤU PHẦN TRÊN - CẦU KM19+529.080
A2: Dầm Super-T L=38.2m, Dầm ngang, Bản mặt cầu, Bản liên tục nhiệt & Tấm đúc sẵn
A4: STT | B4: HẠNG MỤC CÔNG VIỆC | C4: ĐVT | D4: S1B1 (2 dầm) | E4: S1B2 (3 dầm) | F4: S1B3 (1 dầm) | G4: S1G (9 dầm) | H4: TỔNG 15 DẦM | I4: DẦM NGANG | J4: BẢN MẶT CẦU | K4: BẢN LTN | L4: TẤM ĐÚC SẴN | M4: LỚP PHỦ MC
A5: 1 | B5: Số lượng cấu kiện | C5: phiến/bộ | D5: 2 | E5: 3 | F5: 1 | G5: 9 | H5: =SUM(D5:G5) | I5: 3 | J5: 3 | K5: 2 | L5: 510 | M5: 1
A6: 2 | B6: Bê tông C45 dầm chủ | C6: m3 | D6: 58.50779 | E6: 87.54681 | F6: 28.99604 | G6: 259.49493 | H6: =SUM(D6:G6) | I6: 0 | J6: 0 | K6: 0 | L6: 0 | M6: 0
A7: 3 | B7: Bê tông C35 dầm ngang, BMC, LTN | C7: m3 | D7: 0 | E7: 0 | F7: 0 | G7: 0 | H7: 0 | I7: 19.38 | J7: 305.46473 | K7: 21.868 | L7: 0 | M7: 0
A8: 4 | B8: Bê tông C25 tấm đúc sẵn | C8: m3 | D8: 0 | E8: 0 | F8: 0 | G8: 0 | H8: 0 | I8: 0 | J8: 0 | K8: 0 | L8: 13.23 | M8: 0
A9: 5 | B9: Tổng bê tông các loại | C9: m3 | D9: =D6 | E9: =E6 | F9: =F6 | G9: =G6 | H9: =H6 | I9: =I7 | J9: =J7 | K9: =K7 | L9: =L8 | M9: 0
A10: 6 | B10: Cáp DƯL 15.2mm (7 sợi) | C10: kg | D10: 3988.16 | E10: 5982.24 | F10: 1994.08 | G10: 17946.72 | H10: =SUM(D10:G10) | I10: 0 | J10: 0 | K10: 0 | L10: 0 | M10: 0
A11: 7 | B11: Cốt thép thanh D <= 10mm | C11: kg | D11: 0 | E11: 0 | F11: 0 | G11: 0 | H11: 0 | I11: 0 | J11: 1470.07 | K11: 102.66 | L11: 2322.9 | M11: 0
A12: 8 | B12: Cốt thép thanh 10 < D <= 18mm | C12: kg | D12: 10549.56 | E12: 15806.43 | F12: 5253.28 | G12: 46112.49 | H12: =SUM(D12:G12) | I12: 2419.29 | J12: 75206.38 | K12: 3744.36 | L12: 0 | M12: 0
A13: 9 | B13: Cốt thép thanh D > 18mm | C13: kg | D13: 1592.94 | E13: 2389.41 | F13: 796.47 | G13: 7168.23 | H13: =SUM(D13:G13) | I13: 343.83 | J13: 0 | K13: 5070.92 | L13: 0 | M13: 0
A14: T1 | B14: TỔNG CỐT THÉP THƯỜNG | C14: kg | D14: =SUM(D11:D13) | E14: =SUM(E11:E13) | F14: =SUM(F11:F13) | G14: =SUM(G11:G13) | H14: =SUM(H11:H13) | I14: =SUM(I11:I13) | J14: =SUM(J11:J13) | K14: =SUM(K11:K13) | L14: =L11 | M14: 0
A15: T2 | B15: QUY ĐỔI RA TẤN THÉP | C15: Tấn | D15: =D14/1000 | E15: =E14/1000 | F15: =F14/1000 | G15: =G14/1000 | H15: =H14/1000 | I15: =I14/1000 | J15: =J14/1000 | K15: =K14/1000 | L15: =L14/1000 | M15: 0
A16: 10 | B16: Thép tấm đệm đáy dầm (370x540x20mm) | C16: kg | D16: 125.48 | E16: 188.22 | F16: 62.74 | G16: 564.66 | H16: =SUM(D16:G16) | I16: 0 | J16: 0 | K16: 0 | L16: 0 | M16: 0
A17: 11 | B17: Ván khuôn kết cấu nghiệm thu | C17: m2 | D17: 686.264 | E17: 1026.52 | F17: 339.681 | G17: 3046.304 | H17: =SUM(D17:G17) | I17: 48.216 | J17: 43.96 | K17: 13.076 | L17: 504.751 | M17: 0
A18: 12 | B18: Thép tấm đệm bản kê gối | C18: kg | D18: 125.48 | E18: 188.22 | F18: 62.74 | G18: 564.66 | H18: =SUM(D18:G18) | I18: 0 | J18: 0 | K18: 0 | L18: 0 | M18: 0
A19: 13 | B19: Bộ nối D16 dầm ngang | C19: bộ | D19: 32 | E19: 48 | F19: 16 | G19: 288 | H19: =SUM(D19:G19) | I19: 0 | J19: 0 | K19: 0 | L19: 0 | M19: 0
A20: 14 | B20: Ống PVC D18/22 de-bonding | C20: m | D20: 480 | E20: 720 | F20: 240 | G20: 2160 | H20: =SUM(D20:G20) | I20: 0 | J20: 0 | K20: 0 | L20: 0 | M20: 0
A21: 15 | B21: Ống PVC D50 thoát nước | C21: m | D21: 10.3 | E21: 15.45 | F21: 5.15 | G21: 46.35 | H21: =SUM(D21:G21) | I21: 0 | J21: 0 | K21: 0 | L21: 0 | M21: 0
A22: 16 | B22: Móc cẩu dầm (cáp 15.2mm) | C22: m | D22: 64 | E22: 96 | F22: 32 | G22: 288 | H22: =SUM(D22:G22) | I22: 0 | J22: 0 | K22: 0 | L22: 0 | M22: 0
A23: 17 | B23: Quét Epoxy đầu dầm | C23: m2 | D23: 0.82 | E23: 1.23 | F23: 0.41 | G23: 3.69 | H23: =SUM(D23:G23) | I23: 0 | J23: 0 | K23: 0 | L23: 0 | M23: 0
A24: 18 | B24: Bê tông nhựa Asphalt C16 | C24: m2 | D24: 0 | E24: 0 | F24: 0 | G24: 0 | H24: 0 | I24: 0 | J24: 0 | K24: 0 | L24: 0 | M24: 1380.39
A25: 19 | B25: Lớp phòng nước phun chống thấm | C25: m2 | D25: 0 | E25: 0 | F25: 0 | G25: 0 | H25: 0 | I25: 0 | J25: 0 | K25: 0 | L25: 0 | M25: 1380.39

Sheet 01_DAM_SUPER_T_15_PHIEN
A1: BẢNG PHÂN TÍCH KHỐI LƯỢNG HÌNH HỌC 4 LOẠI DẦM SUPER-T L=38.2M (S1B1, S1B2, S1B3, S1G)
A2: Phân đoạn theo 3 mặt cắt: mc 1 (Đầu dầm 1.4m), mc 2 (Vát sườn 3.45m), mc 3 (Thân rỗng chữ U 33.35m)
A4: LOẠI DẦM | B4: SỐ DẦM | C4: ĐOẠN MẶT CẮT | D4: CHIỀU DÀI L (m) | E4: DIỆN TÍCH S (m2) | F4: THỂ TÍCH 1 DẦM (m3) | G4: TỔNG THỂ TÍCH (m3) | H4: VÁN KHUÔN CỐ ĐỊNH (m2) | I4: VÁN KHUÔN DI ĐỘNG (m2) | J4: TỔNG VÁN KHUÔN (m2) | K4: CÁP DƯL 15.2MM (kg) | L4: THÉP 10<D<=18 (kg) | M4: THÉP D>18 (kg) | N4: TỔNG THÉP (kg)
A5: S1B1 (Dầm biên loại 1) | B5: 2 | C5: mc 1: Đầu đặc | D5: 1.4 | E5: 1.605477 | F5: =D5*E5 | G5: =F5*B5 | H5: 7.028 | I5: 0 | J5: =H5+I5 | K5: 1994.08 | L5: 5274.78 | M5: 796.47 | N5: =L5+M5
C6: mc 2: Vát sườn | D6: 3.45 | E6: 1.650477 | F6: =D6*E6 | G6: =F6*B5 | H6: 19.39 | I6: 0 | J6: =H6+I6 | K6: 0 | L6: 0 | M6: 0 | N6: 0
C7: mc 3: Thân rỗng chữ U | D7: 33.35 | E7: 0.639043 | F7: =D7*E7 | G7: =F7*B5 | H7: 187.436 | I7: 129.277 | J7: =H7+I7 | K7: 0 | L7: 0 | M7: 0 | N7: 0
A8: TỔNG S1B1 (2 dầm) | B8: 2 | C8: Toàn dầm L=38.2m | D8: =SUM(D5:D7) | F8: =SUM(F5:F7) | G8: =SUM(G5:G7) | H8: =SUM(H5:H7) | I8: =SUM(I5:I7) | J8: =SUM(J5:J7) | K8: =B5*K5 | L8: =B5*L5 | M8: =B5*M5 | N8: =B5*N5
A9: S1B2 (Dầm biên loại 2) | B9: 3 | C9: mc 1: Đầu đặc | D9: 1.4 | E9: 1.603602 | F9: =D9*E9 | G9: =F9*B9 | H9: 6.993 | I9: 0 | J9: =H9+I9 | K9: 1994.08 | L9: 5268.81 | M9: 796.47 | N9: =L9+M9
C10: mc 2: Vát sườn | D10: 3.45 | E10: 1.648602 | F10: =D10*E10 | G10: =F10*B9 | H10: 19.304 | I10: 0 | J10: =H10+I10 | K10: 0 | L10: 0 | M10: 0 | N10: 0
C11: mc 3: Thân rỗng chữ U | D11: 33.35 | E11: 0.637168 | F11: =D11*E11 | G11: =F11*B9 | H11: 186.602 | I11: 129.277 | J11: =H11+I11 | K11: 0 | L11: 0 | M11: 0 | N11: 0
A12: TỔNG S1B2 (3 dầm) | B12: 3 | C12: Toàn dầm L=38.2m | D12: =SUM(D9:D11) | F12: =SUM(F9:F11) | G12: =SUM(G9:G11) | H12: =SUM(H9:H11) | I12: =SUM(I9:I11) | J12: =SUM(J9:J11) | K12: =B9*K9 | L12: =B9*L9 | M12: =B9*M9 | N12: =B9*N9
A13: S1B3 (Dầm biên loại 3) | B13: 1 | C13: mc 1: Đầu đặc | D13: 1.4 | E13: 1.598727 | F13: =D13*E13 | G13: =F13*B13 | H13: 6.902 | I13: 0 | J13: =H13+I13 | K13: 1994.08 | L13: 5253.28 | M13: 796.47 | N13: =L13+M13
C14: mc 2: Vát sườn | D14: 3.45 | E14: 1.643727 | F14: =D14*E14 | G14: =F14*B13 | H14: 19.079 | I14: 0 | J14: =H14+I14 | K14: 0 | L14: 0 | M14: 0 | N14: 0
C15: mc 3: Thân rỗng chữ U | D15: 33.35 | E15: 0.632293 | F15: =D15*E15 | G15: =F15*B13 | H15: 184.435 | I15: 129.277 | J15: =H15+I15 | K15: 0 | L15: 0 | M15: 0 | N15: 0
A16: TỔNG S1B3 (1 dầm) | B16: 1 | C16: Toàn dầm L=38.2m | D16: =SUM(D13:D15) | F16: =SUM(F13:F15) | G16: =SUM(G13:G15) | H16: =SUM(H13:H15) | I16: =SUM(I13:I15) | J16: =SUM(J13:J15) | K16: =B13*K13 | L16: =B13*L13 | M16: =B13*M13 | N16: =B13*N13
A17: S1G (Dầm giữa/trong) | B17: 9 | C17: mc 1: Đầu đặc | D17: 1.4 | E17: 1.551102 | F17: =D17*E17 | G17: =F17*B17 | H17: 6.993 | I17: 0 | J17: =H17+I17 | K17: 1994.08 | L17: 5123.61 | M17: 796.47 | N17: =L17+M17
C18: mc 2: Vát sườn | D18: 3.45 | E18: 1.641102 | F18: =D18*E18 | G18: =F18*B17 | H18: 18.959 | I18: 0 | J18: =H18+I18 | K18: 0 | L18: 0 | M18: 0 | N18: 0
C19: mc 3: Thân rỗng chữ U | D19: 33.35 | E19: 0.629668 | F19: =D19*E19 | G19: =F19*B17 | H19: 183.267 | I19: 129.277 | J19: =H19+I19 | K19: 0 | L19: 0 | M19: 0 | N19: 0
A20: TỔNG S1G (9 dầm) | B20: 9 | C20: Toàn dầm L=38.2m | D20: =SUM(D17:D19) | F20: =SUM(F17:F19) | G20: =SUM(G17:G19) | H20: =SUM(H17:H19) | I20: =SUM(I17:I19) | J20: =SUM(J17:J19) | K20: =B17*K17 | L20: =B17*L17 | M20: =B17*M17 | N20: =B17*N17
A21: TỔNG CỘNG 15 DẦM TOÀN CẦU | B21: 15 | C21: 3 Nhịp x 5 Dầm | D21: 38.2 | G21: =G8+G12+G16+G20 | H21: =B5*H8+B9*H12+B13*H16+B17*H20 | I21: =15*129.2775 | J21: =H21+I21 | K21: =K8+K12+K16+K20 | L21: =L8+L12+L16+L20 | M21: =M8+M12+M16+M20 | N21: =N8+N12+N16+N20

Sheet 02_CAP_DUL_VA_DEBONDING
A1: BẢNG KHỐI LƯỢNG CÁP DỰ ỨNG LỰC & CHIỀU DÀI KHÔNG BÁM DÍNH (DE-BONDING)
A2: Cáp 15.2mm ASTM A416 Grade 270 (7 sợi kéo trước, fpu=1860MPa) | Ống bọc PVC D18/22
A4: 1. BẢNG KHỐI LƯỢNG CÁP DƯL 15.2MM CHO 1 DẦM VÀ TOÀN BỘ 15 PHIẾN DẦM
A5: TÊN TAO CÁP | B5: SỐ LƯỢNG TAO | C5: L TRONG DẦM (m) | D5: L THI CÔNG 2 ĐẦU (m) | E5: TỔNG CHIỀU DÀI (m) | F5: KHỐI LƯỢNG 1 DẦM (kg) | G5: SỐ LƯỢNG DẦM | H5: TỔNG KHỐI LƯỢNG (kg)
A6: Tao 1 -:- 42 (Đáy và sườn dầm) | B6: 42 | C6: 38.2 | D6: 3 | E6: =B6*(C6+D6) | F6: =E6*1.1 | G6: 15 | H6: =F6*G6
A7: Tao 43, 44 (Bản cánh trên) | B7: 2 | C7: 38.2 | D7: 3 | E7: =B7*(C7+D7) | F7: =E7*1.1 | G7: 15 | H7: =F7*G7
A8: TỔNG CỘNG CÁP DƯL 15.2MM | B8: =SUM(B6:B7) | C8: 38.2 | D8: 3 | E8: =SUM(E6:E7) | F8: =SUM(F6:F7) | G8: 15 | H8: =SUM(H6:H7)
A9: QUY ĐỔI RA TẤN CÁP | F9: =F8/1000 | H9: =H8/1000
A11: 2. BẢNG PHÂN BỐ CHIỀU DÀI ỐNG NHỰA PVC D18/22 BỌC CÁP KHÔNG DÍNH BÁM (DE-BONDING)
A12: TÊN TAO CÁP | B12: SỐ TAO CÁP | C12: KÝ HIỆU MÀU | D12: L BỌC 1 ĐẦU (m) | E12: TỔNG 1 DẦM (2 ĐẦU) (m) | F12: TỔNG 15 DẦM (m)
A13: Tao 1, 2, 5, 7, 10, 11, 12, 17, 19, 21, 24, 26, 30, 31, 35, 38, 41 | B13: 18 | C13: Đỏ (Bám dính 100%) | D13: 0 | E13: =B13*D13*2 | F13: =E13*15
A14: Tao 43, 44 (Bản cánh trên) | B14: 2 | C14: Vàng | D14: 1 | E14: =B14*D14*2 | F14: =E14*15
A15: Tao 13, 23, 37, 42 | B15: 4 | C15: Xanh da trời | D15: 1.7 | E15: =B15*D15*2 | F15: =E15*15
A16: Tao 4, 8, 25, 27, 34, 36, 39, 40 | B16: 8 | C16: Xanh lá cây | D16: 3.4 | E16: =B16*D16*2 | F16: =E16*15
A17: Tao 3, 9, 14, 22, 28, 33 | B17: 6 | C17: Tím | D17: 6 | E17: =B17*D17*2 | F17: =E17*15
A18: Tao 6, 16, 18, 20, 29, 32 | B18: 6 | C18: Xanh dương | D18: 8 | E18: =B18*D18*2 | F18: =E18*15
A19: TỔNG CHIỀU DÀI ỐNG PVC D18/22 DE-BONDING | B19: =SUM(B13:B18) | C19: Ống PVC D18/22 | E19: =SUM(E13:E18) | F19: =SUM(F13:F18)

Sheet 03_COT_THEP_BBS_DAM
A1: BẢNG THỐNG KÊ CỐT THÉP CHI TIẾT (BBS) 15 PHIẾN DẦM SUPER-T L=38.2M
A2: Tiêu chuẩn TCVN 1651:2018 | Thép CB240-T (D<=10) và CB400-V (D>10) | Chiều dài thanh mm, Trọng lượng kg
A4: STT | B4: KÝ HIỆU THANH | C4: ĐƯỜNG KÍNH (mm) | D4: SỐ LƯỢNG (thanh/dầm) | E4: CHIỀU DÀI 1 THANH (mm) | F4: TRỌNG LƯỢNG ĐƠN VỊ (kg/m) | G4: TỔNG DÀI 1 DẦM (m) | H4: KHỐI LƯỢNG 1 DẦM (kg) | I4: TỔNG 15 DẦM (kg) | J4: VỊ TRÍ BỐ TRÍ & GHI CHÚ
A5: 1 | B5: G1a | C5: 16 | D5: 144 | E5: 5056 | F5: 1.58 | G5: =D5*E5/1000 | H5: =G5*F5 | I5: =H5*15 | J5: Thép đai chữ U sườn dầm (khoảng cách a=200..100mm)
A6: 2 | B6: G1b | C6: 12 | D6: 125 | E6: 5075 | F6: 0.888 | G6: =D6*E6/1000 | H6: =G6*F6 | I6: =H6*15 | J6: Thép đai chữ U sườn dầm phụ
A7: 3 | B7: G2 | C7: 12 | D7: 255 | E7: 1184 | F7: 0.888 | G7: =D7*E7/1000 | H7: =G7*F7 | I7: =H7*15 | J7: Thép đai kín bản cánh trên
A8: 4 | B8: G2a | C8: 12 | D8: 269 | E8: 1309 | F8: 0.888 | G8: =D8*E8/1000 | H8: =G8*F8 | I8: =H8*15 | J8: Thép đai móc neo bản cánh trên
A9: 5 | B9: G3 | C9: 12 | D9: 269 | E9: 1259 | F9: 0.888 | G9: =D9*E9/1000 | H9: =G9*F9 | I9: =H9*15 | J9: Thép đai đáy dầm ôm tao cáp DƯL
A10: 6 | B10: G4a1 | C10: 12 | D10: 21 | E10: 11700 | F10: 0.888 | G10: =D10*E10/1000 | H10: =G10*F10 | I10: =H10*15 | J10: Thép dọc cấu tạo bản cánh dầm (cây nguyên 11.7m)
A11: 7 | B11: G4a2 | C11: 12 | D11: 7 | E11: 4460 | F11: 0.888 | G11: =D11*E11/1000 | H11: =G11*F11 | I11: =H11*15 | J11: Thép dọc cấu tạo đoạn nối cánh
A12: 8 | B12: G4b1 | C12: 12 | D12: 12 | E12: 11700 | F12: 0.888 | G12: =D12*E12/1000 | H12: =G12*F12 | I12: =H12*15 | J12: Thép dọc cấu tạo đáy dầm (cây nguyên 11.7m)
A13: 9 | B13: G4b2 | C13: 12 | D13: 4 | E13: 3060 | F13: 0.888 | G13: =D13*E13/1000 | H13: =G13*F13 | I13: =H13*15 | J13: Thép dọc cấu tạo đoạn nối đáy
A14: 10 | B14: G5a | C14: 16 | D14: 28 | E14: 11700 | F14: 1.58 | G14: =D14*E14/1000 | H14: =G14*F14 | I14: =H14*15 | J14: Thép dọc chịu lực sườn dầm (cây nguyên 11.7m)
A15: 11 | B15: G5b | C15: 18 | D15: 14 | E15: 2860 | F15: 2 | G15: =D15*E15/1000 | H15: =G15*F15 | I15: =H15*15 | J15: Thép dọc tăng cường đầu dầm
A16: 12 | B16: G5c | C16: 16 | D16: 14 | E16: 10680 | F16: 1.58 | G16: =D16*E16/1000 | H16: =G16*F16 | I16: =H16*15 | J16: Thép dọc sườn dầm đoạn chuyển tiếp
... A27: 23 | B27: K1b | C27: 16 | D27: 8 | E27: 776 | F27: 1.58 | G27: =D27*E27/1000 | H27: =G27*F27 | I27: =H27*15 | J27: Khung thép tăng cường móc cẩu phụ
A28: T1 | B28: TỔNG CỐT THÉP THANH DẦM SUPER-T | G28: =SUM(G5:G27) | H28: =SUM(H5:H27) | I28: =SUM(I5:I27) | J28: Tổng 15 dầm tính theo cấu hình S1B1 (Phân tách 4 loại dầm = 89,668.81 kg)
A29: T2 | B29: QUY ĐỔI RA TẤN THÉP | H29: =H28/1000 | I29: =I28/1000 | J29: Khớp 100% hồ sơ: 89.669 Tấn

Sheet 04_DAM_NGANG_BMC_LTN
A1: BẢNG KHỐI LƯỢNG DẦM NGANG, BẢN MẶT CẦU, BẢN LIÊN TỤC NHIỆT & TẤM ĐÚC SẴN
A2: Các cấu kiện kết cấu phần trên thi công tại chỗ và đúc sẵn trên bãi | Cầu Km19+529.080
A4: 1. KHỐI LƯỢNG DẦM NGANG BTCT C35 ĐỔ TẠI CHỖ (03 NHỊP - 05 DẦM/NHỊP)
A5: STT | B5: HẠNG MỤC CẤU KIỆN | C5: ĐVT | D5: SỐ LƯỢNG | E5: 1 NHỊP | F5: TỔNG 3 NHỊP | G5: ĐƠN GIÁ / HÀM LƯỢNG | H5: GHI CHÚ KỸ THUẬT
A6: 1 | B6: Bê tông kết cấu C35 dầm ngang | C6: m3 | D6: 3 | E6: 6.46 | F6: =D6*E6 | G6: Bản vẽ 05 DAM NGANG.dwg | H6: 6.46 m3/nhịp x 3 nhịp = 19.38 m3
A7: 2 | B7: Ván khuôn dầm ngang kết cấu | C7: m2 | D7: 3 | E7: 16.072 | F7: =D7*E7 | G7: Ván khuôn thành bên dầm ngang | H7: 16.072 m2/nhịp x 3 nhịp = 48.216 m2
A8: 3 | B8: Cốt thép thanh 10 < D <= 18mm (D16) | C8: kg | D8: 3 | E8: 806.43 | F8: =D8*E8 | G8: Thanh A1, A3, A4, A5, A6 | H8: Tổng 3 nhịp = 2,419.29 kg
A9: 4 | B9: Cốt thép thanh D > 18mm (D20) | C9: kg | D9: 3 | E9: 114.61 | F9: =D9*E9 | G9: Thanh A2 chịu lực dầm ngang | H9: Tổng 3 nhịp = 343.83 kg
A10: T1 | B10: TỔNG CỐT THÉP DẦM NGANG | C10: kg | D10: 3 | E10: =SUM(E8:E9) | F10: =SUM(F8:F9) | G10: Hàm lượng = 142.6 kg/m3 | H10: 2,763.12 kg (~2.76 Tấn)
A12: 2. KHỐI LƯỢNG BẢN MẶT CẦU BTCT C35 ĐỔ TẠI CHỖ (03 NHỊP)
A13: STT | B13: HẠNG MỤC CẤU KIỆN | C13: ĐVT | D13: SỐ LƯỢNG | E13: 1 NHỊP | F13: TỔNG 3 NHỊP | G13: ĐƠN GIÁ / HÀM LƯỢNG | H13: GHI CHÚ KỸ THUẬT
A14: 1 | B14: Bê tông kết cấu C35 bản mặt cầu | C14: m3 | D14: 3 | E14: 101.8216 | F14: =D14*E14 | G14: B=12.515m, H=0.20m | H14: Tổng 3 nhịp = 305.465 m3
A15: 2 | B15: Ván khuôn bản mặt cầu mép biên | C15: m2 | D15: 3 | E15: 14.653 | F15: =D15*E15 | G15: Ván khuôn thành mép gờ biên | H15: Tổng 3 nhịp = 43.960 m2
A16: 3 | B16: Cốt thép D <= 10mm (D10) | C16: kg | D16: 3 | E16: 490.02 | F16: =D16*E16 | G16: Thanh S3 (D10) | H16: Tổng 3 nhịp = 1,470.07 kg
A17: 4 | B17: Cốt thép 10 < D <= 18mm (D14, D18) | C17: kg | D17: 3 | E17: 25068.79 | F17: =D17*E17 | G17: Thanh S1, S1a, S2, S4, DR1-3 | H17: Tổng 3 nhịp = 75,206.38 kg
A18: T1 | B18: TỔNG CỐT THÉP BẢN MẶT CẦU | C18: kg | D18: 3 | E18: =SUM(E16:E17) | F18: =SUM(F16:F17) | G18: Hàm lượng = 251.0 kg/m3 | H18: 76,676.45 kg (~76.68 Tấn)
A20: 3. KHỐI LƯỢNG BẢN LIÊN TỤC NHIỆT (TRỤ T1, T2) & TẤM VÁN KHUÔN ĐÚC SẴN
A21: STT | B21: HẠNG MỤC CẤU KIỆN | C21: ĐVT | D21: SỐ LƯỢNG | E21: 1 NHỊP | F21: TỔNG 3 NHỊP | G21: ĐƠN GIÁ / HÀM LƯỢNG | H21: GHI CHÚ KỸ THUẬT
A22: 1 | B22: Bê tông C35 Bản liên tục nhiệt (T1, T2) | C22: m3 | D22: 2 | E22: 10.934 | F22: =D22*E22 | G22: Đổ liền khối tại trụ T1, T2 | H22: 2 vị trí = 21.868 m3
A23: 2 | B23: Ván khuôn bản liên tục nhiệt | C23: m2 | D23: 2 | E23: 6.538 | F23: =D23*E23 | G23: Ván khuôn khe liên tục nhiệt | H23: 2 vị trí = 13.076 m2
A24: 3 | B24: Cốt thép bản liên tục nhiệt | C24: kg | D24: 2 | E24: 4458.97 | F24: =D24*E24 | G24: Thép L1-L3, S4 (D10, D18, D25) | H24: Tổng 2 vị trí = 8,917.94 kg
A25: 4 | B25: Xốp chèn khe co giãn | C25: m2 | D25: 2 | E25: 1.2425 | F25: =D25*E25 | G25: Chèn khe bản liên tục nhiệt | H25: Tổng = 2.485 m2
A26: 5 | B26: Lớp cao su đệm dày 20mm | C26: m2 | D26: 2 | E26: 19.88 | F26: =D26*E26 | G26: Đệm trượt gối liên tục nhiệt | H26: Tổng = 39.760 m2
A27: 6 | B27: Bê tông C25 Tấm ván khuôn đúc sẵn | C27: m3 | D27: 510 | E27: 0.0259 | F27: =D27*E27 | G27: Tấm P1, P2, P3 gác cánh dầm | H27: 510 tấm = 13.230 m3
A28: 7 | B28: Ván khuôn tấm đúc sẵn | C28: m2 | D28: 510 | E28: 0.9897 | F28: =D28*E28 | G28: Ván khuôn bệ đúc tấm sẵn | H28: 510 tấm = 504.751 m2
A29: 8 | B29: Cốt thép tấm đúc sẵn D6, D8 | C29: kg | D29: 510 | E29: 4.5547 | F29: =D29*E29 | G29: Thép F1, F2, F3 (D6, D8) | H29: 510 tấm = 2,322.90 kg
