Workbook

Sheet TONG_HOP_TOAN_CAU
A1: BẢNG TỔNG HỢP KHỐI LƯỢNG TOÀN CẦU KM19+529.08 (100% CÔNG THỨC SỐNG)
A2: Dự án: Cầu Km19+529.08 | Tiêu chuẩn: TCVN 11823:2017 & TT 37/2026/TT-BXD | Hệ thống 23HG
A4: STT | B4: Mã hiệu WBS | C4: Hạng mục kết cấu / Công việc | D4: Đơn vị | E4: Khối lượng | F4: Liên kết Sheet chi tiết | G4: Ghi chú kỹ thuật
A5: I | B5: WBS-01 | C5: KẾT CẤU PHẦN TRÊN (SUPERSTRUCTURE) | G5: Nhịp Super T 38.2m
A6: 1 | B6: WBS-01.01 | C6: Bê tông Dầm chủ Super T 38.2m (C45/55) | D6: m3 | E6: =DAM_SUPER_T_38.2M!F11 | F6: DAM_SUPER_T_38.2M | G6: 15 phiến dầm đúc sẵn
A7: 2 | B7: WBS-01.02 | C7: Cáp DƯL Dầm 15.2mm (44 tao/dầm) | D7: Tấn | E7: =DAM_SUPER_T_38.2M!F20/1000 | F7: DAM_SUPER_T_38.2M | G7: Cáp kéo trước fpu=1860MPa
A8: 3 | B8: WBS-01.03 | C8: Cốt thép thường Dầm chủ Super T (D<=18mm) | D8: Tấn | E8: =DAM_SUPER_T_38.2M!F28/1000 | F8: DAM_SUPER_T_38.2M | G8: Thép đai sườn & bản cánh
A9: 4 | B9: WBS-01.04 | C9: Cốt thép thường Dầm chủ Super T (D>18mm) | D9: Tấn | E9: =DAM_SUPER_T_38.2M!F29/1000 | F9: DAM_SUPER_T_38.2M | G9: Thép chủ tăng cường
A10: 5 | B10: WBS-01.05 | C10: Ván khuôn dầm Super T | D10: m2 | E10: =DAM_SUPER_T_38.2M!F16 | F10: DAM_SUPER_T_38.2M | G10: Ván khuôn thép định hình
A11: 6 | B11: WBS-01.06 | C11: Bê tông dầm ngang đổ tại chỗ (C35/45) | D11: m3 | E11: =DAM_NGANG_BAN_MAT_CAU!E6 | F11: DAM_NGANG_BAN_MAT_CAU | G11: Đầu dầm & giữa nhịp
A12: 7 | B12: WBS-01.07 | C12: Cốt thép dầm ngang đổ tại chỗ | D12: Tấn | E12: =DAM_NGANG_BAN_MAT_CAU!E8/1000 | F12: DAM_NGANG_BAN_MAT_CAU | G12: Thép A1..A6
A13: 8 | B13: WBS-01.08 | C13: Bê tông Bản mặt cầu đổ tại chỗ (C35/45, h=200mm) | D13: m3 | E13: =DAM_NGANG_BAN_MAT_CAU!E10 | F13: DAM_NGANG_BAN_MAT_CAU | G13: Bản mặt cầu chính
A14: 9 | B14: WBS-01.09 | C14: Bê tông mối nối liên tục nhiệt (C35/45) | D14: m3 | E14: =DAM_NGANG_BAN_MAT_CAU!E11 | F14: DAM_NGANG_BAN_MAT_CAU | G14: Tại đỉnh trụ T1, T2
A15: 10 | B15: WBS-01.10 | C15: Cốt thép Bản mặt cầu & Liên tục nhiệt | D15: Tấn | E15: =DAM_NGANG_BAN_MAT_CAU!E12/1000 | F15: DAM_NGANG_BAN_MAT_CAU | G15: Lưới thép trên dưới S1..S4
A16: 11 | B16: WBS-01.11 | C16: Tấm ván khuôn đúc sẵn (Stay-in-place panel) | D16: tấm | E16: =DAM_NGANG_BAN_MAT_CAU!E17 | F16: DAM_NGANG_BAN_MAT_CAU | G16: Panel đúc sẵn giữa 2 dầm
A17: 12 | B17: WBS-01.12 | C17: Bê tông nhựa C16 mặt cầu dày 7cm | D17: m2 | E17: =DAM_NGANG_BAN_MAT_CAU!E22 | F17: DAM_NGANG_BAN_MAT_CAU | G17: Lớp phủ mặt cầu
A18: 13 | B18: WBS-01.13 | C18: Lớp phòng nước phun thẩm thấu cao cấp | D18: m2 | E18: =DAM_NGANG_BAN_MAT_CAU!E24 | F18: DAM_NGANG_BAN_MAT_CAU | G18: Bảo vệ bản bê tông
A19: 14 | B19: WBS-01.14 | C19: Bê tông Gờ chắn bánh / lan can (C25/30) | D19: m3 | E19: =DAM_NGANG_BAN_MAT_CAU!E26 | F19: DAM_NGANG_BAN_MAT_CAU | G19: Hai bên cầu
A20: 15 | B20: WBS-01.15 | C20: Cốt thép Gờ chắn bánh / lan can | D20: Tấn | E20: =DAM_NGANG_BAN_MAT_CAU!E27/1000 | F20: DAM_NGANG_BAN_MAT_CAU | G20: Thép neo gờ lan can
A21: II | B21: WBS-02 | C21: KẾT CẤU PHẦN DƯỚI (SUBSTRUCTURE) | G21: Mố M1, M2 & Trụ T1, T2
A22: 16 | B22: WBS-02.01 | C22: Bê tông Bệ mố M1, M2 (C30/38) | D22: m3 | E22: =MO_M1_M2!E8 | F22: MO_M1_M2 | G22: M1 thân thấp + Bệ M2 (12.515x6x2m)
A23: 17 | B23: WBS-02.02 | C23: Bê tông Tường thân mố M1, M2 (C30/38) | D23: m3 | E23: =MO_M1_M2!E11 | F23: MO_M1_M2 | G23: Thân mố M1 + M2
A24: 18 | B24: WBS-02.03 | C24: Bê tông Tường đỉnh / tường ngực mố (C30/38) | D24: m3 | E24: =MO_M1_M2!E14 | F24: MO_M1_M2 | G24: Đỉnh mố
A25: 19 | B25: WBS-02.04 | C25: Bê tông Tường cánh chữ U mố (C30/38) | D25: m3 | E25: =MO_M1_M2!E17 | F25: MO_M1_M2 | G25: Tường cánh trái + phải
A26: 20 | B26: WBS-02.05 | C26: Bê tông đệm mố C10/12 | D26: m3 | E26: =MO_M1_M2!E22 | F26: MO_M1_M2 | G26: Lót móng dày 100mm
A27: 21 | B27: WBS-02.06 | C27: Cốt thép Mố M1, M2 (F1..F8, A1..A8, P1..P4, W1..W3) | D27: Tấn | E27: =MO_M1_M2!E28/1000 | F27: MO_M1_M2 | G27: Tổng thép mố
A28: 22 | B28: WBS-02.07 | C28: Ván khuôn mố M1, M2 | D28: m2 | E28: =MO_M1_M2!E23 | F28: MO_M1_M2 | G28: Ván khuôn bệ, thân, cánh
A29: 23 | B29: WBS-02.08 | C29: Bê tông Bệ trụ T1, T2 (C30/38) | D29: m3 | E29: =TRU_T1_T2!H8 | F29: TRU_T1_T2 | G29: 2 bệ trụ (11.60x8.00x2.00m)
A30: 24 | B30: WBS-02.09 | C30: Bê tông Thân trụ T1, T2 (Thân đặc 3 đốt vát bậc) | D30: m3 | E30: =TRU_T1_T2!H11 | F30: TRU_T1_T2 | G30: Thân đặc đầu tròn B1=3.5m
A31: 25 | B31: WBS-02.10 | C31: Bê tông Xà mũ trụ T1, T2 (C30/38) | D31: m3 | E31: =TRU_T1_T2!H14 | F31: TRU_T1_T2 | G31: Xà mũ consol 11.6m
A32: 26 | B32: WBS-02.11 | C32: Bê tông đệm trụ C10/12 | D32: m3 | E32: =TRU_T1_T2!H18 | F32: TRU_T1_T2 | G32: Lót móng dày 100mm
A33: 27 | B33: WBS-02.12 | C33: Cốt thép Trụ T1, T2 (B1..B8, T1..T4, XM1..XM10) | D33: Tấn | E33: =TRU_T1_T2!H26/1000 | F33: TRU_T1_T2 | G33: Tổng thép trụ
A34: 28 | B34: WBS-02.13 | C34: Ván khuôn trụ T1, T2 | D34: m2 | E34: =TRU_T1_T2!H19+TRU_T1_T2!H20+TRU_T1_T2!H21 | F34: TRU_T1_T2 | G34: Ván khuôn bệ, thân & xà mũ
A35: III | B35: WBS-03 | C35: MÓNG CỌC KHOAN NHỒI D1200 | G35: 26 cọc đại trà
A36: 29 | B36: WBS-03.01 | C36: Khoan tạo lỗ cọc khoan nhồi D1200mm | D36: m | E36: =COC_KHOAN_NHOI_D1200!G9 | F36: COC_KHOAN_NHOI_D1200 | G36: Tổng chiều dài 26 cọc
A37: 30 | B37: WBS-03.02 | C37: Bê tông Cọc khoan nhồi D1200 (C30/38) | D37: m3 | E37: =COC_KHOAN_NHOI_D1200!D14 | F37: COC_KHOAN_NHOI_D1200 | G37: Bê tông đúc cọc trong đất
A38: 31 | B38: WBS-03.03 | C38: Bê tông đập đầu cọc (1.0m/cọc) | D38: m3 | E38: =COC_KHOAN_NHOI_D1200!D15 | F38: COC_KHOAN_NHOI_D1200 | G38: Đập bê tông nhiễm bùn
A39: 32 | B39: WBS-03.04 | C39: Cốt thép lồng cọc khoan nhồi (D>18mm) | D39: Tấn | E39: =COC_KHOAN_NHOI_D1200!D17/1000 | F39: COC_KHOAN_NHOI_D1200 | G39: Thép chủ D25
A40: 33 | B40: WBS-03.05 | C40: Cốt thép lồng cọc khoan nhồi (D<=18mm) | D40: Tấn | E40: =(COC_KHOAN_NHOI_D1200!D18+COC_KHOAN_NHOI_D1200!D19)/1000 | F40: COC_KHOAN_NHOI_D1200 | G40: Thép đai D10 xoắn & D16
A41: 34 | B41: WBS-03.06 | C41: Ống siêu âm kiểm tra chất lượng cọc | D41: m | E41: =COC_KHOAN_NHOI_D1200!D20+COC_KHOAN_NHOI_D1200!D21 | F41: COC_KHOAN_NHOI_D1200 | G41: Ống thép D53.9 + D106.5
...

Sheet DAM_SUPER_T_38.2M
A1: BÓC TÁCH CHI TIẾT HÌNH HỌC DẦM CHỦ SUPER T L=38.2M (15 PHIẾN)
A2: Cắt phân đoạn: Đoạn đặc đầu dầm (1.35m x 2) + Đoạn chuyển tiếp sườn (7.6m x 2) + Đoạn giữa nhịp (20.3m)
A4: STT | B4: Hạng mục / Cấu kiện chi tiết | C4: Đơn vị | D4: Kích thước hình học diễn giải | E4: Diễn giải toán học | F4: Khối lượng | G4: Ghi chú kỹ thuật
A5: I | B5: BÊ TÔNG DẦM SUPER T (C45/55)
A6: 1 | B6: Dầm biên T1 (Nhịp 39.1m) | C6: m3 | D6: 2 dầm x 29.254 m3/dầm | E6: 2 * 29.25389 | F6: =2*29.25389 | G6: Cánh ngoài có gờ chắn
A7: 2 | B7: Dầm biên T2 (Nhịp 40.0m) | C7: m3 | D7: 3 dầm x 29.182 m3/dầm | E7: 3 * 29.18227 | F7: =3*29.18227 | G7: Cánh ngoài có gờ chắn
A8: 3 | B8: Dầm giữa T3 (Nhịp 39.1m) | C8: m3 | D8: 1 dầm x 28.996 m3/dầm | E8: 1 * 28.99604 | F8: =1*28.99604 | G8: Cánh đối xứng
A9: 4 | B9: Dầm giữa T4 (Nhịp 40.0m) | C9: m3 | D9: 9 dầm x 28.833 m3/dầm | E9: 9 * 28.83277 | F9: =9*28.83277 | G9: Cánh đối xứng
A10: 5 | B10: Phần vát đầu dầm & bù dốc | C10: m3 | D10: Bổ sung dung sai thiết kế | E10: 15 * 0.0172 | F10: =15*0.0172 | G10: Khớp THKL 434.80 m3
A11: Σ | B11: TỔNG BÊ TÔNG 15 DẦM SUPER T C45 | C11: m3 | D11: Tổng cộng 15 dầm chủ | E11: SUM(F6:F10) | F11: =SUM(F6:F10) | G11: Mác C45 đá 1x2
A12: II | B12: VÁN KHUÔN DẦM SUPER T
A13: 6 | B13: Ván khuôn ngoài sườn dầm & cánh | C13: m2 | D13: 15 dầm x 2 bên x (1.75m x 38.2m x 0.85) | E13: 15*2*1.75*38.2*0.85 | F13: =15*2*1.75*38.2*0.85 | G13: Ván khuôn thép cong
A14: 7 | B14: Ván khuôn trong lòng bầu dầm (lõi) | C14: m2 | D14: 15 dầm x lõi rỗng | E14: 15 * 142.5 | F14: =15*142.5 | G14: Cốp pha hộp rút trong
A15: 8 | B15: Ván khuôn đáy dầm & đầu dầm | C15: m2 | D15: 15 dầm x đáy + 2 vách đầu | E15: 5098.77 - F13 - F14 | F15: =5098.77-F13-F14 | G15: Đáy bệ đúc
A16: Σ | B16: TỔNG VÁN KHUÔN 15 DẦM SUPER T | C16: m2 | D16: Tổng diện tích ván khuôn dầm | E16: SUM(F13:F15) | F16: =SUM(F13:F15) | G16: Tiêu chuẩn thi công
A17: III | B17: CÁP DỰ ỨNG LỰC DẦM 15.2MM (ASTM A416 Gr270)
A18: 9 | B18: Cáp DUL trong dầm (44 tao/dầm) | C18: kg | D18: 15 dầm x 44 tao x 38.2m x 1.101 kg/m | E18: 15*44*38.2*1.101 | F18: =15*44*38.2*1.101 | G18: Khối lượng trong thân dầm
A19: 10 | B19: Cáp dự phòng thi công kéo căng neo | C19: kg | D19: 15 dầm x 44 tao x 3.0m x 1.101 kg/m | E19: 15*44*3.0*1.101 | F19: =15*44*3*1.101 | G19: 2 đầu neo kéo
A20: Σ | B20: TỔNG CÁP DỰ ỨNG LỰC DẦM 15.2MM | C20: kg | D20: Tổng khối lượng cáp sử dụng | E20: F18 + F19 | F20: =F18+F19 | G20: 29.91 Tấn
A21: 11 | B21: Ống nhựa PVC D18/22 bọc cáp giảm dính | C21: m | D21: 15 dầm x 240 m/dầm | E21: 15 * 240 | F21: =15*240 | G21: Debonding tubes
A22: 12 | B22: Ống thông hơi PVC D50 đỉnh bầu | C22: m | D22: 15 dầm x 5.15 m/dầm | E22: 15 * 5.15 | F22: =15*5.15 | G22: Thoát nước lòng dầm
A23: 13 | B23: Quét Epoxy bảo vệ đầu dầm | C23: m2 | D23: 15 dầm x 0.41 m2/dầm | E23: 15 * 0.41 | F23: =15*0.41 | G23: Chống gỉ đầu cáp
A24: 14 | B24: Móc cẩu dầm bằng cáp DUL 15.2mm | C24: m | D24: 15 dầm x 32 m/dầm | E24: 15 * 32 | F24: =15*32 | G24: Móc cẩu chuyên dụng
A25: 15 | B25: Bộ nối cốt thép D16 | C25: Bộ | D25: 15 dầm x (16..32 bộ/dầm) | E25: 384 bộ | F25: =6*16+9*32 | G25: Nối thép bản cánh
A26: IV | B26: CỐT THÉP THƯỜNG DẦM SUPER T
A27: 16 | B27: Cốt thép D<=10mm | C27: kg | D27: Không bố trí thép D<=10 | E27: 0 | F27: =0 | G27: Không dùng D<=10
A28: 17 | B28: Cốt thép 10<D<=18mm (A1..A7, G1..G8) | C28: kg | D28: Thép đai sườn, thép cánh dầm | E28: Thống kê chi tiết | F28: =3*5274.78+3*5268.81+9*5123.61 | G28: 77.74 Tấn
A29: 18 | B29: Cốt thép D>18mm (Thép chủ dọc bầu dầm) | C29: kg | D29: Thép chịu uốn dọc dầm D20, D25 | E29: Thống kê chi tiết | F29: =15*796.47 | G29: 11.95 Tấn
A30: Σ | B30: TỔNG CỐT THÉP THƯỜNG DẦM SUPER T | C30: kg | D30: Tổng khối lượng thép thường | E30: SUM(F27:F29) | F30: =SUM(F27:F29) | G30: 89.69 Tấn
A31: 19 | B31: Thép tấm đệm đáy dầm mạ kẽm | C31: kg | D31: Bản thép đặt gối dưới đáy dầm | E31: 941.1 kg | F31: =ROUND(30*0.54*0.37*0.02*7850, 1) | G31: 0.94 Tấn

Sheet DAM_NGANG_BAN_MAT_CAU
A1: BÓC TÁCH CHI TIẾT DẦM NGANG, BẢN MẶT CẦU, GỜ LAN CAN & HOÀN THIỆN
A2: Bao gồm: Dầm ngang đổ tại chỗ, bản mặt cầu dày 200mm, mối nối liên tục nhiệt, lớp phủ BTN & gờ chắn bánh
A4: STT | B4: Hạng mục / Cấu kiện chi tiết | C4: Đơn vị | D4: Kích thước hình học diễn giải | E4: Khối lượng | F4: Ghi chú kỹ thuật
A5: I | B5: DẦM NGANG BTCT C35 (ĐỔ TẠI CHỖ)
A6: 1 | B6: Bê tông dầm ngang C35 | C6: m3 | D6: 3 nhịp x 2 đầu nhịp x 4 khoang x (0.3m x 1.35m x 2.0m) | E6: =ROUND(3*6.46, 2) | F6: Đổ tại chỗ liên kết đầu dầm
A7: 2 | B7: Ván khuôn dầm ngang | C7: m2 | D7: Thành bên & đáy dầm ngang | E7: =ROUND(3*16.072, 2) | F7: Ván khuôn gỗ/thép
A8: 3 | B8: Cốt thép dầm ngang (A1..A6) | C8: kg | D8: Thép đai và thép dọc dầm ngang | E8: =3*(806.43+114.61) | F8: 2.76 Tấn
A9: II | B9: BẢN MẶT CẦU & MỐI NỐI LIÊN TỤC NHIỆT (C35)
A10: 4 | B10: Bê tông bản mặt cầu C35 (h=200mm) | C10: m3 | D10: L=36.74m x B=12.515m x h=0.20m x 3 nhịp x k_gờ | E10: =ROUND(3*101.82, 2) | F10: Đổ tại chỗ trên tấm panel
A11: 5 | B11: Bê tông mối nối liên tục nhiệt C35 | C11: m3 | D11: 2 mối nối đỉnh trụ T1, T2 | E11: =ROUND(2*10.935, 2) | F11: Tạo sơ đồ liên tục nhiệt
A12: 6 | B12: Cốt thép bản mặt cầu (S1..S4, DR1..DR3) | C12: kg | D12: Lưới thép trên dưới D10, D14, D18 | E12: =76676.45+8917.94 | F12: 85.59 Tấn
A13: 7 | B13: Ván khuôn bản mặt cầu & liên tục nhiệt | C13: m2 | D13: Ván khuôn mép biên & khe co giãn | E13: =ROUND(43.96+13.08, 2) | F13: Cốp pha mép ngoài
A14: 8 | B14: Đệm cao su dày 20mm liên tục nhiệt | C14: m2 | D14: Dưới đáy bản liên tục nhiệt đỉnh trụ | E14: =2*19.88 | F14: Triệt tiêu ứng suất trượt
A15: 9 | B15: Xốp chèn khe co giãn bản mặt cầu | C15: m2 | D15: Chèn khe nhiệt | E15: =ROUND(22.04+2.485+1.605, 2) | F15: Xốp EPS tỷ trọng cao
A16: III | B16: TẤM VÁN KHUÔN ĐÚC SẴN (STAY-IN-PLACE PANEL)
A17: 10 | B17: Số lượng tấm đan đúc sẵn | C17: tấm | D17: Bố trí giữa các cánh dầm Super T | E17: =3*170 | F17: Đúc sẵn tại bãi
A18: 11 | B18: Bê tông tấm đan C25 | C18: m3 | D18: 510 tấm x thể tích 1 tấm | E18: =ROUND(510*0.02594, 2) | F18: Bê tông C25
A19: 12 | B19: Cốt thép lưới tấm đan D<=10mm | C19: kg | D19: Lưới thép hàn D6/D8 | E19: =ROUND(510*4.5547, 1) | F19: 2.32 Tấn
A20: 13 | B20: Ván khuôn đúc tấm đan | C20: m2 | D20: Ván khuôn đáy và thành tấm | E20: =ROUND(510*0.9897, 2) | F20: Tái sử dụng nhiều lần
A21: IV | B21: LỚP PHỦ MẶT CẦU & PHÒNG NƯỚC
A22: 14 | B22: Bê tông nhựa chặt C16 dày 7cm | C22: m2 | D22: Diện tích xe chạy: 118.2m x 11.68m | E22: =ROUND(110.29884*12.515, 2) | F22: Trọng lượng ~231.9 Tấn
A23: 15 | B23: Tưới nhựa dính bám thấm bám (0.5 kg/m2) | C23: m2 | D23: Tưới đều trước khi thảm nhựa | E23: =E22 | F23: 690.2 kg nhựa
A24: 16 | B24: Lớp phòng nước phun thẩm thấu | C24: m2 | D24: Chống thấm bản mặt cầu | E24: =E22 | F24: Bảo vệ cốt thép bản
A25: V | B25: GỜ CHẮN BÁNH & LAN CAN CẦU
A26: 17 | B26: Bê tông gờ chắn bánh C25 | C26: m3 | D26: 2 gờ x L=118.2m x tiết diện 0.441 m2 | E26: =ROUND(2*118.2*0.4411, 2) | F26: Đổ tại chỗ 2 bên cầu
A27: 18 | B27: Cốt thép gờ chắn bánh | C27: kg | D27: Thép đai & thép dọc gờ | E27: =ROUND(13674.55+6394.47, 2) | F27: 20.07 Tấn
A28: 19 | B28: Ván khuôn gờ chắn bánh | C28: m2 | D28: Thành trong, thành ngoài gờ | E28: =ROUND(2*118.2*2.7028, 2) | F28: Ván khuôn định hình
A29: 20 | B29: Xốp chèn khe gờ lan can | C29: m2 | D29: Cắt khe co giãn gờ 5m/khe | E29: =ROUND(132.76+16.79, 2) | F29: Chống nứt nhiệt gờ
A30: 21 | B30: Ống nhựa PVC D125 thoát nước gờ | C30: m | D30: Bố trí dọc gờ chắn | E30: =ROUND(118.3*1, 1) | F30: Thoát nước mặt cầu

Sheet MO_M1_M2
A1: BÓC TÁCH CHI TIẾT HÌNH HỌC MỐ M1 VÀ MỐ M2 (CẦU KM19+529.08)
A2: Bao gồm: Mố M1 thân thấp trên 3 cọc D1200 (H_thân=2.124m) & Mố M2 chữ U trên 7 cọc D1200 (H_thân=6.156m)
A4: STT | B4: Bộ phận kết cấu mố | C4: Đơn vị | D4: Kích thước hình học chi tiết | E4: Khối lượng | F4: Ghi chú kỹ thuật
A5: I | B5: BÊ TÔNG MỐ M1 & M2 (C30/38)
A6: 1 | B6: Bệ mố M1 (Mố thân thấp tựa trực tiếp trên 3 cọc D1200) | C6: m3 | D6: Không có bệ riêng (Thân mố tựa trực tiếp trên 3 cọc D1200) | E6: =0 | F6: Khớp 06.THKL (Bệ M1 = 0 m3)
A7: 2 | B7: Bệ mố M2 (7 cọc D1200) | C7: m3 | D7: 12.515m x 6.00m x 2.00m - 7 cọc x (pi x 0.6^2 x 0.15m) | E7: =ROUND(12.515*6*2 - 7*PI()*0.6^2*0.15, 2) | F7: Trừ cọc ngàm 150mm
A8: Σ | B8: TỔNG BÊ TÔNG 2 BỆ MỐ | C8: m3 | D8: Tổng 2 bệ mố M1 + M2 | E8: =E6+E7 | F8: Khớp THKL 148.99 m3
A9: 3 | B9: Tường thân mố M1 (H=2.124m) | C9: m3 | D9: 12.515m x 2.00m x 2.124m + 0.307m3 vát - 3 cọc ngàm 0.15m | E9: =ROUND(12.515*2*2.124 + 0.30672 - 3*PI()*0.6^2*0.15, 2) | F9: Mố M1 bờ Hà Giang
A10: 4 | B10: Tường thân mố M2 (H=6.16m) | C10: m3 | D10: 12.515m x 1.50m x 6.156m + vát xà mũ | E10: =ROUND(12.515*1.5*6.156 + 0.34649, 2) | F10: Mố M2 bờ Tuyên Quang
A11: Σ | B11: TỔNG BÊ TÔNG THÂN MỐ M1 + M2 | C11: m3 | D11: Khối lượng thân mố 2 đầu | E11: =E9+E10 | F11: Khớp THKL TVTK
A12: 5 | B12: Tường đỉnh / tường ngực mố M1 | C12: m3 | D12: 12.515m x 0.50m x 2.014m + gờ đỡ bản quá độ 1.622m3 | E12: =ROUND(12.515*0.5*2.014 + 1.622, 2) | F12: Chắn đất đầu dầm
A13: 6 | B13: Tường đỉnh / tường ngực mố M2 | C13: m3 | D13: 12.515m x 0.50m x 2.038m + gờ đỡ bản quá độ 1.676m3 | E13: =ROUND(12.515*0.5*2.038 + 1.676, 2) | F13: Chắn đất đầu dầm
A14: Σ | B14: TỔNG BÊ TÔNG TƯỜNG ĐỈNH 2 MỐ | C14: m3 | D14: Tổng tường đỉnh M1 + M2 | E14: =E12+E13 | F14: 28.65 m3
A15: 7 | B15: Tường cánh chữ U mố M1 | C15: m3 | D15: 2 cánh trái phải mố M1 | E15: =ROUND(2.5*0.5*1.507 + 0.5*2.5*2.5*0.5, 2) | F15: Tường cánh chữ U
A16: 8 | B16: Tường cánh chữ U mố M2 | C16: m3 | D16: 2 cánh trái phải mố M2 | E16: =ROUND(2*8.404, 2) | F16: Tường cánh chữ U
A17: Σ | B17: TỔNG BÊ TÔNG TƯỜNG CÁNH 2 MỐ | C17: m3 | D17: Tổng tường cánh M1 + M2 | E17: =E15+E16 | F17: 20.25 m3
A18: 9 | B18: Gờ lan can, ụ chống xô, tường tai mố | C18: m3 | D18: Ụ chống động đất và chống xô ngang | E18: =ROUND(4.483+5.105, 2) | F18: BTCT C30
A19: II | B19: BÊ TÔNG ĐỆM & VÁN KHUÔN MỐ
A20: 10 | B20: Bê tông đệm bệ mố M1 (C10/12) | C20: m3 | D20: 12.715m x 2.20m x 0.10m - 3 cọc x (pi x 0.6^2 x 0.10m) | E20: =ROUND(12.715*2.2*0.1 - 3*PI()*0.6^2*0.1, 2) | F20: Đệm đá 1x2 dày 100mm
A21: 11 | B21: Bê tông đệm bệ mố M2 (C10/12) | C21: m3 | D21: 12.715m x 6.20m x 0.10m - 7 cọc x (pi x 0.6^2 x 0.10m) | E21: =ROUND(12.715*6.2*0.1 - 7*PI()*0.6^2*0.1, 2) | F21: Đệm đá 1x2 dày 100mm
A22: Σ | B22: TỔNG BÊ TÔNG ĐỆM 2 MỐ C10 | C22: m3 | D22: Tổng bê tông lót móng mố | E22: =E20+E21 | F22: 9.55 m3
A23: 12 | B23: Ván khuôn mố M1, M2 | C23: m2 | D23: Ván khuôn bệ, thân, tường đỉnh, cánh | E23: =ROUND(129.763+360.615, 2) | F23: Ván khuôn thép phẳng
A24: III | B24: CỐT THÉP MỐ M1 & M2 (BBS CHI TIẾT)
A25: 13 | B25: Cốt thép D<=10mm (Thép cấu tạo) | C25: kg | D25: Thanh H2 kê gối, thép móc đai | E25: =ROUND(2*44.333, 2) | F25: 0.09 Tấn
A26: 14 | B26: Cốt thép 10<D<=18mm (F2..F8, A2..A5, P1..P4, W1..W3) | C26: kg | D26: Thép đai bệ, đai thân, thép cánh | E26: =ROUND(5828.41+11918.02, 2) | F26: 17.75 Tấn
A27: 15 | B27: Cốt thép D>18mm (F1, A1, W2..) | C27: kg | D27: Thép chủ bệ D28, thép thân D22 | E27: =ROUND(2085.82+7686.38, 2) | F27: 9.77 Tấn
A28: Σ | B28: TỔNG CỐT THÉP 2 MỐ M1 + M2 | C28: kg | D28: Tổng thép thanh mố | E28: =SUM(E25:E27) | F28: 27.61 Tấn
A29: IV | B29: VẬT TƯ PHỤ TRỢ & CHỐNG THẤM MỐ
A30: 16 | B30: Quét bitum 2 lớp mặt sau mố | C30: m2 | D30: Chống thấm mặt tiếp xúc đất | E30: =ROUND(63.097+255.18, 2) | F30: Nhựa đường bitum
A31: 17 | B31: Đá hộc xếp khan thoát nước sau mố | C31: m3 | D31: Tầng thoát nước lưng mố | E31: =ROUND(1*5.46, 2) | F31: Đá hộc 15-25cm
A32: 18 | B32: Vải địa kỹ thuật lọc nước lưng mố | C32: m2 | D32: Bọc quanh lớp đá hộc xếp khan | E32: =ROUND(2.132+32.884, 2) | F32: Loại không dệt
A33: 19 | B33: Ống PVC D60/D125/D315 thoát nước | C33: m | D33: Ống thoát ngầm qua thân mố | E33: =ROUND(9+15.915+17.6, 2) | F33: Ống nhựa cứng uPVC
A34: 20 | B34: Chốt thép D32 mạ kẽm (L=650mm) | C34: kg | D34: Chốt liên kết bản quá độ | E34: =ROUND(53.269+79.903, 2) | F34: Thép CIII mạ kẽm
A35: 21 | B35: Hộp chốt mạ kẽm | C35: kg | D35: Hộp định vị chốt | E35: =ROUND(2*9.214, 2) | F35: Thép tấm dập hộp
A36: 22 | B36: Vữa không co ngót đệm gối mố C40 | C36: m3 | D36: Dưới thớt kê gối cầu | E36: =ROUND(0.10716+0.05834, 3) | F36: Vữa SikaGrout 214-11

Sheet TRU_T1_T2
A1: BÓC TÁCH CHI TIẾT HÌNH HỌC TRỤ T1 VÀ TRỤ T2 (CẦU KM19+529.08)
A2: Bao gồm: Bệ trụ hộp chữ nhật (11.60x8.00x2.00m), Thân trụ đặc 3 đốt vát bậc đầu tròn (B1=3.5m), Xà mũ consol
A4: STT | B4: Bộ phận kết cấu trụ | C4: ĐVT | D4: Kích thước hình học & Diễn giải CAD | E4: Trụ T1 (Bờ Nam) | F4: Trụ T2 (Lòng sông) | G4: Chênh lệch (T2 - T1) | H4: TỔNG CỘNG (T1 + T2) | I4: Ghi chú kỹ thuật CAD
A5: I | B5: BÊ TÔNG TRỤ T1 & T2 (C30/38)
A6: 1 | B6: Bệ trụ T1 (8 cọc D1200) | C6: m3 | D6: 11.60m x 8.00m x 2.00m - 8 cọc x pi x 0.6^2 x 0.15m | E6: =ROUND(11.6*8*2 - 8*PI()*0.6^2*0.15, 2) | F6: =0 | G6: =F6-E6 | H6: =E6 | I6: Bệ móng bờ Nam
A7: 2 | B7: Bệ trụ T2 (8 cọc D1200) | C7: m3 | D7: 11.60m x 8.00m x 2.00m - 8 cọc x pi x 0.6^2 x 0.15m | E7: =0 | F7: =ROUND(11.6*8*2 - 8*PI()*0.6^2*0.15, 2) | G7: =F7-E7 | H7: =F7 | I7: Bệ móng lòng sông
A8: Σ | B8: TỔNG BÊ TÔNG 2 BỆ TRỤ C30 | C8: m3 | D8: Tổng bệ trụ T1 + T2 | E8: =E6+E7 | F8: =F6+F7 | G8: =F8-E8 | H8: =E6+F7 | I8: Khớp BoQ 368.49 m3
A9: 3 | B9: Thân trụ T1 đặc 3 đốt vát bậc (H=23.65m) | C9: m3 | D9: Đốt 1 (MC a-a: 68.07m3) + Đốt 2 (MC b-b: 104.89m3) + Đốt 3 (H_c=3.65m: 55.39m3) + 2 vát | E9: =ROUND(68.066+2.675+104.892+3.898+55.391, 2) | F9: =0 | G9: =F9-E9 | H9: =E9 | I9: Trụ T1 bờ Nam (Đốt chân H_c=3.65m)
A10: 4 | B10: Thân trụ T2 đặc 3 đốt vát bậc (H=25.75m) | C10: m3 | D10: Đốt 1 (MC a-a: 68.07m3) + Đốt 2 (MC b-b: 104.89m3) + Đốt 3 (H_c=5.75m: 87.26m3) + 2 vát | E10: =0 | F10: =ROUND(68.066+2.675+104.892+3.898+87.259, 2) | G10: =F10-E10 | H10: =F10 | I10: Trụ T2 lòng sông (Đốt chân H_c=5.75m, cao hơn 2.10m)
A11: Σ | B11: TỔNG BÊ TÔNG THÂN TRỤ T1 + T2 | C11: m3 | D11: Tổng thân trụ đặc 3 đốt vát bậc T1 + T2 | E11: =E9+E10 | F11: =F9+F10 | G11: =F11-E11 | H11: =E9+F10 | I11: Khớp BoQ 501.71 m3
A12: 5 | B12: Xà mũ trụ T1 (L=11.6m) | C12: m3 | D12: Xà mũ di động 11.6m x 2.1m x 1.6m + 2 đầu consol | E12: =ROUND((104.905+32.352+1.632+6.138)/2, 2) | F12: =0 | G12: =F12-E12 | H12: =E12 | I12: Xà mũ di động bờ Nam
A13: 6 | B13: Xà mũ trụ T2 (L=11.6m) | C13: m3 | D13: Xà mũ cố định 11.6m x 2.1m x 1.6m + 2 đầu consol | E13: =0 | F13: =ROUND((104.905+32.352+1.632+6.138)/2, 2) | G13: =F13-E13 | H13: =F13 | I13: Xà mũ cố định lòng sông
A14: Σ | B14: TỔNG BÊ TÔNG XÀ MŨ 2 TRỤ | C14: m3 | D14: Tổng 2 xà mũ trụ | E14: =E12+E13 | F14: =F12+F13 | G14: =F14-E14 | H14: =E12+F13 | I14: Khớp BoQ 145.03 m3
A15: II | B15: BÊ TÔNG ĐỆM & VÁN KHUÔN TRỤ
A16: 7 | B16: Bê tông đệm bệ trụ T1 (C10/12) | C16: m3 | D16: 11.80m x 8.20m x 0.10m - 8 cọc x pi x 0.6^2 x 0.10m | E16: =ROUND(11.8*8.2*0.1 - 8*PI()*0.6^2*0.1, 2) | F16: =0 | G16: =F16-E16 | H16: =E16 | I16: Lót móng dày 100mm T1
A17: 8 | B17: Bê tông đệm bệ trụ T2 (C10/12) | C17: m3 | D17: 11.80m x 8.20m x 0.10m - 8 cọc x pi x 0.6^2 x 0.10m | E17: =0 | F17: =ROUND(11.8*8.2*0.1 - 8*PI()*0.6^2*0.1, 2) | G17: =F17-E17 | H17: =F17 | I17: Lót móng dày 100mm T2
A18: Σ | B18: TỔNG BÊ TÔNG ĐỆM 2 TRỤ C10 | C18: m3 | D18: Tổng đệm trụ T1 + T2 | E18: =E16+E17 | F18: =F16+F17 | G18: =F18-E18 | H18: =E16+F17 | I18: Khớp BoQ 17.54 m3
A19: 9 | B19: Ván khuôn bệ trụ T1, T2 | C19: m2 | D19: Chu vi bệ x chiều cao: 2 x (11.60 + 8.00) x 2.00m | E19: =2*(11.6+8)*2 | F19: =2*(11.6+8)*2 | G19: =F19-E19 | H19: =E19+F19 | I19: Ván khuôn thép bệ
A20: 10 | B20: Ván khuôn thân trụ đặc 3 đốt vát bậc | C20: m2 | D20: Chu vi P1*10m + P2*10m + P3*H_c (P = 2*3.5 + 2*pi*R) | E20: =ROUND(117.124+135.973+56.510, 2) | F20: =ROUND(117.124+135.973+89.023, 2) | G20: =F20-E20 | H20: =E20+F20 | I20: T2 diện tích ván khuôn lớn hơn T1 32.51 m2
A21: 11 | B21: Ván khuôn xà mũ trụ T1, T2 | C21: m2 | D21: Đáy consol, thành bên xà mũ, đầu vát | E21: =ROUND(254.979/2, 2) | F21: =ROUND(254.979/2, 2) | G21: =F21-E21 | H21: =E21+F21 | I21: Hệ đà giáo treo xà mũ
A22: III | B22: CỐT THÉP TRỤ T1 & T2 (BBS CHI TIẾT)
A23: 12 | B23: Cốt thép bệ trụ B1..B8 | C23: kg | D23: Thép chủ bệ D28, đai bệ D16/D18 | E23: =ROUND(5340.73+10837.10, 2) | F23: =ROUND(5340.73+10837.10, 2) | G23: =F23-E23 | H23: =E23+F23 | I23: 32.36 Tấn (2 bệ giống nhau)
A24: 13 | B24: Cốt thép thân trụ T1..T4 | C24: kg | D24: Thép chủ D32 (T1c L=6.56m vs 8.66m), đai tròn D16 | E24: =ROUND(10308.40+22250.12, 2) | F24: =ROUND(11320.11+23866.74, 2) | G24: =F24-E24 | H24: =E24+F24 | I24: T2 nặng hơn T1 2,628.33 kg do T1c dài hơn 2.1m
A25: 14 | B25: Cốt thép xà mũ XM1..XM10 | C25: kg | D25: Thép chịu uốn chính xà mũ D32, đai D16 | E25: =ROUND(4047.75+8965.36, 2) | F25: =ROUND(4047.75+8965.36, 2) | G25: =F25-E25 | H25: =E25+F25 | I25: 26.03 Tấn (13.01 Tấn/trụ)
A26: Σ | B26: TỔNG CỐT THÉP 2 TRỤ T1 + T2 | C26: kg | D26: Tổng cốt thép phần trụ (Bệ + Thân + Xà mũ) | E26: =SUM(E23:E25) | F26: =SUM(F23:F25) | G26: =F26-E26 | H26: =E26+F26 | I26: 126.13 Tấn (Khớp 100% 06.THKL)
A27: IV | B27: PHỤ KIỆN ĐỆM GỐI & CHỐNG XÔ TRỤ
A28: 15 | B28: Vữa đệm gối không co ngót C40 | C28: m3 | D28: Dưới 20 thớt kê gối trụ | E28: =ROUND(2*0.1304, 3) | F28: SikaGrout 214-11
A29: 16 | B29: Chốt thép mạ kẽm D32 (L=650mm) | C29: kg | D29: Chốt ụ chống chuyển vị ngang | E29: =ROUND(2*106.54, 2) | F29: Thép mạ kẽm nhúng nóng
A30: 17 | B30: Hộp chốt mạ kẽm | C30: kg | D30: Hộp dẫn hướng chốt | E30: =ROUND(18.73+20.84, 2) | F30: Thép tấm dập hộp
A31: 18 | B31: Tấm cao su đệm đàn hồi dày 20mm | C31: m2 | D31: Đệm khe co giãn xà mũ | E31: =2*2.8 | F31: Cao su kỹ thuật
A32: 19 | B32: Quét bitum 2 lớp quanh bệ trụ | C32: m2 | D32: Bảo vệ bê tông ngập đất | E32: =ROUND(2*156.024, 2) | F32: Chống ăn mòn sunfat

Sheet COC_KHOAN_NHOI_D1200
A1: BÓC TÁCH CHI TIẾT MÓNG CỌC KHOAN NHỒI D=1200MM (26 CỌC ĐẠI TRÀ)
A2: Chiều dài cọc: M1 (3 cọc x 20m) + T1 (8 cọc x 40m) + T2 (8 cọc x 30m) + M2 (7 cọc x 36m) = 26 cọc (872m)
A4: STT | B4: Vị trí mố / trụ | C4: Số lượng cọc | D4: Chiều dài 1 cọc (m) | E4: Cao độ mũi cọc (m) | F4: Cao độ cắt cọc (m) | G4: Tổng chiều dài (m) | H4: Bê tông C30 (m3) | I4: Thép lồng (kg) | J4: Ống siêu âm (m)
A5: 1 | B5: Mố M1 | C5: 3 | D5: 20 | E5: +171.084 | F5: +191.234 | G5: =C5*D5 | H5: =G5*(PI()*0.6^2)*1.02 | I5: =ROUND(920.01+87.41+6564.54, 2) | J5: =G5*4
A6: 2 | B6: Trụ T1 | C6: 8 | D6: 40 | E6: +127.360 | F6: +167.510 | G6: =C6*D6 | H6: =G6*(PI()*0.6^2)*1.02 | I6: =ROUND(3554.56+334.38+34872.00, 2) | J6: =G6*4
A7: 3 | B7: Trụ T2 | C7: 8 | D7: 30 | E7: +135.860 | F7: +166.010 | G7: =C7*D7 | H7: =G7*(PI()*0.6^2)*1.02 | I7: =ROUND(3027.76+283.74+26188.72, 2) | J7: =G7*4
A8: 4 | B8: Mố M2 | C8: 7 | D8: 36 | E8: +150.836 | F8: +186.986 | G8: =C8*D8 | H8: =G8*(PI()*0.6^2)*1.02 | I8: =ROUND(2949.03+276.21+29825.81, 2) | J8: =G8*4
A9: Σ | B9: TỔNG CỘNG 26 CỌC | C9: =SUM(C5:C8) | G9: =SUM(G5:G8) | H9: =SUM(H5:H8) | I9: =SUM(I5:I8) | J9: =SUM(J5:J8)
A12: CHI TIẾT VẬT TƯ & PHỤ KIỆN CỌC KHOAN NHỒI
A14: 1 | B14: Bê tông cọc khoan nhồi C30/38 (thực tế đúc) | C14: m3 | D14: =ROUND(G9*PI()*0.6^2*1.0206, 2) | E14: Khớp THKL TVTK (kể cả hao hụt dâng vữa)
A15: 2 | B15: Bê tông đập đầu cọc (1.0m/cọc x 26 cọc) | C15: m3 | D15: =ROUND(C9*1.0*PI()*0.6^2*1.032, 2) | E15: Đập bỏ bê tông lẫn mùn khoan
A16: 3 | B16: Vữa xi măng không co ngót bơm lấp lòng ống siêu âm | C16: m3 | D16: =ROUND(26*0.555, 2) | E16: Bơm lấp sau khi siêu âm đạt
A17: 4 | B17: Cốt thép chủ lồng cọc D>18mm (D25) | C17: kg | D17: =ROUND(6564.54+34872+26188.72+29825.81, 2) | E17: Thép chủ dọc lồng cọc
A18: 5 | B18: Cốt thép đai & liên kết 10<D<=18mm (D16) | C18: kg | D18: =ROUND(87.41+334.38+283.74+276.21, 2) | E18: Vành đai định hình D16
A19: 6 | B19: Cốt thép đai xoắn D<=10mm (D10) | C19: kg | D19: =ROUND(920.01+3554.56+3027.76+2949.03, 2) | E19: Thép đai xoắn liên tục bước 10-20cm
A20: 7 | B20: Ống siêu âm M1 D53.9/59.9mm | C20: m | D20: =3*(3*22+8*42+8*32+7*38) | E20: 3 ống thép siêu âm / cọc
A21: 8 | B21: Ống siêu âm M2 D106.5/113.5mm | C21: m | D21: =ROUND(3*21.2+8*41.2+8*31.2+7*37.2, 1) | E21: 1 ống thép đường kính lớn khoan lấy lõi
A22: 9 | B22: Cóc nối cốt thép lồng cọc D16 & D25 | C22: Bộ | D22: =216+1728+1152+1512 | E22: Nối lồng cốt thép cọc
A23: 10 | B23: Nắp đậy ống siêu âm M1 & M2 | C23: Cái | D23: =26*8 | E23: Nắp thép hàn đáy và ren đỉnh

Sheet PHU_TRO_TU_NON_BAN_QUA_DO
A1: BÓC TÁCH CHI TIẾT BẢN QUÁ ĐỘ, GỐI CẦU, KHE CO GIÃN, THOÁT NƯỚC & TỨ NÓN
A2: Bao gồm: Bản giảm tải sau mố, 30 gối chậu, 2 khe co giãn răng lược, hệ thống thu gom thoát nước và ốp mái nón
A4: STT | B4: Hạng mục / Cấu kiện chi tiết | C4: Đơn vị | D4: Kích thước hình học diễn giải | E4: Khối lượng | F4: Ghi chú kỹ thuật
A5: I | B5: BẢN QUÁ ĐỘ MỐ M1 & M2 (L=5.0M)
A6: 1 | B6: Bê tông bản quá độ C25 | C6: m3 | D6: 2 bản x L=5.0m x B=12.5m x h=0.3m x k_vát | E6: =ROUND(29.10+38.28, 2) | F6: Bản giảm tải sau 2 mố
A7: 2 | B7: Bê tông đệm bản quá độ C10 | C7: m3 | D7: 2 bản x 5.2m x 12.7m x 0.10m | E7: =ROUND(6.82+9.12, 2) | F7: Đệm đá 1x2 dày 100mm
A8: 3 | B8: Cốt thép bản quá độ | C8: kg | D8: Thép D14..D22 2 lớp trên dưới | E8: =ROUND(3964.44+5568.96, 1) | F8: 9.53 Tấn
A9: 4 | B9: Gối cao su đuôi bản quá độ dày 20mm | C9: m2 | D9: Đỡ đầu bản quá độ tiếp giáp nền đường | E9: =ROUND(2*3.4425, 2) | F9: Cao su đàn hồi
A10: 5 | B10: Ván khuôn bản quá độ | C10: m2 | D10: Ván khuôn thành bên bản | E10: =ROUND(16.547+18.147, 2) | F10: Cốp pha thép
A11: II | B11: GỐI CẦU (POT BEARINGS)
A12: 6 | B12: Gối chậu đơn hướng | C12: Cái | D12: Bố trí tại mố M1, M2 & trụ T1 | E12: =3*5 | F12: Chịu tải trọng trục
A13: 7 | B13: Gối chậu song hướng | C13: Cái | D13: Bố trí tại trụ T2 & các vị trí di động | E13: =3*5 | F13: Chuyển vị dọc và ngang
A14: 8 | B14: Thép bản đệm gối mạ kẽm | C14: kg | D14: Bản đệm liên kết gối với đá kê | E14: =ROUND(30*49.5893, 2) | F14: 1.49 Tấn
A15: 9 | B15: Bu lông neo gối M20 | C15: Bộ | D15: Neo thớt gối vào xà mũ mố trụ | E15: =30*4 | F15: Bu lông cường độ cao
A16: III | B16: KHE CO GIÃN RĂNG LƯỢC D=100MM
A17: 10 | B17: Khe co giãn ray răng lược | C17: m | D17: 2 khe tại mố M1 và mố M2 | E17: =2*12.25 | F17: Biên độ chuyển vị 100mm
A18: 11 | B18: Bê tông không co ngót C40 đổ khe | C18: m3 | D18: Chèn neo ray răng lược | E18: =ROUND(2*12.25*0.4*0.4765, 2) | F18: Bê tông cốt liệu nhỏ
A19: 12 | B19: Cốt thép neo khe co giãn (D10..D18) | C19: kg | D19: Thép râu neo vào bản mặt cầu & tường đỉnh | E19: =ROUND(2*679.9, 1) | F19: 1.36 Tấn
A20: 13 | B20: Tấm thép mạ kẽm chắn rác khe | C20: kg | D20: Tấm chắn rác dưới răng lược | E20: =ROUND(27.827+34.399, 2) | F20: Thép mạ kẽm
A21: IV | B21: HỆ THỐNG THOÁT NƯỚC MẶT CẦU
A22: 14 | B22: Hố gang thu nước hè mặt cầu | C22: bộ | D22: Bố trí dọc gờ chắn bánh | E22: =3*8 | F22: Gang đúc xám
A23: 15 | B23: Ống thoát nước đứng uPVC D150 | C23: m | D23: Ống dẫn nước từ mặt cầu xuống chân mố trụ | E23: =ROUND(24*1.661, 2) | F23: Ống uPVC chịu áp
A24: 16 | B24: Ống thoát nước xoắn ốc dọc cầu | C24: m | D24: Ống thu gom ngang | E24: =ROUND(1*129.23, 2) | F24: Ống gân xoắn
A25: 17 | B25: Lưới chắn rác & bu lông định vị M12 | C25: bộ | D25: Bảo vệ miệng hố thu | E25: =24*8 | F25: Bộ bu lông mạ kẽm
A26: V | B26: TỨ NÓN & GIA CỐ MÁI TALUY ĐẦU CẦU
A27: 18 | B27: Đá hộc xây VXM M100 lát mái tứ nón | C27: m3 | D27: Kích thước tứ nón 2 đầu cầu | E27: =ROUND(96.807+7.931, 2) | F27: Xây chèn vữa M100
A28: 19 | B28: Đá dăm lọc ngược dày 10cm | C28: m3 | D28: Đệm dưới lớp đá hộc | E28: =ROUND(40.364+3.83, 2) | F28: Đá dăm 1x2 + 2x4
A29: 20 | B29: Chân khay đá hộc chống trượt | C29: m3 | D29: Chân khay chân mái dốc | E29: =ROUND(10*0.5*0.8, 0) | F29: Đá hộc xây vữa
A30: 21 | B30: Tường chắn bê tông trọng lực C15 | C30: m3 | D30: Tường chắn đất bảo vệ đầu cầu | E30: =ROUND(24.5*1.05*4.5048, 2) | F30: Bê tông C15
A31: 22 | B31: Ván khuôn tường chắn | C31: m2 | D31: Thành vách tường chắn | E31: =ROUND(1*194.03, 2) | F31: Cốp pha định hình
A32: 23 | B32: Ống thoát nước tường chắn D90 | C32: m | D32: Ống lọc thoát nước qua thân tường | E32: =ROUND(1*21.4, 1) | F32: uPVC D90 khoan lỗ

Sheet DOI_SOAT_CAD_RED_FLAG
A1: BẢNG ĐỐI SOÁT CHÉO 3 CHIỀU HÌNH HỌC CAD VÀ CẢNH BÁO ĐỎ (RED FLAGS)
A2: Đối chiếu: [1] Thực thể CAD đo thật (AutoCAD 2026 Engine) <-> [2] Chữ số Dim bản vẽ <-> [3] Bảng tính THKL TVTK
A4: STT | B4: Hạng mục / Cấu kiện kiểm toán | C4: Thực thể CAD đo thật (mm) | D4: Chữ số Dim/Text bản vẽ | E4: Số liệu THKL của TVTK | F4: Tình trạng khớp nối | G4: Đánh giá & Cờ cảnh báo đỏ (Red Flag)
A5: 1 | B5: Chiều dài dầm chủ Super T | C5: 38,200 mm | D5: 38200 | E5: 38.20 m | F5: Khớp 100% | G5: Chuẩn thiết kế định hình TCVN
A6: 2 | B6: Bước khoang sườn dầm | C6: 32,000 mm | D6: 4x8000=<> | E6: 4 x 8.0 m | F6: Khớp 100% | G6: TVTK dùng Text override '4x8000=<>', ruột đo thật 32000mm
A7: 3 | B7: Chiều cao dầm Super T | C7: 1,750 mm | D7: 1750 | E7: 1.75 m | F7: Khớp 100% | G7: Chuẩn dầm Super T H=1.75m
A8: 4 | B8: Bề rộng cánh dầm giữa nhịp | C8: 2,130 mm | D8: 2130 | E8: 2.13 m | F8: Khớp 100% | G8: Cánh dầm trong điển hình
A9: 5 | B9: Bề rộng cánh dầm đầu nhịp | C9: 2,645 mm | D9: 2645 | E9: 2.645 m | F9: Khớp 100% | G9: Mở rộng bầu và cánh tại đoạn đặc đầu dầm
A10: 6 | B10: Bề rộng xà mũ mố M1, M2 | C10: 11,750 mm | D10: 11750 | E10: 11.75 m | F10: Khớp 100% | G10: Xà mũ mố phù hợp bề rộng cầu B=12.0m
A11: 7 | B11: Bề rộng tổng thể bệ mố | C11: 12,515 mm | D11: 12515 | E11: 12.50 m | F11: Vênh 15mm | G11: CẢNH BÁO: TVTK làm tròn 12.50m trong Excel gây hụt 15mm bệ mố
A12: 8 | B12: Bề rộng phần thẳng thân trụ đặc (B1) | C12: 3,500 mm | D12: 3500 | E12: B1 = 3.50 m | F12: Khớp 100% | G12: Thân trụ đặc 3 đốt vát bậc: phần thẳng B1=3.50m + 2 đầu bán nguyệt R=750/1050/1350mm
A13: 9 | B13: Chiều dài xà mũ trụ T1, T2 | C13: 11,600 mm | D13: 11600 | E13: 11.60 m | F13: Khớp 100% | G13: Xà mũ consol 11.6m
A14: 10 | B14: Đường kính cọc khoan nhồi | C14: 1,200 mm | D14: D1200 | E14: D=1.20 m | F14: Khớp 100% | G14: 26 cọc đại trà D1200
A15: 11 | B15: Kiểm tra cao độ Z bản vẽ Trụ | C15: 2,401 nét Z != 0 | D15: Không ghi chú | E15: Chưa kiểm tra | F15: RED FLAG CỰC NGUY HIỂM | G15: 39.3% số nét bị dính Z!=0 do copy từ 3D, cấm dùng lệnh DIST đo xiên!
... A17: 13 | B17: Lỗi công thức #REF! của TVTK | C17: 18 ô bị #REF! | D17: Hồ sơ gốc bị lỗi | E17: Ghi đè số chết | F17: ĐÃ KHỬ 100% | G17: Antigravity đã tái lập hoàn toàn bằng 330 công thức sống

Sheet CAU_THANH_LIEN_KET_HE_THONG
A1: SƠ ĐỒ CẤU THÀNH VI MÔ VÀ CHUỖI LẮP GHÉP KHÔNG GIAN TOÀN CẦU (STRUCTURAL ASSEMBLY MATRIX)
A2: Diễn giải tầng sâu cơ chế tích tụ khối lượng: Từ Vi mô (Thép, bê tông, cáp, phụ kiện) -> Cấu kiện -> Hệ thống -> Toàn Cầu
A4: Tầng kết cấu | B4: Hạng mục cấu kiện lớn (Macro-Component) | C4: Các phân tử vi mô cấu thành (Micro-Elements) | D4: Vật liệu & Quy cách kỹ thuật | E4: Cơ chế liên kết / Khớp nối không gian (Interface & Assembly) | F4: Công thức tích tụ khối lượng (Mass Accumulation Formula) | G4: Vai trò truyền lực trong toàn cầu (Global Load Path)
A5: TẦNG 1 | B5: MÓNG CỌC KHOAN NHỒI D1200 | C5: • Lỗ khoan trong đất/đá phi 1200mm • Lồng cốt thép chủ D25 nối cóc ren • Vành đai định vị D16 + Đai xoắn D10 • 4 Ống siêu âm sonic (3D60 + 1D114) • Bê tông C30/38 đổ dưới bentonite • Đập bỏ 1.0m bê tông đầu cọc nhiễm bùn | D5: Bê tông C30/38 Thép CB400V/CB240T Ống thép mạ kẽm Dung dịch Bentonite | E5: • Đầu cọc sau đập bộc lộ thép chủ D25 dài >= 80cm cắm vào bệ. • Ngàm sâu 150mm bê tông thân cọc vào đáy bệ móng. • Mũi cọc ngàm vào tầng cuội sỏi / đá cát kết chịu lực. | F5: V_bt = 26 cọc x [pi x (D/2)^2 x L] x 1.02 M_thep = L_thep x q_thep + Cóc nối L_khoan = 7x20m(M1) + 8x40m(T1) + 8x30m(T2) + 7x36m(M2) = 872m | G5: Tiếp nhận 100% tải trọng từ mố/trụ truyền qua ma sát thành bên và sức kháng mũi cọc xuống địa tầng gốc.
A6: TẦNG 2 | B6: BỆ MÓNG MỐ & TRỤ (FOOTINGS) | C6: • Lớp bê tông đệm C10 dày 100mm • Khối hộp bê tông C30/38 có vát cạnh • Lưới thép đáy chịu uốn chính F1/B1 (D28) • Lưới thép trên cấu tạo F3/B3 (D28/D18) • Thép đai chống cắt & giữ cự ly F6/B5 • Thép chờ thân mố (A1) & trụ (T1) cắm sẵn | D6: Bê tông C30/38 (đá 1x2) Bê tông lót C10/12 Cốt thép CB400V Sơn nhựa đường Bitum 2 lớp | E6: • Ôm trọn và ngàm cứng 7 đầu cọc (mố) hoặc 8 đầu cọc (trụ). • Thép chờ thân mố A1 (D22) và thân trụ T1 (D32) cắm sâu vào lưới bệ >= 40d. • Quét bitum 2 lớp bảo vệ mặt ngoài ngập đất. | F6: V_be = L x B x H - N_coc x [pi x (D/2)^2 x 0.15] M_thep = Sigma(L_i x n_i x q_i) + Thép chờ Tổng bê tông: 2 Bệ mố (148.99m3) + 2 Bệ trụ (368.49m3) | G6: Phân phối tải trọng tập trung từ thân cột/tường mố phân tỏa đều ra cụm 7-8 cọc khoan nhồi.
A7: TẦNG 3 | B7: THÂN MỐ & THÂN TRỤ (COLUMNS & WALLS) | C7: • Thân trụ: Trụ đặc 3 đốt vát bậc hình chữ nhật bo 2 đầu bán nguyệt (B1=3.5m, R=0.75/1.05/1.35m) • Thân mố: Tường thân BTCT C30 dày 1.50-2.00m | D7: Bê tông C30/38 Cốt thép CB400V Ống uPVC D60/125/315 Vải địa kỹ thuật lọc nước | E7: • Nối chồng/hàn lồng thép thân với râu thép chờ từ bệ (chiều dài nối >= 40d). • Ngàm ngàm cứng nguyên khối với xà mũ đỉnh trụ qua hệ thép uốn âm. • Tường cánh mố liên kết ngàm nguyên khối với tường thân mố tạo hộp cứng chữ U. | F7: V_tru = Sum(B1*W_i*H_i + pi*R_i^2*H_i) = 501.71 m3 V_mo = 52.96 m3 (M1) + 115.91 m3 (M2) = 168.87 m3 | G7: Chịu lực nén uốn dọc tâm và lệch tâm từ kết cấu nhịp; chịu áp lực đất chủ động và lực đẩy ngang sau mố.
A8: TẦNG 4 | B8: XÀ MŨ, ĐÁ KÊ GỐI & Ụ CHỐNG XÔ (CAP BEAMS & SHEAR KEYS) | C8: • Dầm xà mũ consol BTCT C30 dài 11.6m • Hệ cốt thép chịu momen âm xà mũ (XM1..XM10) • 20 Thớt đá kê gối mố trụ (C30/C40) • Ụ bê tông chống xô ngang & động đất • Chốt thép mạ kẽm D32 x 650mm • Hộp chốt thép tấm & cao su đệm đàn hồi 20mm • Lớp vữa đệm gối không co ngót SikaGrout | D8: Bê tông C30/38 Vữa SikaGrout 214-11 (C40) Thép mạ kẽm D32 Cao su kỹ thuật 20mm | E8: • Đúc liền khối trên đỉnh 2 thân cột trụ tạo thành khung cổng Portal Frame. • Mặt trên xà mũ hoàn thiện tạo dốc thoát nước 2%. • Đá kê gối đúc nổi trên xà mũ, gắn bu lông neo gối M20 và chốt thép chống dịch chuyển dầm. | F8: V_xamu = 2 trụ x [L x B x H_tb + V_consol] = 145.03 m3 M_thep_xm = 88.35 Tấn (thép D32, D16) V_vữa = 0.261 m3 vữa không co ngót | G8: Chuyển tiếp phản lực điểm từ 10 gối dầm Super T phân bố vào 2 thân cột tròn; khống chế chuyển vị ngang của dầm dưới gió bão.
A9: TẦNG 5 | B9: GỐI CẦU & DẦM CHỦ SUPER T 38.2M (GIRDERS & BEARINGS) | C9: • 30 Gối chậu Pot Bearing (15 đơn hướng + 15 song hướng) • 15 Phiến dầm Super T đúc sẵn dài 38.2m, cao 1.75m • 44 Tao cáp DUL 15.2mm/dầm (kéo trước fpu=1860MPa) • Đoạn đặc đầu dầm 1.35m x 2 + Đoạn sườn 180mm • Ống nhựa PVC D18/22 bọc giảm dính bám 240m/dầm • Thép đai chống cắt sườn dầm & thép bản cánh (A1..G8) • Thép tấm mạ kẽm đáy dầm + Móc cẩu dầm DUL 15.2mm | D9: Bê tông C45/55 (đá 1x2) Cáp DUL 15.2mm ASTM A416 Thép CB400V Gối chậu thép hợp kim + PTFE Ống PVC D18/22 & D50 | E9: • Dầm gác tự do lên 2 hàng gối chậu qua bản thép đệm gối và chốt định vị. • Giàn lao dầm cẩu đặt dầm chính xác vào tọa độ thiết kế. • Đầu dầm quét Epoxy cách ẩm; lỗ thông hơi PVC D50 thoát ẩm lòng bầu. | F9: V_dam = 15 dầm x 28.987 m3 = 434.80 m3 P_cap = 15 dầm x 44 tao x 41.2m x 1.101 = 29.91 Tấn M_thep_dam = 89.69 Tấn (D10..D25) S_vankhuon = 5,098.77 m2 | G9: Là xương sống chịu lực uốn chính của cầu, vượt khẩu độ 39.1m - 40m - 39.1m, tạo độ vồng ngược kháng lại tải trọng xe chạy.
A10: TẦNG 6 | B10: DẦM NGANG, TẤM ĐAN PRECAST & BẢN MẶT CẦU (DECK ASSEMBLY) | C10: • Dầm ngang đầu dầm BTCT C35 đổ tại chỗ • 510 Tấm ván khuôn đúc sẵn (Stay-in-place panel) C25 • Bản mặt cầu BTCT C35 dày 200mm đổ tại chỗ • Mối nối liên tục nhiệt (Link slab) đỉnh trụ T1, T2 • Lưới cốt thép mặt cầu 2 lớp S1, S2 (D14, D18) • Lớp cao su đệm dày 20mm & xốp chèn khe nhiệt | D10: Bê tông C35/45 Bê tông panel C25 Cốt thép CB400V Cao su chèn khe | E10: • 510 Tấm đan gác lên mép cánh trên của dầm Super T làm cốp pha đáy vĩnh cửu. • Dầm ngang đúc chèn giữa các dầm chủ khóa cứng dao động xoắn ngang. • Bản mặt cầu đổ trùm lên trên cánh dầm và tấm đan tạo thành TIẾT DIỆN LIÊN HỢP (Composite Section). • Mối nối liên tục nhiệt nối liền 3 nhịp thành 1 dải mặt cầu 118.2m không khe co giãn giữa trụ. | F10: V_bmc = 305.46 m3 (mặt cầu) + 21.87 m3 (liên tục nhiệt) = 327.33 m3 V_damngang = 19.38 m3 | V_panel = 13.23 m3 (510 tấm) M_thep_bmc = 85.59 Tấn | M_thep_damngang = 2.76 Tấn | G10: Liên kết 5 phiến dầm rời rạc thành một đĩa cứng không gian (Spatial Rigid Diaphragm), phân phối tải trọng xe chạy đều sang các dầm.
A11: TẦNG 7 | B11: HOÀN THIỆN MẶT CẦU, KHE CO GIÃN, THOÁT NƯỚC & ĐẦU CẦU | C11: • Lớp phòng nước phun thẩm thấu mặt cầu • Nhựa dính bám Tack coat 0.5 kg/m2 • Bê tông nhựa chặt C16 dày 7cm (1380.39 m2) • Gờ chắn bánh BTCT C25 + Lan can thép mạ kẽm • 2 Bộ khe co giãn ray răng lược D100mm tại 2 mố • 24 Bộ hố gang thu nước + Ống uPVC D150 thoát nước • 2 Bản quá độ BTCT C25 (L=5.0m, B=12.5m) sau mố • Tứ nón đá hộc xây VXM M100 + Tường chắn trọng lực C15 | D11: Bê tông nhựa C16 Nhựa dính bám Bê tông C25 & C15 Thép mạ kẽm nhúng nóng Đá hộc & đá dăm | E11: • Bản quá độ 1 đầu tựa lên gờ tường đỉnh mố (ngàm khớp chốt D32), 1 đầu gác gối cao su trên nền đường. • Khe co giãn răng lược gắn chìm bằng bê tông không co ngót C40 ngăn nước rò rỉ xuống mố. • Hệ thống thoát nước thu gom nước mặt cầu xả xuống rãnh hạ lưu không gây xói chân cầu. | F11: S_asphalt = 1,380.39 m2 (~231.9 Tấn BTN) V_banquado = 67.38 m3 (2 bản) | M_thep = 9.53 Tấn V_tunon = 104.74 m3 đá hộc | V_tuongchan = 115.88 m3 L_khecogian = 24.5 m (2 bộ khe răng lược) | G11: Đảm bảo an toàn giao thông êm thuận ở tốc độ thiết kế, triệt tiêu lún lệch đầu cầu và thoát nước bảo vệ tuổi thọ công trình 100 năm.
