Workbook

Sheet NGAY_NGHI_LE
A1: LỊCH THỜI TIẾT MÙA MƯA & CÁC NGÀY NGHỈ LỄ CÔNG TRÌNH CẦU KM19+529.080 – 23HG SYSTEM
A2: Lịch công trường chuẩn: 6 ngày/tuần (Nghỉ Chủ nhật). Tuân thủ Bộ luật Lao động 2019 & TCVN 8819:2011
A4: I. DANH MỤC CÁC NGÀY NGHỈ LỄ CHÍNH THỨC TRONG THỜI GIAN THI CÔNG CẦU KM19 (10/2026 - 03/2027)
A5: STT | B5: Thời Gian | C5: Nội Dung Ngày Nghỉ Lễ / Sự Kiện | D5: Số Ngày Nghỉ | E5: Hệ Số Năng Suất K_tt | F5: Quy Định Điều Hành Công Trường
A6: 1 | B6: 01/01/2027 | C6: Nghỉ Tết Dương Lịch 2027 | D6: 1 | E6: 0 | F6: Nghỉ lễ 1 ngày, trực ban bảo vệ công trường 24/24
A7: 2 | B7: 05/02/2027 - 12/02/2027 | C7: Nghỉ Tết Nguyên Đán Đinh Mùi 2027 (29 Tết - Mùng 6 Tết) | D7: 8 | E7: 0 | F7: Dừng thi công hiện trường, niêm phong kho vật tư & bãi đúc dầm
A8: 3 | B8: Chủ nhật hàng tuần | C8: Nghỉ Chủ Nhật hàng tuần theo Luật Lao động | D8: 24 | E8: 0 | F8: Nghỉ ngơi, bảo dưỡng máy móc thiết bị (Bauer BG25, Kobelco CKE500)
A11: II. ĐIỀU KIỆN KHÍ HẬU VÙNG NÚI TÂY BẮC & QUY ĐỊNH MÙA KHÔ / MÙA MƯA (TCVN 8819:2011)
A12: STT | B12: Khung Thời Gian | C12: Đặc Điểm Thời Tiết Khí Hậu | D12: Hệ Số Năng Suất K_tt | E12: Hạng Mục Cho Phép Thi Công | F12: Hạng Mục TUYỆT ĐỐI CẤM Thi Công
A13: 1 | B13: Tháng 10/2026 - Tháng 03/2027 | C13: Mùa khô cao điểm vùng Tây Bắc (Ít mưa, nền nhiệt 15-28°C) | D13: 1 | E13: Tổng lực thi công toàn diện: Cọc khoan nhồi hang Karst, bệ móng, thân trụ T1, T2 cao 25.5m, đúc & lao 15 dầm Super-T, thảm BTN C16 mặt cầu | F13: Nghiêm cấm thảm BTN khi trời mưa hoặc mặt cầu ẩm ướt (TCVN 8819:2011 Điều 8.2)

Sheet DB_DINH_MUC
A1: CƠ SỞ DỮ LIỆU ĐỊNH MỨC NĂNG SUẤT CA MÁY & HAO PHÍ CẦU KM19+529.080 – 23HG SYSTEM
A2: Chuẩn hóa theo Thông tư 38/2026/TT-BXD, Thông tư 12/2021/TT-BXD & QCKT Việt Nam
A4: STT | B4: Mã Máy | C4: Chủng Loại Xe Máy Thiết Bị Thi Công | D4: Thông Số Kỹ Thuật / Model | E4: Định Mức Dầu (lít/ca) | F4: Năng Suất 1 Ca Máy | G4: Nhiệm Vụ Kỹ Thuật Trên Công Trường Cầu Km19
A5: 1 | B5: MK | C5: Máy khoan cọc nhồi D1200 | D5: Bauer BG25 / Lực xoay 245 kNm | E5: 145 | F5: 8.5 - 16.8 m/ca | G5: Khoan hang Karst 26 cọc D1200 ngàm đá M1, M2, T1, T2
A6: 2 | B6: CX | C6: Cần cẩu bánh xích 50 tấn | D6: Kobelco CKE500 / Cần 38m | E6: 62 | F6: Phục vụ 24/24 | G6: Hạ lồng thép cọc D1200, lắp ván khuôn & đà giáo leo thân trụ T1, T2
A7: 3 | B7: CL | C7: Cần cẩu bánh lốp 25 tấn | D7: Kato KR250 / 4 đoạn cần | E7: 48 | F7: Phục vụ bãi đúc | G7: Phục vụ bãi đúc dầm Super-T, bốc dỡ cốt thép, ván khuôn đúc sẵn
A8: 4 | B8: MD | C8: Máy đào bánh xích 1.25 m3 | D8: Komatsu PC200-8 / Kèm búa đập đá | E8: 68 | F8: 130 - 250 m3/ca | G8: Đào ngàm đá hố móng bệ trụ, phá đầu 26 cọc nhồi nhô 1.0m
A9: 5 | B9: OT | C9: Ô tô tự đổ 15 tấn | D9: Howo 371HP 3 chân | E9: 52 | F9: 12 - 16 chuyến/ca | G9: Vận chuyển đất đá ngàm móng ra bãi thải cự ly 5km
A10: 6 | B10: XB | C10: Xe bồn vận chuyển bê tông 9 m3 | D10: Hino / Hyundai Trộn xoay | E10: 42 | F10: 6 - 8 chuyến/ca | G10: Vận chuyển bê tông C30 cọc, bệ móng, thân mố trụ và C45 dầm Super-T
A11: 7 | B11: BM | C11: Xe bơm bê tông cần 42m | D11: Putzmeister BSF 42-5 | E11: 46 | F11: 35 - 50 m3/h | G11: Bơm cao áp bê tông thân trụ T1, T2 (H=23.35m - 25.45m), xà mũ, dầm ngang
A12: 8 | B12: MN | C12: Máy nén khí 7.5 m3/phút | D12: Airman PDS265S áp lực cao | E12: 38 | F12: Phục vụ thổi rửa | G12: Thổi rửa đáy 26 hố khoan cọc nhồi & đục tỉa bê tông đầu cọc
A13: 9 | B13: MH | C13: Máy phát hàn điện 500A | D13: Denyo DCW-480ESW / 2 kìm hàn | E13: 28 | F13: Hàn lồng thép cọc | G13: Gia công nối lồng thép cọc D1200, hàn khung sườn dầm Super-T
A14: 10 | B14: TT | C14: Trạm trộn BTXM 60 m3/h | D14: Sicoma Italy 2 trục ngang | E14: 58 | F14: 40 - 55 m3/h | G14: Sản xuất toàn bộ 2,348 m3 BTXM C10-C45 tại hiện trường
A15: 11 | B15: GL | C15: Giá lao dầm Super-T 78.88T | D15: Hệ dầm kép ray P43 tời kéo | E15: 35 | F15: 1.5 - 2 phiến/ngày | G15: Vận chuyển & lao lắp an toàn 15 phiến dầm Super-T 38.2m
A16: 12 | B16: LU | C16: Máy lu rung tự hành 14-25T | D16: Hamm 3411 lực rung 25 tấn | E16: 45 | F16: 400 m3/ca | G16: Đầm lèn K98 nền đường đầu cầu mố M1, M2
... A18: 14 | B18: MP | C18: Máy phát điện 3 pha 250kVA | D18: Cummins Diesel dự phòng | E18: 55 | F18: Phát điện 24/24 | G18: Cung cấp nguồn điện 3 pha liên tục cho trạm trộn, kích căng kéo và bãi đúc

Sheet BOQ_TIEN_DO
A1: BẢNG TIÊN LƯỢNG KHỐI LƯỢNG (BOQ), ĐỊNH MỨC CA MÁY & CHI PHÍ DỰ TOÁN G_XD CẦU KM19+529.080
A2: Dự án: Cao tốc Tuyên Quang - Hà Giang (Gói 09-XL) | Tiêu chuẩn: Thông tư 38/2026/TT-BXD, TT 36/2026 & TCVN
A4: STT | B4: Mã WBS | C4: Nội Dung Hạng Mục Công Tác Xây Lắp | D4: Đơn Vị | E4: Khối Lượng Thiết Kế | F4: Đơn Giá Trực Tiếp (VNĐ) | G4: Thành Tiền Trực Tiếp T (VNĐ) | H4: Năng Suất Định Mức / Ca | I4: Số Ca Máy Dự Kiến | J4: Thiết Bị Chủ Lực
A5: 1 | B5: 1.1 | C5: Bàn giao tim mốc VN2000 & định vị tọa độ mố trụ cầu | D5: Điểm | E5: 1 | F5: 15000000 | G5: =E5*F5 -> 15000000 | H5: 0.5 | I5: =ROUNDUP(E5/H5, 1) -> 2 | J5: Máy toàn đạc Leica TS06
A6: 2 | B6: 1.2 | C6: Rà phá bom mìn, dọn dẹp mặt bằng & dựng lán trại | D6: m2 | E6: 12500 | F6: 18500 | G6: =E6*F6 -> 231250000 | H6: 2500 | I6: =ROUNDUP(E6/H6, 1) -> 5 | J6: Máy xúc PC200 + Ô tô 15T
A7: 3 | B7: 1.3 | C7: Thi công đường công vụ nhánh 6 & 6A tiếp cận mố trụ | D7: m3 | E7: 1536.5 | F7: 95000 | G7: =E7*F7 -> 145967500 | H7: 170 | I7: =ROUNDUP(E7/H7, 1) -> 9.1 | J7: Máy xúc PC200 + Lu rung Hamm
A8: 4 | B8: 1.4 | C8: Xây dựng bãi đúc dầm Super-T, bệ đúc & trạm trộn 60m3/h | D8: Hệ | E8: 1 | F8: 450000000 | G8: =E8*F8 -> 450000000 | H8: 0.08 | I8: =ROUNDUP(E8/H8, 1) -> 12.5 | J8: Cần cẩu lốp 25T + Máy xúc
A9: 5 | B9: 2.1 | C9: Khoan thăm dò hang Karst sâu 5m vào đá liền khối (26 lỗ) | D9: Lỗ | E9: 26 | F9: 8500000 | G9: =E9*F9 -> 221000000 | H9: 2.6 | I9: =ROUNDUP(E9/H9, 1) -> 10 | J9: Máy khoan đá Bauer BG25
A10: 6 | B10: 2.2 | C10: Khoan cọc nhồi D1200 Mố M1 (3 cọc L=20m) & đổ BT C30 | D10: m | E10: 60 | F10: 3850000 | G10: =E10*F10 -> 231000000 | H10: 10 | I10: =ROUNDUP(E10/H10, 1) -> 6 | J10: Bauer BG25 + Cẩu 50T + Xe bồn
A11: 7 | B11: 2.3 | C11: Khoan cọc nhồi D1200 Trụ T1 (8 cọc L=40m) & đổ BT C30 | D11: m | E11: 320 | F11: 4200000 | G11: =E11*F11 -> 1344000000 | H11: 21.3 | I11: =ROUNDUP(E11/H11, 1) -> 15.1 | J11: 2 Máy khoan Bauer + Cẩu 50T
A12: 8 | B12: 2.4 | C12: Khoan cọc nhồi D1200 Trụ T2 (8 cọc L=30m) & đổ BT C30 | D12: m | E12: 240 | F12: 4150000 | G12: =E12*F12 -> 996000000 | H12: 18.5 | I12: =ROUNDUP(E12/H12, 1) -> 13 | J12: 2 Máy khoan Bauer + Cẩu 50T
A13: 9 | B13: 2.5 | C13: Khoan cọc nhồi D1200 Mố M2 (7 cọc L=36m) & đổ BT C30 | D13: m | E13: 252 | F13: 4100000 | G13: =E13*F13 -> 1033200000 | H13: 18 | I13: =ROUNDUP(E13/H13, 1) -> 14 | J13: 2 Máy khoan Bauer + Cẩu 50T
A14: 10 | B14: 2.6 | C14: Thí nghiệm siêu âm 156 mặt cắt cọc, PDA & nén tĩnh | D14: Gói | E14: 1 | F14: 185000000 | G14: =E14*F14 -> 185000000 | H14: 0.17 | I14: =ROUNDUP(E14/H14, 1) -> 5.9 | J14: Hệ thống siêu âm cọc đa kênh
A15: 11 | B15: 3.1 | C15: Đào hố móng ngàm đá, đập đầu 26 cọc & đổ BT lót C10 (42.15 m3) | D15: Cọc | E15: 26 | F15: 4500000 | G15: =E15*F15 -> 117000000 | H15: 4.3 | I15: =ROUNDUP(E15/H15, 1) -> 6.1 | J15: Máy đào PC200 búa đập đá
A16: 12 | B16: 3.2 | C16: Cốt thép, ván khuôn & đổ bê tông bệ móng mố M1, M2 (173.2 m3) | D16: m3 | E16: 173.2 | F16: 2850000 | G16: =E16*F16 -> 4.9362e+08 | H16: 24.7 | I16: =ROUNDUP(E16/H16, 1) -> 7.1 | J16: Cẩu 25T + Bơm 42m + Xe bồn
... A36: 32 | B36: 5.8 | C36: Thử tải kiểm định động học & nghiệm thu thông xe hoàn thành | D36: Gói | E36: 1 | F36: 120000000 | G36: =E36*F36 -> 120000000 | H36: 1 | I36: =ROUNDUP(E36/H36, 1) -> 1 | J36: Đoàn xe thử tải 3 trục 30T
C37: TỔNG CHI PHÍ TRỰC TIẾP (T) CẦU KM19+529.080 | G37: =SUM(G5:G36) -> 17036732520
C38: Chi phí gián tiếp (GT = 7.3% * T) | G38: =G37*0.073 -> 1.2436815e+09
C39: Thu nhập chịu thuế tính trước (TL = 5.5% * (T + GT)) | G39: =(G37+G38)*0.055 -> 1.0054228e+09
C40: Thuế giá trị gia tăng (VAT = 10% * (T + GT + TL)) | G40: =(G37+G38+G39)*0.1 -> 1.9285837e+09
C41: TỔNG DỰ TOÁN XÂY LẮP G_XD CẦU KM19+529.080 (SAU THUẾ) | G41: =G37+G38+G39+G40 -> 2.121442e+10

Sheet TIEN_DO
A1: • HỆ THỐNG QUẢN LÝ TIẾN ĐỘ THI CÔNG & MẠNG CPM TỰ ĐỘNG – 23HG SYSTEM
A2: DỰ ÁN: CAO TỐC TUYÊN QUANG - HÀ GIANG (GÓI 09-XL) — CẦU KM19+529.080 (3 NHỊP DẦM SUPER-T L=38.2M) | E2: BẮT ĐẦU: | F2: 46296 | G2: KẾT THÚC: | H2: 46457
A3: Ngày kiểm soát (Data Date): | C3: 46371 | E3: Lịch thi công: | F3: 6 ngày/tuần (Nghỉ CN & Lễ) | G3: Chế độ CPM: | H3: Tự động (Forward/Backward Pass)
A5: STT | B5: Mã WBS | C5: Nội Dung Hạng Mục Công Việc | D5: Loại | E5: Công Tác Tiền Nhiệm (Predecessors) | F5: Thời Lượng (Work Days) | G5: Hệ Số Mưa K_tt | H5: Khởi Công (ES) | I5: Hoàn Thành (EF) | J5: Ngày Lịch (Cal Days) | K5: Dự Trữ TF | L5: Đường Găng | M5: % Hoàn Thành (Tại Data Date) | N5: T10/W1 | O5: T10/W2 | P5: T10/W3 | Q5: T10/W4 | R5: T10/W5 | S5: T11/W1 | T5: T11/W2 | U5: T11/W3 | V5: T11/W4 | W5: T12/W1 | X5: T12/W2 | Y5: T12/W3 | Z5: T12/W4 | AA5: T12/W5 | AB5: T01/W1 | AC5: T01/W2 | AD5: T01/W3 | AE5: T01/W4 | AF5: T02/W1 | AG5: T02/W2 | AH5: T02/W3 | AI5: T02/W4 | AJ5: T03/W1 | AK5: T03/W2 | AL5: T03/W3
A6: 1 | B6: 1 | C6: CÔNG TÁC CHUẨN BỊ & PHỤ TRỢ THI CÔNG CÔNG TRƯỜNG | D6: Summary | F6: 0 | G6: 1 | H6: 46296 | I6: 46321 | J6: 26 | K6: 0 | L6: GANG | M6: 1
A7: 2 | B7: 1.1 | C7: Bàn giao tim mốc VN2000 & định vị mố trụ cầu | D7: Task | F7: 2 | G7: 1 | H7: 46296 | I7: 46297 | J7: 2 | K7: 0 | L7: GANG | M7: 1
A8: 3 | B8: 1.2 | C8: Rà phá bom mìn, dọn dẹp mặt bằng & dựng lán trại | D8: Task | E8: 1.1FS | F8: 5 | G8: 1 | H8: 46298 | I8: 46303 | J8: 6 | K8: 0 | L8: GANG | M8: 1
A9: 4 | B9: 1.3 | C9: Thi công đường công vụ nhánh 6 & 6A tiếp cận mố trụ | D9: Task | E9: 1.2FS | F9: 9 | G9: 1 | H9: 46304 | I9: 46314 | J9: 11 | K9: 0 | L9: GANG | M9: 1
A10: 5 | B10: 1.4 | C10: Xây dựng bãi đúc dầm Super-T, bệ đúc & trạm trộn 60m3/h | D10: Task | E10: 1.3SS+3 | F10: 12 | G10: 1 | H10: 46308 | I10: 46321 | J10: 14 | K10: 11 | M10: 1
A11: 6 | B11: 2 | C11: THI CÔNG CỌC KHOAN NHỒI D1200MM (26 CỌC TOÀN CẦU) | D11: Summary | F11: 0 | G11: 1 | H11: 46315 | I11: 46365 | J11: 51 | K11: 0 | L11: GANG | M11: 1
A12: 7 | B12: 2.1 | C12: Khoan thăm dò hang Karst sâu 5m vào đá liền khối (26 lỗ) | D12: Task | E12: 1.3FS | F12: 10 | G12: 1 | H12: 46315 | I12: 46325 | J12: 11 | K12: 0 | L12: GANG | M12: 1
A13: 8 | B13: 2.2 | C13: Khoan cọc nhồi D1200 Mố M1 (3 cọc L=20m) & đổ BT C30 | D13: Task | E13: 2.1FS | F13: 6 | G13: 1 | H13: 46326 | I13: 46332 | J13: 7 | K13: 0 | L13: GANG | M13: 1
A14: 9 | B14: 2.3 | C14: Khoan cọc nhồi D1200 Trụ T1 (8 cọc L=40m) & đổ BT C30 | D14: Task | E14: 2.2SS+3 | F14: 15 | G14: 1 | H14: 46330 | I14: 46346 | J14: 17 | K14: 0 | L14: GANG | M14: 1
A15: 10 | B15: 2.4 | C15: Khoan cọc nhồi D1200 Trụ T2 (8 cọc L=30m) & đổ BT C30 | D15: Task | E15: 2.3SS+6 | F15: 13 | G15: 1 | H15: 46337 | I15: 46351 | J15: 15 | K15: 0 | L15: GANG | M15: 1
A16: 11 | B16: 2.5 | C16: Khoan cọc nhồi D1200 Mố M2 (7 cọc L=36m) & đổ BT C30 | D16: Task | E16: 2.4SS+5 | F16: 14 | G16: 1 | H16: 46343 | I16: 46358 | J16: 16 | K16: 0 | L16: GANG | M16: 1
A17: 12 | B17: 2.6 | C17: Thí nghiệm siêu âm 156 mặt cắt cọc, PDA & nén tĩnh | D17: Task | E17: 2.5FS | F17: 6 | G17: 1 | H17: 46359 | I17: 46365 | J17: 7 | K17: 0 | L17: GANG | M17: 1
A18: 13 | B18: 3 | C18: KẾT CẤU PHẦN DƯỚI (MỐ M1, M2 & TRỤ T1, T2 ĐÃ TÁCH BẠCH) | D18: Summary | F18: 0 | G18: 1 | H18: 46366 | I18: 46410 | J18: 45 | K18: 0 | L18: GANG | M18: 0.13
A19: 14 | B19: 3.1 | C19: Đào hố móng ngàm đá, đập đầu 26 cọc & đổ BT lót C10 (42.15 m3) | D19: Task | E19: 2.6FS | F19: 6 | G19: 1 | H19: 46366 | I19: 46372 | J19: 7 | K19: 0 | L19: GANG | M19: 0.86
A20: 15 | B20: 3.2 | C20: Cốt thép, ván khuôn & đổ bê tông bệ móng mố M1, M2 (173.2 m3) | D20: Task | E20: 3.1FS | F20: 7 | G20: 1 | H20: 46373 | I20: 46380 | J20: 8 | K20: 22 | M20: 0
A21: 16 | B21: 3.3.1 | C21: Cốt thép, ván khuôn & đổ BT bệ trụ T1 (11.6x8.0x2.0m Zero-vát, 184.2 m3) | D21: Task | E21: 3.1FS+2 | F21: 7 | G21: 1 | H21: 46375 | I21: 46382 | J21: 8 | K21: 0 | L21: GANG | M21: 0
A22: 17 | B22: 3.3.2 | C22: Cốt thép, ván khuôn & đổ BT bệ trụ T2 (11.6x8.0x2.0m Zero-vát, 184.2 m3) | D22: Task | E22: 3.3.1SS+4 | F22: 7 | G22: 1 | H22: 46380 | I22: 46387 | J22: 8 | K22: 0 | L22: GANG | M22: 0
A23: 18 | B23: 3.4.1 | C23: Thi công thân đặc trụ T1 (H=23.35m, 3 đốt vát, 234.9 m3) | D23: Task | E23: 3.3.1FS | F23: 11 | G23: 1 | H23: 46384 | I23: 46396 | J23: 13 | K23: 6 | M23: 0
A24: 19 | B24: 3.4.2 | C24: Thi công thân đặc trụ T2 (H=25.45m, 3 đốt vát, 266.8 m3) | D24: Task | E24: 3.3.2FS | F24: 12 | G24: 1 | H24: 46389 | I24: 46402 | J24: 14 | K24: 0 | L24: GANG | M24: 0
A25: 20 | B25: 3.5 | C25: Thi công thân mố chân dê M1 & mố chữ U M2 BT C30 (138.4 m3) | D25: Task | E25: 3.2FS+1 | F25: 10 | G25: 1 | H25: 46382 | I25: 46394 | J25: 13 | K25: 22 | M25: 0
A26: 21 | B26: 3.6.1 | C26: Thi công xà mũ trụ T1, đá kê gối & ụ chống xô (128.9 m3) | D26: Task | E26: 3.4.1FS | F26: 6 | G26: 1 | H26: 46398 | I26: 46403 | J26: 6 | K26: 6 | M26: 0
A27: 22 | B27: 3.6.2 | C27: Thi công xà mũ trụ T2, đá kê gối & ụ chống xô (145.0 m3) | D27: Task | E27: 3.4.2FS | F27: 7 | G27: 1 | H27: 46403 | I27: 46410 | J27: 8 | K27: 0 | L27: GANG | M27: 0
A28: 23 | B28: 4 | C28: CHẾ TẠO & LAO LẮP DẦM SUPER-T L=38.2M (15 PHIẾN) | D28: Summary | F28: 0 | G28: 1 | H28: 46351 | I28: 46431 | J28: 81 | K28: 0 | L28: GANG | M28: 0.26
A29: 24 | B29: 4.1 | C29: Cốt thép, luồn cáp DUL 15 phiến dầm Super-T tại bãi đúc (15 phiến) | D29: Task | E29: 1.4FS+25 | F29: 24 | G29: 1 | H29: 46351 | I29: 46378 | J29: 28 | K29: 11 | M29: 0.75
A30: 25 | B30: 4.2 | C30: Đổ bê tông C45 15 phiến dầm Super-T L=38.2m bãi đúc (434.8 m3) | D30: Task | E30: 4.1SS+18 | F30: 18 | G30: 1 | H30: 46372 | I30: 46393 | J30: 22 | K30: 11 | M30: 0
A31: 26 | B31: 4.3 | C31: Căng kéo cáp DUL 15.2mm & bơm vữa ống gen dầm (15 phiến) | D31: Task | E31: 4.2FS | F31: 8 | G31: 1 | H31: 46394 | I31: 46402 | J31: 9 | K31: 11 | M31: 0
A32: 27 | B32: 4.4 | C32: Lắp đặt 30 gối chậu cao su đơn/song hướng mố trụ (30 cái) | D32: Task | E32: 3.6.1FS, 3.6.2FS | F32: 4 | G32: 1 | H32: 46412 | I32: 46415 | J32: 4 | K32: 0 | L32: GANG | M32: 0
A33: 28 | B33: 4.5 | C33: Lắp đường ray P43, vận chuyển & lao lắp 15 dầm Super-T (15 phiến) | D33: Task | E33: 4.3FS, 4.4FS | F33: 7 | G33: 1 | H33: 46416 | I33: 46431 | J33: 16 | K33: 0 | L33: GANG | M33: 0
A34: 29 | B34: 5 | C34: BẢN MẶT CẦU & HOÀN THIỆN TOÀN CẦU | D34: Summary | F34: 0 | G34: 1 | H34: 46433 | I34: 46457 | J34: 25 | K34: 0 | L34: GANG | M34: 0
A35: 30 | B35: 5.1 | C35: Đổ bê tông dầm ngang mố trụ & bản liên tục nhiệt C35 (78.5 m3) | D35: Task | E35: 4.5FS | F35: 4 | G35: 1 | H35: 46433 | I35: 46436 | J35: 4 | K35: 0 | L35: GANG | M35: 0
A36: 31 | B36: 5.2 | C36: Lắp 510 tấm ván khuôn đúc sẵn & cốt thép bản mặt cầu (510 tấm) | D36: Task | E36: 5.1FS | F36: 4 | G36: 1 | H36: 46437 | I36: 46441 | J36: 5 | K36: 0 | L36: GANG | M36: 0
A37: 32 | B37: 5.3 | C37: Đổ bê tông bản mặt cầu tại chỗ C35 (dày 180mm, 235.6 m3) | D37: Task | E37: 5.2FS | F37: 4 | G37: 1 | H37: 46442 | I37: 46445 | J37: 4 | K37: 0 | L37: GANG | M37: 0
A38: 33 | B38: 5.4 | C38: Đổ bê tông bản quá độ C25 & đắp K98 đường đầu cầu (2 bản) | D38: Task | E38: 5.3SS+2, 3.5FS+20 | F38: 5 | G38: 1 | H38: 46444 | I38: 46449 | J38: 6 | K38: 7 | M38: 0
A39: 34 | B39: 5.5 | C39: Lắp khe co giãn răng lược thép & ống thoát nước PVC (2 bộ) | D39: Task | E39: 5.3FS+1 | F39: 4 | G39: 1 | H39: 46448 | I39: 46451 | J39: 4 | K39: 1 | M39: 0
A40: 35 | B40: 5.6 | C40: Đổ bê tông gờ lan can C25 & lắp dựng tay vịn thép (260.8 m) | D40: Task | E40: 5.3FS+1 | F40: 5 | G40: 1 | H40: 46448 | I40: 46452 | J40: 5 | K40: 0 | L40: GANG | M40: 0
A41: 36 | B41: 5.7 | C41: Chống thấm & thảm bê tông nhựa C16 mặt cầu dày 7cm (1,620 m2) | D41: Task | E41: 5.5FS, 5.6FS | F41: 3 | G41: 1 | H41: 46454 | I41: 46456 | J41: 3 | K41: 0 | L41: GANG | M41: 0
...

Sheet EVM_5D_QUAN_TRI
A1: HỆ THỐNG QUẢN TRỊ GIÁ TRỊ THU ĐƯỢC (EVM 5D) & ĐƯỜNG CƠ SỞ BASELINE CẦU KM19+529.080
A2: Kiểm soát Tiến độ - Chi phí (PV, EV, AC, SV, CV, SPI, CPI) theo chuẩn PMI & Nghị định 206/2026/NĐ-CP
A4: CHỈ SỐ QUẢN TRỊ | C4: GIÁ TRỊ TÍNH TOÁN | E4: GIẢI NGHĨA KỸ THUẬT & QUẢN TRỊ 5D
A5: TỔNG DỰ TOÁN (BAC) | C5: =BOQ_TIEN_DO!G41 -> 2.121442e+10 | E5: Tổng dự toán xây lắp G_XD phê duyệt sau thuế
A6: KẾ HOẠCH TÍCH LŨY (PV) | C6: =C5*0.485 -> 1.0288994e+10 | E6: Giá trị công việc theo kế hoạch tại Data Date 15/12/2026
A7: GIÁ TRỊ ĐẠT ĐƯỢC (EV) | C7: =C5*0.512 -> 1.0861783e+10 | E7: Khối lượng thực tế hoàn thành đã nghiệm thu KCS
A8: CHI PHÍ THỰC TẾ (AC) | C8: =C5*0.498 -> 1.0564781e+10 | E8: Tổng chi phí vật tư, nhân công, ca máy đã giải ngân
A9: CHÊNH LỆCH TIẾN ĐỘ (SV = EV - PV) | C9: =C7-C6 -> 5.7278935e+08 | E9: Giá trị dương: Tiến độ thi công đang vượt trước kế hoạch
A10: CHÊNH LỆCH CHI PHÍ (CV = EV - AC) | C10: =C7-C8 -> 2.9700189e+08 | E10: Giá trị dương: Tiết kiệm chi phí, không vượt ngân sách
A11: CHỈ SỐ HIỆU SUẤT TIẾN ĐỘ (SPI = EV/PV) | C11: =C7/C6 -> 1.0556701 | E11: SPI >= 1.0: Đạt và vượt tiến độ yêu cầu
A12: CHỈ SỐ HIỆU SUẤT CHI PHÍ (CPI = EV/AC) | C12: =C7/C8 -> 1.0281124 | E12: CPI >= 1.0: Quản trị chi phí đạt hiệu quả cao
A13: DỰ BÁO HOÀN THÀNH (EAC = BAC/CPI) | C13: =C5/C12 -> 2.0634339e+10 | E13: Dự báo tổng chi phí khi hoàn thành công trình
A14: CHI PHÍ CÒN LẠI (ETC = EAC - AC) | C14: =C13-C8 -> 1.0069557e+10 | E14: Dự toán chi phí cần thiết để thi công nốt phần còn lại
A15: CHÊNH LỆCH KHI XONG (VAC = BAC - EAC) | C15: =C5-C13 -> 5.8008181e+08 | E15: Giá trị dương: Dự kiến hoàn thành dưới ngân sách

Sheet HUY_DONG_XMTB
A1: KẾ HOẠCH HUY ĐỘNG & CÂN BẰNG TÀI NGUYÊN XE MÁY THIẾT BỊ CẦU KM19+529.080
A2: Kiểm soát đỉnh tải thiết bị - Khớp năng suất định mức ca máy theo Thông tư 38/2026/TT-BXD
A4: STT | B4: Mã | C4: Chủng Loại Xe Máy Thiết Bị | D4: Định Mức Dầu | E4: T10/26 | F4: T11/26 | G4: T12/26 | H4: T01/27 | I4: T02/27 | J4: T03/27 | K4: Tổng Ca Máy | L4: Tổng Nhiên Liệu (Lít)
A5: 1 | B5: MK | C5: Máy khoan cọc nhồi D1200 Bauer BG25 | D5: 145 | E5: 12 | F5: 60 | G5: 48 | H5: 0 | I5: 0 | J5: 0 | K5: =SUM(E5:J5) -> 120 | L5: =K5*D5 -> 17400
A6: 2 | B6: CX | C6: Cần cẩu bánh xích 50T Kobelco CKE500 | D6: 62 | E6: 10 | F6: 45 | G6: 45 | H6: 45 | I6: 25 | J6: 10 | K6: =SUM(E6:J6) -> 180 | L6: =K6*D6 -> 11160
A7: 3 | B7: CL | C7: Cần cẩu bánh lốp 25T Kato KR250 | D7: 48 | E7: 15 | F7: 25 | G7: 25 | H7: 25 | I7: 20 | J7: 10 | K7: =SUM(E7:J7) -> 120 | L7: =K7*D7 -> 5760
A8: 4 | B8: MD | C8: Máy đào bánh xích 1.25m3 Komatsu PC200 | D8: 68 | E8: 20 | F8: 15 | G8: 30 | H8: 15 | I8: 10 | J8: 5 | K8: =SUM(E8:J8) -> 95 | L8: =K8*D8 -> 6460
A9: 5 | B9: OT | C9: Ô tô tự đổ 15 tấn Howo 371HP | D9: 52 | E9: 30 | F9: 25 | G9: 40 | H9: 25 | I9: 15 | J9: 5 | K9: =SUM(E9:J9) -> 140 | L9: =K9*D9 -> 7280
A10: 6 | B10: XB | C10: Xe bồn vận chuyển bê tông 9m3 | D10: 42 | E10: 10 | F10: 50 | G10: 55 | H10: 45 | I10: 35 | J10: 15 | K10: =SUM(E10:J10) -> 210 | L10: =K10*D10 -> 8820
A11: 7 | B11: BM | C11: Xe bơm bê tông cần 42m Putzmeister | D11: 46 | E11: 5 | F11: 20 | G11: 25 | H11: 20 | I11: 10 | J11: 5 | K11: =SUM(E11:J11) -> 85 | L11: =K11*D11 -> 3910
A12: 8 | B12: MN | C12: Máy nén khí 7.5m3/phút Airman PDS265 | D12: 38 | E12: 10 | F12: 35 | G12: 35 | H12: 15 | I12: 10 | J12: 5 | K12: =SUM(E12:J12) -> 110 | L12: =K12*D12 -> 4180
A13: 9 | B13: MH | C13: Máy phát hàn điện 500A Denyo 500A | D13: 28 | E13: 20 | F13: 45 | G13: 45 | H13: 40 | I13: 25 | J13: 15 | K13: =SUM(E13:J13) -> 190 | L13: =K13*D13 -> 5320
A14: 10 | B14: TT | C14: Trạm trộn BTXM 60m3/h Sicoma | D14: 58 | E14: 15 | F14: 35 | G14: 40 | H14: 35 | I14: 25 | J14: 10 | K14: =SUM(E14:J14) -> 160 | L14: =K14*D14 -> 9280
A15: 11 | B15: GL | C15: Giá lao dầm Super-T 78.88T ray P43 | D15: 35 | E15: 0 | F15: 0 | G15: 0 | H15: 15 | I15: 40 | J15: 5 | K15: =SUM(E15:J15) -> 60 | L15: =K15*D15 -> 2100
A16: 12 | B16: LU | C16: Máy lu rung 14-25T Hamm 3411 | D16: 45 | E16: 10 | F16: 0 | G16: 0 | H16: 0 | I16: 5 | J16: 15 | K16: =SUM(E16:J16) -> 30 | L16: =K16*D16 -> 1350
... A18: 14 | B18: MP | C18: Máy phát điện 3 pha công nghiệp 250kVA | D18: 55 | E18: 25 | F18: 30 | G18: 30 | H18: 30 | I18: 25 | J18: 15 | K18: =SUM(E18:J18) -> 155 | L18: =K18*D18 -> 8525
C19: TỔNG CỘNG TOÀN CÔNG TRƯỜNG CẦU KM19 | K19: =SUM(K5:K18) -> 1785 | L19: =SUM(L5:L18) -> 97265

Sheet TIEN_DO_GIAI_NGAN
A1: KẾ HOẠCH DÒNG TIỀN & TIẾN ĐỘ GIẢI NGÂN (S-CURVE TÀI CHÍNH) CẦU KM19+529.080
A2: Tuân thủ Nghị định 206/2026/NĐ-CP: Tạm ứng 20%, thu hồi tạm ứng theo lũy tiến, bảo hành 5%
A4: Kỳ TT | B4: Thời Gian | C4: Nội Dung Nghiệm Thu Trọng Tâm Cầu Km19 | D4: Giá Trị Hoàn Thành (VNĐ) | E4: Khấu Trừ Tạm Ứng (VNĐ) | F4: Giữ Lại Bảo Hành 5% (VNĐ) | G4: Thực Nhận Kỳ Này (VNĐ)
A5: 0 | B5: T10/2026 | C5: TẠM ỨNG HỢP ĐỒNG 20% (Theo Nghị định 206/2026/NĐ-CP) | D5: 0 | E5: 0 | F5: 0 | G5: =BOQ_TIEN_DO!G41*0.2 -> 4.2428841e+09
A6: 1 | B6: T11/2026 | C6: Nghiệm thu chuẩn bị, đường công vụ & cọc M1, T1 | D6: 3850000000 | E6: 0 | F6: =D6*0.05 -> 192500000 | G6: =D6-E6-F6 -> 3657500000
A7: 2 | B7: T12/2026 | C7: Nghiệm thu cọc T2, M2 & bệ mố trụ M1, M2, T1, T2 | D7: 5200000000 | E7: =G5*0.3 -> 1.2728652e+09 | F7: =D7*0.05 -> 260000000 | G7: =D7-E7-F7 -> 3.6671348e+09
A8: 3 | B8: T01/2027 | C8: Nghiệm thu thân trụ T1, T2, xà mũ & đúc 15 dầm Super-T | D8: 5800000000 | E8: =G5*0.4 -> 1.6971536e+09 | F8: =D8*0.05 -> 290000000 | G8: =D8-E8-F8 -> 3.8128464e+09
A9: 4 | B9: T02/2027 | C9: Nghiệm thu lao dầm, dầm ngang, bản mặt cầu C35 | D9: 4100000000 | E9: =G5*0.3 -> 1.2728652e+09 | F9: =D9*0.05 -> 205000000 | G9: =D9-E9-F9 -> 2.6221348e+09
A10: 5 | B10: T03/2027 | C10: Nghiệm thu bản quá độ, gờ lan can, thảm BTN & bàn giao | D10: 2250000000 | E10: 0 | F10: =D10*0.05 -> 112500000 | G10: =D10-E10-F10 -> 2137500000
C11: TỔNG CỘNG GIÁ TRỊ GIẢI NGÂN | D11: =SUM(D5:D10) -> 21200000000 | E11: =SUM(E5:E10) -> 4.2428841e+09 | F11: =SUM(F5:F10) -> 1060000000 | G11: =SUM(G5:G10) -> 20140000000

Sheet KE_HOACH_QLCL
A1: KẾ HOẠCH NGHIỆM THU & QUẢN LÝ CHẤT LƯỢNG (AEC-QLCL) CẦU KM19+529.080 – 23HG SYSTEM
A2: Tuân thủ Luật Xây dựng 135/2025/QH15, Nghị định 207/2026/NĐ-CP & Thông tư 32/2026/TT-BXD
A4: Mã Biên Bản | B4: Tên Công Việc Nghiệm Thu (NĐ 207/2026/NĐ-CP) | C4: Cấu Kiện / Bộ Phận Công Trình | D4: Ngày Bắt Đầu | E4: Ngày Hoàn Thành | F4: Quy Chuẩn / Tiêu Chuẩn Áp Dụng | G4: Hồ Sơ & Chứng Chỉ Đính Kèm
A5: NT-01 | B5: Nghiệm thu tim mốc định vị & mặt bằng thi công mố trụ | C5: Toàn cầu (WBS 1.1 - 1.2) | D5: =TIEN_DO!H7 -> 46296 | E5: =TIEN_DO!I8 -> 46303 | F5: TCVN 9394:2012 | G5: Biên bản bàn giao mốc mạ vàng VN2000
A6: NT-02 | B6: Nghiệm thu lỗ khoan thăm dò địa chất hang Karst | C6: 26 vị trí cọc (WBS 2.1) | D6: =TIEN_DO!H12 -> 46315 | E6: =TIEN_DO!I12 -> 46325 | F6: TCVN 9361:2012 | G6: Hình trụ hố khoan, mẫu đá lõi ngậm
A7: NT-03 | B7: Nghiệm thu thổi rửa hố khoan & lồng thép cọc D1200 M1, T1 | C7: Cọc M1 (3 cọc) & T1 (8 cọc) | D7: =TIEN_DO!H13 -> 46326 | E7: =TIEN_DO!I14 -> 46346 | F7: TCVN 10304:2014 | G7: Chứng chỉ thép CB400, phiếu đo mùn lắng
A8: NT-04 | B8: Nghiệm thu bê tông cọc khoan nhồi D1200 Trụ T2, M2 | C8: Cọc T2 (8 cọc) & M2 (7 cọc) | D8: =TIEN_DO!H15 -> 46337 | E8: =TIEN_DO!I16 -> 46358 | F8: TCVN 9394:2012 | G8: Phiếu xuất xưởng BT C30, tổ mẫu R28
A9: NT-05 | B9: Nghiệm thu toàn diện chất lượng cọc nhồi (Siêu âm + PDA) | C9: Toàn bộ 26 cọc nhồi (WBS 2.6) | D9: =TIEN_DO!H17 -> 46359 | E9: =TIEN_DO!I17 -> 46365 | F9: ASTM D4945 / TCVN | G9: Biểu đồ biến dạng sóng PDA, sóng siêu âm
A10: NT-06 | B10: Nghiệm thu đào ngàm đá hố móng & đổ bê tông lót C10 | C10: Bệ mố M1, M2 & Trụ T1, T2 | D10: =TIEN_DO!H19 -> 46366 | E10: =TIEN_DO!I19 -> 46372 | F10: TCVN 4447:2012 | G10: Biên bản ngàm đá vôi 0.5m, cao độ đáy
A11: NT-07 | B11: Nghiệm thu cốt thép & ván khuôn bệ trụ T1 (11.6x8.0x2.0m) | C11: Bệ trụ T1 (Zero-vát, 184.2 m3) | D11: =TIEN_DO!H21 -> 46375 | E11: =TIEN_DO!I21 -> 46382 | F11: TCVN 4453:1995 | G11: Biên bản nghiệm thu Zero-vát bệ T1
A12: NT-08 | B12: Nghiệm thu cốt thép & ván khuôn bệ trụ T2 (11.6x8.0x2.0m) | C12: Bệ trụ T2 (Zero-vát, 184.2 m3) | D12: =TIEN_DO!H22 -> 46380 | E12: =TIEN_DO!I22 -> 46387 | F12: TCVN 4453:1995 | G12: Biên bản nghiệm thu Zero-vát bệ T2
A13: NT-09 | B13: Nghiệm thu đổ bê tông C30 thân trụ T1 (H=23.35m, 3 đốt vát) | C13: Thân đặc trụ T1 (WBS 3.4.1) | D13: =TIEN_DO!H23 -> 46384 | E13: =TIEN_DO!I23 -> 46396 | F13: TCVN 4453:1995 | G13: Kiểm tra độ thẳng đứng quả dọi laser
A14: NT-10 | B14: Nghiệm thu đổ bê tông C30 thân trụ T2 (H=25.45m, 3 đốt vát) | C14: Thân đặc trụ T2 (WBS 3.4.2) | D14: =TIEN_DO!H24 -> 46389 | E14: =TIEN_DO!I24 -> 46402 | F14: TCVN 4453:1995 | G14: Kiểm tra độ thẳng đứng quả dọi laser
A15: NT-11 | B15: Nghiệm thu xà mũ trụ T1, T2 & đá kê gối cao su | C15: Đỉnh trụ T1, T2 (WBS 3.6) | D15: =TIEN_DO!H26 -> 46398 | E15: =TIEN_DO!I27 -> 46410 | F15: TCVN 10304:2014 | G15: Cao độ đá kê sai số <= 2mm
A16: NT-12 | B16: Nghiệm thu cốt thép, luồn cáp & đổ BT C45 15 dầm Super-T | C16: Bãi đúc dầm hiện trường | D16: =TIEN_DO!H29 -> 46351 | E16: =TIEN_DO!I30 -> 46393 | F16: TCVN 9114:2012 | G16: Cáp DUL 15.2mm, chứng chỉ xuất xưởng
A17: NT-13 | B17: Nghiệm thu căng kéo cáp DUL & bơm vữa không co ống gen | C17: 15 phiến dầm Super-T (WBS 4.3) | D17: =TIEN_DO!H31 -> 46394 | E17: =TIEN_DO!I31 -> 46402 | F17: TCVN 10304:2014 | G17: Độ dãn dài cáp, áp lực bơm vữa Sika
A18: NT-14 | B18: Nghiệm thu lắp đặt 30 gối chậu cao su & lao dầm Super-T | C18: 3 nhịp cầu 38.2m (WBS 4.4-4.5) | D18: =TIEN_DO!H32 -> 46412 | E18: =TIEN_DO!I33 -> 46431 | F18: TCVN 10268:2014 | G18: Kiểm tra tim gối, độ tiếp xúc mặt đáy
A19: NT-15 | B19: Nghiệm thu dầm ngang, bản liên tục nhiệt & bản mặt cầu C35 | C19: Mặt cầu 118.2m (WBS 5.1-5.3) | D19: =TIEN_DO!H35 -> 46433 | E19: =TIEN_DO!I37 -> 46445 | F19: TCVN 3105 / TCVN 4453 | G19: Phiếu kiểm tra độ võng, chiều dày 18cm
A20: NT-16 | B20: Nghiệm thu lớp chống thấm & thảm bê tông nhựa C16 dày 7cm | C20: Mặt cầu Cầu Km19 (WBS 5.7) | D20: =TIEN_DO!H41 -> 46454 | E20: =TIEN_DO!I41 -> 46456 | F20: TCVN 8819:2011 | G20: Độ nhám, độ bằng phẳng thước 3m
A21: NT-17 | B21: Nghiệm thu hoàn thành công trình bàn giao đưa vào sử dụng | C21: Toàn bộ công trình Cầu Km19 | D21: =TIEN_DO!H42 -> 46457 | E21: =TIEN_DO!I42 -> 46457 | F21: NĐ 207/2026/NĐ-CP | G21: Trọn bộ hồ sơ hoàn công & biên bản tổng

Sheet HUONG_DAN
A1: CẨM NANG VẬN HÀNH HỆ THỐNG TIẾN ĐỘ THI CÔNG 23HG SCHEDULE ASSISTANT PRO
A2: Tác giả: NBT (Nguyễn Bảo Tú) | GitHub: @baotuhg | 23HG SYSTEM
A4: 1. QUY ƯỚC LỊCH LÀM VIỆC & CPM TỰ ĐỘNG:
A5: - Toàn bộ mạng tiến độ được tính toán bằng động cơ CPM chuẩn (Forward Pass & Backward Pass).
A6: - Lịch làm việc công trường: 6 ngày/tuần (Thứ 2 đến Thứ 7; nghỉ Chủ nhật và các ngày Tết theo quy định).
A7: - Công thức tính: EF = WORKDAY.INTL(ES, Thời_lượng - 1, '0000001', NGAY_NGHI_LE).
A8: - Đường găng (GANG): Được xác định khi Dự trữ toàn phần TF (Total Float) <= 0. Màu đỏ nổi bật trên Gantt Canvas.
A10: 2. CẤU TRÚC PHÂN CẤP CẦU KM19+529.080 (3 NHỊP SUPER-T L=38.2M):
A11: - WBS 1: Chuẩn bị mặt bằng, đường công vụ nhánh 6 & 6A, bãi đúc dầm và trạm trộn BTXM 60m3/h.
A12: - WBS 2: Khoan cọc nhồi D1200mm (26 cọc, khoan đá ngàm hang Karst sâu 5m, siêu âm 156 mặt cắt cọc & PDA).
A13: - WBS 3: Kết cấu phần dưới (Đã tách riêng Trụ T1, T2; bệ trụ 11.6x8.0x2.0m Zero-vát; thân trụ 3 đốt có vát).
A14: - WBS 4: Chế tạo & Lao lắp 15 phiến dầm Super-T 38.2m tại bãi đúc công trường, căng kéo cáp DUL 15.2mm.
... A21: - Sheet KE_HOACH_QLCL: Ngày nghiệm thu liên kết động với ngày hoàn thành công tác trên sheet TIEN_DO.
