Workbook

Sheet Danh mục công việc
K1: DANH MỤC CÔNG VIỆC
K2: =" Dự án: "&_xlfn.SINGLE(QLCL_DuAn)
K3: =" Gói thầu: "&_xlfn.SINGLE(QLCL_GoiThau)
K4: =" Công trình: "&_xlfn.SINGLE(QLCL_CongTrinh)
K5: =" Địa điểm xây dựng: "&_xlfn.SINGLE(QLCL_DiaDiemXD)
A7: MÃ HIỆU CHUNG | B7: LƯU MÃ HIỆU | C7: MÃ CV | D7: TIÊU CHUẨN ÁP DỤNG | E7: NỘI DUNG, PHƯƠNG PHÁP KIỂM TRA | F7: THÔNG SỐ LẤY MẪU THÍ NGHIỆM | G7: THIẾT BỊ THI CÔNG | H7: THÔNG SỐ BẢNG PHỤ | J7: STT | K7: MÃ HIỆU ▼ | L7: NỘI DUNG CÔNG VIỆC | M7: LỚP SỐ | N7: LÝ TRÌNH | O7: VỊ TRÍ THI CÔNG/ VỊ TRÍ LẤY MẪU | P7: NGÀY BẮT ĐẦU | Q7: NGÀY KẾT THÚC | R7: NGÀY PHIẾU YC | S7: NGÀY NT/ LM/ KT | T7: GIỜ BẮT ĐẦU | U7: GIỜ KẾT THÚC | V7: GIỜ TÍNH | W7: GIỜ BIÊN BẢN | X7: Cao độ đáy khoan TK | Y7: Cao độ đáy khoan TT | Z7: Số Phụ lục | AA7: Tên cv PYC | AB7: Số PYCNT | AC7: Số BBNT | AD7: Cọc trục X | AE7: Cọc trục Y | AF7: Cao độ | AG7: Mã BB | AH7: Filter | AI7: NGÀY KHÔNG THI CÔNG | AJ7: MÃ CV | AK7: TÊN CV | AL7: ĐƠN VỊ | AM7: KHỐI LƯỢNG NGHIỆM THU | AN7: ĐỢT THANH TOÁN | AO7: SL NHÂN CÔNG | AP7: TÊN BẢNG | AQ7: LINK ẢNH | AR7: NHÓM KÝ BB | AS7: TIỀN TỐ PRINT | AT7: MÃ HẠNG MỤC | AU7: MÃ BIÊN BẢN | AV7: STT SORT DMCV | AW7: STT SORT HM | AX7: GHI CHÚ
A8: =COLUMN() | B8: =COLUMN() | C8: =COLUMN() | D8: =COLUMN() | E8: =COLUMN() | F8: =COLUMN() | G8: =COLUMN() | H8: =COLUMN() | J8: =COLUMN()-9 | K8: =COLUMN()-9 | L8: =COLUMN()-9 | O8: =COLUMN()-9 | P8: =COLUMN()-9 | Q8: =COLUMN()-9 | R8: =COLUMN()-9 | S8: =COLUMN()-9 | W8: =COLUMN()-9 | AI8: =COLUMN()-9 | AJ8: =COLUMN()-9 | AK8: =COLUMN()-9 | AL8: =COLUMN()-9 | AM8: =COLUMN()-9 | AN8: =COLUMN()-9 | AO8: =COLUMN()-9 | AP8: =COLUMN()-9 | ... AX8: =COLUMN()-9
A9: HM | B9: HM | C9: HM.0533424 | J9: HM01 | K9: HM | L9: Vật liệu đầu vào | AT9: HM01 | AU9: HM
A10: BBK_BIA | B10: TRANGBIA | C10: BBK_BIA.0579518 | J10: 01 | K10: TRANGBIA | L10: Biên bản lấy mẫu, kết quả thí nghiệm và biên bản nghiệm thu vật liệu đầu vào | AR10: Nhóm 1 | AT10: HM01 | AU10: TRANGBIA | AV10: 1 | AW10: 1
A11: BBK_ML | B11: MUCLUC | C11: BBK_ML.0289562 | J11: 02 | K11: MUCLUC | L11: Vật liệu đầu vào | AR11: Nhóm 1 | AT11: HM01 | AU11: MUCLUC | AV11: 1 | AW11: 1
A12: LMDV | B12: LMDV | C12: LMDV.0301948 | D12: TC.000205|TC.000204|TC.000206 | F12: VL.0008^Lưới cốt thủy tinh 100/100 kN/m^^2^^^^TC.000205|TC.000204|TC.000206 | J12: 03 | K12: LMDV | L12: Lưới cốt sợi thủy tinh 100/100 kN/m | O12: Công ty cổ phần dịch vụ và công nghệ Trường Khánh (Địa chỉ: Số 2, ngõ 46/15 đường Yên Hòa, Tổ 14 phường Yên nghĩa, Tp Hà nội) | S12: 46154 | T12: 0.375 | U12: =T12+V12 | V12: 0.0625 | W12: =TEXT(T12,"HH""h""MM'")&"÷"&TEXT(U12,"HH""h""MM'") | AR12: Nhóm 1 | AT12: HM01 | AU12: LMDV | AV12: 5 | AW12: 5
A13: LMDV | B13: LMDV | C13: LMDV.0774740 | D13: TC.000205|TC.000204 | F13: VL.0010^Bentonite - API Bentonite STAR-số lô :2003^^25kg^Công ty TNHH Thương mại & Sản xuất Hùng Ngọc (Địa chỉ: Số 23 khu đất đấu giá TT5A, phường Phúc Lợi, TP Hà Nội)^^^TC.000205|TC.000204 | J13: 04 | K13: LMDV | L13: Bentonite | O13: Công ty TNHH Thương mại & Sản xuất Hùng Ngọc (Địa chỉ: Số 23 khu đất đấu giá TT5A, phường Phúc Lợi, TP Hà Nội) | S13: 46168 | T13: 0.35416667 | U13: =T13+V13 | V13: 0.03125 | W13: =TEXT(T13,"HH""h""MM'")&"÷"&TEXT(U13,"HH""h""MM'") | AR13: Nhóm 1 | AT13: HM01 | AU13: LMDV | AV13: 6 | AW13: 6
A14: LMDV | B14: LMDV | C14: LMDV.0014017 | D14: TC.000205|TC.000204|TC.000773 | F14: VL.0010^Cóc nối thép dọc M16, L=285mm^^6^^^^TC.000205|TC.000204~VL.0055^Thép ống D113.5x3.5mm^^6^^^^TC.000773~VL.0055^Thép ống D59.9x3mm^^6^^^^TC.000773 | J14: 05 | K14: LMDV | L14: Cóc nối thép dọc, Ống thép | O14: Công ty TNHH SX và TM CTGT Hòa Bình (Địa chỉ: Số nhà 69 ngõ 157/10 Tổ 18, Đường Đức Giang, Phường Việt Hưng, TP Hà Nội) | S14: 46168 | T14: =U13 | U14: =T14+V14 | V14: 0.03125 | W14: =TEXT(T14,"HH""h""MM'")&"÷"&TEXT(U14,"HH""h""MM'") | AR14: Nhóm 1 | AT14: HM01 | AU14: LMDV | AV14: 7 | AW14: 7
A15: LMDV | B15: LMDV | C15: LMDV.0760723 | D15: TC.000401|TC.000393.A|TC.000393.B|TC.000657 | F15: VL.0012^Xi măng^50 kg^01 mẫu^Vincem Hải phòng^^^TC.000401|TC.000393.A|TC.000393.B~VL.0042^ROADCON-SK3000^5 lít^1 mẫu^^^^TC.000657~VL.0012^Xi măng^200 kg^01 mẫu^Vincem Hải phòng^^^TC.000401|TC.000393.A|TC.000393.B | J15: 06 | K15: LMDV | L15: Xi măng Vicem Hải phòng PCB40 | O15: Trạm trộn bê tông Phúc Lâm - Thí nghiệm các chỉ tiêu cơ lý | S15: 46128 | T15: 0.375 | U15: =T15+V15 | V15: 0.020833333 | W15: =TEXT(T15,"HH""h""MM'")&"÷"&TEXT(U15,"HH""h""MM'") | AR15: Nhóm 1 | AT15: HM01 | AU15: LMDV | AV15: 1 | AW15: 1 | AX15: Xi măng (50 tấn): Lần 1 [BT 4] → Lần 2 [BT 6] → Lần 3 [BT 9] → Lần 4 [BT 12] → Lần 5 [BT 15] → Lần 6 [BT 17] → Lần 7 [BT 20] → Lần 8 [BT 23] → Lần 9 [BT 26] → Lần 10 [BT 32] → Lần 11 [BT 34] → Lần 12 [BT 35] → Lần 13 [BT 38] → Lần 14 [BT 40] → Lần 15 [BT 40] → Lần 16 [BT 43] → Lần 17 [BT 44] → Lần 18 [BT 46] → Lần 19 [BT 47] → Lần 20 [BT 49] → Lần 21 [BT 54] → Lần 22 [BT 57] → Lần 23 [BT 62] → Lần 24 [BT 67] → Lần 25 [BT 71] → Lần 26 [BT 78] → Lần 27 [BT 80] → Lần 28 [BT 81] → Lần 29 [BT 83] → Lần 30 [BT 85]
A16: LMDV | B16: LMDV | C16: LMDV.0814490 | D16: TC.000401|TC.000393.A|TC.000393.B|TC.000205|TC.000204|TC.000206 | F16: VL.0012^Cát vàng^50 kg^01 mẫu^Sông Lô^^^TC.000401|TC.000393.A|TC.000393.B~VL.0008^Cát vàng^400 kg^01 mẫu^Sông Lô^^^TC.000205|TC.000204|TC.000206 | J16: 07 | K16: LMDV | L16: Cát vàng | O16: Trạm trộn bê tông Phúc Lâm - Thí nghiệm các chỉ tiêu cơ lý | S16: 46128 | T16: =U15 | U16: =T16+V16 | V16: 0.020833333 | W16: =TEXT(T16,"HH""h""MM'")&"÷"&TEXT(U16,"HH""h""MM'") | AR16: Nhóm 1 | AT16: HM01 | AU16: LMDV | AV16: 2 | AW16: 2 | AX16: Cát (200 m³): Lần 1 [BT 4] → Lần 2 [BT 13] → Lần 3 [BT 22] → Lần 4 [BT 34] → Lần 5 [BT 40] → Lần 6 [BT 45] → Lần 7 [BT 49] → Lần 8 [BT 64] → Lần 9 [BT 79] → Lần 10 [BT 84]
A17: LMDV | B17: LMDV | C17: LMDV.0709037 | D17: TC.000401|TC.000393.A|TC.000393.B|TC.000205|TC.000204 | F17: VL.0012^Đá dăm 5-20mm^150 kg^01 mẫu^Mỏ đá Thạch Bàn-Hùng An-Tuyên Quang^^^TC.000401|TC.000393.A|TC.000393.B~VL.0010^Đá dăm 5-20mm^450 kg^01 mẫu^Mỏ đá Thạch Bàn-Hùng An-Tuyên Quang^^^TC.000205|TC.000204 | J17: 08 | K17: LMDV | L17: Đá dăm 5-20mm | O17: Trạm trộn bê tông Phúc Lâm - Thí nghiệm các chỉ tiêu cơ lý | S17: 46128 | T17: =U16 | U17: =T17+V17 | V17: 0.020833333 | W17: =TEXT(T17,"HH""h""MM'")&"÷"&TEXT(U17,"HH""h""MM'") | AR17: Nhóm 1 | AT17: HM01 | AU17: LMDV | AV17: 3 | AW17: 3 | AX17: Đá (350 m³): Lần 1 [BT 4] → Lần 2 [BT 16] → Lần 3 [BT 29] → Lần 4 [BT 40] → Lần 5 [BT 47] → Lần 6 [BT 61] → Lần 7 [BT 80]
A18: LMDV | B18: LMDV | C18: LMDV.0045352 | D18: TC.000709|TC.000226|TC.000227|TC.000713 | F18: VL.0013^Thép tròn trơn D6(CB240-T)^150 cm^06 thanh^Hòa Phát^^^TC.000709|TC.000226|TC.000227|TC.000713~VL.0013^Thép tròn trơn D8(CB240-T)^150 cm^06 thanh^Hòa Phát^^^TC.000709|TC.000226|TC.000227|TC.000713~VL.0013^Thép thanh vằn D10(CB400-V)^150 cm^03 thanh^Hòa Phát^^^TC.000709|TC.000226|TC.000227|TC.000713~VL.0013^Thép thanh vằn D12(CB400-V)^150 cm^06 thanh^Hòa Phát^^^TC.000709|TC.000226|TC.000227|TC.000713~VL.0013^Thép thanh vằn D14(CB400-V)^150 cm^06 thanh^Hòa Phát^^^TC.000709|TC.000226|TC.000227|TC.000713~VL.0013^Thép thanh vằn D16(CB400-V)^150 cm^06 thanh^Hòa Phát^^^TC.000709|TC.000226|TC.000227|TC.000713~VL.0013^Thép thanh vằn D18(CB400-V)^150 cm^06 thanh^Hòa Phát^^^TC.000709|TC.000226|TC.000227|TC.000713~VL.0013^Thép thanh vằn D20(CB400-V)^150 cm^06 thanh^Hòa Phát^^^TC.000709|TC.000226|TC.000227|TC.000713~VL.0013^Thép thanh vằn D22(CB400-V)^150 cm^06 thanh^Hòa Phát^^^TC.000709|TC.000226|TC.000227|TC.000713~VL.0013^Thép thanh vằn D25(CB400-V)^150 cm^06 thanh^Hòa Phát^^^TC.000709|TC.000226|TC.000227|TC.000713~VL.0013^Thép thanh vằn D28(CB400-V)^150 cm^06 thanh^Hòa Phát^^^TC.000709|TC.000226|TC.000227|TC.000713~VL.0013^Thép thanh vằn D32(CB400-V)^100 cm^06 thanh^Hòa Phát^^^TC.000709|TC.000226|TC.000227|TC.000713 | J18: 09 | K18: LMDV | L18: Thép D6; Thép D8; Thép D10; Thép D12; Thép D14;Thép D16; Thép D18; Thép D20; Thép D22; Thép D25; Thép D28; Thép D32 | O18: Công ty TNHH vật liệu xây dựng Phong Dung xã Bắc Quang, tỉnh Tuyên Quang | S18: 46135 | T18: 0.375 | U18: =T18+V18 | V18: 0.0625 | W18: =TEXT(T18,"HH""h""MM'")&"÷"&TEXT(U18,"HH""h""MM'") | AR18: Nhóm 1 | AT18: HM01 | AU18: LMDV | AV18: 4 | AW18: 4 | AX18: Thép (riêng từng Ø, 20 tấn): Ø10 Lần 1 [Thép 4] → Ø25 Lần 1 [Thép 9] → Ø12 Lần 1 [Thép 14] → Ø20 Lần 1 [Thép 16] → Ø16 Lần 1 [Thép 18] → Ø25 Lần 2 [Thép 91] → Ø25 Lần 3 [Thép 171] → Ø28 Lần 1 [Thép 265] → Ø25 Lần 4 [Thép 269] → Ø25 Lần 5 [Thép 392] → Ø32 Lần 1 [Thép 431] → Ø18 Lần 1 [Thép 432] → Ø32 Lần 2 [Thép 441] → Ø14 Lần 1 [Thép 448] → Ø22 Lần 1 [Thép 490] → Ø16 Lần 2 [Thép 524] → Ø32 Lần 3 [Thép 527] → Ø32 Lần 4 [Thép 595] → Ø16 Lần 3 [Thép 602] → Ø16 Lần 4 [Thép 688] → Ø16 Lần 5 [Thép 734] → Ø12 Lần 2 [Thép 736] → Ø32 Lần 5 [Thép 746] → Cáp 15.2 Lần 1 [Thép 756] → Cáp 15.2 Lần 2 [Thép 756] → Ø16 Lần 6 [Thép 762] → Ø18 Lần 2 [Thép 767] → Ø18 Lần 3 [Thép 774] → Ø14 Lần 2 [Thép 780] → Ø18 Lần 4 [Thép 784] → Ø25 Lần 6 [Thép 790]
A19: HM | B19: HM | C19: HM.0414032 | J19: HM02 | K19: HM | L19: Mặt bằng công trường, đường công vụ | AT19: HM02 | AU19: HM
A20: BBK_BIA | B20: TRANGBIA | C20: BBK_BIA.0862619 | J20: 01 | K20: TRANGBIA | L20: =+L19 | O20: Cầu Km19+529.080 | AP20: Đường công vụ 6, 6A | AR20: Nhóm 1 | AT20: HM02 | AU20: TRANGBIA | AV20: 2 | AW20: 1
A21: BBK_ML | B21: MUCLUC | C21: BBK_ML.0790480 | J21: 02 | K21: MUCLUC | L21: Danh mục biên bản Kiểm tra/Nghiệm thu | O21: Cầu Km19+529.080 | AR21: Nhóm 1 | AT21: HM02 | AU21: MUCLUC | AV21: 2 | AW21: 1
A22: BBK680 | B22: PYC | C22: BBK680.0373536 | J22: 03 | K22: PYC | L22: phiếu yêu cầu | R22: =R23 | S22: =S23 | AB22: 09-XL-307HG/PYCNT/MB-ĐCV | AG22: NTCV | AH22: >=1;<=2 | AR22: Nhóm 1 | AT22: HM02 | AU22: PYC | AV22: 1 | AW22: 1
A23: NTCV | B23: K.9999 | C23: NTCV.0961953 | J23: 04 | K23: K.9999 | L23: Đào nền đường công vụ nhánh 6 | N23: Km0+0 -:- 9(Km0+89.62) | O23: Cầu Km19+529.080 | P23: 46096 | Q23: =+P23+8 | R23: =+Q23-1 | S23: =+Q23 | T23: 0.35416667 | U23: =+T23+V23 | V23: 0.020833333 | W23: =TEXT(T23,"HH""h""MM'")&"÷"&TEXT(U23,"HH""h""MM'") | Z23: 01; | AA23: =+L23 | AB23: 09-XL-307HG/PYCNT/MB-ĐCV-1 | AC23: 09-XL-307HG/PYCNT/MB-ĐCV-1 | AR23: Nhóm 1 | AT23: HM02 | AU23: NTCV | AV23: 1 | AW23: 1
A24: BBK513 | B24: CD-KTHH | C24: BBK513.0871445 | J24: 05 | K24: CD-KTHH | L24: =L23 | N24: Km0+0 -:- 9(Km0+89.62) | O24: Cầu Km19+529.080 | S24: =+S23 | T24: =T23 | U24: =U23 | V24: =V23 | AC24: =+AC23 | AH24: DAONEN_DCV6 | AQ24: Ảnh\daonen dcv.png | AR24: Nhóm 1 | AT24: HM02 | AU24: CD-KTHH | AV24: 1 | AW24: 1
A25: BBK957 | B25: PLKL01 | C25: BBK957.0056236 | J25: 06 | K25: PLKL01 | L25: =+L24 | N25: =+N24 | O25: =+O24 | S25: =+S24 | AG25: =+AH24 | AH25: >=1;<=19 | AR25: Nhóm 1 | AT25: HM02 | AU25: PLKL01 | AV25: 1 | AW25: 1
A26: NTCV | B26: K.9999 | C26: NTCV.0949556 | J26: 07 | K26: K.9999 | L26: Đào nền đường công vụ nhánh 6A | N26: Km0+0 -:- 9(Km0+81.23) | O26: Cầu Km19+529.080 | P26: =+P23+1 | Q26: =+P26+7 | R26: =+Q26-1 | S26: =+Q26 | T26: 0.375 | U26: =+T26+V26 | V26: 0.020833333 | W26: =TEXT(T26,"HH""h""MM'")&"÷"&TEXT(U26,"HH""h""MM'") | Z26: 01; | AA26: =+L26 | AB26: =+AB23 | AC26: 09-XL-307HG/PYCNT/MB-ĐCV-2 | AR26: Nhóm 1 | AT26: HM02 | AU26: NTCV | AV26: 2 | AW26: 2
A27: BBK513 | B27: CD-KTHH | C27: BBK513.0364018 | J27: 08 | K27: CD-KTHH | L27: =L26 | N27: Km0+0 -:- 9(Km0+81.23) | O27: Cầu Km19+529.080 | S27: =+S26 | T27: =T26 | U27: =U26 | V27: =V26 | AC27: =+AC26 | AH27: DAONEN_DCV6A | AQ27: Ảnh\daonen dcv.png | AR27: Nhóm 1 | AT27: HM02 | AU27: CD-KTHH | AV27: 2 | AW27: 2
A28: BBK957 | B28: PLKL01 | C28: BBK957.0524868 | J28: 09 | K28: PLKL01 | L28: =+L27 | N28: =+N27 | O28: =+O27 | S28: =+S27 | AG28: =+AH27 | AH28: >=21;<=36 | AR28: Nhóm 1 | AT28: HM02 | AU28: PLKL01 | AV28: 2 | AW28: 2
A29: BBK680 | B29: PYC | C29: BBK680.0767111 | J29: 10 | K29: PYC | L29: phiếu yêu cầu | R29: =+R30 | S29: =+S30 | AB29: 09-XL-307HG/PYCNT/MB-ĐCV | AG29: NTCV | AH29: >=3;<=6 | AR29: Nhóm 1 | AT29: HM02 | AU29: PYC | AV29: 2 | AW29: 2
A30: NTCV | B30: K.9999 | C30: NTCV.0053504 | J30: 11 | K30: K.9999 | L30: ="Đắp nền đường công vụ nhánh 6 lớp số "&M30 | M30: 29 | N30: Km0+0 -:- 9(Km0+89.62) | O30: Cầu Km19+529.080 | P30: =+S23 | Q30: =+P30+1 | R30: =+Q30-1 | S30: =+Q30 | T30: 0.35416667 | U30: =+T30+V30 | V30: 0.010416667 | W30: =TEXT(T30,"HH""h""MM'")&"÷"&TEXT(U30,"HH""h""MM'") | Z30: 01A; | AA30: =+L30 | AB30: 09-XL-307HG/PYCNT/MB-ĐCV-2 | AC30: 09-XL-307HG/PYCNT/MB-ĐCV-2 | AR30: Nhóm 1 | AT30: HM02 | AU30: NTCV | AV30: 3 | AW30: 3
A31: BBK371 | B31: KTHH_DAP | C31: BBK371.0592458 | J31: 12 | K31: KTHH_DAP | L31: =L30 | M31: =+M30 | N31: Km0+0 -:- 9(Km0+89.62) | O31: Cầu Km19+529.080 | S31: =+S30 | AC31: =AC30 | AG31: DAPNEN_DCV6 | AH31: >=1;<=19 | AQ31: Ảnh\dapnendcv.png | AR31: Nhóm 1 | AT31: HM02 | AU31: KTHH_DAP | AV31: 1 | AW31: 1
A32: BBK957 | B32: PLKL01 | C32: BBK957.0468700 | J32: 13 | K32: PLKL01 | L32: =+L31 | M32: =+M31 | N32: =+N31 | O32: =+O31 | S32: =+S31 | AG32: =+AG31 | AH32: >=38;<=56 | AR32: Nhóm 1 | AT32: HM02 | AU32: PLKL01 | AV32: 3 | AW32: 3
A33: NTCV | B33: K.9999 | C33: NTCV.0298165 | J33: 14 | K33: K.9999 | L33: ="Đắp nền đường công vụ nhánh 6 lớp số "&M33 | M33: 28 | N33: Km0+0 -:- 9(Km0+89.62) | O33: Cầu Km19+529.080 | P33: =+P30 | Q33: =+P33+1 | R33: =+Q33-1 | S33: =+Q33 | T33: =U30+TIME(,10,) | U33: =+T33+V33 | V33: 0.010416667 | W33: =TEXT(T33,"HH""h""MM'")&"÷"&TEXT(U33,"HH""h""MM'") | Z33: 01A; | AA33: =+L33 | AB33: =+AB30 | AC33: =+AC30 | AR33: Nhóm 1 | AT33: HM02 | AU33: NTCV | AV33: 4 | AW33: 4
A34: BBK371 | B34: KTHH_DAP | C34: BBK371.0622696 | J34: 15 | K34: KTHH_DAP | L34: =L33 | M34: =+M33 | N34: Km0+0 -:- 9(Km0+89.62) | O34: Cầu Km19+529.080 | S34: =+S33 | AC34: =+AC33 | AG34: DAPNEN_DCV6 | AH34: >=1;<=19 | AQ34: Ảnh\dapnendcv.png | AR34: Nhóm 1 | AT34: HM02 | AU34: KTHH_DAP | AV34: 2 | AW34: 2
A35: BBK957 | B35: PLKL01 | C35: BBK957.0647821 | J35: 16 | K35: PLKL01 | L35: =+L34 | M35: =+M34 | N35: =+N34 | O35: =+O34 | S35: =+S34 | AG35: =+AG34 | AH35: >=38;<=56 | AR35: Nhóm 1 | AT35: HM02 | AU35: PLKL01 | AV35: 4 | AW35: 4
A36: NTCV | B36: K.9999 | C36: NTCV.0263792 | J36: 17 | K36: K.9999 | L36: ="Đắp nền đường công vụ nhánh 6 lớp số "&M36 | M36: 27 | N36: Km0+0 -:- 9(Km0+89.62) | O36: Cầu Km19+529.080 | P36: =+P33 | Q36: =+P36+1 | R36: =+Q36-1 | S36: =+Q36 | T36: =U33+TIME(,10,) | U36: =+T36+V36 | V36: 0.010416667 | W36: =TEXT(T36,"HH""h""MM'")&"÷"&TEXT(U36,"HH""h""MM'") | Z36: 01A; | AA36: =+L36 | AB36: =+AB33 | AC36: =+AC33 | AR36: Nhóm 1 | AT36: HM02 | AU36: NTCV | AV36: 5 | AW36: 5
A37: BBK371 | B37: KTHH_DAP | C37: BBK371.0279342 | J37: 18 | K37: KTHH_DAP | L37: =L36 | M37: =+M36 | N37: Km0+0 -:- 9(Km0+89.62) | O37: Cầu Km19+529.080 | S37: =+S36 | AC37: =+AC36 | AG37: DAPNEN_DCV6 | AH37: >=1;<=19 | AQ37: Ảnh\dapnendcv.png | AR37: Nhóm 1 | AT37: HM02 | AU37: KTHH_DAP | AV37: 3 | AW37: 3
A38: BBK957 | B38: PLKL01 | C38: BBK957.0829801 | J38: 19 | K38: PLKL01 | L38: =+L37 | M38: =+M37 | N38: =+N37 | O38: =+O37 | S38: =+S37 | AG38: =+AG37 | AH38: >=38;<=56 | AR38: Nhóm 1 | AT38: HM02 | AU38: PLKL01 | AV38: 5 | AW38: 5
A39: NTCV | B39: K.9999 | C39: NTCV.0824602 | J39: 20 | K39: K.9999 | L39: ="Đắp nền đường công vụ nhánh 6 lớp số "&M39 | M39: 26 | N39: Km0+0 -:- 9(Km0+89.62) | O39: Cầu Km19+529.080 | P39: =+P36 | Q39: =+P39+1 | R39: =+Q39-1 | S39: =+Q39 | T39: =U36+TIME(,10,) | U39: =+T39+V39 | V39: 0.010416667 | W39: =TEXT(T39,"HH""h""MM'")&"÷"&TEXT(U39,"HH""h""MM'") | Z39: 01A; | AA39: =+L39 | AB39: =+AB36 | AC39: =+AC36 | AR39: Nhóm 1 | AT39: HM02 | AU39: NTCV | AV39: 6 | AW39: 6
A40: BBK371 | B40: KTHH_DAP | C40: BBK371.0589163 | J40: 21 | K40: KTHH_DAP | L40: =L39 | M40: =+M39 | N40: Km0+0 -:- 9(Km0+89.62) | O40: Cầu Km19+529.080 | S40: =+S39 | AC40: =+AC39 | AG40: DAPNEN_DCV6 | AH40: >=1;<=19 | AQ40: Ảnh\dapnendcv.png | AR40: Nhóm 1 | AT40: HM02 | AU40: KTHH_DAP | AV40: 4 | AW40: 4
A41: BBK957 | B41: PLKL01 | C41: BBK957.0986093 | J41: 22 | K41: PLKL01 | L41: =+L40 | M41: =+M40 | N41: =+N40 | O41: =+O40 | S41: =+S40 | AG41: =+AG40 | AH41: >=38;<=56 | AR41: Nhóm 1 | AT41: HM02 | AU41: PLKL01 | AV41: 6 | AW41: 6
...

Sheet Theo_Doi_Tan_Suat_Be_Tong
A1: STT | B1: HẠNG MỤC CÔNG VIỆC | C1: N/T/N | E1: KL/T.tế (m3) | F1: Tuổi Bt | H1: 30Mpa-18±2 (Cọc nhồi) | K1: 30Mpa-14±2 (Bệ, thân, mố, trụ, dầm) | N1: Khối lượng vật tư lũy kế | Q1: Tần suất lấy mẫu thí nghiệm | T1: Số lô | U1: KL (Tấn) | AK1: NGUỒN BẢN VẼ / NGHI VẤN (soát & ghim)
F2: R7 | G2: R28 | H2: Xi măng 0,445 | I2: Cát 0,525 | J2: Đá 0,696 | K2: Xi măng 0,425 | L2: Cát 0,555 | M2: Đá 0,700 | N2: Xi măng (Tấn) | O2: Cát (m3) | P2: Đá (m3) | Q2: Xi măng 50 tấn Lần | R2: Cát 200m3 Lần | S2: Đá 350m3 Lần
A3: I. HẠNG MỤC CỌC KHOAN NHỒI D1.2M (C30 ĐỘ SỤT 18±2CM) - 26 CỌC (L=872M) | AF3: Mã hiệu | AG3: Xi măng | AH3: Đơn vị Xm | AI3: KL riêng XM | AJ3: Nguồn gốc
A4: 1 | B4: Bê tông cọc khoan nhồi - C5 trụ T1 (L=40m) | C4: 46180 | D4: =MIN(C4:C29) | E4: 45.88 | F4: =IF(C4="","",C4+7) | G4: =IF(C4="","",C4+28) | H4: 0.445 | I4: 0.525 | J4: 0.696 | N4: =IF(E4="","",ROUND(IF(H4>0,E4*H4,E4*K4),2)) | O4: =IF(E4="","",ROUND(IF(I4>0,E4*I4,E4*L4),2)) | P4: =IF(E4="","",ROUND(IF(J4>0,E4*J4,E4*M4),2)) | Q4: =IF(N4="","",IF(ROUNDUP(N4/50,0)>0,"Lần " & ROUNDUP(N4/50,0),"")) | R4: =IF(O4="","",IF(ROUNDUP(O4/200,0)>0,"Lần " & ROUNDUP(O4/200,0),"")) | S4: =IF(P4="","",IF(ROUNDUP(P4/350,0)>0,"Lần " & ROUNDUP(P4/350,0),"")) | AF4: BTXMC10R28 | AG4: 235 | AH4: Tân | AI4: 3.1500001 | AJ4: Hà Tiên PCB40 | AK4: Bản vẽ: 47,01 → 45,88 m³ (tr.68 thể tích 1 cọc (đã gồm bê tông đầu cọc)). File cũ cộng thêm 1,13 m³ đập đầu cọc vào thể tích đã gồm đầu cọc. Cột 'KL thực tế': thay bằng phiếu đổ (có nở thành) khi có.
A5: 2 | B5: Bê tông cọc khoan nhồi - C8 trụ T2 (L=30m) | C5: 46208 | D5: =MAX(C4:C29) | E5: 34.73 | F5: =IF(C5="","",C5+7) | G5: =IF(C5="","",C5+28) | H5: 0.445 | I5: 0.525 | J5: 0.696 | N5: =IF(E5="","",ROUND(N4+IF(H5>0,E5*H5,E5*K5),2)) | O5: =IF(E5="","",ROUND(O4+IF(I5>0,E5*I5,E5*L5),2)) | P5: =IF(E5="","",ROUND(P4+IF(J5>0,E5*J5,E5*M5),2)) | Q5: =IF(N5="","",IF(ROUNDUP(N5/50,0)>ROUNDUP(N4/50,0),"Lần " & ROUNDUP(N5/50,0),"")) | R5: =IF(O5="","",IF(ROUNDUP(O5/200,0)>ROUNDUP(O4/200,0),"Lần " & ROUNDUP(O5/200,0),"")) | S5: =IF(P5="","",IF(ROUNDUP(P5/350,0)>ROUNDUP(P4/350,0),"Lần " & ROUNDUP(P5/350,0),"")) | AF5: BTXMC20R28 | AG5: 310 | AH5: Tân | AI5: 3.1500001 | AJ5: Hà Tiên PCB40 | AK5: Bản vẽ: 35,86 → 34,73 m³ (tr.70 thể tích 1 cọc (đã gồm bê tông đầu cọc)). File cũ cộng thêm 1,13 m³ đập đầu cọc. Thay bằng phiếu đổ thực tế khi có.
A6: 3 | B6: Bê tông cọc khoan nhồi - C1 trụ T1 (L=40m) | C6: 46209 | E6: 45.88 | F6: =IF(C6="","",C6+7) | G6: =IF(C6="","",C6+28) | H6: 0.445 | I6: 0.525 | J6: 0.696 | N6: =IF(E6="","",ROUND(N5+IF(H6>0,E6*H6,E6*K6),2)) | O6: =IF(E6="","",ROUND(O5+IF(I6>0,E6*I6,E6*L6),2)) | P6: =IF(E6="","",ROUND(P5+IF(J6>0,E6*J6,E6*M6),2)) | Q6: =IF(N6="","",IF(ROUNDUP(N6/50,0)>ROUNDUP(N5/50,0),"Lần " & ROUNDUP(N6/50,0),"")) | R6: =IF(O6="","",IF(ROUNDUP(O6/200,0)>ROUNDUP(O5/200,0),"Lần " & ROUNDUP(O6/200,0),"")) | S6: =IF(P6="","",IF(ROUNDUP(P6/350,0)>ROUNDUP(P5/350,0),"Lần " & ROUNDUP(P6/350,0),"")) | AF6: BTXMC40BSF | AG6: 449 | AH6: Tấn | AI6: 3.0999999 | AJ6: Hà Tiên PCMSR40 | AK6: Bản vẽ: 47,01 → 45,88 m³ (tr.68 thể tích 1 cọc (đã gồm bê tông đầu cọc)). File cũ cộng thêm 1,13 m³ đập đầu cọc vào thể tích đã gồm đầu cọc. Cột 'KL thực tế': thay bằng phiếu đổ (có nở thành) khi có.
A7: 4 | B7: Bê tông cọc khoan nhồi - C7 trụ T2 (L=30m) | C7: 46210 | E7: 34.73 | F7: =IF(C7="","",C7+7) | G7: =IF(C7="","",C7+28) | H7: 0.445 | I7: 0.525 | J7: 0.696 | N7: =IF(E7="","",ROUND(N6+IF(H7>0,E7*H7,E7*K7),2)) | O7: =IF(E7="","",ROUND(O6+IF(I7>0,E7*I7,E7*L7),2)) | P7: =IF(E7="","",ROUND(P6+IF(J7>0,E7*J7,E7*M7),2)) | Q7: =IF(N7="","",IF(ROUNDUP(N7/50,0)>ROUNDUP(N6/50,0),"Lần " & ROUNDUP(N7/50,0),"")) | R7: =IF(O7="","",IF(ROUNDUP(O7/200,0)>ROUNDUP(O6/200,0),"Lần " & ROUNDUP(O7/200,0),"")) | S7: =IF(P7="","",IF(ROUNDUP(P7/350,0)>ROUNDUP(P6/350,0),"Lần " & ROUNDUP(P7/350,0),"")) | AF7: BTXMC30R28W10 | AG7: 409 | AH7: Tân | AI7: 3.1500001 | AJ7: Hà Tiên PCB40 | AK7: Bản vẽ: 35,86 → 34,73 m³ (tr.70 thể tích 1 cọc (đã gồm bê tông đầu cọc)). File cũ cộng thêm 1,13 m³ đập đầu cọc. Thay bằng phiếu đổ thực tế khi có.
A8: 5 | B8: Bê tông cọc khoan nhồi - C2 trụ T1 (L=40m) | C8: 46211 | E8: 45.88 | F8: =IF(C8="","",C8+7) | G8: =IF(C8="","",C8+28) | H8: 0.445 | I8: 0.525 | J8: 0.696 | N8: =IF(E8="","",ROUND(N7+IF(H8>0,E8*H8,E8*K8),2)) | O8: =IF(E8="","",ROUND(O7+IF(I8>0,E8*I8,E8*L8),2)) | P8: =IF(E8="","",ROUND(P7+IF(J8>0,E8*J8,E8*M8),2)) | Q8: =IF(N8="","",IF(ROUNDUP(N8/50,0)>ROUNDUP(N7/50,0),"Lần " & ROUNDUP(N8/50,0),"")) | R8: =IF(O8="","",IF(ROUNDUP(O8/200,0)>ROUNDUP(O7/200,0),"Lần " & ROUNDUP(O8/200,0),"")) | S8: =IF(P8="","",IF(ROUNDUP(P8/350,0)>ROUNDUP(P7/350,0),"Lần " & ROUNDUP(P8/350,0),"")) | AF8: BTXMC35R7W10 | AG8: 459 | AH8: Tân | AI8: 3.1500001 | AJ8: Hà Tiên PCB40 | AK8: Bản vẽ: 47,01 → 45,88 m³ (tr.68 thể tích 1 cọc (đã gồm bê tông đầu cọc)). File cũ cộng thêm 1,13 m³ đập đầu cọc vào thể tích đã gồm đầu cọc. Cột 'KL thực tế': thay bằng phiếu đổ (có nở thành) khi có.
A9: 6 | B9: Bê tông cọc khoan nhồi - C6 trụ T2 (L=30m) | C9: 46212 | E9: 34.73 | F9: =IF(C9="","",C9+7) | G9: =IF(C9="","",C9+28) | H9: 0.445 | I9: 0.525 | J9: 0.696 | N9: =IF(E9="","",ROUND(N8+IF(H9>0,E9*H9,E9*K9),2)) | O9: =IF(E9="","",ROUND(O8+IF(I9>0,E9*I9,E9*L9),2)) | P9: =IF(E9="","",ROUND(P8+IF(J9>0,E9*J9,E9*M9),2)) | Q9: =IF(N9="","",IF(ROUNDUP(N9/50,0)>ROUNDUP(N8/50,0),"Lần " & ROUNDUP(N9/50,0),"")) | R9: =IF(O9="","",IF(ROUNDUP(O9/200,0)>ROUNDUP(O8/200,0),"Lần " & ROUNDUP(O9/200,0),"")) | S9: =IF(P9="","",IF(ROUNDUP(P9/350,0)>ROUNDUP(P8/350,0),"Lần " & ROUNDUP(P9/350,0),"")) | AF9: BTXMC35 R7W10BSF | AG9: 459 | AH9: Tấn | AI9: 3.0999999 | AJ9: Hà Tiên PCMSR40 | AK9: Bản vẽ: 35,86 → 34,73 m³ (tr.70 thể tích 1 cọc (đã gồm bê tông đầu cọc)). File cũ cộng thêm 1,13 m³ đập đầu cọc. Thay bằng phiếu đổ thực tế khi có.
A10: 7 | B10: Bê tông cọc khoan nhồi - C3 trụ T1 (L=40m) | C10: 46213 | E10: 45.88 | F10: =IF(C10="","",C10+7) | G10: =IF(C10="","",C10+28) | H10: 0.445 | I10: 0.525 | J10: 0.696 | N10: =IF(E10="","",ROUND(N9+IF(H10>0,E10*H10,E10*K10),2)) | O10: =IF(E10="","",ROUND(O9+IF(I10>0,E10*I10,E10*L10),2)) | P10: =IF(E10="","",ROUND(P9+IF(J10>0,E10*J10,E10*M10),2)) | Q10: =IF(N10="","",IF(ROUNDUP(N10/50,0)>ROUNDUP(N9/50,0),"Lần " & ROUNDUP(N10/50,0),"")) | R10: =IF(O10="","",IF(ROUNDUP(O10/200,0)>ROUNDUP(O9/200,0),"Lần " & ROUNDUP(O10/200,0),"")) | S10: =IF(P10="","",IF(ROUNDUP(P10/350,0)>ROUNDUP(P9/350,0),"Lần " & ROUNDUP(P10/350,0),"")) | AF10: BTXMC10R7 | AG10: 285 | AH10: Tấn | AI10: 3.1500001 | AJ10: Hà Tiên PCB40 | AK10: Bản vẽ: 47,01 → 45,88 m³ (tr.68 thể tích 1 cọc (đã gồm bê tông đầu cọc)). File cũ cộng thêm 1,13 m³ đập đầu cọc vào thể tích đã gồm đầu cọc. Cột 'KL thực tế': thay bằng phiếu đổ (có nở thành) khi có.
A11: 8 | B11: Bê tông cọc khoan nhồi - C5 trụ T2 (L=30m) | C11: 46214 | E11: 34.73 | F11: =IF(C11="","",C11+7) | G11: =IF(C11="","",C11+28) | H11: 0.445 | I11: 0.525 | J11: 0.696 | N11: =IF(E11="","",ROUND(N10+IF(H11>0,E11*H11,E11*K11),2)) | O11: =IF(E11="","",ROUND(O10+IF(I11>0,E11*I11,E11*L11),2)) | P11: =IF(E11="","",ROUND(P10+IF(J11>0,E11*J11,E11*M11),2)) | Q11: =IF(N11="","",IF(ROUNDUP(N11/50,0)>ROUNDUP(N10/50,0),"Lần " & ROUNDUP(N11/50,0),"")) | R11: =IF(O11="","",IF(ROUNDUP(O11/200,0)>ROUNDUP(O10/200,0),"Lần " & ROUNDUP(O11/200,0),"")) | S11: =IF(P11="","",IF(ROUNDUP(P11/350,0)>ROUNDUP(P10/350,0),"Lần " & ROUNDUP(P11/350,0),"")) | AF11: BTXMC20R7 | AG11: 365 | AH11: Tân | AI11: 3.1500001 | AJ11: Hà Tiên PCB40 | AK11: Bản vẽ: 35,86 → 34,73 m³ (tr.70 thể tích 1 cọc (đã gồm bê tông đầu cọc)). File cũ cộng thêm 1,13 m³ đập đầu cọc. Thay bằng phiếu đổ thực tế khi có.
A12: 9 | B12: Bê tông cọc khoan nhồi - C4 trụ T1 (L=40m) | C12: 46215 | E12: 45.88 | F12: =IF(C12="","",C12+7) | G12: =IF(C12="","",C12+28) | H12: 0.445 | I12: 0.525 | J12: 0.696 | N12: =IF(E12="","",ROUND(N11+IF(H12>0,E12*H12,E12*K12),2)) | O12: =IF(E12="","",ROUND(O11+IF(I12>0,E12*I12,E12*L12),2)) | P12: =IF(E12="","",ROUND(P11+IF(J12>0,E12*J12,E12*M12),2)) | Q12: =IF(N12="","",IF(ROUNDUP(N12/50,0)>ROUNDUP(N11/50,0),"Lần " & ROUNDUP(N12/50,0),"")) | R12: =IF(O12="","",IF(ROUNDUP(O12/200,0)>ROUNDUP(O11/200,0),"Lần " & ROUNDUP(O12/200,0),"")) | S12: =IF(P12="","",IF(ROUNDUP(P12/350,0)>ROUNDUP(P11/350,0),"Lần " & ROUNDUP(P12/350,0),"")) | AK12: Bản vẽ: 47,01 → 45,88 m³ (tr.68 thể tích 1 cọc (đã gồm bê tông đầu cọc)). File cũ cộng thêm 1,13 m³ đập đầu cọc vào thể tích đã gồm đầu cọc. Cột 'KL thực tế': thay bằng phiếu đổ (có nở thành) khi có.
A13: 10 | B13: Bê tông cọc khoan nhồi - C4 trụ T2 (L=30m) | C13: 46216 | E13: 34.73 | F13: =IF(C13="","",C13+7) | G13: =IF(C13="","",C13+28) | H13: 0.445 | I13: 0.525 | J13: 0.696 | N13: =IF(E13="","",ROUND(N12+IF(H13>0,E13*H13,E13*K13),2)) | O13: =IF(E13="","",ROUND(O12+IF(I13>0,E13*I13,E13*L13),2)) | P13: =IF(E13="","",ROUND(P12+IF(J13>0,E13*J13,E13*M13),2)) | Q13: =IF(N13="","",IF(ROUNDUP(N13/50,0)>ROUNDUP(N12/50,0),"Lần " & ROUNDUP(N13/50,0),"")) | R13: =IF(O13="","",IF(ROUNDUP(O13/200,0)>ROUNDUP(O12/200,0),"Lần " & ROUNDUP(O13/200,0),"")) | S13: =IF(P13="","",IF(ROUNDUP(P13/350,0)>ROUNDUP(P12/350,0),"Lần " & ROUNDUP(P13/350,0),"")) | AK13: Bản vẽ: 35,86 → 34,73 m³ (tr.70 thể tích 1 cọc (đã gồm bê tông đầu cọc)). File cũ cộng thêm 1,13 m³ đập đầu cọc. Thay bằng phiếu đổ thực tế khi có.
A14: 11 | B14: Bê tông cọc khoan nhồi - C6 trụ T1 (L=40m) | C14: 46217 | E14: 45.88 | F14: =IF(C14="","",C14+7) | G14: =IF(C14="","",C14+28) | H14: 0.445 | I14: 0.525 | J14: 0.696 | N14: =IF(E14="","",ROUND(N13+IF(H14>0,E14*H14,E14*K14),2)) | O14: =IF(E14="","",ROUND(O13+IF(I14>0,E14*I14,E14*L14),2)) | P14: =IF(E14="","",ROUND(P13+IF(J14>0,E14*J14,E14*M14),2)) | Q14: =IF(N14="","",IF(ROUNDUP(N14/50,0)>ROUNDUP(N13/50,0),"Lần " & ROUNDUP(N14/50,0),"")) | R14: =IF(O14="","",IF(ROUNDUP(O14/200,0)>ROUNDUP(O13/200,0),"Lần " & ROUNDUP(O14/200,0),"")) | S14: =IF(P14="","",IF(ROUNDUP(P14/350,0)>ROUNDUP(P13/350,0),"Lần " & ROUNDUP(P14/350,0),"")) | AK14: Bản vẽ: 47,01 → 45,88 m³ (tr.68 thể tích 1 cọc (đã gồm bê tông đầu cọc)). File cũ cộng thêm 1,13 m³ đập đầu cọc vào thể tích đã gồm đầu cọc. Cột 'KL thực tế': thay bằng phiếu đổ (có nở thành) khi có.
A15: 12 | B15: Bê tông cọc khoan nhồi - C3 trụ T2 (L=30m) | C15: 46218 | E15: 34.73 | F15: =IF(C15="","",C15+7) | G15: =IF(C15="","",C15+28) | H15: 0.445 | I15: 0.525 | J15: 0.696 | N15: =IF(E15="","",ROUND(N14+IF(H15>0,E15*H15,E15*K15),2)) | O15: =IF(E15="","",ROUND(O14+IF(I15>0,E15*I15,E15*L15),2)) | P15: =IF(E15="","",ROUND(P14+IF(J15>0,E15*J15,E15*M15),2)) | Q15: =IF(N15="","",IF(ROUNDUP(N15/50,0)>ROUNDUP(N14/50,0),"Lần " & ROUNDUP(N15/50,0),"")) | R15: =IF(O15="","",IF(ROUNDUP(O15/200,0)>ROUNDUP(O14/200,0),"Lần " & ROUNDUP(O15/200,0),"")) | S15: =IF(P15="","",IF(ROUNDUP(P15/350,0)>ROUNDUP(P14/350,0),"Lần " & ROUNDUP(P15/350,0),"")) | AK15: Bản vẽ: 35,86 → 34,73 m³ (tr.70 thể tích 1 cọc (đã gồm bê tông đầu cọc)). File cũ cộng thêm 1,13 m³ đập đầu cọc. Thay bằng phiếu đổ thực tế khi có.
A16: 13 | B16: Bê tông cọc khoan nhồi - C7 trụ T1 (L=40m) | C16: 46219 | E16: 45.88 | F16: =IF(C16="","",C16+7) | G16: =IF(C16="","",C16+28) | H16: 0.445 | I16: 0.525 | J16: 0.696 | N16: =IF(E16="","",ROUND(N15+IF(H16>0,E16*H16,E16*K16),2)) | O16: =IF(E16="","",ROUND(O15+IF(I16>0,E16*I16,E16*L16),2)) | P16: =IF(E16="","",ROUND(P15+IF(J16>0,E16*J16,E16*M16),2)) | Q16: =IF(N16="","",IF(ROUNDUP(N16/50,0)>ROUNDUP(N15/50,0),"Lần " & ROUNDUP(N16/50,0),"")) | R16: =IF(O16="","",IF(ROUNDUP(O16/200,0)>ROUNDUP(O15/200,0),"Lần " & ROUNDUP(O16/200,0),"")) | S16: =IF(P16="","",IF(ROUNDUP(P16/350,0)>ROUNDUP(P15/350,0),"Lần " & ROUNDUP(P16/350,0),"")) | AK16: Bản vẽ: 47,01 → 45,88 m³ (tr.68 thể tích 1 cọc (đã gồm bê tông đầu cọc)). File cũ cộng thêm 1,13 m³ đập đầu cọc vào thể tích đã gồm đầu cọc. Cột 'KL thực tế': thay bằng phiếu đổ (có nở thành) khi có.
A17: 14 | B17: Bê tông cọc khoan nhồi - C2 trụ T2 (L=30m) | C17: 46220 | E17: 34.73 | F17: =IF(C17="","",C17+7) | G17: =IF(C17="","",C17+28) | H17: 0.445 | I17: 0.525 | J17: 0.696 | N17: =IF(E17="","",ROUND(N16+IF(H17>0,E17*H17,E17*K17),2)) | O17: =IF(E17="","",ROUND(O16+IF(I17>0,E17*I17,E17*L17),2)) | P17: =IF(E17="","",ROUND(P16+IF(J17>0,E17*J17,E17*M17),2)) | Q17: =IF(N17="","",IF(ROUNDUP(N17/50,0)>ROUNDUP(N16/50,0),"Lần " & ROUNDUP(N17/50,0),"")) | R17: =IF(O17="","",IF(ROUNDUP(O17/200,0)>ROUNDUP(O16/200,0),"Lần " & ROUNDUP(O17/200,0),"")) | S17: =IF(P17="","",IF(ROUNDUP(P17/350,0)>ROUNDUP(P16/350,0),"Lần " & ROUNDUP(P17/350,0),"")) | AK17: Bản vẽ: 35,86 → 34,73 m³ (tr.70 thể tích 1 cọc (đã gồm bê tông đầu cọc)). File cũ cộng thêm 1,13 m³ đập đầu cọc. Thay bằng phiếu đổ thực tế khi có.
A18: 15 | B18: Bê tông cọc khoan nhồi - C8 trụ T1 (L=40m) | C18: 46221 | E18: 45.88 | F18: =IF(C18="","",C18+7) | G18: =IF(C18="","",C18+28) | H18: 0.445 | I18: 0.525 | J18: 0.696 | N18: =IF(E18="","",ROUND(N17+IF(H18>0,E18*H18,E18*K18),2)) | O18: =IF(E18="","",ROUND(O17+IF(I18>0,E18*I18,E18*L18),2)) | P18: =IF(E18="","",ROUND(P17+IF(J18>0,E18*J18,E18*M18),2)) | Q18: =IF(N18="","",IF(ROUNDUP(N18/50,0)>ROUNDUP(N17/50,0),"Lần " & ROUNDUP(N18/50,0),"")) | R18: =IF(O18="","",IF(ROUNDUP(O18/200,0)>ROUNDUP(O17/200,0),"Lần " & ROUNDUP(O18/200,0),"")) | S18: =IF(P18="","",IF(ROUNDUP(P18/350,0)>ROUNDUP(P17/350,0),"Lần " & ROUNDUP(P18/350,0),"")) | AK18: Bản vẽ: 47,01 → 45,88 m³ (tr.68 thể tích 1 cọc (đã gồm bê tông đầu cọc)). File cũ cộng thêm 1,13 m³ đập đầu cọc vào thể tích đã gồm đầu cọc. Cột 'KL thực tế': thay bằng phiếu đổ (có nở thành) khi có.
A19: 16 | B19: Bê tông cọc khoan nhồi - C1 trụ T2 (L=30m) | C19: 46222 | E19: 34.73 | F19: =IF(C19="","",C19+7) | G19: =IF(C19="","",C19+28) | H19: 0.445 | I19: 0.525 | J19: 0.696 | N19: =IF(E19="","",ROUND(N18+IF(H19>0,E19*H19,E19*K19),2)) | O19: =IF(E19="","",ROUND(O18+IF(I19>0,E19*I19,E19*L19),2)) | P19: =IF(E19="","",ROUND(P18+IF(J19>0,E19*J19,E19*M19),2)) | Q19: =IF(N19="","",IF(ROUNDUP(N19/50,0)>ROUNDUP(N18/50,0),"Lần " & ROUNDUP(N19/50,0),"")) | R19: =IF(O19="","",IF(ROUNDUP(O19/200,0)>ROUNDUP(O18/200,0),"Lần " & ROUNDUP(O19/200,0),"")) | S19: =IF(P19="","",IF(ROUNDUP(P19/350,0)>ROUNDUP(P18/350,0),"Lần " & ROUNDUP(P19/350,0),"")) | AK19: Bản vẽ: 35,86 → 34,73 m³ (tr.70 thể tích 1 cọc (đã gồm bê tông đầu cọc)). File cũ cộng thêm 1,13 m³ đập đầu cọc. Thay bằng phiếu đổ thực tế khi có.
A20: 17 | B20: Bê tông cọc khoan nhồi - C7 mố M2 (L=36m) | C20: 46223 | E20: 41.56 | F20: =IF(C20="","",C20+7) | G20: =IF(C20="","",C20+28) | H20: 0.445 | I20: 0.525 | J20: 0.696 | N20: =IF(E20="","",ROUND(N19+IF(H20>0,E20*H20,E20*K20),2)) | O20: =IF(E20="","",ROUND(O19+IF(I20>0,E20*I20,E20*L20),2)) | P20: =IF(E20="","",ROUND(P19+IF(J20>0,E20*J20,E20*M20),2)) | Q20: =IF(N20="","",IF(ROUNDUP(N20/50,0)>ROUNDUP(N19/50,0),"Lần " & ROUNDUP(N20/50,0),"")) | R20: =IF(O20="","",IF(ROUNDUP(O20/200,0)>ROUNDUP(O19/200,0),"Lần " & ROUNDUP(O20/200,0),"")) | S20: =IF(P20="","",IF(ROUNDUP(P20/350,0)>ROUNDUP(P19/350,0),"Lần " & ROUNDUP(P20/350,0),"")) | AK20: Bản vẽ: 42,83 → 41,56 m³ (tr.66 thể tích 1 cọc (đã gồm bê tông đầu cọc)). File cũ cộng thêm 1,27 m³ đập đầu cọc. Thay bằng phiếu đổ thực tế khi có.
A21: 18 | B21: Bê tông cọc khoan nhồi - C5 mố M2 (L=36m) | C21: 46224 | E21: 41.56 | F21: =IF(C21="","",C21+7) | G21: =IF(C21="","",C21+28) | H21: 0.445 | I21: 0.525 | J21: 0.696 | N21: =IF(E21="","",ROUND(N20+IF(H21>0,E21*H21,E21*K21),2)) | O21: =IF(E21="","",ROUND(O20+IF(I21>0,E21*I21,E21*L21),2)) | P21: =IF(E21="","",ROUND(P20+IF(J21>0,E21*J21,E21*M21),2)) | Q21: =IF(N21="","",IF(ROUNDUP(N21/50,0)>ROUNDUP(N20/50,0),"Lần " & ROUNDUP(N21/50,0),"")) | R21: =IF(O21="","",IF(ROUNDUP(O21/200,0)>ROUNDUP(O20/200,0),"Lần " & ROUNDUP(O21/200,0),"")) | S21: =IF(P21="","",IF(ROUNDUP(P21/350,0)>ROUNDUP(P20/350,0),"Lần " & ROUNDUP(P21/350,0),"")) | AK21: Bản vẽ: 42,83 → 41,56 m³ (tr.66 thể tích 1 cọc (đã gồm bê tông đầu cọc)). File cũ cộng thêm 1,27 m³ đập đầu cọc. Thay bằng phiếu đổ thực tế khi có.
A22: 19 | B22: Bê tông cọc khoan nhồi - C3 mố M2 (L=36m) | C22: 46225 | E22: 41.56 | F22: =IF(C22="","",C22+7) | G22: =IF(C22="","",C22+28) | H22: 0.445 | I22: 0.525 | J22: 0.696 | N22: =IF(E22="","",ROUND(N21+IF(H22>0,E22*H22,E22*K22),2)) | O22: =IF(E22="","",ROUND(O21+IF(I22>0,E22*I22,E22*L22),2)) | P22: =IF(E22="","",ROUND(P21+IF(J22>0,E22*J22,E22*M22),2)) | Q22: =IF(N22="","",IF(ROUNDUP(N22/50,0)>ROUNDUP(N21/50,0),"Lần " & ROUNDUP(N22/50,0),"")) | R22: =IF(O22="","",IF(ROUNDUP(O22/200,0)>ROUNDUP(O21/200,0),"Lần " & ROUNDUP(O22/200,0),"")) | S22: =IF(P22="","",IF(ROUNDUP(P22/350,0)>ROUNDUP(P21/350,0),"Lần " & ROUNDUP(P22/350,0),"")) | AK22: Bản vẽ: 42,83 → 41,56 m³ (tr.66 thể tích 1 cọc (đã gồm bê tông đầu cọc)). File cũ cộng thêm 1,27 m³ đập đầu cọc. Thay bằng phiếu đổ thực tế khi có.
A23: 20 | B23: Bê tông cọc khoan nhồi - C4 mố M2 (L=36m) | C23: 46226 | E23: 41.56 | F23: =IF(C23="","",C23+7) | G23: =IF(C23="","",C23+28) | H23: 0.445 | I23: 0.525 | J23: 0.696 | N23: =IF(E23="","",ROUND(N22+IF(H23>0,E23*H23,E23*K23),2)) | O23: =IF(E23="","",ROUND(O22+IF(I23>0,E23*I23,E23*L23),2)) | P23: =IF(E23="","",ROUND(P22+IF(J23>0,E23*J23,E23*M23),2)) | Q23: =IF(N23="","",IF(ROUNDUP(N23/50,0)>ROUNDUP(N22/50,0),"Lần " & ROUNDUP(N23/50,0),"")) | R23: =IF(O23="","",IF(ROUNDUP(O23/200,0)>ROUNDUP(O22/200,0),"Lần " & ROUNDUP(O23/200,0),"")) | S23: =IF(P23="","",IF(ROUNDUP(P23/350,0)>ROUNDUP(P22/350,0),"Lần " & ROUNDUP(P23/350,0),"")) | AK23: Bản vẽ: 42,83 → 41,56 m³ (tr.66 thể tích 1 cọc (đã gồm bê tông đầu cọc)). File cũ cộng thêm 1,27 m³ đập đầu cọc. Thay bằng phiếu đổ thực tế khi có.
... A29: 26 | B29: Bê tông cọc khoan nhồi - C2 mố M1 (L=20m) | C29: 46232 | E29: 23.58 | F29: =IF(C29="","",C29+7) | G29: =IF(C29="","",C29+28) | H29: 0.445 | I29: 0.525 | J29: 0.696 | N29: =IF(E29="","",ROUND(N28+IF(H29>0,E29*H29,E29*K29),2)) | O29: =IF(E29="","",ROUND(O28+IF(I29>0,E29*I29,E29*L29),2)) | P29: =IF(E29="","",ROUND(P28+IF(J29>0,E29*J29,E29*M29),2)) | Q29: =IF(N29="","",IF(ROUNDUP(N29/50,0)>ROUNDUP(N28/50,0),"Lần " & ROUNDUP(N29/50,0),"")) | R29: =IF(O29="","",IF(ROUNDUP(O29/200,0)>ROUNDUP(O28/200,0),"Lần " & ROUNDUP(O29/200,0),"")) | S29: =IF(P29="","",IF(ROUNDUP(P29/350,0)>ROUNDUP(P28/350,0),"Lần " & ROUNDUP(P29/350,0),"")) | AK29: Bản vẽ: 24,71 → 23,58 m³ (tr.64 thể tích 1 cọc (đã gồm bê tông đầu cọc)). File cũ cộng thêm 1,13 m³ đập đầu cọc. Thay bằng phiếu đổ thực tế khi có.
A30: II. HẠNG MỤC BÊ TÔNG BỆ MỐ & BỆ TRỤ (C30 ĐỘ SỤT 14±2CM)
A31: 27 | B31: Bê tông lót móng bệ mố M1 (M100 đá 4x6) | C31: =IF('Danh mục công việc'!$S$1251="","",'Danh mục công việc'!$S$1251) | E31: 2.46 | F31: =IF(C31="","",C31+7) | G31: =IF(C31="","",C31+28) | K31: 0.425 | L31: 0.555 | M31: 0.7 | N31: =IF(E31="","",ROUND(N29+IF(H31>0,E31*H31,E31*K31),2)) | O31: =IF(E31="","",ROUND(O29+IF(I31>0,E31*I31,E31*L31),2)) | P31: =IF(E31="","",ROUND(P29+IF(J31>0,E31*J31,E31*M31),2)) | Q31: =IF(N31="","",IF(ROUNDUP(N31/50,0)>ROUNDUP(N29/50,0),"Lần " & ROUNDUP(N31/50,0),"")) | R31: =IF(O31="","",IF(ROUNDUP(O31/200,0)>ROUNDUP(O29/200,0),"Lần " & ROUNDUP(O31/200,0),"")) | S31: =IF(P31="","",IF(ROUNDUP(P31/350,0)>ROUNDUP(P29/350,0),"Lần " & ROUNDUP(P31/350,0),"")) | AK31: Khớp bản vẽ (tr.31 bê tông đệm C10) | Mác M100 chưa có cấp phối riêng — đang dùng cấp phối C30 (0,425 t XM; 0,555 m³ cát; 0,700 m³ đá / m³). Nhập cấp phối được duyệt.
A32: 28 | B32: Bê tông tường thân mố M1 (C30 đá 1x2) | C32: =IF('Danh mục công việc'!$S$1261="","",'Danh mục công việc'!$S$1261) | E32: 52.96 | F32: =IF(C32="","",C32+7) | G32: =IF(C32="","",C32+28) | K32: 0.425 | L32: 0.555 | M32: 0.7 | N32: =IF(E32="","",ROUND(N31+IF(H32>0,E32*H32,E32*K32),2)) | O32: =IF(E32="","",ROUND(O31+IF(I32>0,E32*I32,E32*L32),2)) | P32: =IF(E32="","",ROUND(P31+IF(J32>0,E32*J32,E32*M32),2)) | Q32: =IF(N32="","",IF(ROUNDUP(N32/50,0)>ROUNDUP(N31/50,0),"Lần " & ROUNDUP(N32/50,0),"")) | R32: =IF(O32="","",IF(ROUNDUP(O32/200,0)>ROUNDUP(O31/200,0),"Lần " & ROUNDUP(O32/200,0),"")) | S32: =IF(P32="","",IF(ROUNDUP(P32/350,0)>ROUNDUP(P31/350,0),"Lần " & ROUNDUP(P32/350,0),"")) | AK32: Khớp bản vẽ (tr.31 tường thân mố M1)
A33: 29 | B33: Bê tông lót móng bệ trụ T1 (M100 đá 4x6) | C33: =IF('Danh mục công việc'!S1185="","",'Danh mục công việc'!S1185) | E33: 8.77 | F33: =IF(C33="","",C33+7) | G33: =IF(C33="","",C33+28) | K33: 0.425 | L33: 0.555 | M33: 0.7 | N33: =IF(E33="","",ROUND(N32+IF(H33>0,E33*H33,E33*K33),2)) | O33: =IF(E33="","",ROUND(O32+IF(I33>0,E33*I33,E33*L33),2)) | P33: =IF(E33="","",ROUND(P32+IF(J33>0,E33*J33,E33*M33),2)) | Q33: =IF(N33="","",IF(ROUNDUP(N33/50,0)>ROUNDUP(N32/50,0),"Lần " & ROUNDUP(N33/50,0),"")) | R33: =IF(O33="","",IF(ROUNDUP(O33/200,0)>ROUNDUP(O32/200,0),"Lần " & ROUNDUP(O33/200,0),"")) | S33: =IF(P33="","",IF(ROUNDUP(P33/350,0)>ROUNDUP(P32/350,0),"Lần " & ROUNDUP(P33/350,0),"")) | AK33: Khớp bản vẽ (tr.44 bê tông đệm C10) | Mác M100 chưa có cấp phối riêng — đang dùng cấp phối C30 (0,425 t XM; 0,555 m³ cát; 0,700 m³ đá / m³). Nhập cấp phối được duyệt.
A34: 30 | B34: Bê tông bệ trụ T1 - Đợt 1 (C30 đá 1x2) | C34: =IF('Danh mục công việc'!S1197="","",'Danh mục công việc'!S1197) | E34: 92.12 | F34: =IF(C34="","",C34+7) | G34: =IF(C34="","",C34+28) | K34: 0.425 | L34: 0.555 | M34: 0.7 | N34: =IF(E34="","",ROUND(N33+IF(H34>0,E34*H34,E34*K34),2)) | O34: =IF(E34="","",ROUND(O33+IF(I34>0,E34*I34,E34*L34),2)) | P34: =IF(E34="","",ROUND(P33+IF(J34>0,E34*J34,E34*M34),2)) | Q34: =IF(N34="","",IF(ROUNDUP(N34/50,0)>ROUNDUP(N33/50,0),"Lần " & ROUNDUP(N34/50,0),"")) | R34: =IF(O34="","",IF(ROUNDUP(O34/200,0)>ROUNDUP(O33/200,0),"Lần " & ROUNDUP(O34/200,0),"")) | S34: =IF(P34="","",IF(ROUNDUP(P34/350,0)>ROUNDUP(P33/350,0),"Lần " & ROUNDUP(P34/350,0),"")) | AK34: Khớp bản vẽ (tr.44 bệ trụ T1, chia theo tỷ lệ 2 đợt cũ)
A35: 31 | B35: Bê tông bệ trụ T1 - Đợt 2 (C30 đá 1x2) | C35: =IF('Danh mục công việc'!S1197="","",'Danh mục công việc'!S1197) | E35: 92.12 | F35: =IF(C35="","",C35+7) | G35: =IF(C35="","",C35+28) | K35: 0.425 | L35: 0.555 | M35: 0.7 | N35: =IF(E35="","",ROUND(N34+IF(H35>0,E35*H35,E35*K35),2)) | O35: =IF(E35="","",ROUND(O34+IF(I35>0,E35*I35,E35*L35),2)) | P35: =IF(E35="","",ROUND(P34+IF(J35>0,E35*J35,E35*M35),2)) | Q35: =IF(N35="","",IF(ROUNDUP(N35/50,0)>ROUNDUP(N34/50,0),"Lần " & ROUNDUP(N35/50,0),"")) | R35: =IF(O35="","",IF(ROUNDUP(O35/200,0)>ROUNDUP(O34/200,0),"Lần " & ROUNDUP(O35/200,0),"")) | S35: =IF(P35="","",IF(ROUNDUP(P35/350,0)>ROUNDUP(P34/350,0),"Lần " & ROUNDUP(P35/350,0),"")) | AK35: Khớp bản vẽ (tr.44 bệ trụ T1, chia theo tỷ lệ 2 đợt cũ)
A36: 32 | B36: Bê tông lót móng bệ trụ T2 (M100 đá 4x6) | C36: =IF('Danh mục công việc'!S1219="","",'Danh mục công việc'!S1219) | E36: 8.77 | F36: =IF(C36="","",C36+7) | G36: =IF(C36="","",C36+28) | K36: 0.425 | L36: 0.555 | M36: 0.7 | N36: =IF(E36="","",ROUND(N35+IF(H36>0,E36*H36,E36*K36),2)) | O36: =IF(E36="","",ROUND(O35+IF(I36>0,E36*I36,E36*L36),2)) | P36: =IF(E36="","",ROUND(P35+IF(J36>0,E36*J36,E36*M36),2)) | Q36: =IF(N36="","",IF(ROUNDUP(N36/50,0)>ROUNDUP(N35/50,0),"Lần " & ROUNDUP(N36/50,0),"")) | R36: =IF(O36="","",IF(ROUNDUP(O36/200,0)>ROUNDUP(O35/200,0),"Lần " & ROUNDUP(O36/200,0),"")) | S36: =IF(P36="","",IF(ROUNDUP(P36/350,0)>ROUNDUP(P35/350,0),"Lần " & ROUNDUP(P36/350,0),"")) | AK36: Bản vẽ: 12,50 → 8,77 m³ (tr.55 bê tông đệm C10) | Mác M100 chưa có cấp phối riêng — đang dùng cấp phối C30 (0,425 t XM; 0,555 m³ cát; 0,700 m³ đá / m³). Nhập cấp phối được duyệt.
A37: 33 | B37: Bê tông bệ trụ T2 - Đợt 1 (C30 đá 1x2) | C37: =IF('Danh mục công việc'!S1231="","",'Danh mục công việc'!S1231) | E37: 92.12 | F37: =IF(C37="","",C37+7) | G37: =IF(C37="","",C37+28) | K37: 0.425 | L37: 0.555 | M37: 0.7 | N37: =IF(E37="","",ROUND(N36+IF(H37>0,E37*H37,E37*K37),2)) | O37: =IF(E37="","",ROUND(O36+IF(I37>0,E37*I37,E37*L37),2)) | P37: =IF(E37="","",ROUND(P36+IF(J37>0,E37*J37,E37*M37),2)) | Q37: =IF(N37="","",IF(ROUNDUP(N37/50,0)>ROUNDUP(N36/50,0),"Lần " & ROUNDUP(N37/50,0),"")) | R37: =IF(O37="","",IF(ROUNDUP(O37/200,0)>ROUNDUP(O36/200,0),"Lần " & ROUNDUP(O37/200,0),"")) | S37: =IF(P37="","",IF(ROUNDUP(P37/350,0)>ROUNDUP(P36/350,0),"Lần " & ROUNDUP(P37/350,0),"")) | AK37: Khớp bản vẽ (tr.55 bệ trụ T2, chia theo tỷ lệ 2 đợt cũ)
A38: 34 | B38: Bê tông bệ trụ T2 - Đợt 2 (C30 đá 1x2) | C38: =IF('Danh mục công việc'!S1231="","",'Danh mục công việc'!S1231) | E38: 92.12 | F38: =IF(C38="","",C38+7) | G38: =IF(C38="","",C38+28) | K38: 0.425 | L38: 0.555 | M38: 0.7 | N38: =IF(E38="","",ROUND(N37+IF(H38>0,E38*H38,E38*K38),2)) | O38: =IF(E38="","",ROUND(O37+IF(I38>0,E38*I38,E38*L38),2)) | P38: =IF(E38="","",ROUND(P37+IF(J38>0,E38*J38,E38*M38),2)) | Q38: =IF(N38="","",IF(ROUNDUP(N38/50,0)>ROUNDUP(N37/50,0),"Lần " & ROUNDUP(N38/50,0),"")) | R38: =IF(O38="","",IF(ROUNDUP(O38/200,0)>ROUNDUP(O37/200,0),"Lần " & ROUNDUP(O38/200,0),"")) | S38: =IF(P38="","",IF(ROUNDUP(P38/350,0)>ROUNDUP(P37/350,0),"Lần " & ROUNDUP(P38/350,0),"")) | AK38: Khớp bản vẽ (tr.55 bệ trụ T2, chia theo tỷ lệ 2 đợt cũ)
A39: 35 | B39: Bê tông lót móng bệ mố M2 (M100 đá 4x6) | C39: =IF('Danh mục công việc'!S1148="","",'Danh mục công việc'!S1148) | E39: 7.09 | F39: =IF(C39="","",C39+7) | G39: =IF(C39="","",C39+28) | K39: 0.425 | L39: 0.555 | M39: 0.7 | N39: =IF(E39="","",ROUND(N38+IF(H39>0,E39*H39,E39*K39),2)) | O39: =IF(E39="","",ROUND(O38+IF(I39>0,E39*I39,E39*L39),2)) | P39: =IF(E39="","",ROUND(P38+IF(J39>0,E39*J39,E39*M39),2)) | Q39: =IF(N39="","",IF(ROUNDUP(N39/50,0)>ROUNDUP(N38/50,0),"Lần " & ROUNDUP(N39/50,0),"")) | R39: =IF(O39="","",IF(ROUNDUP(O39/200,0)>ROUNDUP(O38/200,0),"Lần " & ROUNDUP(O39/200,0),"")) | S39: =IF(P39="","",IF(ROUNDUP(P39/350,0)>ROUNDUP(P38/350,0),"Lần " & ROUNDUP(P39/350,0),"")) | AK39: Bản vẽ: 9,55 → 7,09 m³ (tr.40 bê tông đệm C10). File cũ 9,55 m³ là tổng đệm của CẢ 2 mố (tr.175). | Mác M100 chưa có cấp phối riêng — đang dùng cấp phối C30 (0,425 t XM; 0,555 m³ cát; 0,700 m³ đá / m³). Nhập cấp phối được duyệt.
A40: 36 | B40: Bê tông bệ mố M2 (C30 đá 1x2) | C40: =IF('Danh mục công việc'!S1160="","",'Danh mục công việc'!S1160) | E40: 148.99 | F40: =IF(C40="","",C40+7) | G40: =IF(C40="","",C40+28) | K40: 0.425 | L40: 0.555 | M40: 0.7 | N40: =IF(E40="","",ROUND(N39+IF(H40>0,E40*H40,E40*K40),2)) | O40: =IF(E40="","",ROUND(O39+IF(I40>0,E40*I40,E40*L40),2)) | P40: =IF(E40="","",ROUND(P39+IF(J40>0,E40*J40,E40*M40),2)) | Q40: =IF(N40="","",IF(ROUNDUP(N40/50,0)>ROUNDUP(N39/50,0),"Lần " & ROUNDUP(N40/50,0),"")) | R40: =IF(O40="","",IF(ROUNDUP(O40/200,0)>ROUNDUP(O39/200,0),"Lần " & ROUNDUP(O40/200,0),"")) | S40: =IF(P40="","",IF(ROUNDUP(P40/350,0)>ROUNDUP(P39/350,0),"Lần " & ROUNDUP(P40/350,0),"")) | AK40: Khớp bản vẽ (tr.40 bệ mố M2)
A41: III. HẠNG MỤC THÂN TRỤ, THÂN MỐ & XÀ MŨ (CÁC ĐỐT LÊN HOÀN THIỆN)
A42: 37 | B42: Bê tông thân trụ T1 - Đốt 1 (C30 đá 1x2) | C42: =IF('Danh mục công việc'!S1411="","",'Danh mục công việc'!S1411) | E42: 80.87 | F42: =IF(C42="","",C42+7) | G42: =IF(C42="","",C42+28) | K42: 0.425 | L42: 0.555 | M42: 0.7 | N42: =IF(E42="","",ROUND(N40+IF(H42>0,E42*H42,E42*K42),2)) | O42: =IF(E42="","",ROUND(O40+IF(I42>0,E42*I42,E42*L42),2)) | P42: =IF(E42="","",ROUND(P40+IF(J42>0,E42*J42,E42*M42),2)) | Q42: =IF(N42="","",IF(ROUNDUP(N42/50,0)>ROUNDUP(N40/50,0),"Lần " & ROUNDUP(N42/50,0),"")) | R42: =IF(O42="","",IF(ROUNDUP(O42/200,0)>ROUNDUP(O40/200,0),"Lần " & ROUNDUP(O42/200,0),"")) | S42: =IF(P42="","",IF(ROUNDUP(P42/350,0)>ROUNDUP(P40/350,0),"Lần " & ROUNDUP(P42/350,0),"")) | AK42: Bản vẽ: 42,00 → 80,87 m³ (tr.48 thân trụ T1, chia theo tỷ lệ 3 đốt cũ). Bản vẽ 234,92 m³ (file cũ 122 m³) — chia 3 đốt theo tỷ lệ cũ; xác nhận chiều cao từng đốt.
A43: 38 | B43: Bê tông thân trụ T1 - Đốt 2 (C30 đá 1x2) | C43: =IF('Danh mục công việc'!S1369="","",'Danh mục công việc'!S1369) | E43: 80.87 | F43: =IF(C43="","",C43+7) | G43: =IF(C43="","",C43+28) | K43: 0.425 | L43: 0.555 | M43: 0.7 | N43: =IF(E43="","",ROUND(N42+IF(H43>0,E43*H43,E43*K43),2)) | O43: =IF(E43="","",ROUND(O42+IF(I43>0,E43*I43,E43*L43),2)) | P43: =IF(E43="","",ROUND(P42+IF(J43>0,E43*J43,E43*M43),2)) | Q43: =IF(N43="","",IF(ROUNDUP(N43/50,0)>ROUNDUP(N42/50,0),"Lần " & ROUNDUP(N43/50,0),"")) | R43: =IF(O43="","",IF(ROUNDUP(O43/200,0)>ROUNDUP(O42/200,0),"Lần " & ROUNDUP(O43/200,0),"")) | S43: =IF(P43="","",IF(ROUNDUP(P43/350,0)>ROUNDUP(P42/350,0),"Lần " & ROUNDUP(P43/350,0),"")) | AK43: Bản vẽ: 42,00 → 80,87 m³ (tr.48 thân trụ T1, chia theo tỷ lệ 3 đốt cũ). Bản vẽ 234,92 m³ (file cũ 122 m³) — chia 3 đốt theo tỷ lệ cũ; xác nhận chiều cao từng đốt.
A44: 39 | B44: Bê tông thân trụ T1 - Đốt 3 (C30 đá 1x2) | C44: =IF('Danh mục công việc'!S1348="","",'Danh mục công việc'!S1348) | E44: 73.18 | F44: =IF(C44="","",C44+7) | G44: =IF(C44="","",C44+28) | K44: 0.425 | L44: 0.555 | M44: 0.7 | N44: =IF(E44="","",ROUND(N43+IF(H44>0,E44*H44,E44*K44),2)) | O44: =IF(E44="","",ROUND(O43+IF(I44>0,E44*I44,E44*L44),2)) | P44: =IF(E44="","",ROUND(P43+IF(J44>0,E44*J44,E44*M44),2)) | Q44: =IF(N44="","",IF(ROUNDUP(N44/50,0)>ROUNDUP(N43/50,0),"Lần " & ROUNDUP(N44/50,0),"")) | R44: =IF(O44="","",IF(ROUNDUP(O44/200,0)>ROUNDUP(O43/200,0),"Lần " & ROUNDUP(O44/200,0),"")) | S44: =IF(P44="","",IF(ROUNDUP(P44/350,0)>ROUNDUP(P43/350,0),"Lần " & ROUNDUP(P44/350,0),"")) | AK44: Bản vẽ: 38,00 → 73,18 m³ (tr.48 thân trụ T1, chia theo tỷ lệ 3 đốt cũ). Bản vẽ 234,92 m³ (file cũ 122 m³) — chia 3 đốt theo tỷ lệ cũ; xác nhận chiều cao từng đốt.
A45: 40 | B45: Bê tông xà mũ trụ T1 & đá kê gối (C35/C30 đá 1x2) | E45: 72.51 | F45: =IF(C45="","",C45+7) | G45: =IF(C45="","",C45+28) | K45: 0.425 | L45: 0.555 | M45: 0.7 | N45: =IF(E45="","",ROUND(N44+IF(H45>0,E45*H45,E45*K45),2)) | O45: =IF(E45="","",ROUND(O44+IF(I45>0,E45*I45,E45*L45),2)) | P45: =IF(E45="","",ROUND(P44+IF(J45>0,E45*J45,E45*M45),2)) | Q45: =IF(N45="","",IF(ROUNDUP(N45/50,0)>ROUNDUP(N44/50,0),"Lần " & ROUNDUP(N45/50,0),"")) | R45: =IF(O45="","",IF(ROUNDUP(O45/200,0)>ROUNDUP(O44/200,0),"Lần " & ROUNDUP(O45/200,0),"")) | S45: =IF(P45="","",IF(ROUNDUP(P45/350,0)>ROUNDUP(P44/350,0),"Lần " & ROUNDUP(P45/350,0),"")) | AK45: Bản vẽ: 45,00 → 72,51 m³ (tr.51 xà mũ trụ T1) | Mác C35 chưa có cấp phối riêng — đang dùng cấp phối C30 (0,425 t XM; 0,555 m³ cát; 0,700 m³ đá / m³). Nhập cấp phối được duyệt.
...

Sheet Theo_Doi_Tan_Suat_Cot_Thep
A1: STT | B1: HẠNG MỤC CẤU KIỆN | C1: BỘ PHẬN / VỊ TRÍ CHI TIẾT | D1: KÝ HIỆU THANH | E1: ĐƯỜNG KÍNH Ø (mm) | F1: MÁC THÉP / TIÊU CHUẨN | G1: HÌNH DẠNG / QUY CÁCH | H1: CHIỀU DÀI 1 THANH (m) | I1: SỐ LƯỢNG (Thanh) | J1: TRỌNG LƯỢNG 1M (kg/m) | K1: TỔNG KL (kg) | L1: KHỐI LƯỢNG (Tấn) | M1: N/T/N LẮP DỰNG | N1: SỐ LÔ / HEAT NO CO-CQ RIÊNG TỪNG Ø | O1: CẢNH BÁO LẤY MẪU TN KÉO/UỐN (50T/LẦN) | P1: KHỐI LƯỢNG LŨY KẾ THEO TỪNG LOẠI ĐƯỜNG KÍNH Ø (TẤN) | AA1: TẦN SUẤT THÍ NGHIỆM CƠ LÝ KÉO / UỐN RIÊNG TỪNG Ø (50 TẤN / LẦN - TCVN 1651:2018) | AL1: ĐÁNH GIÁ & KẾT LUẬN | AN1: LOẠI HẠNG MỤC (OFFSET) | AO1: DÒNG BÊ TÔNG ĐỐI CHIẾU | AQ1: LOẠI HẠNG MỤC | AR1: SỐ NGÀY LẮP DỰNG TRƯỚC ĐỔ BT
P2: Ø10 (kèm Ø6, Ø8) (CB240-T) | Q2: Ø12 (CB400-V) | R2: Ø14 (CB400-V) | S2: Ø16 (CB400-V) | T2: Ø18 (CB400-V) | U2: Ø20 (CB400-V) | V2: Ø22 (CB400-V) | W2: Ø25 (CB400-V) | X2: Ø28 (CB400-V) | Y2: Ø32 (CB400-V) | Z2: Cáp DƯL 15.2 (ASTM A416) | AA2: TN Ø10 50T / Lần | AB2: TN Ø12 50T / Lần | AC2: TN Ø14 50T / Lần | AD2: TN Ø16 50T / Lần | AE2: TN Ø18 50T / Lần | AF2: TN Ø20 50T / Lần | AG2: TN Ø22 50T / Lần | AH2: TN Ø25 50T / Lần | AI2: TN Ø28 50T / Lần | AJ2: TN Ø32 50T / Lần | AK2: TN Cáp 15.2 50T / Lần | AQ2: Coc | AR2: 1
A3: --- CỌC KHOAN NHỒI C5 TRỤ T1 (D1.2M, L=40.0M) --- | AQ3: Be | AR3: 3
A4: 1 | B4: Cọc khoan nhồi C5 Trụ T1 (D1.2m, L=40.0m) | C4: Cọc trụ T1 L=40m (tr.68) | D4: P1 | E4: 10 | F4: CB240-T | H4: 96.604 | I4: 1 | J4: 0.617 | K4: =ROUND(H4*I4*J4, 2) | L4: =ROUND(K4/1000, 3) | M4: =IF(AO4="","",IF(N(INDEX(Theo_Doi_Tan_Suat_Be_Tong!$C:$C,AO4))<=0,"",INDEX(Theo_Doi_Tan_Suat_Be_Tong!$C:$C,AO4)-VLOOKUP(AN4,$AQ$2:$AR$7,2,FALSE))) | O4: =IF(ROUNDUP(P4/20,0)>0,"TN Ø10 (Lần " & ROUNDUP(P4/20,0) & ")","") | P4: =ROUND(IF(AND(E4<=10,F4<>"ASTM A416"),L4,0),3) | Q4: =ROUND(IF(AND(E4=12,F4<>"ASTM A416"),L4,0),3) | R4: =ROUND(IF(AND(E4=14,F4<>"ASTM A416"),L4,0),3) | S4: =ROUND(IF(AND(E4=16,F4<>"ASTM A416"),L4,0),3) | T4: =ROUND(IF(AND(E4=18,F4<>"ASTM A416"),L4,0),3) | U4: =ROUND(IF(AND(E4=20,F4<>"ASTM A416"),L4,0),3) | V4: =ROUND(IF(AND(E4=22,F4<>"ASTM A416"),L4,0),3) | W4: =ROUND(IF(AND(E4=25,F4<>"ASTM A416"),L4,0),3) | X4: =ROUND(IF(AND(E4=28,F4<>"ASTM A416"),L4,0),3) | Y4: =ROUND(IF(AND(E4=32,F4<>"ASTM A416"),L4,0),3) | Z4: =ROUND(IF(F4="ASTM A416",L4,0),3) | AA4: =IF(ROUNDUP(P4/20,0)>0,"Lần " & ROUNDUP(P4/20,0),"") | AB4: =IF(ROUNDUP(Q4/20,0)>0,"Lần " & ROUNDUP(Q4/20,0),"") | AC4: =IF(ROUNDUP(R4/20,0)>0,"Lần " & ROUNDUP(R4/20,0),"") | AD4: =IF(ROUNDUP(S4/20,0)>0,"Lần " & ROUNDUP(S4/20,0),"") | AE4: =IF(ROUNDUP(T4/20,0)>0,"Lần " & ROUNDUP(T4/20,0),"") | AF4: =IF(ROUNDUP(U4/20,0)>0,"Lần " & ROUNDUP(U4/20,0),"") | AG4: =IF(ROUNDUP(V4/20,0)>0,"Lần " & ROUNDUP(V4/20,0),"") | AH4: =IF(ROUNDUP(W4/20,0)>0,"Lần " & ROUNDUP(W4/20,0),"") | ... AK4: =IF(ROUNDUP(Z4/20,0)>0,"Lần " & ROUNDUP(Z4/20,0),"") | AN4: Coc | AO4: 4 | AQ4: Than | AR4: 2
A5: 2 | B5: Cọc khoan nhồi C5 Trụ T1 (D1.2m, L=40.0m) | C5: Cọc trụ T1 L=40m (tr.68) | D5: P1A | E5: 10 | F5: CB240-T | H5: 389.636 | I5: 1 | J5: 0.617 | K5: =ROUND(H5*I5*J5, 2) | L5: =ROUND(K5/1000, 3) | M5: =IF(AO5="","",IF(N(INDEX(Theo_Doi_Tan_Suat_Be_Tong!$C:$C,AO5))<=0,"",INDEX(Theo_Doi_Tan_Suat_Be_Tong!$C:$C,AO5)-VLOOKUP(AN5,$AQ$2:$AR$7,2,FALSE))) | O5: =IF(ROUNDUP(P5/20,0)>ROUNDUP(P4/20,0),"TN Ø10 (Lần " & ROUNDUP(P5/20,0) & ")","") | P5: =ROUND(P4+IF(AND(E5<=10,F5<>"ASTM A416"),L5,0),3) | Q5: =ROUND(Q4+IF(AND(E5=12,F5<>"ASTM A416"),L5,0),3) | R5: =ROUND(R4+IF(AND(E5=14,F5<>"ASTM A416"),L5,0),3) | S5: =ROUND(S4+IF(AND(E5=16,F5<>"ASTM A416"),L5,0),3) | T5: =ROUND(T4+IF(AND(E5=18,F5<>"ASTM A416"),L5,0),3) | U5: =ROUND(U4+IF(AND(E5=20,F5<>"ASTM A416"),L5,0),3) | V5: =ROUND(V4+IF(AND(E5=22,F5<>"ASTM A416"),L5,0),3) | W5: =ROUND(W4+IF(AND(E5=25,F5<>"ASTM A416"),L5,0),3) | X5: =ROUND(X4+IF(AND(E5=28,F5<>"ASTM A416"),L5,0),3) | Y5: =ROUND(Y4+IF(AND(E5=32,F5<>"ASTM A416"),L5,0),3) | Z5: =ROUND(Z4+IF(F5="ASTM A416",L5,0),3) | AA5: =IF(ROUNDUP(P5/20,0)>ROUNDUP(P4/20,0),"Lần " & ROUNDUP(P5/20,0),"") | AB5: =IF(ROUNDUP(Q5/20,0)>ROUNDUP(Q4/20,0),"Lần " & ROUNDUP(Q5/20,0),"") | AC5: =IF(ROUNDUP(R5/20,0)>ROUNDUP(R4/20,0),"Lần " & ROUNDUP(R5/20,0),"") | AD5: =IF(ROUNDUP(S5/20,0)>ROUNDUP(S4/20,0),"Lần " & ROUNDUP(S5/20,0),"") | AE5: =IF(ROUNDUP(T5/20,0)>ROUNDUP(T4/20,0),"Lần " & ROUNDUP(T5/20,0),"") | AF5: =IF(ROUNDUP(U5/20,0)>ROUNDUP(U4/20,0),"Lần " & ROUNDUP(U5/20,0),"") | AG5: =IF(ROUNDUP(V5/20,0)>ROUNDUP(V4/20,0),"Lần " & ROUNDUP(V5/20,0),"") | AH5: =IF(ROUNDUP(W5/20,0)>ROUNDUP(W4/20,0),"Lần " & ROUNDUP(W5/20,0),"") | ... AK5: =IF(ROUNDUP(Z5/20,0)>ROUNDUP(Z4/20,0),"Lần " & ROUNDUP(Z5/20,0),"") | AN5: Coc | AO5: 4 | AQ5: Dam | AR5: 4
A6: 3 | B6: Cọc khoan nhồi C5 Trụ T1 (D1.2m, L=40.0m) | C6: Cọc trụ T1 L=40m (tr.68) | D6: P1B | E6: 10 | F6: CB240-T | H6: 206.981 | I6: 1 | J6: 0.617 | K6: =ROUND(H6*I6*J6, 2) | L6: =ROUND(K6/1000, 3) | M6: =IF(AO6="","",IF(N(INDEX(Theo_Doi_Tan_Suat_Be_Tong!$C:$C,AO6))<=0,"",INDEX(Theo_Doi_Tan_Suat_Be_Tong!$C:$C,AO6)-VLOOKUP(AN6,$AQ$2:$AR$7,2,FALSE))) | O6: =IF(ROUNDUP(P6/20,0)>ROUNDUP(P5/20,0),"TN Ø10 (Lần " & ROUNDUP(P6/20,0) & ")","") | P6: =ROUND(P5+IF(AND(E6<=10,F6<>"ASTM A416"),L6,0),3) | Q6: =ROUND(Q5+IF(AND(E6=12,F6<>"ASTM A416"),L6,0),3) | R6: =ROUND(R5+IF(AND(E6=14,F6<>"ASTM A416"),L6,0),3) | S6: =ROUND(S5+IF(AND(E6=16,F6<>"ASTM A416"),L6,0),3) | T6: =ROUND(T5+IF(AND(E6=18,F6<>"ASTM A416"),L6,0),3) | U6: =ROUND(U5+IF(AND(E6=20,F6<>"ASTM A416"),L6,0),3) | V6: =ROUND(V5+IF(AND(E6=22,F6<>"ASTM A416"),L6,0),3) | W6: =ROUND(W5+IF(AND(E6=25,F6<>"ASTM A416"),L6,0),3) | X6: =ROUND(X5+IF(AND(E6=28,F6<>"ASTM A416"),L6,0),3) | Y6: =ROUND(Y5+IF(AND(E6=32,F6<>"ASTM A416"),L6,0),3) | Z6: =ROUND(Z5+IF(F6="ASTM A416",L6,0),3) | AA6: =IF(ROUNDUP(P6/20,0)>ROUNDUP(P5/20,0),"Lần " & ROUNDUP(P6/20,0),"") | AB6: =IF(ROUNDUP(Q6/20,0)>ROUNDUP(Q5/20,0),"Lần " & ROUNDUP(Q6/20,0),"") | AC6: =IF(ROUNDUP(R6/20,0)>ROUNDUP(R5/20,0),"Lần " & ROUNDUP(R6/20,0),"") | AD6: =IF(ROUNDUP(S6/20,0)>ROUNDUP(S5/20,0),"Lần " & ROUNDUP(S6/20,0),"") | AE6: =IF(ROUNDUP(T6/20,0)>ROUNDUP(T5/20,0),"Lần " & ROUNDUP(T6/20,0),"") | AF6: =IF(ROUNDUP(U6/20,0)>ROUNDUP(U5/20,0),"Lần " & ROUNDUP(U6/20,0),"") | AG6: =IF(ROUNDUP(V6/20,0)>ROUNDUP(V5/20,0),"Lần " & ROUNDUP(V6/20,0),"") | AH6: =IF(ROUNDUP(W6/20,0)>ROUNDUP(W5/20,0),"Lần " & ROUNDUP(W6/20,0),"") | ... AK6: =IF(ROUNDUP(Z6/20,0)>ROUNDUP(Z5/20,0),"Lần " & ROUNDUP(Z6/20,0),"") | AN6: Coc | AO6: 4 | AQ6: HoanThien | AR6: 2
A7: 4 | B7: Cọc khoan nhồi C5 Trụ T1 (D1.2m, L=40.0m) | C7: Cọc trụ T1 L=40m (tr.68) | D7: P1C | E7: 10 | F7: CB240-T | H7: 3.592 | I7: 2 | J7: 0.617 | K7: =ROUND(H7*I7*J7, 2) | L7: =ROUND(K7/1000, 3) | M7: =IF(AO7="","",IF(N(INDEX(Theo_Doi_Tan_Suat_Be_Tong!$C:$C,AO7))<=0,"",INDEX(Theo_Doi_Tan_Suat_Be_Tong!$C:$C,AO7)-VLOOKUP(AN7,$AQ$2:$AR$7,2,FALSE))) | O7: =IF(ROUNDUP(P7/20,0)>ROUNDUP(P6/20,0),"TN Ø10 (Lần " & ROUNDUP(P7/20,0) & ")","") | P7: =ROUND(P6+IF(AND(E7<=10,F7<>"ASTM A416"),L7,0),3) | Q7: =ROUND(Q6+IF(AND(E7=12,F7<>"ASTM A416"),L7,0),3) | R7: =ROUND(R6+IF(AND(E7=14,F7<>"ASTM A416"),L7,0),3) | S7: =ROUND(S6+IF(AND(E7=16,F7<>"ASTM A416"),L7,0),3) | T7: =ROUND(T6+IF(AND(E7=18,F7<>"ASTM A416"),L7,0),3) | U7: =ROUND(U6+IF(AND(E7=20,F7<>"ASTM A416"),L7,0),3) | V7: =ROUND(V6+IF(AND(E7=22,F7<>"ASTM A416"),L7,0),3) | W7: =ROUND(W6+IF(AND(E7=25,F7<>"ASTM A416"),L7,0),3) | X7: =ROUND(X6+IF(AND(E7=28,F7<>"ASTM A416"),L7,0),3) | Y7: =ROUND(Y6+IF(AND(E7=32,F7<>"ASTM A416"),L7,0),3) | Z7: =ROUND(Z6+IF(F7="ASTM A416",L7,0),3) | AA7: =IF(ROUNDUP(P7/20,0)>ROUNDUP(P6/20,0),"Lần " & ROUNDUP(P7/20,0),"") | AB7: =IF(ROUNDUP(Q7/20,0)>ROUNDUP(Q6/20,0),"Lần " & ROUNDUP(Q7/20,0),"") | AC7: =IF(ROUNDUP(R7/20,0)>ROUNDUP(R6/20,0),"Lần " & ROUNDUP(R7/20,0),"") | AD7: =IF(ROUNDUP(S7/20,0)>ROUNDUP(S6/20,0),"Lần " & ROUNDUP(S7/20,0),"") | AE7: =IF(ROUNDUP(T7/20,0)>ROUNDUP(T6/20,0),"Lần " & ROUNDUP(T7/20,0),"") | AF7: =IF(ROUNDUP(U7/20,0)>ROUNDUP(U6/20,0),"Lần " & ROUNDUP(U7/20,0),"") | AG7: =IF(ROUNDUP(V7/20,0)>ROUNDUP(V6/20,0),"Lần " & ROUNDUP(V7/20,0),"") | AH7: =IF(ROUNDUP(W7/20,0)>ROUNDUP(W6/20,0),"Lần " & ROUNDUP(W7/20,0),"") | ... AK7: =IF(ROUNDUP(Z7/20,0)>ROUNDUP(Z6/20,0),"Lần " & ROUNDUP(Z7/20,0),"") | AN7: Coc | AO7: 4
A8: 5 | B8: Cọc khoan nhồi C5 Trụ T1 (D1.2m, L=40.0m) | C8: Cọc trụ T1 L=40m (tr.68) | D8: P1D | E8: 10 | F8: CB240-T | H8: 19.721 | I8: 1 | J8: 0.617 | K8: =ROUND(H8*I8*J8, 2) | L8: =ROUND(K8/1000, 3) | M8: =IF(AO8="","",IF(N(INDEX(Theo_Doi_Tan_Suat_Be_Tong!$C:$C,AO8))<=0,"",INDEX(Theo_Doi_Tan_Suat_Be_Tong!$C:$C,AO8)-VLOOKUP(AN8,$AQ$2:$AR$7,2,FALSE))) | O8: =IF(ROUNDUP(P8/20,0)>ROUNDUP(P7/20,0),"TN Ø10 (Lần " & ROUNDUP(P8/20,0) & ")","") | P8: =ROUND(P7+IF(AND(E8<=10,F8<>"ASTM A416"),L8,0),3) | Q8: =ROUND(Q7+IF(AND(E8=12,F8<>"ASTM A416"),L8,0),3) | R8: =ROUND(R7+IF(AND(E8=14,F8<>"ASTM A416"),L8,0),3) | S8: =ROUND(S7+IF(AND(E8=16,F8<>"ASTM A416"),L8,0),3) | T8: =ROUND(T7+IF(AND(E8=18,F8<>"ASTM A416"),L8,0),3) | U8: =ROUND(U7+IF(AND(E8=20,F8<>"ASTM A416"),L8,0),3) | V8: =ROUND(V7+IF(AND(E8=22,F8<>"ASTM A416"),L8,0),3) | W8: =ROUND(W7+IF(AND(E8=25,F8<>"ASTM A416"),L8,0),3) | X8: =ROUND(X7+IF(AND(E8=28,F8<>"ASTM A416"),L8,0),3) | Y8: =ROUND(Y7+IF(AND(E8=32,F8<>"ASTM A416"),L8,0),3) | Z8: =ROUND(Z7+IF(F8="ASTM A416",L8,0),3) | AA8: =IF(ROUNDUP(P8/20,0)>ROUNDUP(P7/20,0),"Lần " & ROUNDUP(P8/20,0),"") | AB8: =IF(ROUNDUP(Q8/20,0)>ROUNDUP(Q7/20,0),"Lần " & ROUNDUP(Q8/20,0),"") | AC8: =IF(ROUNDUP(R8/20,0)>ROUNDUP(R7/20,0),"Lần " & ROUNDUP(R8/20,0),"") | AD8: =IF(ROUNDUP(S8/20,0)>ROUNDUP(S7/20,0),"Lần " & ROUNDUP(S8/20,0),"") | AE8: =IF(ROUNDUP(T8/20,0)>ROUNDUP(T7/20,0),"Lần " & ROUNDUP(T8/20,0),"") | AF8: =IF(ROUNDUP(U8/20,0)>ROUNDUP(U7/20,0),"Lần " & ROUNDUP(U8/20,0),"") | AG8: =IF(ROUNDUP(V8/20,0)>ROUNDUP(V7/20,0),"Lần " & ROUNDUP(V8/20,0),"") | AH8: =IF(ROUNDUP(W8/20,0)>ROUNDUP(W7/20,0),"Lần " & ROUNDUP(W8/20,0),"") | ... AK8: =IF(ROUNDUP(Z8/20,0)>ROUNDUP(Z7/20,0),"Lần " & ROUNDUP(Z8/20,0),"") | AN8: Coc | AO8: 4
A9: 6 | B9: Cọc khoan nhồi C5 Trụ T1 (D1.2m, L=40.0m) | C9: Cọc trụ T1 L=40m (tr.68) | D9: P2B | E9: 25 | F9: CB400-V | H9: 2.985 | I9: 16 | J9: 3.853 | K9: =ROUND(H9*I9*J9, 2) | L9: =ROUND(K9/1000, 3) | M9: =IF(AO9="","",IF(N(INDEX(Theo_Doi_Tan_Suat_Be_Tong!$C:$C,AO9))<=0,"",INDEX(Theo_Doi_Tan_Suat_Be_Tong!$C:$C,AO9)-VLOOKUP(AN9,$AQ$2:$AR$7,2,FALSE))) | O9: =IF(ROUNDUP(W9/20,0)>ROUNDUP(W8/20,0),"TN Ø25 (Lần " & ROUNDUP(W9/20,0) & ")","") | P9: =ROUND(P8+IF(AND(E9<=10,F9<>"ASTM A416"),L9,0),3) | Q9: =ROUND(Q8+IF(AND(E9=12,F9<>"ASTM A416"),L9,0),3) | R9: =ROUND(R8+IF(AND(E9=14,F9<>"ASTM A416"),L9,0),3) | S9: =ROUND(S8+IF(AND(E9=16,F9<>"ASTM A416"),L9,0),3) | T9: =ROUND(T8+IF(AND(E9=18,F9<>"ASTM A416"),L9,0),3) | U9: =ROUND(U8+IF(AND(E9=20,F9<>"ASTM A416"),L9,0),3) | V9: =ROUND(V8+IF(AND(E9=22,F9<>"ASTM A416"),L9,0),3) | W9: =ROUND(W8+IF(AND(E9=25,F9<>"ASTM A416"),L9,0),3) | X9: =ROUND(X8+IF(AND(E9=28,F9<>"ASTM A416"),L9,0),3) | Y9: =ROUND(Y8+IF(AND(E9=32,F9<>"ASTM A416"),L9,0),3) | Z9: =ROUND(Z8+IF(F9="ASTM A416",L9,0),3) | AA9: =IF(ROUNDUP(P9/20,0)>ROUNDUP(P8/20,0),"Lần " & ROUNDUP(P9/20,0),"") | AB9: =IF(ROUNDUP(Q9/20,0)>ROUNDUP(Q8/20,0),"Lần " & ROUNDUP(Q9/20,0),"") | AC9: =IF(ROUNDUP(R9/20,0)>ROUNDUP(R8/20,0),"Lần " & ROUNDUP(R9/20,0),"") | AD9: =IF(ROUNDUP(S9/20,0)>ROUNDUP(S8/20,0),"Lần " & ROUNDUP(S9/20,0),"") | AE9: =IF(ROUNDUP(T9/20,0)>ROUNDUP(T8/20,0),"Lần " & ROUNDUP(T9/20,0),"") | AF9: =IF(ROUNDUP(U9/20,0)>ROUNDUP(U8/20,0),"Lần " & ROUNDUP(U9/20,0),"") | AG9: =IF(ROUNDUP(V9/20,0)>ROUNDUP(V8/20,0),"Lần " & ROUNDUP(V9/20,0),"") | AH9: =IF(ROUNDUP(W9/20,0)>ROUNDUP(W8/20,0),"Lần " & ROUNDUP(W9/20,0),"") | ... AK9: =IF(ROUNDUP(Z9/20,0)>ROUNDUP(Z8/20,0),"Lần " & ROUNDUP(Z9/20,0),"") | AN9: Coc | AO9: 4
A10: 7 | B10: Cọc khoan nhồi C5 Trụ T1 (D1.2m, L=40.0m) | C10: Cọc trụ T1 L=40m (tr.68) | D10: P3 | E10: 25 | F10: CB400-V | H10: 10.7 | I10: 12 | J10: 3.853 | K10: =ROUND(H10*I10*J10, 2) | L10: =ROUND(K10/1000, 3) | M10: =IF(AO10="","",IF(N(INDEX(Theo_Doi_Tan_Suat_Be_Tong!$C:$C,AO10))<=0,"",INDEX(Theo_Doi_Tan_Suat_Be_Tong!$C:$C,AO10)-VLOOKUP(AN10,$AQ$2:$AR$7,2,FALSE))) | O10: =IF(ROUNDUP(W10/20,0)>ROUNDUP(W9/20,0),"TN Ø25 (Lần " & ROUNDUP(W10/20,0) & ")","") | P10: =ROUND(P9+IF(AND(E10<=10,F10<>"ASTM A416"),L10,0),3) | Q10: =ROUND(Q9+IF(AND(E10=12,F10<>"ASTM A416"),L10,0),3) | R10: =ROUND(R9+IF(AND(E10=14,F10<>"ASTM A416"),L10,0),3) | S10: =ROUND(S9+IF(AND(E10=16,F10<>"ASTM A416"),L10,0),3) | T10: =ROUND(T9+IF(AND(E10=18,F10<>"ASTM A416"),L10,0),3) | U10: =ROUND(U9+IF(AND(E10=20,F10<>"ASTM A416"),L10,0),3) | V10: =ROUND(V9+IF(AND(E10=22,F10<>"ASTM A416"),L10,0),3) | W10: =ROUND(W9+IF(AND(E10=25,F10<>"ASTM A416"),L10,0),3) | X10: =ROUND(X9+IF(AND(E10=28,F10<>"ASTM A416"),L10,0),3) | Y10: =ROUND(Y9+IF(AND(E10=32,F10<>"ASTM A416"),L10,0),3) | Z10: =ROUND(Z9+IF(F10="ASTM A416",L10,0),3) | AA10: =IF(ROUNDUP(P10/20,0)>ROUNDUP(P9/20,0),"Lần " & ROUNDUP(P10/20,0),"") | AB10: =IF(ROUNDUP(Q10/20,0)>ROUNDUP(Q9/20,0),"Lần " & ROUNDUP(Q10/20,0),"") | AC10: =IF(ROUNDUP(R10/20,0)>ROUNDUP(R9/20,0),"Lần " & ROUNDUP(R10/20,0),"") | AD10: =IF(ROUNDUP(S10/20,0)>ROUNDUP(S9/20,0),"Lần " & ROUNDUP(S10/20,0),"") | AE10: =IF(ROUNDUP(T10/20,0)>ROUNDUP(T9/20,0),"Lần " & ROUNDUP(T10/20,0),"") | AF10: =IF(ROUNDUP(U10/20,0)>ROUNDUP(U9/20,0),"Lần " & ROUNDUP(U10/20,0),"") | AG10: =IF(ROUNDUP(V10/20,0)>ROUNDUP(V9/20,0),"Lần " & ROUNDUP(V10/20,0),"") | AH10: =IF(ROUNDUP(W10/20,0)>ROUNDUP(W9/20,0),"Lần " & ROUNDUP(W10/20,0),"") | ... AK10: =IF(ROUNDUP(Z10/20,0)>ROUNDUP(Z9/20,0),"Lần " & ROUNDUP(Z10/20,0),"") | AN10: Coc | AO10: 4
