Workbook

Sheet Theo_Doi_Tan_Suat_Be_Tong
A1: STT | B1: HẠNG MỤC CÔNG VIỆC | C1: N/T/N | D1: KL/T.tế (m3) | E1: Tuổi Bt | G1: 30Mpa-18±2 (Cọc nhồi) | J1: 30Mpa-14±2 (Bệ, thân, mố, trụ, dầm) | M1: Khối lượng vật tư lũy kế | P1: Tần suất lấy mẫu thí nghiệm | S1: Số lô | T1: KL (Tấn) | U1: NGUỒN BẢN VẼ / NGHI VẤN (soát & ghim)
E2: R7 | F2: R28 | G2: Xi măng 0,445 | H2: Cát 0,525 | I2: Đá 0,696 | J2: Xi măng 0,425 | K2: Cát 0,555 | L2: Đá 0,700 | M2: Xi măng (Tấn) | N2: Cát (m3) | O2: Đá (m3) | P2: Xi măng 50 tấn Lần | Q2: Cát 200m3 Lần | R2: Đá 350m3 Lần
A3: I. HẠNG MỤC CỌC KHOAN NHỒI D1.2M (C30 ĐỘ SỤT 18±2CM) - 26 CỌC (L=872M)
A4: 1 | B4: Bê tông cọc khoan nhồi - C1 mố M1 (L=20m) | D4: 23.58 | E4: =IF(C4="","",C4+7) | F4: =IF(C4="","",C4+28) | G4: 0.445 | H4: 0.525 | I4: 0.696 | M4: =IF(D4="","",ROUND(IF(G4>0,D4*G4,D4*J4),2)) | N4: =IF(D4="","",ROUND(IF(H4>0,D4*H4,D4*K4),2)) | O4: =IF(D4="","",ROUND(IF(I4>0,D4*I4,D4*L4),2)) | P4: =IF(M4="","",IF(ROUNDUP(M4/50,0)>0,"Lần " & ROUNDUP(M4/50,0),"")) | Q4: =IF(N4="","",IF(ROUNDUP(N4/200,0)>0,"Lần " & ROUNDUP(N4/200,0),"")) | R4: =IF(O4="","",IF(ROUNDUP(O4/350,0)>0,"Lần " & ROUNDUP(O4/350,0),"")) | U4: Bản vẽ: 24,71 → 23,58 m³ (tr.64 thể tích 1 cọc (đã gồm bê tông đầu cọc)). File cũ cộng thêm 1,13 m³ đập đầu cọc. Thay bằng phiếu đổ thực tế khi có.
A5: 2 | B5: Bê tông cọc khoan nhồi - C2 mố M1 (L=20m) | D5: 23.58 | E5: =IF(C5="","",C5+7) | F5: =IF(C5="","",C5+28) | G5: 0.445 | H5: 0.525 | I5: 0.696 | M5: =IF(D5="","",ROUND(M4+IF(G5>0,D5*G5,D5*J5),2)) | N5: =IF(D5="","",ROUND(N4+IF(H5>0,D5*H5,D5*K5),2)) | O5: =IF(D5="","",ROUND(O4+IF(I5>0,D5*I5,D5*L5),2)) | P5: =IF(M5="","",IF(ROUNDUP(M5/50,0)>ROUNDUP(M4/50,0),"Lần " & ROUNDUP(M5/50,0),"")) | Q5: =IF(N5="","",IF(ROUNDUP(N5/200,0)>ROUNDUP(N4/200,0),"Lần " & ROUNDUP(N5/200,0),"")) | R5: =IF(O5="","",IF(ROUNDUP(O5/350,0)>ROUNDUP(O4/350,0),"Lần " & ROUNDUP(O5/350,0),"")) | U5: Bản vẽ: 24,71 → 23,58 m³ (tr.64 thể tích 1 cọc (đã gồm bê tông đầu cọc)). File cũ cộng thêm 1,13 m³ đập đầu cọc. Thay bằng phiếu đổ thực tế khi có.
A6: 3 | B6: Bê tông cọc khoan nhồi - C3 mố M1 (L=20m) | D6: 23.58 | E6: =IF(C6="","",C6+7) | F6: =IF(C6="","",C6+28) | G6: 0.445 | H6: 0.525 | I6: 0.696 | M6: =IF(D6="","",ROUND(M5+IF(G6>0,D6*G6,D6*J6),2)) | N6: =IF(D6="","",ROUND(N5+IF(H6>0,D6*H6,D6*K6),2)) | O6: =IF(D6="","",ROUND(O5+IF(I6>0,D6*I6,D6*L6),2)) | P6: =IF(M6="","",IF(ROUNDUP(M6/50,0)>ROUNDUP(M5/50,0),"Lần " & ROUNDUP(M6/50,0),"")) | Q6: =IF(N6="","",IF(ROUNDUP(N6/200,0)>ROUNDUP(N5/200,0),"Lần " & ROUNDUP(N6/200,0),"")) | R6: =IF(O6="","",IF(ROUNDUP(O6/350,0)>ROUNDUP(O5/350,0),"Lần " & ROUNDUP(O6/350,0),"")) | U6: Bản vẽ: 24,71 → 23,58 m³ (tr.64 thể tích 1 cọc (đã gồm bê tông đầu cọc)). File cũ cộng thêm 1,13 m³ đập đầu cọc. Thay bằng phiếu đổ thực tế khi có.
A7: 4 | B7: Bê tông cọc khoan nhồi - C1 trụ T1 (L=40m) | D7: 45.88 | E7: =IF(C7="","",C7+7) | F7: =IF(C7="","",C7+28) | G7: 0.445 | H7: 0.525 | I7: 0.696 | M7: =IF(D7="","",ROUND(M6+IF(G7>0,D7*G7,D7*J7),2)) | N7: =IF(D7="","",ROUND(N6+IF(H7>0,D7*H7,D7*K7),2)) | O7: =IF(D7="","",ROUND(O6+IF(I7>0,D7*I7,D7*L7),2)) | P7: =IF(M7="","",IF(ROUNDUP(M7/50,0)>ROUNDUP(M6/50,0),"Lần " & ROUNDUP(M7/50,0),"")) | Q7: =IF(N7="","",IF(ROUNDUP(N7/200,0)>ROUNDUP(N6/200,0),"Lần " & ROUNDUP(N7/200,0),"")) | R7: =IF(O7="","",IF(ROUNDUP(O7/350,0)>ROUNDUP(O6/350,0),"Lần " & ROUNDUP(O7/350,0),"")) | U7: Bản vẽ: 47,01 → 45,88 m³ (tr.68 thể tích 1 cọc (đã gồm bê tông đầu cọc)). File cũ cộng thêm 1,13 m³ đập đầu cọc vào thể tích đã gồm đầu cọc. Cột 'KL thực tế': thay bằng phiếu đổ (có nở thành) khi có.
A8: 5 | B8: Bê tông cọc khoan nhồi - C2 trụ T1 (L=40m) | D8: 45.88 | E8: =IF(C8="","",C8+7) | F8: =IF(C8="","",C8+28) | G8: 0.445 | H8: 0.525 | I8: 0.696 | M8: =IF(D8="","",ROUND(M7+IF(G8>0,D8*G8,D8*J8),2)) | N8: =IF(D8="","",ROUND(N7+IF(H8>0,D8*H8,D8*K8),2)) | O8: =IF(D8="","",ROUND(O7+IF(I8>0,D8*I8,D8*L8),2)) | P8: =IF(M8="","",IF(ROUNDUP(M8/50,0)>ROUNDUP(M7/50,0),"Lần " & ROUNDUP(M8/50,0),"")) | Q8: =IF(N8="","",IF(ROUNDUP(N8/200,0)>ROUNDUP(N7/200,0),"Lần " & ROUNDUP(N8/200,0),"")) | R8: =IF(O8="","",IF(ROUNDUP(O8/350,0)>ROUNDUP(O7/350,0),"Lần " & ROUNDUP(O8/350,0),"")) | U8: Bản vẽ: 47,01 → 45,88 m³ (tr.68 thể tích 1 cọc (đã gồm bê tông đầu cọc)). File cũ cộng thêm 1,13 m³ đập đầu cọc vào thể tích đã gồm đầu cọc. Cột 'KL thực tế': thay bằng phiếu đổ (có nở thành) khi có.
A9: 6 | B9: Bê tông cọc khoan nhồi - C3 trụ T1 (L=40m) | D9: 45.88 | E9: =IF(C9="","",C9+7) | F9: =IF(C9="","",C9+28) | G9: 0.445 | H9: 0.525 | I9: 0.696 | M9: =IF(D9="","",ROUND(M8+IF(G9>0,D9*G9,D9*J9),2)) | N9: =IF(D9="","",ROUND(N8+IF(H9>0,D9*H9,D9*K9),2)) | O9: =IF(D9="","",ROUND(O8+IF(I9>0,D9*I9,D9*L9),2)) | P9: =IF(M9="","",IF(ROUNDUP(M9/50,0)>ROUNDUP(M8/50,0),"Lần " & ROUNDUP(M9/50,0),"")) | Q9: =IF(N9="","",IF(ROUNDUP(N9/200,0)>ROUNDUP(N8/200,0),"Lần " & ROUNDUP(N9/200,0),"")) | R9: =IF(O9="","",IF(ROUNDUP(O9/350,0)>ROUNDUP(O8/350,0),"Lần " & ROUNDUP(O9/350,0),"")) | U9: Bản vẽ: 47,01 → 45,88 m³ (tr.68 thể tích 1 cọc (đã gồm bê tông đầu cọc)). File cũ cộng thêm 1,13 m³ đập đầu cọc vào thể tích đã gồm đầu cọc. Cột 'KL thực tế': thay bằng phiếu đổ (có nở thành) khi có.
A10: 7 | B10: Bê tông cọc khoan nhồi - C4 trụ T1 (L=40m) | D10: 45.88 | E10: =IF(C10="","",C10+7) | F10: =IF(C10="","",C10+28) | G10: 0.445 | H10: 0.525 | I10: 0.696 | M10: =IF(D10="","",ROUND(M9+IF(G10>0,D10*G10,D10*J10),2)) | N10: =IF(D10="","",ROUND(N9+IF(H10>0,D10*H10,D10*K10),2)) | O10: =IF(D10="","",ROUND(O9+IF(I10>0,D10*I10,D10*L10),2)) | P10: =IF(M10="","",IF(ROUNDUP(M10/50,0)>ROUNDUP(M9/50,0),"Lần " & ROUNDUP(M10/50,0),"")) | Q10: =IF(N10="","",IF(ROUNDUP(N10/200,0)>ROUNDUP(N9/200,0),"Lần " & ROUNDUP(N10/200,0),"")) | R10: =IF(O10="","",IF(ROUNDUP(O10/350,0)>ROUNDUP(O9/350,0),"Lần " & ROUNDUP(O10/350,0),"")) | U10: Bản vẽ: 47,01 → 45,88 m³ (tr.68 thể tích 1 cọc (đã gồm bê tông đầu cọc)). File cũ cộng thêm 1,13 m³ đập đầu cọc vào thể tích đã gồm đầu cọc. Cột 'KL thực tế': thay bằng phiếu đổ (có nở thành) khi có.
A11: 8 | B11: Bê tông cọc khoan nhồi - C5 trụ T1 (L=40m) | D11: 45.88 | E11: =IF(C11="","",C11+7) | F11: =IF(C11="","",C11+28) | G11: 0.445 | H11: 0.525 | I11: 0.696 | M11: =IF(D11="","",ROUND(M10+IF(G11>0,D11*G11,D11*J11),2)) | N11: =IF(D11="","",ROUND(N10+IF(H11>0,D11*H11,D11*K11),2)) | O11: =IF(D11="","",ROUND(O10+IF(I11>0,D11*I11,D11*L11),2)) | P11: =IF(M11="","",IF(ROUNDUP(M11/50,0)>ROUNDUP(M10/50,0),"Lần " & ROUNDUP(M11/50,0),"")) | Q11: =IF(N11="","",IF(ROUNDUP(N11/200,0)>ROUNDUP(N10/200,0),"Lần " & ROUNDUP(N11/200,0),"")) | R11: =IF(O11="","",IF(ROUNDUP(O11/350,0)>ROUNDUP(O10/350,0),"Lần " & ROUNDUP(O11/350,0),"")) | U11: Bản vẽ: 47,01 → 45,88 m³ (tr.68 thể tích 1 cọc (đã gồm bê tông đầu cọc)). File cũ cộng thêm 1,13 m³ đập đầu cọc vào thể tích đã gồm đầu cọc. Cột 'KL thực tế': thay bằng phiếu đổ (có nở thành) khi có.
A12: 9 | B12: Bê tông cọc khoan nhồi - C6 trụ T1 (L=40m) | D12: 45.88 | E12: =IF(C12="","",C12+7) | F12: =IF(C12="","",C12+28) | G12: 0.445 | H12: 0.525 | I12: 0.696 | M12: =IF(D12="","",ROUND(M11+IF(G12>0,D12*G12,D12*J12),2)) | N12: =IF(D12="","",ROUND(N11+IF(H12>0,D12*H12,D12*K12),2)) | O12: =IF(D12="","",ROUND(O11+IF(I12>0,D12*I12,D12*L12),2)) | P12: =IF(M12="","",IF(ROUNDUP(M12/50,0)>ROUNDUP(M11/50,0),"Lần " & ROUNDUP(M12/50,0),"")) | Q12: =IF(N12="","",IF(ROUNDUP(N12/200,0)>ROUNDUP(N11/200,0),"Lần " & ROUNDUP(N12/200,0),"")) | R12: =IF(O12="","",IF(ROUNDUP(O12/350,0)>ROUNDUP(O11/350,0),"Lần " & ROUNDUP(O12/350,0),"")) | U12: Bản vẽ: 47,01 → 45,88 m³ (tr.68 thể tích 1 cọc (đã gồm bê tông đầu cọc)). File cũ cộng thêm 1,13 m³ đập đầu cọc vào thể tích đã gồm đầu cọc. Cột 'KL thực tế': thay bằng phiếu đổ (có nở thành) khi có.
A13: 10 | B13: Bê tông cọc khoan nhồi - C7 trụ T1 (L=40m) | D13: 45.88 | E13: =IF(C13="","",C13+7) | F13: =IF(C13="","",C13+28) | G13: 0.445 | H13: 0.525 | I13: 0.696 | M13: =IF(D13="","",ROUND(M12+IF(G13>0,D13*G13,D13*J13),2)) | N13: =IF(D13="","",ROUND(N12+IF(H13>0,D13*H13,D13*K13),2)) | O13: =IF(D13="","",ROUND(O12+IF(I13>0,D13*I13,D13*L13),2)) | P13: =IF(M13="","",IF(ROUNDUP(M13/50,0)>ROUNDUP(M12/50,0),"Lần " & ROUNDUP(M13/50,0),"")) | Q13: =IF(N13="","",IF(ROUNDUP(N13/200,0)>ROUNDUP(N12/200,0),"Lần " & ROUNDUP(N13/200,0),"")) | R13: =IF(O13="","",IF(ROUNDUP(O13/350,0)>ROUNDUP(O12/350,0),"Lần " & ROUNDUP(O13/350,0),"")) | U13: Bản vẽ: 47,01 → 45,88 m³ (tr.68 thể tích 1 cọc (đã gồm bê tông đầu cọc)). File cũ cộng thêm 1,13 m³ đập đầu cọc vào thể tích đã gồm đầu cọc. Cột 'KL thực tế': thay bằng phiếu đổ (có nở thành) khi có.
A14: 11 | B14: Bê tông cọc khoan nhồi - C8 trụ T1 (L=40m) | D14: 45.88 | E14: =IF(C14="","",C14+7) | F14: =IF(C14="","",C14+28) | G14: 0.445 | H14: 0.525 | I14: 0.696 | M14: =IF(D14="","",ROUND(M13+IF(G14>0,D14*G14,D14*J14),2)) | N14: =IF(D14="","",ROUND(N13+IF(H14>0,D14*H14,D14*K14),2)) | O14: =IF(D14="","",ROUND(O13+IF(I14>0,D14*I14,D14*L14),2)) | P14: =IF(M14="","",IF(ROUNDUP(M14/50,0)>ROUNDUP(M13/50,0),"Lần " & ROUNDUP(M14/50,0),"")) | Q14: =IF(N14="","",IF(ROUNDUP(N14/200,0)>ROUNDUP(N13/200,0),"Lần " & ROUNDUP(N14/200,0),"")) | R14: =IF(O14="","",IF(ROUNDUP(O14/350,0)>ROUNDUP(O13/350,0),"Lần " & ROUNDUP(O14/350,0),"")) | U14: Bản vẽ: 47,01 → 45,88 m³ (tr.68 thể tích 1 cọc (đã gồm bê tông đầu cọc)). File cũ cộng thêm 1,13 m³ đập đầu cọc vào thể tích đã gồm đầu cọc. Cột 'KL thực tế': thay bằng phiếu đổ (có nở thành) khi có.
A15: 12 | B15: Bê tông cọc khoan nhồi - C1 trụ T2 (L=30m) | D15: 34.73 | E15: =IF(C15="","",C15+7) | F15: =IF(C15="","",C15+28) | G15: 0.445 | H15: 0.525 | I15: 0.696 | M15: =IF(D15="","",ROUND(M14+IF(G15>0,D15*G15,D15*J15),2)) | N15: =IF(D15="","",ROUND(N14+IF(H15>0,D15*H15,D15*K15),2)) | O15: =IF(D15="","",ROUND(O14+IF(I15>0,D15*I15,D15*L15),2)) | P15: =IF(M15="","",IF(ROUNDUP(M15/50,0)>ROUNDUP(M14/50,0),"Lần " & ROUNDUP(M15/50,0),"")) | Q15: =IF(N15="","",IF(ROUNDUP(N15/200,0)>ROUNDUP(N14/200,0),"Lần " & ROUNDUP(N15/200,0),"")) | R15: =IF(O15="","",IF(ROUNDUP(O15/350,0)>ROUNDUP(O14/350,0),"Lần " & ROUNDUP(O15/350,0),"")) | U15: Bản vẽ: 35,86 → 34,73 m³ (tr.70 thể tích 1 cọc (đã gồm bê tông đầu cọc)). File cũ cộng thêm 1,13 m³ đập đầu cọc. Thay bằng phiếu đổ thực tế khi có.
A16: 13 | B16: Bê tông cọc khoan nhồi - C2 trụ T2 (L=30m) | D16: 34.73 | E16: =IF(C16="","",C16+7) | F16: =IF(C16="","",C16+28) | G16: 0.445 | H16: 0.525 | I16: 0.696 | M16: =IF(D16="","",ROUND(M15+IF(G16>0,D16*G16,D16*J16),2)) | N16: =IF(D16="","",ROUND(N15+IF(H16>0,D16*H16,D16*K16),2)) | O16: =IF(D16="","",ROUND(O15+IF(I16>0,D16*I16,D16*L16),2)) | P16: =IF(M16="","",IF(ROUNDUP(M16/50,0)>ROUNDUP(M15/50,0),"Lần " & ROUNDUP(M16/50,0),"")) | Q16: =IF(N16="","",IF(ROUNDUP(N16/200,0)>ROUNDUP(N15/200,0),"Lần " & ROUNDUP(N16/200,0),"")) | R16: =IF(O16="","",IF(ROUNDUP(O16/350,0)>ROUNDUP(O15/350,0),"Lần " & ROUNDUP(O16/350,0),"")) | U16: Bản vẽ: 35,86 → 34,73 m³ (tr.70 thể tích 1 cọc (đã gồm bê tông đầu cọc)). File cũ cộng thêm 1,13 m³ đập đầu cọc. Thay bằng phiếu đổ thực tế khi có.
... A29: 26 | B29: Bê tông cọc khoan nhồi - C7 mố M2 (L=36m) | D29: 41.56 | E29: =IF(C29="","",C29+7) | F29: =IF(C29="","",C29+28) | G29: 0.445 | H29: 0.525 | I29: 0.696 | M29: =IF(D29="","",ROUND(M28+IF(G29>0,D29*G29,D29*J29),2)) | N29: =IF(D29="","",ROUND(N28+IF(H29>0,D29*H29,D29*K29),2)) | O29: =IF(D29="","",ROUND(O28+IF(I29>0,D29*I29,D29*L29),2)) | P29: =IF(M29="","",IF(ROUNDUP(M29/50,0)>ROUNDUP(M28/50,0),"Lần " & ROUNDUP(M29/50,0),"")) | Q29: =IF(N29="","",IF(ROUNDUP(N29/200,0)>ROUNDUP(N28/200,0),"Lần " & ROUNDUP(N29/200,0),"")) | R29: =IF(O29="","",IF(ROUNDUP(O29/350,0)>ROUNDUP(O28/350,0),"Lần " & ROUNDUP(O29/350,0),"")) | U29: Bản vẽ: 42,83 → 41,56 m³ (tr.66 thể tích 1 cọc (đã gồm bê tông đầu cọc)). File cũ cộng thêm 1,27 m³ đập đầu cọc. Thay bằng phiếu đổ thực tế khi có.
A30: II. HẠNG MỤC BÊ TÔNG BỆ MỐ & BỆ TRỤ (C30 ĐỘ SỤT 14±2CM)
A31: 27 | B31: Bê tông lót móng bệ mố M1 (M100 đá 4x6) | D31: 2.46 | E31: =IF(C31="","",C31+7) | F31: =IF(C31="","",C31+28) | J31: 0.425 | K31: 0.555 | L31: 0.7 | M31: =IF(D31="","",ROUND(M29+IF(G31>0,D31*G31,D31*J31),2)) | N31: =IF(D31="","",ROUND(N29+IF(H31>0,D31*H31,D31*K31),2)) | O31: =IF(D31="","",ROUND(O29+IF(I31>0,D31*I31,D31*L31),2)) | P31: =IF(M31="","",IF(ROUNDUP(M31/50,0)>ROUNDUP(M29/50,0),"Lần " & ROUNDUP(M31/50,0),"")) | Q31: =IF(N31="","",IF(ROUNDUP(N31/200,0)>ROUNDUP(N29/200,0),"Lần " & ROUNDUP(N31/200,0),"")) | R31: =IF(O31="","",IF(ROUNDUP(O31/350,0)>ROUNDUP(O29/350,0),"Lần " & ROUNDUP(O31/350,0),"")) | U31: Bản vẽ: 9,55 → 2,46 m³ (tr.31 bê tông đệm C10) | Mác M100 chưa có cấp phối riêng — đang dùng cấp phối C30 (0,425 t XM; 0,555 m³ cát; 0,700 m³ đá / m³). Nhập cấp phối được duyệt.
A32: 28 | B32: Bê tông bệ mố M1 (C30 đá 1x2) | D32: 0 | E32: =IF(C32="","",C32+7) | F32: =IF(C32="","",C32+28) | J32: 0.425 | K32: 0.555 | L32: 0.7 | M32: =IF(D32="","",ROUND(M31+IF(G32>0,D32*G32,D32*J32),2)) | N32: =IF(D32="","",ROUND(N31+IF(H32>0,D32*H32,D32*K32),2)) | O32: =IF(D32="","",ROUND(O31+IF(I32>0,D32*I32,D32*L32),2)) | P32: =IF(M32="","",IF(ROUNDUP(M32/50,0)>ROUNDUP(M31/50,0),"Lần " & ROUNDUP(M32/50,0),"")) | Q32: =IF(N32="","",IF(ROUNDUP(N32/200,0)>ROUNDUP(N31/200,0),"Lần " & ROUNDUP(N32/200,0),"")) | R32: =IF(O32="","",IF(ROUNDUP(O32/350,0)>ROUNDUP(O31/350,0),"Lần " & ROUNDUP(O32/350,0),"")) | U32: Bản vẽ: 74,50 → 0,00 m³ (tr.31 không có bệ mố M1). Tr.31 (mố M1 chân dê): tổng 75,12 m³ = tường thân 52,96 + tường đỉnh 14,23 + tường cánh 3,45 + gờ/ụ/tường tai 4,48 — không có bệ mố.
A33: 29 | B33: Bê tông lót móng bệ trụ T1 (M100 đá 4x6) | D33: 8.77 | E33: =IF(C33="","",C33+7) | F33: =IF(C33="","",C33+28) | J33: 0.425 | K33: 0.555 | L33: 0.7 | M33: =IF(D33="","",ROUND(M32+IF(G33>0,D33*G33,D33*J33),2)) | N33: =IF(D33="","",ROUND(N32+IF(H33>0,D33*H33,D33*K33),2)) | O33: =IF(D33="","",ROUND(O32+IF(I33>0,D33*I33,D33*L33),2)) | P33: =IF(M33="","",IF(ROUNDUP(M33/50,0)>ROUNDUP(M32/50,0),"Lần " & ROUNDUP(M33/50,0),"")) | Q33: =IF(N33="","",IF(ROUNDUP(N33/200,0)>ROUNDUP(N32/200,0),"Lần " & ROUNDUP(N33/200,0),"")) | R33: =IF(O33="","",IF(ROUNDUP(O33/350,0)>ROUNDUP(O32/350,0),"Lần " & ROUNDUP(O33/350,0),"")) | U33: Bản vẽ: 12,50 → 8,77 m³ (tr.44 bê tông đệm C10) | Mác M100 chưa có cấp phối riêng — đang dùng cấp phối C30 (0,425 t XM; 0,555 m³ cát; 0,700 m³ đá / m³). Nhập cấp phối được duyệt.
A34: 30 | B34: Bê tông bệ trụ T1 - Đợt 1 (C30 đá 1x2) | D34: 92.12 | E34: =IF(C34="","",C34+7) | F34: =IF(C34="","",C34+28) | J34: 0.425 | K34: 0.555 | L34: 0.7 | M34: =IF(D34="","",ROUND(M33+IF(G34>0,D34*G34,D34*J34),2)) | N34: =IF(D34="","",ROUND(N33+IF(H34>0,D34*H34,D34*K34),2)) | O34: =IF(D34="","",ROUND(O33+IF(I34>0,D34*I34,D34*L34),2)) | P34: =IF(M34="","",IF(ROUNDUP(M34/50,0)>ROUNDUP(M33/50,0),"Lần " & ROUNDUP(M34/50,0),"")) | Q34: =IF(N34="","",IF(ROUNDUP(N34/200,0)>ROUNDUP(N33/200,0),"Lần " & ROUNDUP(N34/200,0),"")) | R34: =IF(O34="","",IF(ROUNDUP(O34/350,0)>ROUNDUP(O33/350,0),"Lần " & ROUNDUP(O34/350,0),"")) | U34: Bản vẽ: 82,50 → 92,12 m³ (tr.44 bệ trụ T1, chia theo tỷ lệ 2 đợt cũ)
A35: 31 | B35: Bê tông bệ trụ T1 - Đợt 2 (C30 đá 1x2) | D35: 92.12 | E35: =IF(C35="","",C35+7) | F35: =IF(C35="","",C35+28) | J35: 0.425 | K35: 0.555 | L35: 0.7 | M35: =IF(D35="","",ROUND(M34+IF(G35>0,D35*G35,D35*J35),2)) | N35: =IF(D35="","",ROUND(N34+IF(H35>0,D35*H35,D35*K35),2)) | O35: =IF(D35="","",ROUND(O34+IF(I35>0,D35*I35,D35*L35),2)) | P35: =IF(M35="","",IF(ROUNDUP(M35/50,0)>ROUNDUP(M34/50,0),"Lần " & ROUNDUP(M35/50,0),"")) | Q35: =IF(N35="","",IF(ROUNDUP(N35/200,0)>ROUNDUP(N34/200,0),"Lần " & ROUNDUP(N35/200,0),"")) | R35: =IF(O35="","",IF(ROUNDUP(O35/350,0)>ROUNDUP(O34/350,0),"Lần " & ROUNDUP(O35/350,0),"")) | U35: Bản vẽ: 82,50 → 92,12 m³ (tr.44 bệ trụ T1, chia theo tỷ lệ 2 đợt cũ)
A36: 32 | B36: Bê tông lót móng bệ trụ T2 (M100 đá 4x6) | D36: 8.77 | E36: =IF(C36="","",C36+7) | F36: =IF(C36="","",C36+28) | J36: 0.425 | K36: 0.555 | L36: 0.7 | M36: =IF(D36="","",ROUND(M35+IF(G36>0,D36*G36,D36*J36),2)) | N36: =IF(D36="","",ROUND(N35+IF(H36>0,D36*H36,D36*K36),2)) | O36: =IF(D36="","",ROUND(O35+IF(I36>0,D36*I36,D36*L36),2)) | P36: =IF(M36="","",IF(ROUNDUP(M36/50,0)>ROUNDUP(M35/50,0),"Lần " & ROUNDUP(M36/50,0),"")) | Q36: =IF(N36="","",IF(ROUNDUP(N36/200,0)>ROUNDUP(N35/200,0),"Lần " & ROUNDUP(N36/200,0),"")) | R36: =IF(O36="","",IF(ROUNDUP(O36/350,0)>ROUNDUP(O35/350,0),"Lần " & ROUNDUP(O36/350,0),"")) | U36: Bản vẽ: 12,50 → 8,77 m³ (tr.55 bê tông đệm C10) | Mác M100 chưa có cấp phối riêng — đang dùng cấp phối C30 (0,425 t XM; 0,555 m³ cát; 0,700 m³ đá / m³). Nhập cấp phối được duyệt.
A37: 33 | B37: Bê tông bệ trụ T2 - Đợt 1 (C30 đá 1x2) | D37: 92.12 | E37: =IF(C37="","",C37+7) | F37: =IF(C37="","",C37+28) | J37: 0.425 | K37: 0.555 | L37: 0.7 | M37: =IF(D37="","",ROUND(M36+IF(G37>0,D37*G37,D37*J37),2)) | N37: =IF(D37="","",ROUND(N36+IF(H37>0,D37*H37,D37*K37),2)) | O37: =IF(D37="","",ROUND(O36+IF(I37>0,D37*I37,D37*L37),2)) | P37: =IF(M37="","",IF(ROUNDUP(M37/50,0)>ROUNDUP(M36/50,0),"Lần " & ROUNDUP(M37/50,0),"")) | Q37: =IF(N37="","",IF(ROUNDUP(N37/200,0)>ROUNDUP(N36/200,0),"Lần " & ROUNDUP(N37/200,0),"")) | R37: =IF(O37="","",IF(ROUNDUP(O37/350,0)>ROUNDUP(O36/350,0),"Lần " & ROUNDUP(O37/350,0),"")) | U37: Bản vẽ: 82,50 → 92,12 m³ (tr.55 bệ trụ T2, chia theo tỷ lệ 2 đợt cũ)
A38: 34 | B38: Bê tông bệ trụ T2 - Đợt 2 (C30 đá 1x2) | D38: 92.12 | E38: =IF(C38="","",C38+7) | F38: =IF(C38="","",C38+28) | J38: 0.425 | K38: 0.555 | L38: 0.7 | M38: =IF(D38="","",ROUND(M37+IF(G38>0,D38*G38,D38*J38),2)) | N38: =IF(D38="","",ROUND(N37+IF(H38>0,D38*H38,D38*K38),2)) | O38: =IF(D38="","",ROUND(O37+IF(I38>0,D38*I38,D38*L38),2)) | P38: =IF(M38="","",IF(ROUNDUP(M38/50,0)>ROUNDUP(M37/50,0),"Lần " & ROUNDUP(M38/50,0),"")) | Q38: =IF(N38="","",IF(ROUNDUP(N38/200,0)>ROUNDUP(N37/200,0),"Lần " & ROUNDUP(N38/200,0),"")) | R38: =IF(O38="","",IF(ROUNDUP(O38/350,0)>ROUNDUP(O37/350,0),"Lần " & ROUNDUP(O38/350,0),"")) | U38: Bản vẽ: 82,50 → 92,12 m³ (tr.55 bệ trụ T2, chia theo tỷ lệ 2 đợt cũ)
A39: 35 | B39: Bê tông lót móng bệ mố M2 (M100 đá 4x6) | D39: 7.09 | E39: =IF(C39="","",C39+7) | F39: =IF(C39="","",C39+28) | J39: 0.425 | K39: 0.555 | L39: 0.7 | M39: =IF(D39="","",ROUND(M38+IF(G39>0,D39*G39,D39*J39),2)) | N39: =IF(D39="","",ROUND(N38+IF(H39>0,D39*H39,D39*K39),2)) | O39: =IF(D39="","",ROUND(O38+IF(I39>0,D39*I39,D39*L39),2)) | P39: =IF(M39="","",IF(ROUNDUP(M39/50,0)>ROUNDUP(M38/50,0),"Lần " & ROUNDUP(M39/50,0),"")) | Q39: =IF(N39="","",IF(ROUNDUP(N39/200,0)>ROUNDUP(N38/200,0),"Lần " & ROUNDUP(N39/200,0),"")) | R39: =IF(O39="","",IF(ROUNDUP(O39/350,0)>ROUNDUP(O38/350,0),"Lần " & ROUNDUP(O39/350,0),"")) | U39: Bản vẽ: 9,55 → 7,09 m³ (tr.40 bê tông đệm C10). File cũ 9,55 m³ là tổng đệm của CẢ 2 mố (tr.175). | Mác M100 chưa có cấp phối riêng — đang dùng cấp phối C30 (0,425 t XM; 0,555 m³ cát; 0,700 m³ đá / m³). Nhập cấp phối được duyệt.
A40: 36 | B40: Bê tông bệ mố M2 (C30 đá 1x2) | D40: 148.99 | E40: =IF(C40="","",C40+7) | F40: =IF(C40="","",C40+28) | J40: 0.425 | K40: 0.555 | L40: 0.7 | M40: =IF(D40="","",ROUND(M39+IF(G40>0,D40*G40,D40*J40),2)) | N40: =IF(D40="","",ROUND(N39+IF(H40>0,D40*H40,D40*K40),2)) | O40: =IF(D40="","",ROUND(O39+IF(I40>0,D40*I40,D40*L40),2)) | P40: =IF(M40="","",IF(ROUNDUP(M40/50,0)>ROUNDUP(M39/50,0),"Lần " & ROUNDUP(M40/50,0),"")) | Q40: =IF(N40="","",IF(ROUNDUP(N40/200,0)>ROUNDUP(N39/200,0),"Lần " & ROUNDUP(N40/200,0),"")) | R40: =IF(O40="","",IF(ROUNDUP(O40/350,0)>ROUNDUP(O39/350,0),"Lần " & ROUNDUP(O40/350,0),"")) | U40: Bản vẽ: 74,50 → 148,99 m³ (tr.40 bệ mố M2)
A41: III. HẠNG MỤC THÂN TRỤ, THÂN MỐ & XÀ MŨ (CÁC ĐỐT LÊN HOÀN THIỆN)
A42: 37 | B42: Bê tông thân trụ T1 - Đốt 1 (C30 đá 1x2) | D42: 80.87 | E42: =IF(C42="","",C42+7) | F42: =IF(C42="","",C42+28) | J42: 0.425 | K42: 0.555 | L42: 0.7 | M42: =IF(D42="","",ROUND(M40+IF(G42>0,D42*G42,D42*J42),2)) | N42: =IF(D42="","",ROUND(N40+IF(H42>0,D42*H42,D42*K42),2)) | O42: =IF(D42="","",ROUND(O40+IF(I42>0,D42*I42,D42*L42),2)) | P42: =IF(M42="","",IF(ROUNDUP(M42/50,0)>ROUNDUP(M40/50,0),"Lần " & ROUNDUP(M42/50,0),"")) | Q42: =IF(N42="","",IF(ROUNDUP(N42/200,0)>ROUNDUP(N40/200,0),"Lần " & ROUNDUP(N42/200,0),"")) | R42: =IF(O42="","",IF(ROUNDUP(O42/350,0)>ROUNDUP(O40/350,0),"Lần " & ROUNDUP(O42/350,0),"")) | U42: Bản vẽ: 42,00 → 80,87 m³ (tr.48 thân trụ T1, chia theo tỷ lệ 3 đốt cũ). Bản vẽ 234,92 m³ (file cũ 122 m³) — chia 3 đốt theo tỷ lệ cũ; xác nhận chiều cao từng đốt.
A43: 38 | B43: Bê tông thân trụ T1 - Đốt 2 (C30 đá 1x2) | D43: 80.87 | E43: =IF(C43="","",C43+7) | F43: =IF(C43="","",C43+28) | J43: 0.425 | K43: 0.555 | L43: 0.7 | M43: =IF(D43="","",ROUND(M42+IF(G43>0,D43*G43,D43*J43),2)) | N43: =IF(D43="","",ROUND(N42+IF(H43>0,D43*H43,D43*K43),2)) | O43: =IF(D43="","",ROUND(O42+IF(I43>0,D43*I43,D43*L43),2)) | P43: =IF(M43="","",IF(ROUNDUP(M43/50,0)>ROUNDUP(M42/50,0),"Lần " & ROUNDUP(M43/50,0),"")) | Q43: =IF(N43="","",IF(ROUNDUP(N43/200,0)>ROUNDUP(N42/200,0),"Lần " & ROUNDUP(N43/200,0),"")) | R43: =IF(O43="","",IF(ROUNDUP(O43/350,0)>ROUNDUP(O42/350,0),"Lần " & ROUNDUP(O43/350,0),"")) | U43: Bản vẽ: 42,00 → 80,87 m³ (tr.48 thân trụ T1, chia theo tỷ lệ 3 đốt cũ). Bản vẽ 234,92 m³ (file cũ 122 m³) — chia 3 đốt theo tỷ lệ cũ; xác nhận chiều cao từng đốt.
A44: 39 | B44: Bê tông thân trụ T1 - Đốt 3 (C30 đá 1x2) | D44: 73.18 | E44: =IF(C44="","",C44+7) | F44: =IF(C44="","",C44+28) | J44: 0.425 | K44: 0.555 | L44: 0.7 | M44: =IF(D44="","",ROUND(M43+IF(G44>0,D44*G44,D44*J44),2)) | N44: =IF(D44="","",ROUND(N43+IF(H44>0,D44*H44,D44*K44),2)) | O44: =IF(D44="","",ROUND(O43+IF(I44>0,D44*I44,D44*L44),2)) | P44: =IF(M44="","",IF(ROUNDUP(M44/50,0)>ROUNDUP(M43/50,0),"Lần " & ROUNDUP(M44/50,0),"")) | Q44: =IF(N44="","",IF(ROUNDUP(N44/200,0)>ROUNDUP(N43/200,0),"Lần " & ROUNDUP(N44/200,0),"")) | R44: =IF(O44="","",IF(ROUNDUP(O44/350,0)>ROUNDUP(O43/350,0),"Lần " & ROUNDUP(O44/350,0),"")) | U44: Bản vẽ: 38,00 → 73,18 m³ (tr.48 thân trụ T1, chia theo tỷ lệ 3 đốt cũ). Bản vẽ 234,92 m³ (file cũ 122 m³) — chia 3 đốt theo tỷ lệ cũ; xác nhận chiều cao từng đốt.
A45: 40 | B45: Bê tông xà mũ trụ T1 & đá kê gối (C35/C30 đá 1x2) | D45: 72.51 | E45: =IF(C45="","",C45+7) | F45: =IF(C45="","",C45+28) | J45: 0.425 | K45: 0.555 | L45: 0.7 | M45: =IF(D45="","",ROUND(M44+IF(G45>0,D45*G45,D45*J45),2)) | N45: =IF(D45="","",ROUND(N44+IF(H45>0,D45*H45,D45*K45),2)) | O45: =IF(D45="","",ROUND(O44+IF(I45>0,D45*I45,D45*L45),2)) | P45: =IF(M45="","",IF(ROUNDUP(M45/50,0)>ROUNDUP(M44/50,0),"Lần " & ROUNDUP(M45/50,0),"")) | Q45: =IF(N45="","",IF(ROUNDUP(N45/200,0)>ROUNDUP(N44/200,0),"Lần " & ROUNDUP(N45/200,0),"")) | R45: =IF(O45="","",IF(ROUNDUP(O45/350,0)>ROUNDUP(O44/350,0),"Lần " & ROUNDUP(O45/350,0),"")) | U45: Bản vẽ: 45,00 → 72,51 m³ (tr.51 xà mũ trụ T1) | Mác C35 chưa có cấp phối riêng — đang dùng cấp phối C30 (0,425 t XM; 0,555 m³ cát; 0,700 m³ đá / m³). Nhập cấp phối được duyệt.
A46: 41 | B46: Bê tông thân trụ T2 - Đốt 1 (C30 đá 1x2) | D46: 90.95 | E46: =IF(C46="","",C46+7) | F46: =IF(C46="","",C46+28) | J46: 0.425 | K46: 0.555 | L46: 0.7 | M46: =IF(D46="","",ROUND(M45+IF(G46>0,D46*G46,D46*J46),2)) | N46: =IF(D46="","",ROUND(N45+IF(H46>0,D46*H46,D46*K46),2)) | O46: =IF(D46="","",ROUND(O45+IF(I46>0,D46*I46,D46*L46),2)) | P46: =IF(M46="","",IF(ROUNDUP(M46/50,0)>ROUNDUP(M45/50,0),"Lần " & ROUNDUP(M46/50,0),"")) | Q46: =IF(N46="","",IF(ROUNDUP(N46/200,0)>ROUNDUP(N45/200,0),"Lần " & ROUNDUP(N46/200,0),"")) | R46: =IF(O46="","",IF(ROUNDUP(O46/350,0)>ROUNDUP(O45/350,0),"Lần " & ROUNDUP(O46/350,0),"")) | U46: Bản vẽ: 45,00 → 90,95 m³ (tr.59 thân trụ T2, chia theo tỷ lệ 3 đốt cũ). Bản vẽ 266,79 m³ (file cũ 132 m³) — chia 3 đốt theo tỷ lệ cũ; xác nhận chiều cao từng đốt.
A47: 42 | B47: Bê tông thân trụ T2 - Đốt 2 (C30 đá 1x2) | D47: 90.95 | E47: =IF(C47="","",C47+7) | F47: =IF(C47="","",C47+28) | J47: 0.425 | K47: 0.555 | L47: 0.7 | M47: =IF(D47="","",ROUND(M46+IF(G47>0,D47*G47,D47*J47),2)) | N47: =IF(D47="","",ROUND(N46+IF(H47>0,D47*H47,D47*K47),2)) | O47: =IF(D47="","",ROUND(O46+IF(I47>0,D47*I47,D47*L47),2)) | P47: =IF(M47="","",IF(ROUNDUP(M47/50,0)>ROUNDUP(M46/50,0),"Lần " & ROUNDUP(M47/50,0),"")) | Q47: =IF(N47="","",IF(ROUNDUP(N47/200,0)>ROUNDUP(N46/200,0),"Lần " & ROUNDUP(N47/200,0),"")) | R47: =IF(O47="","",IF(ROUNDUP(O47/350,0)>ROUNDUP(O46/350,0),"Lần " & ROUNDUP(O47/350,0),"")) | U47: Bản vẽ: 45,00 → 90,95 m³ (tr.59 thân trụ T2, chia theo tỷ lệ 3 đốt cũ). Bản vẽ 266,79 m³ (file cũ 132 m³) — chia 3 đốt theo tỷ lệ cũ; xác nhận chiều cao từng đốt.
A48: 43 | B48: Bê tông thân trụ T2 - Đốt 3 (C30 đá 1x2) | D48: 84.89 | E48: =IF(C48="","",C48+7) | F48: =IF(C48="","",C48+28) | J48: 0.425 | K48: 0.555 | L48: 0.7 | M48: =IF(D48="","",ROUND(M47+IF(G48>0,D48*G48,D48*J48),2)) | N48: =IF(D48="","",ROUND(N47+IF(H48>0,D48*H48,D48*K48),2)) | O48: =IF(D48="","",ROUND(O47+IF(I48>0,D48*I48,D48*L48),2)) | P48: =IF(M48="","",IF(ROUNDUP(M48/50,0)>ROUNDUP(M47/50,0),"Lần " & ROUNDUP(M48/50,0),"")) | Q48: =IF(N48="","",IF(ROUNDUP(N48/200,0)>ROUNDUP(N47/200,0),"Lần " & ROUNDUP(N48/200,0),"")) | R48: =IF(O48="","",IF(ROUNDUP(O48/350,0)>ROUNDUP(O47/350,0),"Lần " & ROUNDUP(O48/350,0),"")) | U48: Bản vẽ: 42,00 → 84,89 m³ (tr.59 thân trụ T2, chia theo tỷ lệ 3 đốt cũ). Bản vẽ 266,79 m³ (file cũ 132 m³) — chia 3 đốt theo tỷ lệ cũ; xác nhận chiều cao từng đốt.
A49: 44 | B49: Bê tông xà mũ trụ T2 & đá kê gối (C35/C30 đá 1x2) | D49: 72.51 | E49: =IF(C49="","",C49+7) | F49: =IF(C49="","",C49+28) | J49: 0.425 | K49: 0.555 | L49: 0.7 | M49: =IF(D49="","",ROUND(M48+IF(G49>0,D49*G49,D49*J49),2)) | N49: =IF(D49="","",ROUND(N48+IF(H49>0,D49*H49,D49*K49),2)) | O49: =IF(D49="","",ROUND(O48+IF(I49>0,D49*I49,D49*L49),2)) | P49: =IF(M49="","",IF(ROUNDUP(M49/50,0)>ROUNDUP(M48/50,0),"Lần " & ROUNDUP(M49/50,0),"")) | Q49: =IF(N49="","",IF(ROUNDUP(N49/200,0)>ROUNDUP(N48/200,0),"Lần " & ROUNDUP(N49/200,0),"")) | R49: =IF(O49="","",IF(ROUNDUP(O49/350,0)>ROUNDUP(O48/350,0),"Lần " & ROUNDUP(O49/350,0),"")) | U49: Bản vẽ: 45,00 → 72,51 m³ (tr.62 xà mũ trụ T2) | Mác C35 chưa có cấp phối riêng — đang dùng cấp phối C30 (0,425 t XM; 0,555 m³ cát; 0,700 m³ đá / m³). Nhập cấp phối được duyệt.
A50: 45 | B50: Bê tông tường thân mố M1 - Đợt 1 (C30 đá 1x2) | D50: 28.22 | E50: =IF(C50="","",C50+7) | F50: =IF(C50="","",C50+28) | J50: 0.425 | K50: 0.555 | L50: 0.7 | M50: =IF(D50="","",ROUND(M49+IF(G50>0,D50*G50,D50*J50),2)) | N50: =IF(D50="","",ROUND(N49+IF(H50>0,D50*H50,D50*K50),2)) | O50: =IF(D50="","",ROUND(O49+IF(I50>0,D50*I50,D50*L50),2)) | P50: =IF(M50="","",IF(ROUNDUP(M50/50,0)>ROUNDUP(M49/50,0),"Lần " & ROUNDUP(M50/50,0),"")) | Q50: =IF(N50="","",IF(ROUNDUP(N50/200,0)>ROUNDUP(N49/200,0),"Lần " & ROUNDUP(N50/200,0),"")) | R50: =IF(O50="","",IF(ROUNDUP(O50/350,0)>ROUNDUP(O49/350,0),"Lần " & ROUNDUP(O50/350,0),"")) | U50: Bản vẽ: 45,00 → 28,22 m³ (tr.31 tường thân mố M1, chia theo tỷ lệ 2 đợt cũ). Bản vẽ 52,96 m³ (file cũ 84,44 m³, giống số của mố M2) — chia 2 đợt theo tỷ lệ cũ; xác nhận cao độ mạch ngừng.
A51: 46 | B51: Bê tông tường thân mố M1 - Đợt 2 (C30 đá 1x2) | D51: 24.74 | E51: =IF(C51="","",C51+7) | F51: =IF(C51="","",C51+28) | J51: 0.425 | K51: 0.555 | L51: 0.7 | M51: =IF(D51="","",ROUND(M50+IF(G51>0,D51*G51,D51*J51),2)) | N51: =IF(D51="","",ROUND(N50+IF(H51>0,D51*H51,D51*K51),2)) | O51: =IF(D51="","",ROUND(O50+IF(I51>0,D51*I51,D51*L51),2)) | P51: =IF(M51="","",IF(ROUNDUP(M51/50,0)>ROUNDUP(M50/50,0),"Lần " & ROUNDUP(M51/50,0),"")) | Q51: =IF(N51="","",IF(ROUNDUP(N51/200,0)>ROUNDUP(N50/200,0),"Lần " & ROUNDUP(N51/200,0),"")) | R51: =IF(O51="","",IF(ROUNDUP(O51/350,0)>ROUNDUP(O50/350,0),"Lần " & ROUNDUP(O51/350,0),"")) | U51: Bản vẽ: 39,44 → 24,74 m³ (tr.31 tường thân mố M1, chia theo tỷ lệ 2 đợt cũ). Bản vẽ 52,96 m³ (file cũ 84,44 m³, giống số của mố M2) — chia 2 đợt theo tỷ lệ cũ; xác nhận cao độ mạch ngừng.
A52: 47 | B52: Bê tông tường đỉnh mố M1 & đá kê gối (C30) | D52: 14.23 | E52: =IF(C52="","",C52+7) | F52: =IF(C52="","",C52+28) | J52: 0.425 | K52: 0.555 | L52: 0.7 | M52: =IF(D52="","",ROUND(M51+IF(G52>0,D52*G52,D52*J52),2)) | N52: =IF(D52="","",ROUND(N51+IF(H52>0,D52*H52,D52*K52),2)) | O52: =IF(D52="","",ROUND(O51+IF(I52>0,D52*I52,D52*L52),2)) | P52: =IF(M52="","",IF(ROUNDUP(M52/50,0)>ROUNDUP(M51/50,0),"Lần " & ROUNDUP(M52/50,0),"")) | Q52: =IF(N52="","",IF(ROUNDUP(N52/200,0)>ROUNDUP(N51/200,0),"Lần " & ROUNDUP(N52/200,0),"")) | R52: =IF(O52="","",IF(ROUNDUP(O52/350,0)>ROUNDUP(O51/350,0),"Lần " & ROUNDUP(O52/350,0),"")) | U52: Bản vẽ: 14,33 → 14,23 m³ (tr.31 tường đỉnh mố M1)
...

Sheet Theo_Doi_Tan_Suat_Cot_Thep
A1: STT | B1: HẠNG MỤC CẤU KIỆN | C1: BỘ PHẬN / VỊ TRÍ CHI TIẾT | D1: KÝ HIỆU THANH | E1: ĐƯỜNG KÍNH Ø (mm) | F1: MÁC THÉP / TIÊU CHUẨN | G1: HÌNH DẠNG / QUY CÁCH | H1: CHIỀU DÀI 1 THANH (m) | I1: SỐ LƯỢNG (Thanh) | J1: TRỌNG LƯỢNG 1M (kg/m) | K1: TỔNG KL (kg) | L1: KHỐI LƯỢNG (Tấn) | M1: N/T/N LẮP DỰNG | N1: SỐ LÔ / HEAT NO CO-CQ RIÊNG TỪNG Ø | O1: CẢNH BÁO LẤY MẪU TN KÉO/UỐN (20T/LẦN) | P1: KHỐI LƯỢNG LŨY KẾ THEO TỪNG LOẠI ĐƯỜNG KÍNH Ø (TẤN) | AA1: TẦN SUẤT THÍ NGHIỆM CƠ LÝ KÉO / UỐN RIÊNG TỪNG Ø (20 TẤN / LẦN - TCVN 1651:2018) | AL1: ĐÁNH GIÁ & KẾT LUẬN | AN1: LOẠI HẠNG MỤC (OFFSET) | AO1: DÒNG BÊ TÔNG ĐỐI CHIẾU | AQ1: LOẠI HẠNG MỤC | AR1: LÙI (ngày)
P2: Ø10 (kèm Ø6, Ø8) (CB240-T) | Q2: Ø12 (CB400-V) | R2: Ø14 (CB400-V) | S2: Ø16 (CB400-V) | T2: Ø18 (CB400-V) | U2: Ø20 (CB400-V) | V2: Ø22 (CB400-V) | W2: Ø25 (CB400-V) | X2: Ø28 (CB400-V) | Y2: Ø32 (CB400-V) | Z2: Cáp DƯL 15.2 (ASTM A416) | AA2: TN Ø10 20T / Lần | AB2: TN Ø12 20T / Lần | AC2: TN Ø14 20T / Lần | AD2: TN Ø16 20T / Lần | AE2: TN Ø18 20T / Lần | AF2: TN Ø20 20T / Lần | AG2: TN Ø22 20T / Lần | AH2: TN Ø25 20T / Lần | AI2: TN Ø28 20T / Lần | AJ2: TN Ø32 20T / Lần | AK2: TN Cáp 15.2 20T / Lần | AQ2: Coc | AR2: 1
A3: --- MỐ M1 --- | AQ3: Be | AR3: 3
A4: 1 | B4: Mố M1 | C4: Mố M1 (tr.31) | D4: M1 | E4: 28 | F4: CB400-V | H4: 14.213 | I4: 13 | J4: 4.834 | K4: =ROUND(H4*I4*J4, 2) | L4: =ROUND(K4/1000, 3) | M4: =IF(AO4="","",IF(INDEX(Theo_Doi_Tan_Suat_Be_Tong!$C:$C,AO4)="","",INDEX(Theo_Doi_Tan_Suat_Be_Tong!$C:$C,AO4)-VLOOKUP(AN4,$AQ$2:$AR$7,2,FALSE))) | O4: =IF(ROUNDUP(X4/20,0)>0,"TN Ø28 (Lần " & ROUNDUP(X4/20,0) & ")","") | P4: =ROUND(IF(AND(E4<=10,F4<>"ASTM A416"),L4,0),3) | Q4: =ROUND(IF(AND(E4=12,F4<>"ASTM A416"),L4,0),3) | R4: =ROUND(IF(AND(E4=14,F4<>"ASTM A416"),L4,0),3) | S4: =ROUND(IF(AND(E4=16,F4<>"ASTM A416"),L4,0),3) | T4: =ROUND(IF(AND(E4=18,F4<>"ASTM A416"),L4,0),3) | U4: =ROUND(IF(AND(E4=20,F4<>"ASTM A416"),L4,0),3) | V4: =ROUND(IF(AND(E4=22,F4<>"ASTM A416"),L4,0),3) | W4: =ROUND(IF(AND(E4=25,F4<>"ASTM A416"),L4,0),3) | X4: =ROUND(IF(AND(E4=28,F4<>"ASTM A416"),L4,0),3) | Y4: =ROUND(IF(AND(E4=32,F4<>"ASTM A416"),L4,0),3) | Z4: =ROUND(IF(F4="ASTM A416",L4,0),3) | AA4: =IF(ROUNDUP(P4/20,0)>0,"Lần " & ROUNDUP(P4/20,0),"") | AB4: =IF(ROUNDUP(Q4/20,0)>0,"Lần " & ROUNDUP(Q4/20,0),"") | AC4: =IF(ROUNDUP(R4/20,0)>0,"Lần " & ROUNDUP(R4/20,0),"") | AD4: =IF(ROUNDUP(S4/20,0)>0,"Lần " & ROUNDUP(S4/20,0),"") | AE4: =IF(ROUNDUP(T4/20,0)>0,"Lần " & ROUNDUP(T4/20,0),"") | AF4: =IF(ROUNDUP(U4/20,0)>0,"Lần " & ROUNDUP(U4/20,0),"") | AG4: =IF(ROUNDUP(V4/20,0)>0,"Lần " & ROUNDUP(V4/20,0),"") | AH4: =IF(ROUNDUP(W4/20,0)>0,"Lần " & ROUNDUP(W4/20,0),"") | ... AK4: =IF(ROUNDUP(Z4/20,0)>0,"Lần " & ROUNDUP(Z4/20,0),"") | AN4: Than | AO4: 50 | AQ4: Than | AR4: 2
A5: 2 | B5: Mố M1 | C5: Mố M1 (tr.31) | D5: A1 | E5: 16 | F5: CB400-V | H5: 7.857 | I5: 166 | J5: 1.578 | K5: =ROUND(H5*I5*J5, 2) | L5: =ROUND(K5/1000, 3) | M5: =IF(AO5="","",IF(INDEX(Theo_Doi_Tan_Suat_Be_Tong!$C:$C,AO5)="","",INDEX(Theo_Doi_Tan_Suat_Be_Tong!$C:$C,AO5)-VLOOKUP(AN5,$AQ$2:$AR$7,2,FALSE))) | O5: =IF(ROUNDUP(S5/20,0)>ROUNDUP(S4/20,0),"TN Ø16 (Lần " & ROUNDUP(S5/20,0) & ")","") | P5: =ROUND(P4+IF(AND(E5<=10,F5<>"ASTM A416"),L5,0),3) | Q5: =ROUND(Q4+IF(AND(E5=12,F5<>"ASTM A416"),L5,0),3) | R5: =ROUND(R4+IF(AND(E5=14,F5<>"ASTM A416"),L5,0),3) | S5: =ROUND(S4+IF(AND(E5=16,F5<>"ASTM A416"),L5,0),3) | T5: =ROUND(T4+IF(AND(E5=18,F5<>"ASTM A416"),L5,0),3) | U5: =ROUND(U4+IF(AND(E5=20,F5<>"ASTM A416"),L5,0),3) | V5: =ROUND(V4+IF(AND(E5=22,F5<>"ASTM A416"),L5,0),3) | W5: =ROUND(W4+IF(AND(E5=25,F5<>"ASTM A416"),L5,0),3) | X5: =ROUND(X4+IF(AND(E5=28,F5<>"ASTM A416"),L5,0),3) | Y5: =ROUND(Y4+IF(AND(E5=32,F5<>"ASTM A416"),L5,0),3) | Z5: =ROUND(Z4+IF(F5="ASTM A416",L5,0),3) | AA5: =IF(ROUNDUP(P5/20,0)>ROUNDUP(P4/20,0),"Lần " & ROUNDUP(P5/20,0),"") | AB5: =IF(ROUNDUP(Q5/20,0)>ROUNDUP(Q4/20,0),"Lần " & ROUNDUP(Q5/20,0),"") | AC5: =IF(ROUNDUP(R5/20,0)>ROUNDUP(R4/20,0),"Lần " & ROUNDUP(R5/20,0),"") | AD5: =IF(ROUNDUP(S5/20,0)>ROUNDUP(S4/20,0),"Lần " & ROUNDUP(S5/20,0),"") | AE5: =IF(ROUNDUP(T5/20,0)>ROUNDUP(T4/20,0),"Lần " & ROUNDUP(T5/20,0),"") | AF5: =IF(ROUNDUP(U5/20,0)>ROUNDUP(U4/20,0),"Lần " & ROUNDUP(U5/20,0),"") | AG5: =IF(ROUNDUP(V5/20,0)>ROUNDUP(V4/20,0),"Lần " & ROUNDUP(V5/20,0),"") | AH5: =IF(ROUNDUP(W5/20,0)>ROUNDUP(W4/20,0),"Lần " & ROUNDUP(W5/20,0),"") | ... AK5: =IF(ROUNDUP(Z5/20,0)>ROUNDUP(Z4/20,0),"Lần " & ROUNDUP(Z5/20,0),"") | AN5: Than | AO5: 50 | AQ5: Dam | AR5: 4
A6: 3 | B6: Mố M1 | C6: Mố M1 (tr.31) | D6: A2 | E6: 16 | F6: CB400-V | H6: 13.437 | I6: 12 | J6: 1.578 | K6: =ROUND(H6*I6*J6, 2) | L6: =ROUND(K6/1000, 3) | M6: =IF(AO6="","",IF(INDEX(Theo_Doi_Tan_Suat_Be_Tong!$C:$C,AO6)="","",INDEX(Theo_Doi_Tan_Suat_Be_Tong!$C:$C,AO6)-VLOOKUP(AN6,$AQ$2:$AR$7,2,FALSE))) | O6: =IF(ROUNDUP(S6/20,0)>ROUNDUP(S5/20,0),"TN Ø16 (Lần " & ROUNDUP(S6/20,0) & ")","") | P6: =ROUND(P5+IF(AND(E6<=10,F6<>"ASTM A416"),L6,0),3) | Q6: =ROUND(Q5+IF(AND(E6=12,F6<>"ASTM A416"),L6,0),3) | R6: =ROUND(R5+IF(AND(E6=14,F6<>"ASTM A416"),L6,0),3) | S6: =ROUND(S5+IF(AND(E6=16,F6<>"ASTM A416"),L6,0),3) | T6: =ROUND(T5+IF(AND(E6=18,F6<>"ASTM A416"),L6,0),3) | U6: =ROUND(U5+IF(AND(E6=20,F6<>"ASTM A416"),L6,0),3) | V6: =ROUND(V5+IF(AND(E6=22,F6<>"ASTM A416"),L6,0),3) | W6: =ROUND(W5+IF(AND(E6=25,F6<>"ASTM A416"),L6,0),3) | X6: =ROUND(X5+IF(AND(E6=28,F6<>"ASTM A416"),L6,0),3) | Y6: =ROUND(Y5+IF(AND(E6=32,F6<>"ASTM A416"),L6,0),3) | Z6: =ROUND(Z5+IF(F6="ASTM A416",L6,0),3) | AA6: =IF(ROUNDUP(P6/20,0)>ROUNDUP(P5/20,0),"Lần " & ROUNDUP(P6/20,0),"") | AB6: =IF(ROUNDUP(Q6/20,0)>ROUNDUP(Q5/20,0),"Lần " & ROUNDUP(Q6/20,0),"") | AC6: =IF(ROUNDUP(R6/20,0)>ROUNDUP(R5/20,0),"Lần " & ROUNDUP(R6/20,0),"") | AD6: =IF(ROUNDUP(S6/20,0)>ROUNDUP(S5/20,0),"Lần " & ROUNDUP(S6/20,0),"") | AE6: =IF(ROUNDUP(T6/20,0)>ROUNDUP(T5/20,0),"Lần " & ROUNDUP(T6/20,0),"") | AF6: =IF(ROUNDUP(U6/20,0)>ROUNDUP(U5/20,0),"Lần " & ROUNDUP(U6/20,0),"") | AG6: =IF(ROUNDUP(V6/20,0)>ROUNDUP(V5/20,0),"Lần " & ROUNDUP(V6/20,0),"") | AH6: =IF(ROUNDUP(W6/20,0)>ROUNDUP(W5/20,0),"Lần " & ROUNDUP(W6/20,0),"") | ... AK6: =IF(ROUNDUP(Z6/20,0)>ROUNDUP(Z5/20,0),"Lần " & ROUNDUP(Z6/20,0),"") | AN6: Than | AO6: 50 | AQ6: HoanThien | AR6: 2
A7: 4 | B7: Mố M1 | C7: Mố M1 (tr.31) | D7: A2A | E7: 16 | F7: CB400-V | H7: 5.371 | I7: 1 | J7: 1.578 | K7: =ROUND(H7*I7*J7, 2) | L7: =ROUND(K7/1000, 3) | M7: =IF(AO7="","",IF(INDEX(Theo_Doi_Tan_Suat_Be_Tong!$C:$C,AO7)="","",INDEX(Theo_Doi_Tan_Suat_Be_Tong!$C:$C,AO7)-VLOOKUP(AN7,$AQ$2:$AR$7,2,FALSE))) | O7: =IF(ROUNDUP(S7/20,0)>ROUNDUP(S6/20,0),"TN Ø16 (Lần " & ROUNDUP(S7/20,0) & ")","") | P7: =ROUND(P6+IF(AND(E7<=10,F7<>"ASTM A416"),L7,0),3) | Q7: =ROUND(Q6+IF(AND(E7=12,F7<>"ASTM A416"),L7,0),3) | R7: =ROUND(R6+IF(AND(E7=14,F7<>"ASTM A416"),L7,0),3) | S7: =ROUND(S6+IF(AND(E7=16,F7<>"ASTM A416"),L7,0),3) | T7: =ROUND(T6+IF(AND(E7=18,F7<>"ASTM A416"),L7,0),3) | U7: =ROUND(U6+IF(AND(E7=20,F7<>"ASTM A416"),L7,0),3) | V7: =ROUND(V6+IF(AND(E7=22,F7<>"ASTM A416"),L7,0),3) | W7: =ROUND(W6+IF(AND(E7=25,F7<>"ASTM A416"),L7,0),3) | X7: =ROUND(X6+IF(AND(E7=28,F7<>"ASTM A416"),L7,0),3) | Y7: =ROUND(Y6+IF(AND(E7=32,F7<>"ASTM A416"),L7,0),3) | Z7: =ROUND(Z6+IF(F7="ASTM A416",L7,0),3) | AA7: =IF(ROUNDUP(P7/20,0)>ROUNDUP(P6/20,0),"Lần " & ROUNDUP(P7/20,0),"") | AB7: =IF(ROUNDUP(Q7/20,0)>ROUNDUP(Q6/20,0),"Lần " & ROUNDUP(Q7/20,0),"") | AC7: =IF(ROUNDUP(R7/20,0)>ROUNDUP(R6/20,0),"Lần " & ROUNDUP(R7/20,0),"") | AD7: =IF(ROUNDUP(S7/20,0)>ROUNDUP(S6/20,0),"Lần " & ROUNDUP(S7/20,0),"") | AE7: =IF(ROUNDUP(T7/20,0)>ROUNDUP(T6/20,0),"Lần " & ROUNDUP(T7/20,0),"") | AF7: =IF(ROUNDUP(U7/20,0)>ROUNDUP(U6/20,0),"Lần " & ROUNDUP(U7/20,0),"") | AG7: =IF(ROUNDUP(V7/20,0)>ROUNDUP(V6/20,0),"Lần " & ROUNDUP(V7/20,0),"") | AH7: =IF(ROUNDUP(W7/20,0)>ROUNDUP(W6/20,0),"Lần " & ROUNDUP(W7/20,0),"") | ... AK7: =IF(ROUNDUP(Z7/20,0)>ROUNDUP(Z6/20,0),"Lần " & ROUNDUP(Z7/20,0),"") | AN7: Than | AO7: 50
A8: 5 | B8: Mố M1 | C8: Mố M1 (tr.31) | D8: A3 | E8: 16 | F8: CB400-V | H8: 13.437 | I8: 12 | J8: 1.578 | K8: =ROUND(H8*I8*J8, 2) | L8: =ROUND(K8/1000, 3) | M8: =IF(AO8="","",IF(INDEX(Theo_Doi_Tan_Suat_Be_Tong!$C:$C,AO8)="","",INDEX(Theo_Doi_Tan_Suat_Be_Tong!$C:$C,AO8)-VLOOKUP(AN8,$AQ$2:$AR$7,2,FALSE))) | O8: =IF(ROUNDUP(S8/20,0)>ROUNDUP(S7/20,0),"TN Ø16 (Lần " & ROUNDUP(S8/20,0) & ")","") | P8: =ROUND(P7+IF(AND(E8<=10,F8<>"ASTM A416"),L8,0),3) | Q8: =ROUND(Q7+IF(AND(E8=12,F8<>"ASTM A416"),L8,0),3) | R8: =ROUND(R7+IF(AND(E8=14,F8<>"ASTM A416"),L8,0),3) | S8: =ROUND(S7+IF(AND(E8=16,F8<>"ASTM A416"),L8,0),3) | T8: =ROUND(T7+IF(AND(E8=18,F8<>"ASTM A416"),L8,0),3) | U8: =ROUND(U7+IF(AND(E8=20,F8<>"ASTM A416"),L8,0),3) | V8: =ROUND(V7+IF(AND(E8=22,F8<>"ASTM A416"),L8,0),3) | W8: =ROUND(W7+IF(AND(E8=25,F8<>"ASTM A416"),L8,0),3) | X8: =ROUND(X7+IF(AND(E8=28,F8<>"ASTM A416"),L8,0),3) | Y8: =ROUND(Y7+IF(AND(E8=32,F8<>"ASTM A416"),L8,0),3) | Z8: =ROUND(Z7+IF(F8="ASTM A416",L8,0),3) | AA8: =IF(ROUNDUP(P8/20,0)>ROUNDUP(P7/20,0),"Lần " & ROUNDUP(P8/20,0),"") | AB8: =IF(ROUNDUP(Q8/20,0)>ROUNDUP(Q7/20,0),"Lần " & ROUNDUP(Q8/20,0),"") | AC8: =IF(ROUNDUP(R8/20,0)>ROUNDUP(R7/20,0),"Lần " & ROUNDUP(R8/20,0),"") | AD8: =IF(ROUNDUP(S8/20,0)>ROUNDUP(S7/20,0),"Lần " & ROUNDUP(S8/20,0),"") | AE8: =IF(ROUNDUP(T8/20,0)>ROUNDUP(T7/20,0),"Lần " & ROUNDUP(T8/20,0),"") | AF8: =IF(ROUNDUP(U8/20,0)>ROUNDUP(U7/20,0),"Lần " & ROUNDUP(U8/20,0),"") | AG8: =IF(ROUNDUP(V8/20,0)>ROUNDUP(V7/20,0),"Lần " & ROUNDUP(V8/20,0),"") | AH8: =IF(ROUNDUP(W8/20,0)>ROUNDUP(W7/20,0),"Lần " & ROUNDUP(W8/20,0),"") | ... AK8: =IF(ROUNDUP(Z8/20,0)>ROUNDUP(Z7/20,0),"Lần " & ROUNDUP(Z8/20,0),"") | AN8: Than | AO8: 50
A9: 6 | B9: Mố M1 | C9: Mố M1 (tr.31) | D9: A4 | E9: 28 | F9: CB400-V | H9: 14.216 | I9: 10 | J9: 4.834 | K9: =ROUND(H9*I9*J9, 2) | L9: =ROUND(K9/1000, 3) | M9: =IF(AO9="","",IF(INDEX(Theo_Doi_Tan_Suat_Be_Tong!$C:$C,AO9)="","",INDEX(Theo_Doi_Tan_Suat_Be_Tong!$C:$C,AO9)-VLOOKUP(AN9,$AQ$2:$AR$7,2,FALSE))) | O9: =IF(ROUNDUP(X9/20,0)>ROUNDUP(X8/20,0),"TN Ø28 (Lần " & ROUNDUP(X9/20,0) & ")","") | P9: =ROUND(P8+IF(AND(E9<=10,F9<>"ASTM A416"),L9,0),3) | Q9: =ROUND(Q8+IF(AND(E9=12,F9<>"ASTM A416"),L9,0),3) | R9: =ROUND(R8+IF(AND(E9=14,F9<>"ASTM A416"),L9,0),3) | S9: =ROUND(S8+IF(AND(E9=16,F9<>"ASTM A416"),L9,0),3) | T9: =ROUND(T8+IF(AND(E9=18,F9<>"ASTM A416"),L9,0),3) | U9: =ROUND(U8+IF(AND(E9=20,F9<>"ASTM A416"),L9,0),3) | V9: =ROUND(V8+IF(AND(E9=22,F9<>"ASTM A416"),L9,0),3) | W9: =ROUND(W8+IF(AND(E9=25,F9<>"ASTM A416"),L9,0),3) | X9: =ROUND(X8+IF(AND(E9=28,F9<>"ASTM A416"),L9,0),3) | Y9: =ROUND(Y8+IF(AND(E9=32,F9<>"ASTM A416"),L9,0),3) | Z9: =ROUND(Z8+IF(F9="ASTM A416",L9,0),3) | AA9: =IF(ROUNDUP(P9/20,0)>ROUNDUP(P8/20,0),"Lần " & ROUNDUP(P9/20,0),"") | AB9: =IF(ROUNDUP(Q9/20,0)>ROUNDUP(Q8/20,0),"Lần " & ROUNDUP(Q9/20,0),"") | AC9: =IF(ROUNDUP(R9/20,0)>ROUNDUP(R8/20,0),"Lần " & ROUNDUP(R9/20,0),"") | AD9: =IF(ROUNDUP(S9/20,0)>ROUNDUP(S8/20,0),"Lần " & ROUNDUP(S9/20,0),"") | AE9: =IF(ROUNDUP(T9/20,0)>ROUNDUP(T8/20,0),"Lần " & ROUNDUP(T9/20,0),"") | AF9: =IF(ROUNDUP(U9/20,0)>ROUNDUP(U8/20,0),"Lần " & ROUNDUP(U9/20,0),"") | AG9: =IF(ROUNDUP(V9/20,0)>ROUNDUP(V8/20,0),"Lần " & ROUNDUP(V9/20,0),"") | AH9: =IF(ROUNDUP(W9/20,0)>ROUNDUP(W8/20,0),"Lần " & ROUNDUP(W9/20,0),"") | ... AK9: =IF(ROUNDUP(Z9/20,0)>ROUNDUP(Z8/20,0),"Lần " & ROUNDUP(Z9/20,0),"") | AN9: Than | AO9: 50
A10: 7 | B10: Mố M1 | C10: Mố M1 (tr.31) | D10: A5(P) | E10: 16 | F10: CB400-V | H10: 2.282 | I10: 10 | J10: 1.578 | K10: =ROUND(H10*I10*J10, 2) | L10: =ROUND(K10/1000, 3) | M10: =IF(AO10="","",IF(INDEX(Theo_Doi_Tan_Suat_Be_Tong!$C:$C,AO10)="","",INDEX(Theo_Doi_Tan_Suat_Be_Tong!$C:$C,AO10)-VLOOKUP(AN10,$AQ$2:$AR$7,2,FALSE))) | O10: =IF(ROUNDUP(S10/20,0)>ROUNDUP(S9/20,0),"TN Ø16 (Lần " & ROUNDUP(S10/20,0) & ")","") | P10: =ROUND(P9+IF(AND(E10<=10,F10<>"ASTM A416"),L10,0),3) | Q10: =ROUND(Q9+IF(AND(E10=12,F10<>"ASTM A416"),L10,0),3) | R10: =ROUND(R9+IF(AND(E10=14,F10<>"ASTM A416"),L10,0),3) | S10: =ROUND(S9+IF(AND(E10=16,F10<>"ASTM A416"),L10,0),3) | T10: =ROUND(T9+IF(AND(E10=18,F10<>"ASTM A416"),L10,0),3) | U10: =ROUND(U9+IF(AND(E10=20,F10<>"ASTM A416"),L10,0),3) | V10: =ROUND(V9+IF(AND(E10=22,F10<>"ASTM A416"),L10,0),3) | W10: =ROUND(W9+IF(AND(E10=25,F10<>"ASTM A416"),L10,0),3) | X10: =ROUND(X9+IF(AND(E10=28,F10<>"ASTM A416"),L10,0),3) | Y10: =ROUND(Y9+IF(AND(E10=32,F10<>"ASTM A416"),L10,0),3) | Z10: =ROUND(Z9+IF(F10="ASTM A416",L10,0),3) | AA10: =IF(ROUNDUP(P10/20,0)>ROUNDUP(P9/20,0),"Lần " & ROUNDUP(P10/20,0),"") | AB10: =IF(ROUNDUP(Q10/20,0)>ROUNDUP(Q9/20,0),"Lần " & ROUNDUP(Q10/20,0),"") | AC10: =IF(ROUNDUP(R10/20,0)>ROUNDUP(R9/20,0),"Lần " & ROUNDUP(R10/20,0),"") | AD10: =IF(ROUNDUP(S10/20,0)>ROUNDUP(S9/20,0),"Lần " & ROUNDUP(S10/20,0),"") | AE10: =IF(ROUNDUP(T10/20,0)>ROUNDUP(T9/20,0),"Lần " & ROUNDUP(T10/20,0),"") | AF10: =IF(ROUNDUP(U10/20,0)>ROUNDUP(U9/20,0),"Lần " & ROUNDUP(U10/20,0),"") | AG10: =IF(ROUNDUP(V10/20,0)>ROUNDUP(V9/20,0),"Lần " & ROUNDUP(V10/20,0),"") | AH10: =IF(ROUNDUP(W10/20,0)>ROUNDUP(W9/20,0),"Lần " & ROUNDUP(W10/20,0),"") | ... AK10: =IF(ROUNDUP(Z10/20,0)>ROUNDUP(Z9/20,0),"Lần " & ROUNDUP(Z10/20,0),"") | AN10: Than | AO10: 50
A11: 8 | B11: Mố M1 | C11: Mố M1 (tr.31) | D11: A5（T) | E11: 16 | F11: CB400-V | H11: 2.032 | I11: 10 | J11: 1.578 | K11: =ROUND(H11*I11*J11, 2) | L11: =ROUND(K11/1000, 3) | M11: =IF(AO11="","",IF(INDEX(Theo_Doi_Tan_Suat_Be_Tong!$C:$C,AO11)="","",INDEX(Theo_Doi_Tan_Suat_Be_Tong!$C:$C,AO11)-VLOOKUP(AN11,$AQ$2:$AR$7,2,FALSE))) | O11: =IF(ROUNDUP(S11/20,0)>ROUNDUP(S10/20,0),"TN Ø16 (Lần " & ROUNDUP(S11/20,0) & ")","") | P11: =ROUND(P10+IF(AND(E11<=10,F11<>"ASTM A416"),L11,0),3) | Q11: =ROUND(Q10+IF(AND(E11=12,F11<>"ASTM A416"),L11,0),3) | R11: =ROUND(R10+IF(AND(E11=14,F11<>"ASTM A416"),L11,0),3) | S11: =ROUND(S10+IF(AND(E11=16,F11<>"ASTM A416"),L11,0),3) | T11: =ROUND(T10+IF(AND(E11=18,F11<>"ASTM A416"),L11,0),3) | U11: =ROUND(U10+IF(AND(E11=20,F11<>"ASTM A416"),L11,0),3) | V11: =ROUND(V10+IF(AND(E11=22,F11<>"ASTM A416"),L11,0),3) | W11: =ROUND(W10+IF(AND(E11=25,F11<>"ASTM A416"),L11,0),3) | X11: =ROUND(X10+IF(AND(E11=28,F11<>"ASTM A416"),L11,0),3) | Y11: =ROUND(Y10+IF(AND(E11=32,F11<>"ASTM A416"),L11,0),3) | Z11: =ROUND(Z10+IF(F11="ASTM A416",L11,0),3) | AA11: =IF(ROUNDUP(P11/20,0)>ROUNDUP(P10/20,0),"Lần " & ROUNDUP(P11/20,0),"") | AB11: =IF(ROUNDUP(Q11/20,0)>ROUNDUP(Q10/20,0),"Lần " & ROUNDUP(Q11/20,0),"") | AC11: =IF(ROUNDUP(R11/20,0)>ROUNDUP(R10/20,0),"Lần " & ROUNDUP(R11/20,0),"") | AD11: =IF(ROUNDUP(S11/20,0)>ROUNDUP(S10/20,0),"Lần " & ROUNDUP(S11/20,0),"") | AE11: =IF(ROUNDUP(T11/20,0)>ROUNDUP(T10/20,0),"Lần " & ROUNDUP(T11/20,0),"") | AF11: =IF(ROUNDUP(U11/20,0)>ROUNDUP(U10/20,0),"Lần " & ROUNDUP(U11/20,0),"") | AG11: =IF(ROUNDUP(V11/20,0)>ROUNDUP(V10/20,0),"Lần " & ROUNDUP(V11/20,0),"") | AH11: =IF(ROUNDUP(W11/20,0)>ROUNDUP(W10/20,0),"Lần " & ROUNDUP(W11/20,0),"") | ... AK11: =IF(ROUNDUP(Z11/20,0)>ROUNDUP(Z10/20,0),"Lần " & ROUNDUP(Z11/20,0),"") | AN11: Than | AO11: 50
A12: 9 | B12: Mố M1 | C12: Mố M1 (tr.31) | D12: P1 | E12: 16 | F12: CB400-V | H12: 13.437 | I12: 30 | J12: 1.578 | K12: =ROUND(H12*I12*J12, 2) | L12: =ROUND(K12/1000, 3) | M12: =IF(AO12="","",IF(INDEX(Theo_Doi_Tan_Suat_Be_Tong!$C:$C,AO12)="","",INDEX(Theo_Doi_Tan_Suat_Be_Tong!$C:$C,AO12)-VLOOKUP(AN12,$AQ$2:$AR$7,2,FALSE))) | O12: =IF(ROUNDUP(S12/20,0)>ROUNDUP(S11/20,0),"TN Ø16 (Lần " & ROUNDUP(S12/20,0) & ")","") | P12: =ROUND(P11+IF(AND(E12<=10,F12<>"ASTM A416"),L12,0),3) | Q12: =ROUND(Q11+IF(AND(E12=12,F12<>"ASTM A416"),L12,0),3) | R12: =ROUND(R11+IF(AND(E12=14,F12<>"ASTM A416"),L12,0),3) | S12: =ROUND(S11+IF(AND(E12=16,F12<>"ASTM A416"),L12,0),3) | T12: =ROUND(T11+IF(AND(E12=18,F12<>"ASTM A416"),L12,0),3) | U12: =ROUND(U11+IF(AND(E12=20,F12<>"ASTM A416"),L12,0),3) | V12: =ROUND(V11+IF(AND(E12=22,F12<>"ASTM A416"),L12,0),3) | W12: =ROUND(W11+IF(AND(E12=25,F12<>"ASTM A416"),L12,0),3) | X12: =ROUND(X11+IF(AND(E12=28,F12<>"ASTM A416"),L12,0),3) | Y12: =ROUND(Y11+IF(AND(E12=32,F12<>"ASTM A416"),L12,0),3) | Z12: =ROUND(Z11+IF(F12="ASTM A416",L12,0),3) | AA12: =IF(ROUNDUP(P12/20,0)>ROUNDUP(P11/20,0),"Lần " & ROUNDUP(P12/20,0),"") | AB12: =IF(ROUNDUP(Q12/20,0)>ROUNDUP(Q11/20,0),"Lần " & ROUNDUP(Q12/20,0),"") | AC12: =IF(ROUNDUP(R12/20,0)>ROUNDUP(R11/20,0),"Lần " & ROUNDUP(R12/20,0),"") | AD12: =IF(ROUNDUP(S12/20,0)>ROUNDUP(S11/20,0),"Lần " & ROUNDUP(S12/20,0),"") | AE12: =IF(ROUNDUP(T12/20,0)>ROUNDUP(T11/20,0),"Lần " & ROUNDUP(T12/20,0),"") | AF12: =IF(ROUNDUP(U12/20,0)>ROUNDUP(U11/20,0),"Lần " & ROUNDUP(U12/20,0),"") | AG12: =IF(ROUNDUP(V12/20,0)>ROUNDUP(V11/20,0),"Lần " & ROUNDUP(V12/20,0),"") | AH12: =IF(ROUNDUP(W12/20,0)>ROUNDUP(W11/20,0),"Lần " & ROUNDUP(W12/20,0),"") | ... AK12: =IF(ROUNDUP(Z12/20,0)>ROUNDUP(Z11/20,0),"Lần " & ROUNDUP(Z12/20,0),"") | AN12: Than | AO12: 50
A13: 10 | B13: Mố M1 | C13: Mố M1 (tr.31) | D13: PIA | E13: 16 | F13: CB400-V | H13: 13.44 | I13: 2 | J13: 1.578 | K13: =ROUND(H13*I13*J13, 2) | L13: =ROUND(K13/1000, 3) | M13: =IF(AO13="","",IF(INDEX(Theo_Doi_Tan_Suat_Be_Tong!$C:$C,AO13)="","",INDEX(Theo_Doi_Tan_Suat_Be_Tong!$C:$C,AO13)-VLOOKUP(AN13,$AQ$2:$AR$7,2,FALSE))) | O13: =IF(ROUNDUP(S13/20,0)>ROUNDUP(S12/20,0),"TN Ø16 (Lần " & ROUNDUP(S13/20,0) & ")","") | P13: =ROUND(P12+IF(AND(E13<=10,F13<>"ASTM A416"),L13,0),3) | Q13: =ROUND(Q12+IF(AND(E13=12,F13<>"ASTM A416"),L13,0),3) | R13: =ROUND(R12+IF(AND(E13=14,F13<>"ASTM A416"),L13,0),3) | S13: =ROUND(S12+IF(AND(E13=16,F13<>"ASTM A416"),L13,0),3) | T13: =ROUND(T12+IF(AND(E13=18,F13<>"ASTM A416"),L13,0),3) | U13: =ROUND(U12+IF(AND(E13=20,F13<>"ASTM A416"),L13,0),3) | V13: =ROUND(V12+IF(AND(E13=22,F13<>"ASTM A416"),L13,0),3) | W13: =ROUND(W12+IF(AND(E13=25,F13<>"ASTM A416"),L13,0),3) | X13: =ROUND(X12+IF(AND(E13=28,F13<>"ASTM A416"),L13,0),3) | Y13: =ROUND(Y12+IF(AND(E13=32,F13<>"ASTM A416"),L13,0),3) | Z13: =ROUND(Z12+IF(F13="ASTM A416",L13,0),3) | AA13: =IF(ROUNDUP(P13/20,0)>ROUNDUP(P12/20,0),"Lần " & ROUNDUP(P13/20,0),"") | AB13: =IF(ROUNDUP(Q13/20,0)>ROUNDUP(Q12/20,0),"Lần " & ROUNDUP(Q13/20,0),"") | AC13: =IF(ROUNDUP(R13/20,0)>ROUNDUP(R12/20,0),"Lần " & ROUNDUP(R13/20,0),"") | AD13: =IF(ROUNDUP(S13/20,0)>ROUNDUP(S12/20,0),"Lần " & ROUNDUP(S13/20,0),"") | AE13: =IF(ROUNDUP(T13/20,0)>ROUNDUP(T12/20,0),"Lần " & ROUNDUP(T13/20,0),"") | AF13: =IF(ROUNDUP(U13/20,0)>ROUNDUP(U12/20,0),"Lần " & ROUNDUP(U13/20,0),"") | AG13: =IF(ROUNDUP(V13/20,0)>ROUNDUP(V12/20,0),"Lần " & ROUNDUP(V13/20,0),"") | AH13: =IF(ROUNDUP(W13/20,0)>ROUNDUP(W12/20,0),"Lần " & ROUNDUP(W13/20,0),"") | ... AK13: =IF(ROUNDUP(Z13/20,0)>ROUNDUP(Z12/20,0),"Lần " & ROUNDUP(Z13/20,0),"") | AN13: Than | AO13: 50
A14: 11 | B14: Mố M1 | C14: Mố M1 (tr.31) | D14: P1B | E14: 16 | F14: CB400-V | H14: 10.084 | I14: 2 | J14: 1.578 | K14: =ROUND(H14*I14*J14, 2) | L14: =ROUND(K14/1000, 3) | M14: =IF(AO14="","",IF(INDEX(Theo_Doi_Tan_Suat_Be_Tong!$C:$C,AO14)="","",INDEX(Theo_Doi_Tan_Suat_Be_Tong!$C:$C,AO14)-VLOOKUP(AN14,$AQ$2:$AR$7,2,FALSE))) | O14: =IF(ROUNDUP(S14/20,0)>ROUNDUP(S13/20,0),"TN Ø16 (Lần " & ROUNDUP(S14/20,0) & ")","") | P14: =ROUND(P13+IF(AND(E14<=10,F14<>"ASTM A416"),L14,0),3) | Q14: =ROUND(Q13+IF(AND(E14=12,F14<>"ASTM A416"),L14,0),3) | R14: =ROUND(R13+IF(AND(E14=14,F14<>"ASTM A416"),L14,0),3) | S14: =ROUND(S13+IF(AND(E14=16,F14<>"ASTM A416"),L14,0),3) | T14: =ROUND(T13+IF(AND(E14=18,F14<>"ASTM A416"),L14,0),3) | U14: =ROUND(U13+IF(AND(E14=20,F14<>"ASTM A416"),L14,0),3) | V14: =ROUND(V13+IF(AND(E14=22,F14<>"ASTM A416"),L14,0),3) | W14: =ROUND(W13+IF(AND(E14=25,F14<>"ASTM A416"),L14,0),3) | X14: =ROUND(X13+IF(AND(E14=28,F14<>"ASTM A416"),L14,0),3) | Y14: =ROUND(Y13+IF(AND(E14=32,F14<>"ASTM A416"),L14,0),3) | Z14: =ROUND(Z13+IF(F14="ASTM A416",L14,0),3) | AA14: =IF(ROUNDUP(P14/20,0)>ROUNDUP(P13/20,0),"Lần " & ROUNDUP(P14/20,0),"") | AB14: =IF(ROUNDUP(Q14/20,0)>ROUNDUP(Q13/20,0),"Lần " & ROUNDUP(Q14/20,0),"") | AC14: =IF(ROUNDUP(R14/20,0)>ROUNDUP(R13/20,0),"Lần " & ROUNDUP(R14/20,0),"") | AD14: =IF(ROUNDUP(S14/20,0)>ROUNDUP(S13/20,0),"Lần " & ROUNDUP(S14/20,0),"") | AE14: =IF(ROUNDUP(T14/20,0)>ROUNDUP(T13/20,0),"Lần " & ROUNDUP(T14/20,0),"") | AF14: =IF(ROUNDUP(U14/20,0)>ROUNDUP(U13/20,0),"Lần " & ROUNDUP(U14/20,0),"") | AG14: =IF(ROUNDUP(V14/20,0)>ROUNDUP(V13/20,0),"Lần " & ROUNDUP(V14/20,0),"") | AH14: =IF(ROUNDUP(W14/20,0)>ROUNDUP(W13/20,0),"Lần " & ROUNDUP(W14/20,0),"") | ... AK14: =IF(ROUNDUP(Z14/20,0)>ROUNDUP(Z13/20,0),"Lần " & ROUNDUP(Z14/20,0),"") | AN14: Than | AO14: 50
A15: 12 | B15: Mố M1 | C15: Mố M1 (tr.31) | D15: P2 | E15: 16 | F15: CB400-V | H15: 5.504 | I15: 83 | J15: 1.578 | K15: =ROUND(H15*I15*J15, 2) | L15: =ROUND(K15/1000, 3) | M15: =IF(AO15="","",IF(INDEX(Theo_Doi_Tan_Suat_Be_Tong!$C:$C,AO15)="","",INDEX(Theo_Doi_Tan_Suat_Be_Tong!$C:$C,AO15)-VLOOKUP(AN15,$AQ$2:$AR$7,2,FALSE))) | O15: =IF(ROUNDUP(S15/20,0)>ROUNDUP(S14/20,0),"TN Ø16 (Lần " & ROUNDUP(S15/20,0) & ")","") | P15: =ROUND(P14+IF(AND(E15<=10,F15<>"ASTM A416"),L15,0),3) | Q15: =ROUND(Q14+IF(AND(E15=12,F15<>"ASTM A416"),L15,0),3) | R15: =ROUND(R14+IF(AND(E15=14,F15<>"ASTM A416"),L15,0),3) | S15: =ROUND(S14+IF(AND(E15=16,F15<>"ASTM A416"),L15,0),3) | T15: =ROUND(T14+IF(AND(E15=18,F15<>"ASTM A416"),L15,0),3) | U15: =ROUND(U14+IF(AND(E15=20,F15<>"ASTM A416"),L15,0),3) | V15: =ROUND(V14+IF(AND(E15=22,F15<>"ASTM A416"),L15,0),3) | W15: =ROUND(W14+IF(AND(E15=25,F15<>"ASTM A416"),L15,0),3) | X15: =ROUND(X14+IF(AND(E15=28,F15<>"ASTM A416"),L15,0),3) | Y15: =ROUND(Y14+IF(AND(E15=32,F15<>"ASTM A416"),L15,0),3) | Z15: =ROUND(Z14+IF(F15="ASTM A416",L15,0),3) | AA15: =IF(ROUNDUP(P15/20,0)>ROUNDUP(P14/20,0),"Lần " & ROUNDUP(P15/20,0),"") | AB15: =IF(ROUNDUP(Q15/20,0)>ROUNDUP(Q14/20,0),"Lần " & ROUNDUP(Q15/20,0),"") | AC15: =IF(ROUNDUP(R15/20,0)>ROUNDUP(R14/20,0),"Lần " & ROUNDUP(R15/20,0),"") | AD15: =IF(ROUNDUP(S15/20,0)>ROUNDUP(S14/20,0),"Lần " & ROUNDUP(S15/20,0),"") | AE15: =IF(ROUNDUP(T15/20,0)>ROUNDUP(T14/20,0),"Lần " & ROUNDUP(T15/20,0),"") | AF15: =IF(ROUNDUP(U15/20,0)>ROUNDUP(U14/20,0),"Lần " & ROUNDUP(U15/20,0),"") | AG15: =IF(ROUNDUP(V15/20,0)>ROUNDUP(V14/20,0),"Lần " & ROUNDUP(V15/20,0),"") | AH15: =IF(ROUNDUP(W15/20,0)>ROUNDUP(W14/20,0),"Lần " & ROUNDUP(W15/20,0),"") | ... AK15: =IF(ROUNDUP(Z15/20,0)>ROUNDUP(Z14/20,0),"Lần " & ROUNDUP(Z15/20,0),"") | AN15: Than | AO15: 50
A16: 13 | B16: Mố M1 | C16: Mố M1 (tr.31) | D16: P3 | E16: 16 | F16: CB400-V | G16: S57 | H16: 2.071 | I16: 77 | J16: 1.578 | K16: =ROUND(H16*I16*J16, 2) | L16: =ROUND(K16/1000, 3) | M16: =IF(AO16="","",IF(INDEX(Theo_Doi_Tan_Suat_Be_Tong!$C:$C,AO16)="","",INDEX(Theo_Doi_Tan_Suat_Be_Tong!$C:$C,AO16)-VLOOKUP(AN16,$AQ$2:$AR$7,2,FALSE))) | O16: =IF(ROUNDUP(S16/20,0)>ROUNDUP(S15/20,0),"TN Ø16 (Lần " & ROUNDUP(S16/20,0) & ")","") | P16: =ROUND(P15+IF(AND(E16<=10,F16<>"ASTM A416"),L16,0),3) | Q16: =ROUND(Q15+IF(AND(E16=12,F16<>"ASTM A416"),L16,0),3) | R16: =ROUND(R15+IF(AND(E16=14,F16<>"ASTM A416"),L16,0),3) | S16: =ROUND(S15+IF(AND(E16=16,F16<>"ASTM A416"),L16,0),3) | T16: =ROUND(T15+IF(AND(E16=18,F16<>"ASTM A416"),L16,0),3) | U16: =ROUND(U15+IF(AND(E16=20,F16<>"ASTM A416"),L16,0),3) | V16: =ROUND(V15+IF(AND(E16=22,F16<>"ASTM A416"),L16,0),3) | W16: =ROUND(W15+IF(AND(E16=25,F16<>"ASTM A416"),L16,0),3) | X16: =ROUND(X15+IF(AND(E16=28,F16<>"ASTM A416"),L16,0),3) | Y16: =ROUND(Y15+IF(AND(E16=32,F16<>"ASTM A416"),L16,0),3) | Z16: =ROUND(Z15+IF(F16="ASTM A416",L16,0),3) | AA16: =IF(ROUNDUP(P16/20,0)>ROUNDUP(P15/20,0),"Lần " & ROUNDUP(P16/20,0),"") | AB16: =IF(ROUNDUP(Q16/20,0)>ROUNDUP(Q15/20,0),"Lần " & ROUNDUP(Q16/20,0),"") | AC16: =IF(ROUNDUP(R16/20,0)>ROUNDUP(R15/20,0),"Lần " & ROUNDUP(R16/20,0),"") | AD16: =IF(ROUNDUP(S16/20,0)>ROUNDUP(S15/20,0),"Lần " & ROUNDUP(S16/20,0),"") | AE16: =IF(ROUNDUP(T16/20,0)>ROUNDUP(T15/20,0),"Lần " & ROUNDUP(T16/20,0),"") | AF16: =IF(ROUNDUP(U16/20,0)>ROUNDUP(U15/20,0),"Lần " & ROUNDUP(U16/20,0),"") | AG16: =IF(ROUNDUP(V16/20,0)>ROUNDUP(V15/20,0),"Lần " & ROUNDUP(V16/20,0),"") | AH16: =IF(ROUNDUP(W16/20,0)>ROUNDUP(W15/20,0),"Lần " & ROUNDUP(W16/20,0),"") | ... AK16: =IF(ROUNDUP(Z16/20,0)>ROUNDUP(Z15/20,0),"Lần " & ROUNDUP(Z16/20,0),"") | AN16: Than | AO16: 50
A17: 14 | B17: Mố M1 | C17: Mố M1 (tr.31) | D17: P4 | E17: 12 | F17: CB400-V | H17: 0.555 | I17: 95 | J17: 0.888 | K17: =ROUND(H17*I17*J17, 2) | L17: =ROUND(K17/1000, 3) | M17: =IF(AO17="","",IF(INDEX(Theo_Doi_Tan_Suat_Be_Tong!$C:$C,AO17)="","",INDEX(Theo_Doi_Tan_Suat_Be_Tong!$C:$C,AO17)-VLOOKUP(AN17,$AQ$2:$AR$7,2,FALSE))) | O17: =IF(ROUNDUP(Q17/20,0)>ROUNDUP(Q16/20,0),"TN Ø12 (Lần " & ROUNDUP(Q17/20,0) & ")","") | P17: =ROUND(P16+IF(AND(E17<=10,F17<>"ASTM A416"),L17,0),3) | Q17: =ROUND(Q16+IF(AND(E17=12,F17<>"ASTM A416"),L17,0),3) | R17: =ROUND(R16+IF(AND(E17=14,F17<>"ASTM A416"),L17,0),3) | S17: =ROUND(S16+IF(AND(E17=16,F17<>"ASTM A416"),L17,0),3) | T17: =ROUND(T16+IF(AND(E17=18,F17<>"ASTM A416"),L17,0),3) | U17: =ROUND(U16+IF(AND(E17=20,F17<>"ASTM A416"),L17,0),3) | V17: =ROUND(V16+IF(AND(E17=22,F17<>"ASTM A416"),L17,0),3) | W17: =ROUND(W16+IF(AND(E17=25,F17<>"ASTM A416"),L17,0),3) | X17: =ROUND(X16+IF(AND(E17=28,F17<>"ASTM A416"),L17,0),3) | Y17: =ROUND(Y16+IF(AND(E17=32,F17<>"ASTM A416"),L17,0),3) | Z17: =ROUND(Z16+IF(F17="ASTM A416",L17,0),3) | AA17: =IF(ROUNDUP(P17/20,0)>ROUNDUP(P16/20,0),"Lần " & ROUNDUP(P17/20,0),"") | AB17: =IF(ROUNDUP(Q17/20,0)>ROUNDUP(Q16/20,0),"Lần " & ROUNDUP(Q17/20,0),"") | AC17: =IF(ROUNDUP(R17/20,0)>ROUNDUP(R16/20,0),"Lần " & ROUNDUP(R17/20,0),"") | AD17: =IF(ROUNDUP(S17/20,0)>ROUNDUP(S16/20,0),"Lần " & ROUNDUP(S17/20,0),"") | AE17: =IF(ROUNDUP(T17/20,0)>ROUNDUP(T16/20,0),"Lần " & ROUNDUP(T17/20,0),"") | AF17: =IF(ROUNDUP(U17/20,0)>ROUNDUP(U16/20,0),"Lần " & ROUNDUP(U17/20,0),"") | AG17: =IF(ROUNDUP(V17/20,0)>ROUNDUP(V16/20,0),"Lần " & ROUNDUP(V17/20,0),"") | AH17: =IF(ROUNDUP(W17/20,0)>ROUNDUP(W16/20,0),"Lần " & ROUNDUP(W17/20,0),"") | ... AK17: =IF(ROUNDUP(Z17/20,0)>ROUNDUP(Z16/20,0),"Lần " & ROUNDUP(Z17/20,0),"") | AN17: Than | AO17: 50
A18: 15 | B18: Mố M1 | C18: Mố M1 (tr.31) | D18: H1 | E18: 25 | F18: CB240-T | G18: S05 | H18: 1.07 | I18: 23 | J18: 3.853 | K18: =ROUND(H18*I18*J18, 2) | L18: =ROUND(K18/1000, 3) | M18: =IF(AO18="","",IF(INDEX(Theo_Doi_Tan_Suat_Be_Tong!$C:$C,AO18)="","",INDEX(Theo_Doi_Tan_Suat_Be_Tong!$C:$C,AO18)-VLOOKUP(AN18,$AQ$2:$AR$7,2,FALSE))) | O18: =IF(ROUNDUP(W18/20,0)>ROUNDUP(W17/20,0),"TN Ø25 (Lần " & ROUNDUP(W18/20,0) & ")","") | P18: =ROUND(P17+IF(AND(E18<=10,F18<>"ASTM A416"),L18,0),3) | Q18: =ROUND(Q17+IF(AND(E18=12,F18<>"ASTM A416"),L18,0),3) | R18: =ROUND(R17+IF(AND(E18=14,F18<>"ASTM A416"),L18,0),3) | S18: =ROUND(S17+IF(AND(E18=16,F18<>"ASTM A416"),L18,0),3) | T18: =ROUND(T17+IF(AND(E18=18,F18<>"ASTM A416"),L18,0),3) | U18: =ROUND(U17+IF(AND(E18=20,F18<>"ASTM A416"),L18,0),3) | V18: =ROUND(V17+IF(AND(E18=22,F18<>"ASTM A416"),L18,0),3) | W18: =ROUND(W17+IF(AND(E18=25,F18<>"ASTM A416"),L18,0),3) | X18: =ROUND(X17+IF(AND(E18=28,F18<>"ASTM A416"),L18,0),3) | Y18: =ROUND(Y17+IF(AND(E18=32,F18<>"ASTM A416"),L18,0),3) | Z18: =ROUND(Z17+IF(F18="ASTM A416",L18,0),3) | AA18: =IF(ROUNDUP(P18/20,0)>ROUNDUP(P17/20,0),"Lần " & ROUNDUP(P18/20,0),"") | AB18: =IF(ROUNDUP(Q18/20,0)>ROUNDUP(Q17/20,0),"Lần " & ROUNDUP(Q18/20,0),"") | AC18: =IF(ROUNDUP(R18/20,0)>ROUNDUP(R17/20,0),"Lần " & ROUNDUP(R18/20,0),"") | AD18: =IF(ROUNDUP(S18/20,0)>ROUNDUP(S17/20,0),"Lần " & ROUNDUP(S18/20,0),"") | AE18: =IF(ROUNDUP(T18/20,0)>ROUNDUP(T17/20,0),"Lần " & ROUNDUP(T18/20,0),"") | AF18: =IF(ROUNDUP(U18/20,0)>ROUNDUP(U17/20,0),"Lần " & ROUNDUP(U18/20,0),"") | AG18: =IF(ROUNDUP(V18/20,0)>ROUNDUP(V17/20,0),"Lần " & ROUNDUP(V18/20,0),"") | AH18: =IF(ROUNDUP(W18/20,0)>ROUNDUP(W17/20,0),"Lần " & ROUNDUP(W18/20,0),"") | ... AK18: =IF(ROUNDUP(Z18/20,0)>ROUNDUP(Z17/20,0),"Lần " & ROUNDUP(Z18/20,0),"") | AN18: Than | AO18: 50
A19: 16 | B19: Mố M1 | C19: Mố M1 (tr.31) | D19: H2 | E19: 8 | F19: CB240-T | G19: S32 | H19: 2.132 | I19: 23 | J19: 0.395 | K19: =ROUND(H19*I19*J19, 2) | L19: =ROUND(K19/1000, 3) | M19: =IF(AO19="","",IF(INDEX(Theo_Doi_Tan_Suat_Be_Tong!$C:$C,AO19)="","",INDEX(Theo_Doi_Tan_Suat_Be_Tong!$C:$C,AO19)-VLOOKUP(AN19,$AQ$2:$AR$7,2,FALSE))) | O19: =IF(ROUNDUP(P19/20,0)>ROUNDUP(P18/20,0),"TN Ø10 (Lần " & ROUNDUP(P19/20,0) & ")","") | P19: =ROUND(P18+IF(AND(E19<=10,F19<>"ASTM A416"),L19,0),3) | Q19: =ROUND(Q18+IF(AND(E19=12,F19<>"ASTM A416"),L19,0),3) | R19: =ROUND(R18+IF(AND(E19=14,F19<>"ASTM A416"),L19,0),3) | S19: =ROUND(S18+IF(AND(E19=16,F19<>"ASTM A416"),L19,0),3) | T19: =ROUND(T18+IF(AND(E19=18,F19<>"ASTM A416"),L19,0),3) | U19: =ROUND(U18+IF(AND(E19=20,F19<>"ASTM A416"),L19,0),3) | V19: =ROUND(V18+IF(AND(E19=22,F19<>"ASTM A416"),L19,0),3) | W19: =ROUND(W18+IF(AND(E19=25,F19<>"ASTM A416"),L19,0),3) | X19: =ROUND(X18+IF(AND(E19=28,F19<>"ASTM A416"),L19,0),3) | Y19: =ROUND(Y18+IF(AND(E19=32,F19<>"ASTM A416"),L19,0),3) | Z19: =ROUND(Z18+IF(F19="ASTM A416",L19,0),3) | AA19: =IF(ROUNDUP(P19/20,0)>ROUNDUP(P18/20,0),"Lần " & ROUNDUP(P19/20,0),"") | AB19: =IF(ROUNDUP(Q19/20,0)>ROUNDUP(Q18/20,0),"Lần " & ROUNDUP(Q19/20,0),"") | AC19: =IF(ROUNDUP(R19/20,0)>ROUNDUP(R18/20,0),"Lần " & ROUNDUP(R19/20,0),"") | AD19: =IF(ROUNDUP(S19/20,0)>ROUNDUP(S18/20,0),"Lần " & ROUNDUP(S19/20,0),"") | AE19: =IF(ROUNDUP(T19/20,0)>ROUNDUP(T18/20,0),"Lần " & ROUNDUP(T19/20,0),"") | AF19: =IF(ROUNDUP(U19/20,0)>ROUNDUP(U18/20,0),"Lần " & ROUNDUP(U19/20,0),"") | AG19: =IF(ROUNDUP(V19/20,0)>ROUNDUP(V18/20,0),"Lần " & ROUNDUP(V19/20,0),"") | AH19: =IF(ROUNDUP(W19/20,0)>ROUNDUP(W18/20,0),"Lần " & ROUNDUP(W19/20,0),"") | ... AK19: =IF(ROUNDUP(Z19/20,0)>ROUNDUP(Z18/20,0),"Lần " & ROUNDUP(Z19/20,0),"") | AN19: Than | AO19: 50
A20: 17 | B20: Mố M1 | C20: Mố M1 (tr.31) | D20: W1A(T) | E20: 16 | F20: CB400-V | H20: 3.436 | I20: 12 | J20: 1.578 | K20: =ROUND(H20*I20*J20, 2) | L20: =ROUND(K20/1000, 3) | M20: =IF(AO20="","",IF(INDEX(Theo_Doi_Tan_Suat_Be_Tong!$C:$C,AO20)="","",INDEX(Theo_Doi_Tan_Suat_Be_Tong!$C:$C,AO20)-VLOOKUP(AN20,$AQ$2:$AR$7,2,FALSE))) | O20: =IF(ROUNDUP(S20/20,0)>ROUNDUP(S19/20,0),"TN Ø16 (Lần " & ROUNDUP(S20/20,0) & ")","") | P20: =ROUND(P19+IF(AND(E20<=10,F20<>"ASTM A416"),L20,0),3) | Q20: =ROUND(Q19+IF(AND(E20=12,F20<>"ASTM A416"),L20,0),3) | R20: =ROUND(R19+IF(AND(E20=14,F20<>"ASTM A416"),L20,0),3) | S20: =ROUND(S19+IF(AND(E20=16,F20<>"ASTM A416"),L20,0),3) | T20: =ROUND(T19+IF(AND(E20=18,F20<>"ASTM A416"),L20,0),3) | U20: =ROUND(U19+IF(AND(E20=20,F20<>"ASTM A416"),L20,0),3) | V20: =ROUND(V19+IF(AND(E20=22,F20<>"ASTM A416"),L20,0),3) | W20: =ROUND(W19+IF(AND(E20=25,F20<>"ASTM A416"),L20,0),3) | X20: =ROUND(X19+IF(AND(E20=28,F20<>"ASTM A416"),L20,0),3) | Y20: =ROUND(Y19+IF(AND(E20=32,F20<>"ASTM A416"),L20,0),3) | Z20: =ROUND(Z19+IF(F20="ASTM A416",L20,0),3) | AA20: =IF(ROUNDUP(P20/20,0)>ROUNDUP(P19/20,0),"Lần " & ROUNDUP(P20/20,0),"") | AB20: =IF(ROUNDUP(Q20/20,0)>ROUNDUP(Q19/20,0),"Lần " & ROUNDUP(Q20/20,0),"") | AC20: =IF(ROUNDUP(R20/20,0)>ROUNDUP(R19/20,0),"Lần " & ROUNDUP(R20/20,0),"") | AD20: =IF(ROUNDUP(S20/20,0)>ROUNDUP(S19/20,0),"Lần " & ROUNDUP(S20/20,0),"") | AE20: =IF(ROUNDUP(T20/20,0)>ROUNDUP(T19/20,0),"Lần " & ROUNDUP(T20/20,0),"") | AF20: =IF(ROUNDUP(U20/20,0)>ROUNDUP(U19/20,0),"Lần " & ROUNDUP(U20/20,0),"") | AG20: =IF(ROUNDUP(V20/20,0)>ROUNDUP(V19/20,0),"Lần " & ROUNDUP(V20/20,0),"") | AH20: =IF(ROUNDUP(W20/20,0)>ROUNDUP(W19/20,0),"Lần " & ROUNDUP(W20/20,0),"") | ... AK20: =IF(ROUNDUP(Z20/20,0)>ROUNDUP(Z19/20,0),"Lần " & ROUNDUP(Z20/20,0),"") | AN20: Than | AO20: 50
